2016-03-14 00:07:09,852 INFO org.apache.hadoop.yarn.server.resourcemanager.ResourceManager: STARTUP_MSG: 
/************************************************************
STARTUP_MSG: Starting ResourceManager
STARTUP_MSG:   host = vishal-VirtualBox/127.0.1.1
STARTUP_MSG:   args = []
STARTUP_MSG:   version = 2.7.2
STARTUP_MSG:   build = https://git-wip-us.apache.org/repos/asf/hadoop.git -r b165c4fe8a74265c792ce23f546c64604acf0e41; compiled by 'jenkins' on 2016-01-26T00:08Z
STARTUP_MSG:   java = 1.8.0_74
************************************************************/
2016-03-14 00:07:09,870 INFO org.apache.hadoop.yarn.server.resourcemanager.ResourceManager: registered UNIX signal handlers for [TERM, HUP, INT]
2016-03-14 00:07:10,717 INFO org.apache.hadoop.conf.Configuration: found resource core-site.xml at file:/usr/local/hadoop/etc/hadoop/core-site.xml
2016-03-14 00:07:10,845 WARN org.apache.hadoop.util.NativeCodeLoader: Unable to load native-hadoop library for your platform... using builtin-java classes where applicable
2016-03-14 00:07:10,937 INFO org.apache.hadoop.security.Groups: clearing userToGroupsMap cache
2016-03-14 00:07:11,101 INFO org.apache.hadoop.conf.Configuration: found resource yarn-site.xml at file:/usr/local/hadoop/etc/hadoop/yarn-site.xml
2016-03-14 00:07:11,470 INFO org.apache.hadoop.yarn.event.AsyncDispatcher: Registering class org.apache.hadoop.yarn.server.resourcemanager.RMFatalEventType for class org.apache.hadoop.yarn.server.resourcemanager.ResourceManager$RMFatalEventDispatcher
2016-03-14 00:07:12,034 INFO org.apache.hadoop.yarn.server.resourcemanager.security.NMTokenSecretManagerInRM: NMTokenKeyRollingInterval: 86400000ms and NMTokenKeyActivationDelay: 900000ms
2016-03-14 00:07:12,043 INFO org.apache.hadoop.yarn.server.resourcemanager.security.RMContainerTokenSecretManager: ContainerTokenKeyRollingInterval: 86400000ms and ContainerTokenKeyActivationDelay: 900000ms
2016-03-14 00:07:12,060 INFO org.apache.hadoop.yarn.server.resourcemanager.security.AMRMTokenSecretManager: AMRMTokenKeyRollingInterval: 86400000ms and AMRMTokenKeyActivationDelay: 900000 ms
2016-03-14 00:07:12,143 INFO org.apache.hadoop.yarn.event.AsyncDispatcher: Registering class org.apache.hadoop.yarn.server.resourcemanager.recovery.RMStateStoreEventType for class org.apache.hadoop.yarn.server.resourcemanager.recovery.RMStateStore$ForwardingEventHandler
2016-03-14 00:07:12,149 INFO org.apache.hadoop.yarn.event.AsyncDispatcher: Registering class org.apache.hadoop.yarn.server.resourcemanager.NodesListManagerEventType for class org.apache.hadoop.yarn.server.resourcemanager.NodesListManager
2016-03-14 00:07:12,149 INFO org.apache.hadoop.yarn.server.resourcemanager.ResourceManager: Using Scheduler: org.apache.hadoop.yarn.server.resourcemanager.scheduler.capacity.CapacityScheduler
2016-03-14 00:07:12,182 INFO org.apache.hadoop.yarn.event.AsyncDispatcher: Registering class org.apache.hadoop.yarn.server.resourcemanager.scheduler.event.SchedulerEventType for class org.apache.hadoop.yarn.server.resourcemanager.ResourceManager$SchedulerEventDispatcher
2016-03-14 00:07:12,183 INFO org.apache.hadoop.yarn.event.AsyncDispatcher: Registering class org.apache.hadoop.yarn.server.resourcemanager.rmapp.RMAppEventType for class org.apache.hadoop.yarn.server.resourcemanager.ResourceManager$ApplicationEventDispatcher
2016-03-14 00:07:12,183 INFO org.apache.hadoop.yarn.event.AsyncDispatcher: Registering class org.apache.hadoop.yarn.server.resourcemanager.rmapp.attempt.RMAppAttemptEventType for class org.apache.hadoop.yarn.server.resourcemanager.ResourceManager$ApplicationAttemptEventDispatcher
2016-03-14 00:07:12,193 INFO org.apache.hadoop.yarn.event.AsyncDispatcher: Registering class org.apache.hadoop.yarn.server.resourcemanager.rmnode.RMNodeEventType for class org.apache.hadoop.yarn.server.resourcemanager.ResourceManager$NodeEventDispatcher
2016-03-14 00:07:12,324 INFO org.apache.hadoop.metrics2.impl.MetricsConfig: loaded properties from hadoop-metrics2.properties
2016-03-14 00:07:12,472 INFO org.apache.hadoop.metrics2.impl.MetricsSystemImpl: Scheduled snapshot period at 10 second(s).
2016-03-14 00:07:12,472 INFO org.apache.hadoop.metrics2.impl.MetricsSystemImpl: ResourceManager metrics system started
2016-03-14 00:07:12,495 INFO org.apache.hadoop.yarn.event.AsyncDispatcher: Registering class org.apache.hadoop.yarn.server.resourcemanager.RMAppManagerEventType for class org.apache.hadoop.yarn.server.resourcemanager.RMAppManager
2016-03-14 00:07:12,502 INFO org.apache.hadoop.yarn.event.AsyncDispatcher: Registering class org.apache.hadoop.yarn.server.resourcemanager.amlauncher.AMLauncherEventType for class org.apache.hadoop.yarn.server.resourcemanager.amlauncher.ApplicationMasterLauncher
2016-03-14 00:07:12,504 INFO org.apache.hadoop.yarn.server.resourcemanager.RMNMInfo: Registered RMNMInfo MBean
2016-03-14 00:07:12,507 INFO org.apache.hadoop.yarn.security.YarnAuthorizationProvider: org.apache.hadoop.yarn.security.ConfiguredYarnAuthorizer is instiantiated.
2016-03-14 00:07:12,507 INFO org.apache.hadoop.util.HostsFileReader: Refreshing hosts (include/exclude) list
2016-03-14 00:07:12,523 INFO org.apache.hadoop.conf.Configuration: found resource capacity-scheduler.xml at file:/usr/local/hadoop/etc/hadoop/capacity-scheduler.xml
2016-03-14 00:07:12,634 INFO org.apache.hadoop.yarn.server.resourcemanager.scheduler.capacity.CapacitySchedulerConfiguration: max alloc mb per queue for root is undefined
2016-03-14 00:07:12,634 INFO org.apache.hadoop.yarn.server.resourcemanager.scheduler.capacity.CapacitySchedulerConfiguration: max alloc vcore per queue for root is undefined
2016-03-14 00:07:12,644 INFO org.apache.hadoop.yarn.server.resourcemanager.scheduler.capacity.ParentQueue: root, capacity=1.0, asboluteCapacity=1.0, maxCapacity=1.0, asboluteMaxCapacity=1.0, state=RUNNING, acls=SUBMIT_APP:*ADMINISTER_QUEUE:*, labels=*,
, reservationsContinueLooking=true
2016-03-14 00:07:12,645 INFO org.apache.hadoop.yarn.server.resourcemanager.scheduler.capacity.ParentQueue: Initialized parent-queue root name=root, fullname=root
2016-03-14 00:07:12,663 INFO org.apache.hadoop.yarn.server.resourcemanager.scheduler.capacity.CapacitySchedulerConfiguration: max alloc mb per queue for root.default is undefined
2016-03-14 00:07:12,663 INFO org.apache.hadoop.yarn.server.resourcemanager.scheduler.capacity.CapacitySchedulerConfiguration: max alloc vcore per queue for root.default is undefined
2016-03-14 00:07:12,664 INFO org.apache.hadoop.yarn.server.resourcemanager.scheduler.capacity.LeafQueue: Initializing default
capacity = 1.0 [= (float) configuredCapacity / 100 ]
asboluteCapacity = 1.0 [= parentAbsoluteCapacity * capacity ]
maxCapacity = 1.0 [= configuredMaxCapacity ]
absoluteMaxCapacity = 1.0 [= 1.0 maximumCapacity undefined, (parentAbsoluteMaxCapacity * maximumCapacity) / 100 otherwise ]
userLimit = 100 [= configuredUserLimit ]
userLimitFactor = 1.0 [= configuredUserLimitFactor ]
maxApplications = 10000 [= configuredMaximumSystemApplicationsPerQueue or (int)(configuredMaximumSystemApplications * absoluteCapacity)]
maxApplicationsPerUser = 10000 [= (int)(maxApplications * (userLimit / 100.0f) * userLimitFactor) ]
usedCapacity = 0.0 [= usedResourcesMemory / (clusterResourceMemory * absoluteCapacity)]
absoluteUsedCapacity = 0.0 [= usedResourcesMemory / clusterResourceMemory]
maxAMResourcePerQueuePercent = 0.1 [= configuredMaximumAMResourcePercent ]
minimumAllocationFactor = 0.875 [= (float)(maximumAllocationMemory - minimumAllocationMemory) / maximumAllocationMemory ]
maximumAllocation = <memory:8192, vCores:32> [= configuredMaxAllocation ]
numContainers = 0 [= currentNumContainers ]
state = RUNNING [= configuredState ]
acls = SUBMIT_APP:*ADMINISTER_QUEUE:* [= configuredAcls ]
nodeLocalityDelay = 40
labels=*,
nodeLocalityDelay = 40
reservationsContinueLooking = true
preemptionDisabled = true

2016-03-14 00:07:12,664 INFO org.apache.hadoop.yarn.server.resourcemanager.scheduler.capacity.CapacityScheduler: Initialized queue: default: capacity=1.0, absoluteCapacity=1.0, usedResources=<memory:0, vCores:0>, usedCapacity=0.0, absoluteUsedCapacity=0.0, numApps=0, numContainers=0
2016-03-14 00:07:12,665 INFO org.apache.hadoop.yarn.server.resourcemanager.scheduler.capacity.CapacityScheduler: Initialized queue: root: numChildQueue= 1, capacity=1.0, absoluteCapacity=1.0, usedResources=<memory:0, vCores:0>usedCapacity=0.0, numApps=0, numContainers=0
2016-03-14 00:07:12,665 INFO org.apache.hadoop.yarn.server.resourcemanager.scheduler.capacity.CapacityScheduler: Initialized root queue root: numChildQueue= 1, capacity=1.0, absoluteCapacity=1.0, usedResources=<memory:0, vCores:0>usedCapacity=0.0, numApps=0, numContainers=0
2016-03-14 00:07:12,665 INFO org.apache.hadoop.yarn.server.resourcemanager.scheduler.capacity.CapacityScheduler: Initialized queue mappings, override: false
2016-03-14 00:07:12,665 INFO org.apache.hadoop.yarn.server.resourcemanager.scheduler.capacity.CapacityScheduler: Initialized CapacityScheduler with calculator=class org.apache.hadoop.yarn.util.resource.DefaultResourceCalculator, minimumAllocation=<<memory:1024, vCores:1>>, maximumAllocation=<<memory:8192, vCores:32>>, asynchronousScheduling=false, asyncScheduleInterval=5ms
2016-03-14 00:07:12,685 INFO org.apache.hadoop.yarn.server.resourcemanager.metrics.SystemMetricsPublisher: YARN system metrics publishing service is not enabled
2016-03-14 00:07:12,685 INFO org.apache.hadoop.yarn.server.resourcemanager.ResourceManager: Transitioning to active state
2016-03-14 00:07:12,712 INFO org.apache.hadoop.yarn.server.resourcemanager.recovery.RMStateStore: Updating AMRMToken
2016-03-14 00:07:12,712 INFO org.apache.hadoop.yarn.server.resourcemanager.security.RMContainerTokenSecretManager: Rolling master-key for container-tokens
2016-03-14 00:07:12,712 INFO org.apache.hadoop.yarn.server.resourcemanager.security.NMTokenSecretManagerInRM: Rolling master-key for nm-tokens
2016-03-14 00:07:12,713 INFO org.apache.hadoop.security.token.delegation.AbstractDelegationTokenSecretManager: Updating the current master key for generating delegation tokens
2016-03-14 00:07:12,714 INFO org.apache.hadoop.yarn.server.resourcemanager.security.RMDelegationTokenSecretManager: storing master key with keyID 1
2016-03-14 00:07:12,714 INFO org.apache.hadoop.yarn.server.resourcemanager.recovery.RMStateStore: Storing RMDTMasterKey.
2016-03-14 00:07:12,718 INFO org.apache.hadoop.security.token.delegation.AbstractDelegationTokenSecretManager: Starting expired delegation token remover thread, tokenRemoverScanInterval=60 min(s)
2016-03-14 00:07:12,718 INFO org.apache.hadoop.security.token.delegation.AbstractDelegationTokenSecretManager: Updating the current master key for generating delegation tokens
2016-03-14 00:07:12,718 INFO org.apache.hadoop.yarn.server.resourcemanager.security.RMDelegationTokenSecretManager: storing master key with keyID 2
2016-03-14 00:07:12,718 INFO org.apache.hadoop.yarn.server.resourcemanager.recovery.RMStateStore: Storing RMDTMasterKey.
2016-03-14 00:07:12,720 INFO org.apache.hadoop.yarn.event.AsyncDispatcher: Registering class org.apache.hadoop.yarn.nodelabels.event.NodeLabelsStoreEventType for class org.apache.hadoop.yarn.nodelabels.CommonNodeLabelsManager$ForwardingEventHandler
2016-03-14 00:07:12,771 INFO org.apache.hadoop.ipc.CallQueueManager: Using callQueue class java.util.concurrent.LinkedBlockingQueue
2016-03-14 00:07:12,785 INFO org.apache.hadoop.ipc.Server: Starting Socket Reader #1 for port 8031
2016-03-14 00:07:12,823 INFO org.apache.hadoop.yarn.factories.impl.pb.RpcServerFactoryPBImpl: Adding protocol org.apache.hadoop.yarn.server.api.ResourceTrackerPB to the server
2016-03-14 00:07:12,823 INFO org.apache.hadoop.ipc.Server: IPC Server Responder: starting
2016-03-14 00:07:12,824 INFO org.apache.hadoop.ipc.Server: IPC Server listener on 8031: starting
2016-03-14 00:07:12,880 INFO org.apache.hadoop.ipc.CallQueueManager: Using callQueue class java.util.concurrent.LinkedBlockingQueue
2016-03-14 00:07:12,886 INFO org.apache.hadoop.ipc.Server: Starting Socket Reader #1 for port 8030
2016-03-14 00:07:12,897 INFO org.apache.hadoop.yarn.factories.impl.pb.RpcServerFactoryPBImpl: Adding protocol org.apache.hadoop.yarn.api.ApplicationMasterProtocolPB to the server
2016-03-14 00:07:12,898 INFO org.apache.hadoop.ipc.Server: IPC Server Responder: starting
2016-03-14 00:07:12,898 INFO org.apache.hadoop.ipc.Server: IPC Server listener on 8030: starting
2016-03-14 00:07:13,112 INFO org.apache.hadoop.ipc.CallQueueManager: Using callQueue class java.util.concurrent.LinkedBlockingQueue
2016-03-14 00:07:13,117 INFO org.apache.hadoop.ipc.Server: Starting Socket Reader #1 for port 8032
2016-03-14 00:07:13,119 INFO org.apache.hadoop.yarn.factories.impl.pb.RpcServerFactoryPBImpl: Adding protocol org.apache.hadoop.yarn.api.ApplicationClientProtocolPB to the server
2016-03-14 00:07:13,125 INFO org.apache.hadoop.ipc.Server: IPC Server Responder: starting
2016-03-14 00:07:13,126 INFO org.apache.hadoop.ipc.Server: IPC Server listener on 8032: starting
2016-03-14 00:07:13,137 INFO org.apache.hadoop.yarn.server.resourcemanager.ResourceManager: Transitioned to active state
2016-03-14 00:07:13,312 INFO org.mortbay.log: Logging to org.slf4j.impl.Log4jLoggerAdapter(org.mortbay.log) via org.mortbay.log.Slf4jLog
2016-03-14 00:07:13,331 INFO org.apache.hadoop.security.authentication.server.AuthenticationFilter: Unable to initialize FileSignerSecretProvider, falling back to use random secrets.
2016-03-14 00:07:13,350 INFO org.apache.hadoop.http.HttpRequestLog: Http request log for http.requests.resourcemanager is not defined
2016-03-14 00:07:13,372 INFO org.apache.hadoop.http.HttpServer2: Added global filter 'safety' (class=org.apache.hadoop.http.HttpServer2$QuotingInputFilter)
2016-03-14 00:07:13,380 INFO org.apache.hadoop.http.HttpServer2: Added filter RMAuthenticationFilter (class=org.apache.hadoop.yarn.server.security.http.RMAuthenticationFilter) to context cluster
2016-03-14 00:07:13,382 INFO org.apache.hadoop.http.HttpServer2: Added filter RMAuthenticationFilter (class=org.apache.hadoop.yarn.server.security.http.RMAuthenticationFilter) to context logs
2016-03-14 00:07:13,382 INFO org.apache.hadoop.http.HttpServer2: Added filter RMAuthenticationFilter (class=org.apache.hadoop.yarn.server.security.http.RMAuthenticationFilter) to context static
2016-03-14 00:07:13,387 INFO org.apache.hadoop.http.HttpServer2: Added filter static_user_filter (class=org.apache.hadoop.http.lib.StaticUserWebFilter$StaticUserFilter) to context cluster
2016-03-14 00:07:13,388 INFO org.apache.hadoop.http.HttpServer2: Added filter static_user_filter (class=org.apache.hadoop.http.lib.StaticUserWebFilter$StaticUserFilter) to context logs
2016-03-14 00:07:13,388 INFO org.apache.hadoop.http.HttpServer2: Added filter static_user_filter (class=org.apache.hadoop.http.lib.StaticUserWebFilter$StaticUserFilter) to context static
2016-03-14 00:07:13,391 INFO org.apache.hadoop.http.HttpServer2: adding path spec: /cluster/*
2016-03-14 00:07:13,402 INFO org.apache.hadoop.http.HttpServer2: adding path spec: /ws/*
2016-03-14 00:07:14,403 INFO org.apache.hadoop.yarn.webapp.WebApps: Registered webapp guice modules
2016-03-14 00:07:14,407 INFO org.apache.hadoop.http.HttpServer2: Jetty bound to port 8088
2016-03-14 00:07:14,407 INFO org.mortbay.log: jetty-6.1.26
2016-03-14 00:07:14,485 INFO org.mortbay.log: Extract jar:file:/usr/local/hadoop/share/hadoop/yarn/hadoop-yarn-common-2.7.2.jar!/webapps/cluster to /tmp/Jetty_0_0_0_0_8088_cluster____u0rgz3/webapp
2016-03-14 00:07:15,106 INFO org.apache.hadoop.security.token.delegation.AbstractDelegationTokenSecretManager: Updating the current master key for generating delegation tokens
2016-03-14 00:07:15,115 INFO org.apache.hadoop.security.token.delegation.AbstractDelegationTokenSecretManager: Starting expired delegation token remover thread, tokenRemoverScanInterval=60 min(s)
2016-03-14 00:07:15,118 INFO org.apache.hadoop.security.token.delegation.AbstractDelegationTokenSecretManager: Updating the current master key for generating delegation tokens
2016-03-14 00:07:17,817 INFO org.mortbay.log: Started HttpServer2$SelectChannelConnectorWithSafeStartup@0.0.0.0:8088
2016-03-14 00:07:17,824 INFO org.apache.hadoop.yarn.webapp.WebApps: Web app cluster started at 8088
2016-03-14 00:07:17,918 INFO org.apache.hadoop.ipc.CallQueueManager: Using callQueue class java.util.concurrent.LinkedBlockingQueue
2016-03-14 00:07:17,921 INFO org.apache.hadoop.ipc.Server: Starting Socket Reader #1 for port 8033
2016-03-14 00:07:17,928 INFO org.apache.hadoop.yarn.factories.impl.pb.RpcServerFactoryPBImpl: Adding protocol org.apache.hadoop.yarn.server.api.ResourceManagerAdministrationProtocolPB to the server
2016-03-14 00:07:17,929 INFO org.apache.hadoop.ipc.Server: IPC Server Responder: starting
2016-03-14 00:07:17,932 INFO org.apache.hadoop.ipc.Server: IPC Server listener on 8033: starting
2016-03-14 00:09:04,795 INFO org.apache.hadoop.yarn.util.RackResolver: Resolved vishal-VirtualBox to /default-rack
2016-03-14 00:09:04,815 INFO org.apache.hadoop.yarn.server.resourcemanager.rmnode.RMNodeImpl: vishal-VirtualBox:33502 Node Transitioned from NEW to RUNNING
2016-03-14 00:09:04,826 INFO org.apache.hadoop.yarn.server.resourcemanager.ResourceTrackerService: NodeManager from node vishal-VirtualBox(cmPort: 33502 httpPort: 8042) registered with capability: <memory:8192, vCores:8>, assigned nodeId vishal-VirtualBox:33502
2016-03-14 00:09:04,835 INFO org.apache.hadoop.yarn.server.resourcemanager.scheduler.capacity.CapacityScheduler: Added node vishal-VirtualBox:33502 clusterResource: <memory:8192, vCores:8>
2016-03-14 00:17:12,522 INFO org.apache.hadoop.yarn.server.resourcemanager.scheduler.AbstractYarnScheduler: Release request cache is cleaned up
2016-03-14 00:18:10,868 INFO org.apache.hadoop.yarn.server.resourcemanager.ClientRMService: Allocated new applicationId: 1
2016-03-14 00:18:13,024 INFO org.apache.hadoop.yarn.server.resourcemanager.rmapp.RMAppImpl: Storing application with id application_1457932032699_0001
2016-03-14 00:18:13,029 INFO org.apache.hadoop.yarn.server.resourcemanager.ClientRMService: Application with id 1 submitted by user vishal
2016-03-14 00:18:13,031 INFO org.apache.hadoop.yarn.server.resourcemanager.RMAuditLogger: USER=vishal	IP=127.0.0.1	OPERATION=Submit Application Request	TARGET=ClientRMService	RESULT=SUCCESS	APPID=application_1457932032699_0001
2016-03-14 00:18:13,037 INFO org.apache.hadoop.yarn.server.resourcemanager.recovery.RMStateStore: Storing info for app: application_1457932032699_0001
2016-03-14 00:18:13,043 INFO org.apache.hadoop.yarn.server.resourcemanager.rmapp.RMAppImpl: application_1457932032699_0001 State change from NEW to NEW_SAVING
2016-03-14 00:18:13,043 INFO org.apache.hadoop.yarn.server.resourcemanager.rmapp.RMAppImpl: application_1457932032699_0001 State change from NEW_SAVING to SUBMITTED
2016-03-14 00:18:13,045 INFO org.apache.hadoop.yarn.server.resourcemanager.scheduler.capacity.ParentQueue: Application added - appId: application_1457932032699_0001 user: vishal leaf-queue of parent: root #applications: 1
2016-03-14 00:18:13,046 INFO org.apache.hadoop.yarn.server.resourcemanager.scheduler.capacity.CapacityScheduler: Accepted application application_1457932032699_0001 from user: vishal, in queue: default
2016-03-14 00:18:13,072 INFO org.apache.hadoop.yarn.server.resourcemanager.rmapp.RMAppImpl: application_1457932032699_0001 State change from SUBMITTED to ACCEPTED
2016-03-14 00:18:13,192 INFO org.apache.hadoop.yarn.server.resourcemanager.ApplicationMasterService: Registering app attempt : appattempt_1457932032699_0001_000001
2016-03-14 00:18:13,193 INFO org.apache.hadoop.yarn.server.resourcemanager.rmapp.attempt.RMAppAttemptImpl: appattempt_1457932032699_0001_000001 State change from NEW to SUBMITTED
2016-03-14 00:18:13,257 WARN org.apache.hadoop.yarn.server.resourcemanager.scheduler.capacity.LeafQueue: maximum-am-resource-percent is insufficient to start a single application in queue, it is likely set too low. skipping enforcement to allow at least one application to start
2016-03-14 00:18:13,258 WARN org.apache.hadoop.yarn.server.resourcemanager.scheduler.capacity.LeafQueue: maximum-am-resource-percent is insufficient to start a single application in queue for user, it is likely set too low. skipping enforcement to allow at least one application to start
2016-03-14 00:18:13,258 INFO org.apache.hadoop.yarn.server.resourcemanager.scheduler.capacity.LeafQueue: Application application_1457932032699_0001 from user: vishal activated in queue: default
2016-03-14 00:18:13,258 INFO org.apache.hadoop.yarn.server.resourcemanager.scheduler.capacity.LeafQueue: Application added - appId: application_1457932032699_0001 user: org.apache.hadoop.yarn.server.resourcemanager.scheduler.capacity.LeafQueue$User@52f32f88, leaf-queue: default #user-pending-applications: 0 #user-active-applications: 1 #queue-pending-applications: 0 #queue-active-applications: 1
2016-03-14 00:18:13,258 INFO org.apache.hadoop.yarn.server.resourcemanager.scheduler.capacity.CapacityScheduler: Added Application Attempt appattempt_1457932032699_0001_000001 to scheduler from user vishal in queue default
2016-03-14 00:18:13,260 INFO org.apache.hadoop.yarn.server.resourcemanager.rmapp.attempt.RMAppAttemptImpl: appattempt_1457932032699_0001_000001 State change from SUBMITTED to SCHEDULED
2016-03-14 00:18:13,725 INFO org.apache.hadoop.yarn.server.resourcemanager.rmcontainer.RMContainerImpl: container_1457932032699_0001_01_000001 Container Transitioned from NEW to ALLOCATED
2016-03-14 00:18:13,725 INFO org.apache.hadoop.yarn.server.resourcemanager.RMAuditLogger: USER=vishal	OPERATION=AM Allocated Container	TARGET=SchedulerApp	RESULT=SUCCESS	APPID=application_1457932032699_0001	CONTAINERID=container_1457932032699_0001_01_000001
2016-03-14 00:18:13,726 INFO org.apache.hadoop.yarn.server.resourcemanager.scheduler.SchedulerNode: Assigned container container_1457932032699_0001_01_000001 of capacity <memory:2048, vCores:1> on host vishal-VirtualBox:33502, which has 1 containers, <memory:2048, vCores:1> used and <memory:6144, vCores:7> available after allocation
2016-03-14 00:18:13,726 INFO org.apache.hadoop.yarn.server.resourcemanager.scheduler.capacity.LeafQueue: assignedContainer application attempt=appattempt_1457932032699_0001_000001 container=Container: [ContainerId: container_1457932032699_0001_01_000001, NodeId: vishal-VirtualBox:33502, NodeHttpAddress: vishal-VirtualBox:8042, Resource: <memory:2048, vCores:1>, Priority: 0, Token: null, ] queue=default: capacity=1.0, absoluteCapacity=1.0, usedResources=<memory:0, vCores:0>, usedCapacity=0.0, absoluteUsedCapacity=0.0, numApps=1, numContainers=0 clusterResource=<memory:8192, vCores:8>
2016-03-14 00:18:13,746 INFO org.apache.hadoop.yarn.server.resourcemanager.scheduler.capacity.ParentQueue: Re-sorting assigned queue: root.default stats: default: capacity=1.0, absoluteCapacity=1.0, usedResources=<memory:2048, vCores:1>, usedCapacity=0.25, absoluteUsedCapacity=0.25, numApps=1, numContainers=1
2016-03-14 00:18:13,747 INFO org.apache.hadoop.yarn.server.resourcemanager.scheduler.capacity.ParentQueue: assignedContainer queue=root usedCapacity=0.25 absoluteUsedCapacity=0.25 used=<memory:2048, vCores:1> cluster=<memory:8192, vCores:8>
2016-03-14 00:18:13,776 INFO org.apache.hadoop.yarn.server.resourcemanager.security.NMTokenSecretManagerInRM: Sending NMToken for nodeId : vishal-VirtualBox:33502 for container : container_1457932032699_0001_01_000001
2016-03-14 00:18:13,805 INFO org.apache.hadoop.yarn.server.resourcemanager.rmcontainer.RMContainerImpl: container_1457932032699_0001_01_000001 Container Transitioned from ALLOCATED to ACQUIRED
2016-03-14 00:18:13,807 INFO org.apache.hadoop.yarn.server.resourcemanager.security.NMTokenSecretManagerInRM: Clear node set for appattempt_1457932032699_0001_000001
2016-03-14 00:18:13,812 INFO org.apache.hadoop.yarn.server.resourcemanager.rmapp.attempt.RMAppAttemptImpl: Storing attempt: AppId: application_1457932032699_0001 AttemptId: appattempt_1457932032699_0001_000001 MasterContainer: Container: [ContainerId: container_1457932032699_0001_01_000001, NodeId: vishal-VirtualBox:33502, NodeHttpAddress: vishal-VirtualBox:8042, Resource: <memory:2048, vCores:1>, Priority: 0, Token: Token { kind: ContainerToken, service: 127.0.1.1:33502 }, ]
2016-03-14 00:18:13,837 INFO org.apache.hadoop.yarn.server.resourcemanager.rmapp.attempt.RMAppAttemptImpl: appattempt_1457932032699_0001_000001 State change from SCHEDULED to ALLOCATED_SAVING
2016-03-14 00:18:13,839 INFO org.apache.hadoop.yarn.server.resourcemanager.rmapp.attempt.RMAppAttemptImpl: appattempt_1457932032699_0001_000001 State change from ALLOCATED_SAVING to ALLOCATED
2016-03-14 00:18:13,851 INFO org.apache.hadoop.yarn.server.resourcemanager.amlauncher.AMLauncher: Launching masterappattempt_1457932032699_0001_000001
2016-03-14 00:18:13,937 INFO org.apache.hadoop.yarn.server.resourcemanager.amlauncher.AMLauncher: Setting up container Container: [ContainerId: container_1457932032699_0001_01_000001, NodeId: vishal-VirtualBox:33502, NodeHttpAddress: vishal-VirtualBox:8042, Resource: <memory:2048, vCores:1>, Priority: 0, Token: Token { kind: ContainerToken, service: 127.0.1.1:33502 }, ] for AM appattempt_1457932032699_0001_000001
2016-03-14 00:18:13,937 INFO org.apache.hadoop.yarn.server.resourcemanager.amlauncher.AMLauncher: Command to launch container container_1457932032699_0001_01_000001 : $JAVA_HOME/bin/java -Djava.io.tmpdir=$PWD/tmp -Dlog4j.configuration=container-log4j.properties -Dyarn.app.container.log.dir=<LOG_DIR> -Dyarn.app.container.log.filesize=0 -Dhadoop.root.logger=INFO,CLA -Dhadoop.root.logfile=syslog  -Xmx1024m org.apache.hadoop.mapreduce.v2.app.MRAppMaster 1><LOG_DIR>/stdout 2><LOG_DIR>/stderr 
2016-03-14 00:18:13,941 INFO org.apache.hadoop.yarn.server.resourcemanager.security.AMRMTokenSecretManager: Create AMRMToken for ApplicationAttempt: appattempt_1457932032699_0001_000001
2016-03-14 00:18:13,947 INFO org.apache.hadoop.yarn.server.resourcemanager.security.AMRMTokenSecretManager: Creating password for appattempt_1457932032699_0001_000001
2016-03-14 00:18:14,575 INFO org.apache.hadoop.yarn.server.resourcemanager.amlauncher.AMLauncher: Done launching container Container: [ContainerId: container_1457932032699_0001_01_000001, NodeId: vishal-VirtualBox:33502, NodeHttpAddress: vishal-VirtualBox:8042, Resource: <memory:2048, vCores:1>, Priority: 0, Token: Token { kind: ContainerToken, service: 127.0.1.1:33502 }, ] for AM appattempt_1457932032699_0001_000001
2016-03-14 00:18:14,583 INFO org.apache.hadoop.yarn.server.resourcemanager.rmapp.attempt.RMAppAttemptImpl: appattempt_1457932032699_0001_000001 State change from ALLOCATED to LAUNCHED
2016-03-14 00:18:14,698 INFO org.apache.hadoop.yarn.server.resourcemanager.rmcontainer.RMContainerImpl: container_1457932032699_0001_01_000001 Container Transitioned from ACQUIRED to RUNNING
2016-03-14 00:18:28,098 INFO SecurityLogger.org.apache.hadoop.ipc.Server: Auth successful for appattempt_1457932032699_0001_000001 (auth:SIMPLE)
2016-03-14 00:18:28,112 INFO org.apache.hadoop.yarn.server.resourcemanager.ApplicationMasterService: AM registration appattempt_1457932032699_0001_000001
2016-03-14 00:18:28,113 INFO org.apache.hadoop.yarn.server.resourcemanager.rmapp.attempt.RMAppAttemptImpl: appattempt_1457932032699_0001_000001 State change from LAUNCHED to RUNNING
2016-03-14 00:18:28,113 INFO org.apache.hadoop.yarn.server.resourcemanager.rmapp.RMAppImpl: application_1457932032699_0001 State change from ACCEPTED to RUNNING
2016-03-14 00:18:28,120 INFO org.apache.hadoop.yarn.server.resourcemanager.RMAuditLogger: USER=vishal	IP=127.0.0.1	OPERATION=Register App Master	TARGET=ApplicationMasterService	RESULT=SUCCESS	APPID=application_1457932032699_0001	APPATTEMPTID=appattempt_1457932032699_0001_000001
2016-03-14 00:18:29,753 INFO org.apache.hadoop.yarn.server.resourcemanager.rmcontainer.RMContainerImpl: container_1457932032699_0001_01_000002 Container Transitioned from NEW to ALLOCATED
2016-03-14 00:18:29,754 INFO org.apache.hadoop.yarn.server.resourcemanager.RMAuditLogger: USER=vishal	OPERATION=AM Allocated Container	TARGET=SchedulerApp	RESULT=SUCCESS	APPID=application_1457932032699_0001	CONTAINERID=container_1457932032699_0001_01_000002
2016-03-14 00:18:29,754 INFO org.apache.hadoop.yarn.server.resourcemanager.scheduler.SchedulerNode: Assigned container container_1457932032699_0001_01_000002 of capacity <memory:1024, vCores:1> on host vishal-VirtualBox:33502, which has 2 containers, <memory:3072, vCores:2> used and <memory:5120, vCores:6> available after allocation
2016-03-14 00:18:29,754 INFO org.apache.hadoop.yarn.server.resourcemanager.scheduler.capacity.LeafQueue: assignedContainer application attempt=appattempt_1457932032699_0001_000001 container=Container: [ContainerId: container_1457932032699_0001_01_000002, NodeId: vishal-VirtualBox:33502, NodeHttpAddress: vishal-VirtualBox:8042, Resource: <memory:1024, vCores:1>, Priority: 20, Token: null, ] queue=default: capacity=1.0, absoluteCapacity=1.0, usedResources=<memory:2048, vCores:1>, usedCapacity=0.25, absoluteUsedCapacity=0.25, numApps=1, numContainers=1 clusterResource=<memory:8192, vCores:8>
2016-03-14 00:18:29,754 INFO org.apache.hadoop.yarn.server.resourcemanager.scheduler.capacity.ParentQueue: Re-sorting assigned queue: root.default stats: default: capacity=1.0, absoluteCapacity=1.0, usedResources=<memory:3072, vCores:2>, usedCapacity=0.375, absoluteUsedCapacity=0.375, numApps=1, numContainers=2
2016-03-14 00:18:29,754 INFO org.apache.hadoop.yarn.server.resourcemanager.scheduler.capacity.ParentQueue: assignedContainer queue=root usedCapacity=0.375 absoluteUsedCapacity=0.375 used=<memory:3072, vCores:2> cluster=<memory:8192, vCores:8>
2016-03-14 00:18:30,350 INFO org.apache.hadoop.yarn.server.resourcemanager.security.NMTokenSecretManagerInRM: Sending NMToken for nodeId : vishal-VirtualBox:33502 for container : container_1457932032699_0001_01_000002
2016-03-14 00:18:30,355 INFO org.apache.hadoop.yarn.server.resourcemanager.rmcontainer.RMContainerImpl: container_1457932032699_0001_01_000002 Container Transitioned from ALLOCATED to ACQUIRED
2016-03-14 00:18:31,381 INFO org.apache.hadoop.yarn.server.resourcemanager.scheduler.AppSchedulingInfo: checking for deactivate of application :application_1457932032699_0001
2016-03-14 00:18:31,754 INFO org.apache.hadoop.yarn.server.resourcemanager.rmcontainer.RMContainerImpl: container_1457932032699_0001_01_000002 Container Transitioned from ACQUIRED to RUNNING
2016-03-14 00:18:37,922 INFO org.apache.hadoop.yarn.server.resourcemanager.rmcontainer.RMContainerImpl: container_1457932032699_0001_01_000002 Container Transitioned from RUNNING to COMPLETED
2016-03-14 00:18:37,923 INFO org.apache.hadoop.yarn.server.resourcemanager.scheduler.common.fica.FiCaSchedulerApp: Completed container: container_1457932032699_0001_01_000002 in state: COMPLETED event:FINISHED
2016-03-14 00:18:37,923 INFO org.apache.hadoop.yarn.server.resourcemanager.RMAuditLogger: USER=vishal	OPERATION=AM Released Container	TARGET=SchedulerApp	RESULT=SUCCESS	APPID=application_1457932032699_0001	CONTAINERID=container_1457932032699_0001_01_000002
2016-03-14 00:18:37,923 INFO org.apache.hadoop.yarn.server.resourcemanager.scheduler.SchedulerNode: Released container container_1457932032699_0001_01_000002 of capacity <memory:1024, vCores:1> on host vishal-VirtualBox:33502, which currently has 1 containers, <memory:2048, vCores:1> used and <memory:6144, vCores:7> available, release resources=true
2016-03-14 00:18:37,923 INFO org.apache.hadoop.yarn.server.resourcemanager.scheduler.capacity.LeafQueue: default used=<memory:2048, vCores:1> numContainers=1 user=vishal user-resources=<memory:2048, vCores:1>
2016-03-14 00:18:37,924 INFO org.apache.hadoop.yarn.server.resourcemanager.scheduler.capacity.LeafQueue: completedContainer container=Container: [ContainerId: container_1457932032699_0001_01_000002, NodeId: vishal-VirtualBox:33502, NodeHttpAddress: vishal-VirtualBox:8042, Resource: <memory:1024, vCores:1>, Priority: 20, Token: Token { kind: ContainerToken, service: 127.0.1.1:33502 }, ] queue=default: capacity=1.0, absoluteCapacity=1.0, usedResources=<memory:2048, vCores:1>, usedCapacity=0.25, absoluteUsedCapacity=0.25, numApps=1, numContainers=1 cluster=<memory:8192, vCores:8>
2016-03-14 00:18:37,925 INFO org.apache.hadoop.yarn.server.resourcemanager.scheduler.capacity.ParentQueue: completedContainer queue=root usedCapacity=0.25 absoluteUsedCapacity=0.25 used=<memory:2048, vCores:1> cluster=<memory:8192, vCores:8>
2016-03-14 00:18:37,925 INFO org.apache.hadoop.yarn.server.resourcemanager.scheduler.capacity.ParentQueue: Re-sorting completed queue: root.default stats: default: capacity=1.0, absoluteCapacity=1.0, usedResources=<memory:2048, vCores:1>, usedCapacity=0.25, absoluteUsedCapacity=0.25, numApps=1, numContainers=1
2016-03-14 00:18:37,925 INFO org.apache.hadoop.yarn.server.resourcemanager.scheduler.capacity.CapacityScheduler: Application attempt appattempt_1457932032699_0001_000001 released container container_1457932032699_0001_01_000002 on node: host: vishal-VirtualBox:33502 #containers=1 available=<memory:6144, vCores:7> used=<memory:2048, vCores:1> with event: FINISHED
2016-03-14 00:18:38,928 INFO org.apache.hadoop.yarn.server.resourcemanager.rmcontainer.RMContainerImpl: container_1457932032699_0001_01_000003 Container Transitioned from NEW to ALLOCATED
2016-03-14 00:18:38,928 INFO org.apache.hadoop.yarn.server.resourcemanager.RMAuditLogger: USER=vishal	OPERATION=AM Allocated Container	TARGET=SchedulerApp	RESULT=SUCCESS	APPID=application_1457932032699_0001	CONTAINERID=container_1457932032699_0001_01_000003
2016-03-14 00:18:38,928 INFO org.apache.hadoop.yarn.server.resourcemanager.scheduler.SchedulerNode: Assigned container container_1457932032699_0001_01_000003 of capacity <memory:1024, vCores:1> on host vishal-VirtualBox:33502, which has 2 containers, <memory:3072, vCores:2> used and <memory:5120, vCores:6> available after allocation
2016-03-14 00:18:38,928 INFO org.apache.hadoop.yarn.server.resourcemanager.scheduler.capacity.LeafQueue: assignedContainer application attempt=appattempt_1457932032699_0001_000001 container=Container: [ContainerId: container_1457932032699_0001_01_000003, NodeId: vishal-VirtualBox:33502, NodeHttpAddress: vishal-VirtualBox:8042, Resource: <memory:1024, vCores:1>, Priority: 10, Token: null, ] queue=default: capacity=1.0, absoluteCapacity=1.0, usedResources=<memory:2048, vCores:1>, usedCapacity=0.25, absoluteUsedCapacity=0.25, numApps=1, numContainers=1 clusterResource=<memory:8192, vCores:8>
2016-03-14 00:18:38,930 INFO org.apache.hadoop.yarn.server.resourcemanager.scheduler.capacity.ParentQueue: Re-sorting assigned queue: root.default stats: default: capacity=1.0, absoluteCapacity=1.0, usedResources=<memory:3072, vCores:2>, usedCapacity=0.375, absoluteUsedCapacity=0.375, numApps=1, numContainers=2
2016-03-14 00:18:38,930 INFO org.apache.hadoop.yarn.server.resourcemanager.scheduler.capacity.ParentQueue: assignedContainer queue=root usedCapacity=0.375 absoluteUsedCapacity=0.375 used=<memory:3072, vCores:2> cluster=<memory:8192, vCores:8>
2016-03-14 00:18:39,448 INFO org.apache.hadoop.yarn.server.resourcemanager.rmcontainer.RMContainerImpl: container_1457932032699_0001_01_000003 Container Transitioned from ALLOCATED to ACQUIRED
2016-03-14 00:18:39,933 INFO org.apache.hadoop.yarn.server.resourcemanager.rmcontainer.RMContainerImpl: container_1457932032699_0001_01_000003 Container Transitioned from ACQUIRED to RUNNING
2016-03-14 00:18:40,454 INFO org.apache.hadoop.yarn.server.resourcemanager.scheduler.AppSchedulingInfo: checking for deactivate of application :application_1457932032699_0001
2016-03-14 00:18:47,834 INFO org.apache.hadoop.yarn.server.resourcemanager.rmapp.attempt.RMAppAttemptImpl: Updating application attempt appattempt_1457932032699_0001_000001 with final state: FINISHING, and exit status: -1000
2016-03-14 00:18:47,848 INFO org.apache.hadoop.yarn.server.resourcemanager.rmapp.attempt.RMAppAttemptImpl: appattempt_1457932032699_0001_000001 State change from RUNNING to FINAL_SAVING
2016-03-14 00:18:47,848 INFO org.apache.hadoop.yarn.server.resourcemanager.rmapp.RMAppImpl: Updating application application_1457932032699_0001 with final state: FINISHING
2016-03-14 00:18:47,853 INFO org.apache.hadoop.yarn.server.resourcemanager.recovery.RMStateStore: Updating info for app: application_1457932032699_0001
2016-03-14 00:18:47,853 INFO org.apache.hadoop.yarn.server.resourcemanager.rmapp.RMAppImpl: application_1457932032699_0001 State change from RUNNING to FINAL_SAVING
2016-03-14 00:18:47,853 INFO org.apache.hadoop.yarn.server.resourcemanager.rmapp.attempt.RMAppAttemptImpl: appattempt_1457932032699_0001_000001 State change from FINAL_SAVING to FINISHING
2016-03-14 00:18:47,853 INFO org.apache.hadoop.yarn.server.resourcemanager.rmapp.RMAppImpl: application_1457932032699_0001 State change from FINAL_SAVING to FINISHING
2016-03-14 00:18:48,004 INFO org.apache.hadoop.yarn.server.resourcemanager.rmcontainer.RMContainerImpl: container_1457932032699_0001_01_000003 Container Transitioned from RUNNING to COMPLETED
2016-03-14 00:18:48,004 INFO org.apache.hadoop.yarn.server.resourcemanager.scheduler.common.fica.FiCaSchedulerApp: Completed container: container_1457932032699_0001_01_000003 in state: COMPLETED event:FINISHED
2016-03-14 00:18:48,004 INFO org.apache.hadoop.yarn.server.resourcemanager.RMAuditLogger: USER=vishal	OPERATION=AM Released Container	TARGET=SchedulerApp	RESULT=SUCCESS	APPID=application_1457932032699_0001	CONTAINERID=container_1457932032699_0001_01_000003
2016-03-14 00:18:48,004 INFO org.apache.hadoop.yarn.server.resourcemanager.scheduler.SchedulerNode: Released container container_1457932032699_0001_01_000003 of capacity <memory:1024, vCores:1> on host vishal-VirtualBox:33502, which currently has 1 containers, <memory:2048, vCores:1> used and <memory:6144, vCores:7> available, release resources=true
2016-03-14 00:18:48,004 INFO org.apache.hadoop.yarn.server.resourcemanager.scheduler.capacity.LeafQueue: default used=<memory:2048, vCores:1> numContainers=1 user=vishal user-resources=<memory:2048, vCores:1>
2016-03-14 00:18:48,005 INFO org.apache.hadoop.yarn.server.resourcemanager.scheduler.capacity.LeafQueue: completedContainer container=Container: [ContainerId: container_1457932032699_0001_01_000003, NodeId: vishal-VirtualBox:33502, NodeHttpAddress: vishal-VirtualBox:8042, Resource: <memory:1024, vCores:1>, Priority: 10, Token: Token { kind: ContainerToken, service: 127.0.1.1:33502 }, ] queue=default: capacity=1.0, absoluteCapacity=1.0, usedResources=<memory:2048, vCores:1>, usedCapacity=0.25, absoluteUsedCapacity=0.25, numApps=1, numContainers=1 cluster=<memory:8192, vCores:8>
2016-03-14 00:18:48,006 INFO org.apache.hadoop.yarn.server.resourcemanager.scheduler.capacity.ParentQueue: completedContainer queue=root usedCapacity=0.25 absoluteUsedCapacity=0.25 used=<memory:2048, vCores:1> cluster=<memory:8192, vCores:8>
2016-03-14 00:18:48,006 INFO org.apache.hadoop.yarn.server.resourcemanager.scheduler.capacity.ParentQueue: Re-sorting completed queue: root.default stats: default: capacity=1.0, absoluteCapacity=1.0, usedResources=<memory:2048, vCores:1>, usedCapacity=0.25, absoluteUsedCapacity=0.25, numApps=1, numContainers=1
2016-03-14 00:18:48,006 INFO org.apache.hadoop.yarn.server.resourcemanager.scheduler.capacity.CapacityScheduler: Application attempt appattempt_1457932032699_0001_000001 released container container_1457932032699_0001_01_000003 on node: host: vishal-VirtualBox:33502 #containers=1 available=<memory:6144, vCores:7> used=<memory:2048, vCores:1> with event: FINISHED
2016-03-14 00:18:48,848 INFO org.apache.hadoop.yarn.server.resourcemanager.ApplicationMasterService: application_1457932032699_0001 unregistered successfully. 
2016-03-14 00:18:54,019 INFO org.apache.hadoop.yarn.server.resourcemanager.rmcontainer.RMContainerImpl: container_1457932032699_0001_01_000001 Container Transitioned from RUNNING to COMPLETED
2016-03-14 00:18:54,019 INFO org.apache.hadoop.yarn.server.resourcemanager.scheduler.common.fica.FiCaSchedulerApp: Completed container: container_1457932032699_0001_01_000001 in state: COMPLETED event:FINISHED
2016-03-14 00:18:54,019 INFO org.apache.hadoop.yarn.server.resourcemanager.RMAuditLogger: USER=vishal	OPERATION=AM Released Container	TARGET=SchedulerApp	RESULT=SUCCESS	APPID=application_1457932032699_0001	CONTAINERID=container_1457932032699_0001_01_000001
2016-03-14 00:18:54,019 INFO org.apache.hadoop.yarn.server.resourcemanager.scheduler.SchedulerNode: Released container container_1457932032699_0001_01_000001 of capacity <memory:2048, vCores:1> on host vishal-VirtualBox:33502, which currently has 0 containers, <memory:0, vCores:0> used and <memory:8192, vCores:8> available, release resources=true
2016-03-14 00:18:54,019 INFO org.apache.hadoop.yarn.server.resourcemanager.scheduler.capacity.LeafQueue: default used=<memory:0, vCores:0> numContainers=0 user=vishal user-resources=<memory:0, vCores:0>
2016-03-14 00:18:54,019 INFO org.apache.hadoop.yarn.server.resourcemanager.scheduler.capacity.LeafQueue: completedContainer container=Container: [ContainerId: container_1457932032699_0001_01_000001, NodeId: vishal-VirtualBox:33502, NodeHttpAddress: vishal-VirtualBox:8042, Resource: <memory:2048, vCores:1>, Priority: 0, Token: Token { kind: ContainerToken, service: 127.0.1.1:33502 }, ] queue=default: capacity=1.0, absoluteCapacity=1.0, usedResources=<memory:0, vCores:0>, usedCapacity=0.0, absoluteUsedCapacity=0.0, numApps=1, numContainers=0 cluster=<memory:8192, vCores:8>
2016-03-14 00:18:54,019 INFO org.apache.hadoop.yarn.server.resourcemanager.scheduler.capacity.ParentQueue: completedContainer queue=root usedCapacity=0.0 absoluteUsedCapacity=0.0 used=<memory:0, vCores:0> cluster=<memory:8192, vCores:8>
2016-03-14 00:18:54,019 INFO org.apache.hadoop.yarn.server.resourcemanager.scheduler.capacity.ParentQueue: Re-sorting completed queue: root.default stats: default: capacity=1.0, absoluteCapacity=1.0, usedResources=<memory:0, vCores:0>, usedCapacity=0.0, absoluteUsedCapacity=0.0, numApps=1, numContainers=0
2016-03-14 00:18:54,019 INFO org.apache.hadoop.yarn.server.resourcemanager.scheduler.capacity.CapacityScheduler: Application attempt appattempt_1457932032699_0001_000001 released container container_1457932032699_0001_01_000001 on node: host: vishal-VirtualBox:33502 #containers=0 available=<memory:8192, vCores:8> used=<memory:0, vCores:0> with event: FINISHED
2016-03-14 00:18:54,020 INFO org.apache.hadoop.yarn.server.resourcemanager.ApplicationMasterService: Unregistering app attempt : appattempt_1457932032699_0001_000001
2016-03-14 00:18:54,025 INFO org.apache.hadoop.yarn.server.resourcemanager.security.AMRMTokenSecretManager: Application finished, removing password for appattempt_1457932032699_0001_000001
2016-03-14 00:18:54,026 INFO org.apache.hadoop.yarn.server.resourcemanager.rmapp.attempt.RMAppAttemptImpl: appattempt_1457932032699_0001_000001 State change from FINISHING to FINISHED
2016-03-14 00:18:54,027 INFO org.apache.hadoop.yarn.server.resourcemanager.rmapp.RMAppImpl: application_1457932032699_0001 State change from FINISHING to FINISHED
2016-03-14 00:18:54,032 INFO org.apache.hadoop.yarn.server.resourcemanager.scheduler.capacity.CapacityScheduler: Application Attempt appattempt_1457932032699_0001_000001 is done. finalState=FINISHED
2016-03-14 00:18:54,033 INFO org.apache.hadoop.yarn.server.resourcemanager.scheduler.AppSchedulingInfo: Application application_1457932032699_0001 requests cleared
2016-03-14 00:18:54,033 INFO org.apache.hadoop.yarn.server.resourcemanager.scheduler.capacity.LeafQueue: Application removed - appId: application_1457932032699_0001 user: vishal queue: default #user-pending-applications: 0 #user-active-applications: 0 #queue-pending-applications: 0 #queue-active-applications: 0
2016-03-14 00:18:54,034 INFO org.apache.hadoop.yarn.server.resourcemanager.scheduler.capacity.ParentQueue: Application removed - appId: application_1457932032699_0001 user: vishal leaf-queue of parent: root #applications: 0
2016-03-14 00:18:54,035 INFO org.apache.hadoop.yarn.server.resourcemanager.RMAuditLogger: USER=vishal	OPERATION=Application Finished - Succeeded	TARGET=RMAppManager	RESULT=SUCCESS	APPID=application_1457932032699_0001
2016-03-14 00:18:54,042 INFO org.apache.hadoop.yarn.server.resourcemanager.amlauncher.AMLauncher: Cleaning master appattempt_1457932032699_0001_000001
2016-03-14 00:18:54,050 INFO org.apache.hadoop.yarn.server.resourcemanager.RMAppManager$ApplicationSummary: appId=application_1457932032699_0001,name=word count,user=vishal,queue=default,state=FINISHED,trackingUrl=http://vishal-VirtualBox:8088/proxy/application_1457932032699_0001/,appMasterHost=vishal-VirtualBox,startTime=1457932693022,finishTime=1457932727848,finalStatus=SUCCEEDED,memorySeconds=100190,vcoreSeconds=57,preemptedAMContainers=0,preemptedNonAMContainers=0,preemptedResources=<memory:0\, vCores:0>,applicationType=MAPREDUCE
2016-03-14 00:18:55,086 INFO org.apache.hadoop.yarn.server.resourcemanager.scheduler.capacity.CapacityScheduler: Null container completed...
2016-03-14 00:22:09,070 INFO org.apache.hadoop.yarn.server.resourcemanager.ClientRMService: Allocated new applicationId: 2
2016-03-14 00:22:11,295 INFO org.apache.hadoop.yarn.server.resourcemanager.ClientRMService: Application with id 2 submitted by user vishal
2016-03-14 00:22:11,295 INFO org.apache.hadoop.yarn.server.resourcemanager.RMAuditLogger: USER=vishal	IP=127.0.0.1	OPERATION=Submit Application Request	TARGET=ClientRMService	RESULT=SUCCESS	APPID=application_1457932032699_0002
2016-03-14 00:22:11,295 INFO org.apache.hadoop.yarn.server.resourcemanager.rmapp.RMAppImpl: Storing application with id application_1457932032699_0002
2016-03-14 00:22:11,295 INFO org.apache.hadoop.yarn.server.resourcemanager.rmapp.RMAppImpl: application_1457932032699_0002 State change from NEW to NEW_SAVING
2016-03-14 00:22:11,295 INFO org.apache.hadoop.yarn.server.resourcemanager.recovery.RMStateStore: Storing info for app: application_1457932032699_0002
2016-03-14 00:22:11,295 INFO org.apache.hadoop.yarn.server.resourcemanager.rmapp.RMAppImpl: application_1457932032699_0002 State change from NEW_SAVING to SUBMITTED
2016-03-14 00:22:11,296 INFO org.apache.hadoop.yarn.server.resourcemanager.scheduler.capacity.ParentQueue: Application added - appId: application_1457932032699_0002 user: vishal leaf-queue of parent: root #applications: 1
2016-03-14 00:22:11,296 INFO org.apache.hadoop.yarn.server.resourcemanager.scheduler.capacity.CapacityScheduler: Accepted application application_1457932032699_0002 from user: vishal, in queue: default
2016-03-14 00:22:11,297 INFO org.apache.hadoop.yarn.server.resourcemanager.rmapp.RMAppImpl: application_1457932032699_0002 State change from SUBMITTED to ACCEPTED
2016-03-14 00:22:11,297 INFO org.apache.hadoop.yarn.server.resourcemanager.ApplicationMasterService: Registering app attempt : appattempt_1457932032699_0002_000001
2016-03-14 00:22:11,297 INFO org.apache.hadoop.yarn.server.resourcemanager.rmapp.attempt.RMAppAttemptImpl: appattempt_1457932032699_0002_000001 State change from NEW to SUBMITTED
2016-03-14 00:22:11,297 WARN org.apache.hadoop.yarn.server.resourcemanager.scheduler.capacity.LeafQueue: maximum-am-resource-percent is insufficient to start a single application in queue, it is likely set too low. skipping enforcement to allow at least one application to start
2016-03-14 00:22:11,297 WARN org.apache.hadoop.yarn.server.resourcemanager.scheduler.capacity.LeafQueue: maximum-am-resource-percent is insufficient to start a single application in queue for user, it is likely set too low. skipping enforcement to allow at least one application to start
2016-03-14 00:22:11,297 INFO org.apache.hadoop.yarn.server.resourcemanager.scheduler.capacity.LeafQueue: Application application_1457932032699_0002 from user: vishal activated in queue: default
2016-03-14 00:22:11,297 INFO org.apache.hadoop.yarn.server.resourcemanager.scheduler.capacity.LeafQueue: Application added - appId: application_1457932032699_0002 user: org.apache.hadoop.yarn.server.resourcemanager.scheduler.capacity.LeafQueue$User@3b558c6e, leaf-queue: default #user-pending-applications: 0 #user-active-applications: 1 #queue-pending-applications: 0 #queue-active-applications: 1
2016-03-14 00:22:11,298 INFO org.apache.hadoop.yarn.server.resourcemanager.scheduler.capacity.CapacityScheduler: Added Application Attempt appattempt_1457932032699_0002_000001 to scheduler from user vishal in queue default
2016-03-14 00:22:11,302 INFO org.apache.hadoop.yarn.server.resourcemanager.rmapp.attempt.RMAppAttemptImpl: appattempt_1457932032699_0002_000001 State change from SUBMITTED to SCHEDULED
2016-03-14 00:22:11,517 INFO org.apache.hadoop.yarn.server.resourcemanager.rmcontainer.RMContainerImpl: container_1457932032699_0002_01_000001 Container Transitioned from NEW to ALLOCATED
2016-03-14 00:22:11,517 INFO org.apache.hadoop.yarn.server.resourcemanager.RMAuditLogger: USER=vishal	OPERATION=AM Allocated Container	TARGET=SchedulerApp	RESULT=SUCCESS	APPID=application_1457932032699_0002	CONTAINERID=container_1457932032699_0002_01_000001
2016-03-14 00:22:11,517 INFO org.apache.hadoop.yarn.server.resourcemanager.scheduler.SchedulerNode: Assigned container container_1457932032699_0002_01_000001 of capacity <memory:2048, vCores:1> on host vishal-VirtualBox:33502, which has 1 containers, <memory:2048, vCores:1> used and <memory:6144, vCores:7> available after allocation
2016-03-14 00:22:11,517 INFO org.apache.hadoop.yarn.server.resourcemanager.scheduler.capacity.LeafQueue: assignedContainer application attempt=appattempt_1457932032699_0002_000001 container=Container: [ContainerId: container_1457932032699_0002_01_000001, NodeId: vishal-VirtualBox:33502, NodeHttpAddress: vishal-VirtualBox:8042, Resource: <memory:2048, vCores:1>, Priority: 0, Token: null, ] queue=default: capacity=1.0, absoluteCapacity=1.0, usedResources=<memory:0, vCores:0>, usedCapacity=0.0, absoluteUsedCapacity=0.0, numApps=1, numContainers=0 clusterResource=<memory:8192, vCores:8>
2016-03-14 00:22:11,517 INFO org.apache.hadoop.yarn.server.resourcemanager.scheduler.capacity.ParentQueue: Re-sorting assigned queue: root.default stats: default: capacity=1.0, absoluteCapacity=1.0, usedResources=<memory:2048, vCores:1>, usedCapacity=0.25, absoluteUsedCapacity=0.25, numApps=1, numContainers=1
2016-03-14 00:22:11,518 INFO org.apache.hadoop.yarn.server.resourcemanager.scheduler.capacity.ParentQueue: assignedContainer queue=root usedCapacity=0.25 absoluteUsedCapacity=0.25 used=<memory:2048, vCores:1> cluster=<memory:8192, vCores:8>
2016-03-14 00:22:11,546 INFO org.apache.hadoop.yarn.server.resourcemanager.security.NMTokenSecretManagerInRM: Sending NMToken for nodeId : vishal-VirtualBox:33502 for container : container_1457932032699_0002_01_000001
2016-03-14 00:22:11,591 INFO org.apache.hadoop.yarn.server.resourcemanager.rmcontainer.RMContainerImpl: container_1457932032699_0002_01_000001 Container Transitioned from ALLOCATED to ACQUIRED
2016-03-14 00:22:11,591 INFO org.apache.hadoop.yarn.server.resourcemanager.security.NMTokenSecretManagerInRM: Clear node set for appattempt_1457932032699_0002_000001
2016-03-14 00:22:11,591 INFO org.apache.hadoop.yarn.server.resourcemanager.rmapp.attempt.RMAppAttemptImpl: Storing attempt: AppId: application_1457932032699_0002 AttemptId: appattempt_1457932032699_0002_000001 MasterContainer: Container: [ContainerId: container_1457932032699_0002_01_000001, NodeId: vishal-VirtualBox:33502, NodeHttpAddress: vishal-VirtualBox:8042, Resource: <memory:2048, vCores:1>, Priority: 0, Token: Token { kind: ContainerToken, service: 127.0.1.1:33502 }, ]
2016-03-14 00:22:11,591 INFO org.apache.hadoop.yarn.server.resourcemanager.rmapp.attempt.RMAppAttemptImpl: appattempt_1457932032699_0002_000001 State change from SCHEDULED to ALLOCATED_SAVING
2016-03-14 00:22:11,591 INFO org.apache.hadoop.yarn.server.resourcemanager.rmapp.attempt.RMAppAttemptImpl: appattempt_1457932032699_0002_000001 State change from ALLOCATED_SAVING to ALLOCATED
2016-03-14 00:22:11,597 INFO org.apache.hadoop.yarn.server.resourcemanager.amlauncher.AMLauncher: Launching masterappattempt_1457932032699_0002_000001
2016-03-14 00:22:11,613 INFO org.apache.hadoop.yarn.server.resourcemanager.amlauncher.AMLauncher: Setting up container Container: [ContainerId: container_1457932032699_0002_01_000001, NodeId: vishal-VirtualBox:33502, NodeHttpAddress: vishal-VirtualBox:8042, Resource: <memory:2048, vCores:1>, Priority: 0, Token: Token { kind: ContainerToken, service: 127.0.1.1:33502 }, ] for AM appattempt_1457932032699_0002_000001
2016-03-14 00:22:11,613 INFO org.apache.hadoop.yarn.server.resourcemanager.amlauncher.AMLauncher: Command to launch container container_1457932032699_0002_01_000001 : $JAVA_HOME/bin/java -Djava.io.tmpdir=$PWD/tmp -Dlog4j.configuration=container-log4j.properties -Dyarn.app.container.log.dir=<LOG_DIR> -Dyarn.app.container.log.filesize=0 -Dhadoop.root.logger=INFO,CLA -Dhadoop.root.logfile=syslog  -Xmx1024m org.apache.hadoop.mapreduce.v2.app.MRAppMaster 1><LOG_DIR>/stdout 2><LOG_DIR>/stderr 
2016-03-14 00:22:11,613 INFO org.apache.hadoop.yarn.server.resourcemanager.security.AMRMTokenSecretManager: Create AMRMToken for ApplicationAttempt: appattempt_1457932032699_0002_000001
2016-03-14 00:22:11,613 INFO org.apache.hadoop.yarn.server.resourcemanager.security.AMRMTokenSecretManager: Creating password for appattempt_1457932032699_0002_000001
2016-03-14 00:22:11,678 INFO org.apache.hadoop.yarn.server.resourcemanager.amlauncher.AMLauncher: Done launching container Container: [ContainerId: container_1457932032699_0002_01_000001, NodeId: vishal-VirtualBox:33502, NodeHttpAddress: vishal-VirtualBox:8042, Resource: <memory:2048, vCores:1>, Priority: 0, Token: Token { kind: ContainerToken, service: 127.0.1.1:33502 }, ] for AM appattempt_1457932032699_0002_000001
2016-03-14 00:22:11,679 INFO org.apache.hadoop.yarn.server.resourcemanager.rmapp.attempt.RMAppAttemptImpl: appattempt_1457932032699_0002_000001 State change from ALLOCATED to LAUNCHED
2016-03-14 00:22:12,518 INFO org.apache.hadoop.yarn.server.resourcemanager.rmcontainer.RMContainerImpl: container_1457932032699_0002_01_000001 Container Transitioned from ACQUIRED to RUNNING
2016-03-14 00:22:23,076 INFO SecurityLogger.org.apache.hadoop.ipc.Server: Auth successful for appattempt_1457932032699_0002_000001 (auth:SIMPLE)
2016-03-14 00:22:23,086 INFO org.apache.hadoop.yarn.server.resourcemanager.ApplicationMasterService: AM registration appattempt_1457932032699_0002_000001
2016-03-14 00:22:23,086 INFO org.apache.hadoop.yarn.server.resourcemanager.RMAuditLogger: USER=vishal	IP=127.0.0.1	OPERATION=Register App Master	TARGET=ApplicationMasterService	RESULT=SUCCESS	APPID=application_1457932032699_0002	APPATTEMPTID=appattempt_1457932032699_0002_000001
2016-03-14 00:22:23,087 INFO org.apache.hadoop.yarn.server.resourcemanager.rmapp.attempt.RMAppAttemptImpl: appattempt_1457932032699_0002_000001 State change from LAUNCHED to RUNNING
2016-03-14 00:22:23,087 INFO org.apache.hadoop.yarn.server.resourcemanager.rmapp.RMAppImpl: application_1457932032699_0002 State change from ACCEPTED to RUNNING
2016-03-14 00:22:24,543 INFO org.apache.hadoop.yarn.server.resourcemanager.rmcontainer.RMContainerImpl: container_1457932032699_0002_01_000002 Container Transitioned from NEW to ALLOCATED
2016-03-14 00:22:24,543 INFO org.apache.hadoop.yarn.server.resourcemanager.RMAuditLogger: USER=vishal	OPERATION=AM Allocated Container	TARGET=SchedulerApp	RESULT=SUCCESS	APPID=application_1457932032699_0002	CONTAINERID=container_1457932032699_0002_01_000002
2016-03-14 00:22:24,543 INFO org.apache.hadoop.yarn.server.resourcemanager.scheduler.SchedulerNode: Assigned container container_1457932032699_0002_01_000002 of capacity <memory:1024, vCores:1> on host vishal-VirtualBox:33502, which has 2 containers, <memory:3072, vCores:2> used and <memory:5120, vCores:6> available after allocation
2016-03-14 00:22:24,543 INFO org.apache.hadoop.yarn.server.resourcemanager.scheduler.capacity.LeafQueue: assignedContainer application attempt=appattempt_1457932032699_0002_000001 container=Container: [ContainerId: container_1457932032699_0002_01_000002, NodeId: vishal-VirtualBox:33502, NodeHttpAddress: vishal-VirtualBox:8042, Resource: <memory:1024, vCores:1>, Priority: 20, Token: null, ] queue=default: capacity=1.0, absoluteCapacity=1.0, usedResources=<memory:2048, vCores:1>, usedCapacity=0.25, absoluteUsedCapacity=0.25, numApps=1, numContainers=1 clusterResource=<memory:8192, vCores:8>
2016-03-14 00:22:24,543 INFO org.apache.hadoop.yarn.server.resourcemanager.scheduler.capacity.ParentQueue: Re-sorting assigned queue: root.default stats: default: capacity=1.0, absoluteCapacity=1.0, usedResources=<memory:3072, vCores:2>, usedCapacity=0.375, absoluteUsedCapacity=0.375, numApps=1, numContainers=2
2016-03-14 00:22:24,544 INFO org.apache.hadoop.yarn.server.resourcemanager.scheduler.capacity.ParentQueue: assignedContainer queue=root usedCapacity=0.375 absoluteUsedCapacity=0.375 used=<memory:3072, vCores:2> cluster=<memory:8192, vCores:8>
2016-03-14 00:22:25,366 INFO org.apache.hadoop.yarn.server.resourcemanager.security.NMTokenSecretManagerInRM: Sending NMToken for nodeId : vishal-VirtualBox:33502 for container : container_1457932032699_0002_01_000002
2016-03-14 00:22:25,377 INFO org.apache.hadoop.yarn.server.resourcemanager.rmcontainer.RMContainerImpl: container_1457932032699_0002_01_000002 Container Transitioned from ALLOCATED to ACQUIRED
2016-03-14 00:22:26,421 INFO org.apache.hadoop.yarn.server.resourcemanager.scheduler.AppSchedulingInfo: checking for deactivate of application :application_1457932032699_0002
2016-03-14 00:22:26,547 INFO org.apache.hadoop.yarn.server.resourcemanager.rmcontainer.RMContainerImpl: container_1457932032699_0002_01_000002 Container Transitioned from ACQUIRED to RUNNING
2016-03-14 00:22:32,238 INFO org.apache.hadoop.yarn.server.resourcemanager.rmcontainer.RMContainerImpl: container_1457932032699_0002_01_000002 Container Transitioned from RUNNING to COMPLETED
2016-03-14 00:22:32,238 INFO org.apache.hadoop.yarn.server.resourcemanager.scheduler.common.fica.FiCaSchedulerApp: Completed container: container_1457932032699_0002_01_000002 in state: COMPLETED event:FINISHED
2016-03-14 00:22:32,238 INFO org.apache.hadoop.yarn.server.resourcemanager.RMAuditLogger: USER=vishal	OPERATION=AM Released Container	TARGET=SchedulerApp	RESULT=SUCCESS	APPID=application_1457932032699_0002	CONTAINERID=container_1457932032699_0002_01_000002
2016-03-14 00:22:32,238 INFO org.apache.hadoop.yarn.server.resourcemanager.scheduler.SchedulerNode: Released container container_1457932032699_0002_01_000002 of capacity <memory:1024, vCores:1> on host vishal-VirtualBox:33502, which currently has 1 containers, <memory:2048, vCores:1> used and <memory:6144, vCores:7> available, release resources=true
2016-03-14 00:22:32,238 INFO org.apache.hadoop.yarn.server.resourcemanager.scheduler.capacity.LeafQueue: default used=<memory:2048, vCores:1> numContainers=1 user=vishal user-resources=<memory:2048, vCores:1>
2016-03-14 00:22:32,240 INFO org.apache.hadoop.yarn.server.resourcemanager.scheduler.capacity.LeafQueue: completedContainer container=Container: [ContainerId: container_1457932032699_0002_01_000002, NodeId: vishal-VirtualBox:33502, NodeHttpAddress: vishal-VirtualBox:8042, Resource: <memory:1024, vCores:1>, Priority: 20, Token: Token { kind: ContainerToken, service: 127.0.1.1:33502 }, ] queue=default: capacity=1.0, absoluteCapacity=1.0, usedResources=<memory:2048, vCores:1>, usedCapacity=0.25, absoluteUsedCapacity=0.25, numApps=1, numContainers=1 cluster=<memory:8192, vCores:8>
2016-03-14 00:22:32,240 INFO org.apache.hadoop.yarn.server.resourcemanager.scheduler.capacity.ParentQueue: completedContainer queue=root usedCapacity=0.25 absoluteUsedCapacity=0.25 used=<memory:2048, vCores:1> cluster=<memory:8192, vCores:8>
2016-03-14 00:22:32,240 INFO org.apache.hadoop.yarn.server.resourcemanager.scheduler.capacity.ParentQueue: Re-sorting completed queue: root.default stats: default: capacity=1.0, absoluteCapacity=1.0, usedResources=<memory:2048, vCores:1>, usedCapacity=0.25, absoluteUsedCapacity=0.25, numApps=1, numContainers=1
2016-03-14 00:22:32,240 INFO org.apache.hadoop.yarn.server.resourcemanager.scheduler.capacity.CapacityScheduler: Application attempt appattempt_1457932032699_0002_000001 released container container_1457932032699_0002_01_000002 on node: host: vishal-VirtualBox:33502 #containers=1 available=<memory:6144, vCores:7> used=<memory:2048, vCores:1> with event: FINISHED
2016-03-14 00:22:33,243 INFO org.apache.hadoop.yarn.server.resourcemanager.rmcontainer.RMContainerImpl: container_1457932032699_0002_01_000003 Container Transitioned from NEW to ALLOCATED
2016-03-14 00:22:33,243 INFO org.apache.hadoop.yarn.server.resourcemanager.RMAuditLogger: USER=vishal	OPERATION=AM Allocated Container	TARGET=SchedulerApp	RESULT=SUCCESS	APPID=application_1457932032699_0002	CONTAINERID=container_1457932032699_0002_01_000003
2016-03-14 00:22:33,243 INFO org.apache.hadoop.yarn.server.resourcemanager.scheduler.SchedulerNode: Assigned container container_1457932032699_0002_01_000003 of capacity <memory:1024, vCores:1> on host vishal-VirtualBox:33502, which has 2 containers, <memory:3072, vCores:2> used and <memory:5120, vCores:6> available after allocation
2016-03-14 00:22:33,243 INFO org.apache.hadoop.yarn.server.resourcemanager.scheduler.capacity.LeafQueue: assignedContainer application attempt=appattempt_1457932032699_0002_000001 container=Container: [ContainerId: container_1457932032699_0002_01_000003, NodeId: vishal-VirtualBox:33502, NodeHttpAddress: vishal-VirtualBox:8042, Resource: <memory:1024, vCores:1>, Priority: 10, Token: null, ] queue=default: capacity=1.0, absoluteCapacity=1.0, usedResources=<memory:2048, vCores:1>, usedCapacity=0.25, absoluteUsedCapacity=0.25, numApps=1, numContainers=1 clusterResource=<memory:8192, vCores:8>
2016-03-14 00:22:33,244 INFO org.apache.hadoop.yarn.server.resourcemanager.scheduler.capacity.ParentQueue: Re-sorting assigned queue: root.default stats: default: capacity=1.0, absoluteCapacity=1.0, usedResources=<memory:3072, vCores:2>, usedCapacity=0.375, absoluteUsedCapacity=0.375, numApps=1, numContainers=2
2016-03-14 00:22:33,244 INFO org.apache.hadoop.yarn.server.resourcemanager.scheduler.capacity.ParentQueue: assignedContainer queue=root usedCapacity=0.375 absoluteUsedCapacity=0.375 used=<memory:3072, vCores:2> cluster=<memory:8192, vCores:8>
2016-03-14 00:22:33,486 INFO org.apache.hadoop.yarn.server.resourcemanager.rmcontainer.RMContainerImpl: container_1457932032699_0002_01_000003 Container Transitioned from ALLOCATED to ACQUIRED
2016-03-14 00:22:34,247 INFO org.apache.hadoop.yarn.server.resourcemanager.rmcontainer.RMContainerImpl: container_1457932032699_0002_01_000003 Container Transitioned from ACQUIRED to RUNNING
2016-03-14 00:22:34,489 INFO org.apache.hadoop.yarn.server.resourcemanager.scheduler.AppSchedulingInfo: checking for deactivate of application :application_1457932032699_0002
2016-03-14 00:22:39,942 INFO org.apache.hadoop.yarn.server.resourcemanager.rmapp.attempt.RMAppAttemptImpl: Updating application attempt appattempt_1457932032699_0002_000001 with final state: FINISHING, and exit status: -1000
2016-03-14 00:22:39,943 INFO org.apache.hadoop.yarn.server.resourcemanager.rmapp.attempt.RMAppAttemptImpl: appattempt_1457932032699_0002_000001 State change from RUNNING to FINAL_SAVING
2016-03-14 00:22:39,943 INFO org.apache.hadoop.yarn.server.resourcemanager.rmapp.RMAppImpl: Updating application application_1457932032699_0002 with final state: FINISHING
2016-03-14 00:22:39,943 INFO org.apache.hadoop.yarn.server.resourcemanager.rmapp.RMAppImpl: application_1457932032699_0002 State change from RUNNING to FINAL_SAVING
2016-03-14 00:22:39,943 INFO org.apache.hadoop.yarn.server.resourcemanager.recovery.RMStateStore: Updating info for app: application_1457932032699_0002
2016-03-14 00:22:39,943 INFO org.apache.hadoop.yarn.server.resourcemanager.rmapp.attempt.RMAppAttemptImpl: appattempt_1457932032699_0002_000001 State change from FINAL_SAVING to FINISHING
2016-03-14 00:22:39,943 INFO org.apache.hadoop.yarn.server.resourcemanager.rmapp.RMAppImpl: application_1457932032699_0002 State change from FINAL_SAVING to FINISHING
2016-03-14 00:22:40,501 INFO org.apache.hadoop.yarn.server.resourcemanager.rmcontainer.RMContainerImpl: container_1457932032699_0002_01_000003 Container Transitioned from RUNNING to COMPLETED
2016-03-14 00:22:40,501 INFO org.apache.hadoop.yarn.server.resourcemanager.scheduler.common.fica.FiCaSchedulerApp: Completed container: container_1457932032699_0002_01_000003 in state: COMPLETED event:FINISHED
2016-03-14 00:22:40,501 INFO org.apache.hadoop.yarn.server.resourcemanager.RMAuditLogger: USER=vishal	OPERATION=AM Released Container	TARGET=SchedulerApp	RESULT=SUCCESS	APPID=application_1457932032699_0002	CONTAINERID=container_1457932032699_0002_01_000003
2016-03-14 00:22:40,501 INFO org.apache.hadoop.yarn.server.resourcemanager.scheduler.SchedulerNode: Released container container_1457932032699_0002_01_000003 of capacity <memory:1024, vCores:1> on host vishal-VirtualBox:33502, which currently has 1 containers, <memory:2048, vCores:1> used and <memory:6144, vCores:7> available, release resources=true
2016-03-14 00:22:40,501 INFO org.apache.hadoop.yarn.server.resourcemanager.scheduler.capacity.LeafQueue: default used=<memory:2048, vCores:1> numContainers=1 user=vishal user-resources=<memory:2048, vCores:1>
2016-03-14 00:22:40,503 INFO org.apache.hadoop.yarn.server.resourcemanager.scheduler.capacity.LeafQueue: completedContainer container=Container: [ContainerId: container_1457932032699_0002_01_000003, NodeId: vishal-VirtualBox:33502, NodeHttpAddress: vishal-VirtualBox:8042, Resource: <memory:1024, vCores:1>, Priority: 10, Token: Token { kind: ContainerToken, service: 127.0.1.1:33502 }, ] queue=default: capacity=1.0, absoluteCapacity=1.0, usedResources=<memory:2048, vCores:1>, usedCapacity=0.25, absoluteUsedCapacity=0.25, numApps=1, numContainers=1 cluster=<memory:8192, vCores:8>
2016-03-14 00:22:40,503 INFO org.apache.hadoop.yarn.server.resourcemanager.scheduler.capacity.ParentQueue: completedContainer queue=root usedCapacity=0.25 absoluteUsedCapacity=0.25 used=<memory:2048, vCores:1> cluster=<memory:8192, vCores:8>
2016-03-14 00:22:40,503 INFO org.apache.hadoop.yarn.server.resourcemanager.scheduler.capacity.ParentQueue: Re-sorting completed queue: root.default stats: default: capacity=1.0, absoluteCapacity=1.0, usedResources=<memory:2048, vCores:1>, usedCapacity=0.25, absoluteUsedCapacity=0.25, numApps=1, numContainers=1
2016-03-14 00:22:40,503 INFO org.apache.hadoop.yarn.server.resourcemanager.scheduler.capacity.CapacityScheduler: Application attempt appattempt_1457932032699_0002_000001 released container container_1457932032699_0002_01_000003 on node: host: vishal-VirtualBox:33502 #containers=1 available=<memory:6144, vCores:7> used=<memory:2048, vCores:1> with event: FINISHED
2016-03-14 00:22:40,948 INFO org.apache.hadoop.yarn.server.resourcemanager.ApplicationMasterService: application_1457932032699_0002 unregistered successfully. 
2016-03-14 00:22:46,518 INFO org.apache.hadoop.yarn.server.resourcemanager.rmcontainer.RMContainerImpl: container_1457932032699_0002_01_000001 Container Transitioned from RUNNING to COMPLETED
2016-03-14 00:22:46,518 INFO org.apache.hadoop.yarn.server.resourcemanager.scheduler.common.fica.FiCaSchedulerApp: Completed container: container_1457932032699_0002_01_000001 in state: COMPLETED event:FINISHED
2016-03-14 00:22:46,518 INFO org.apache.hadoop.yarn.server.resourcemanager.RMAuditLogger: USER=vishal	OPERATION=AM Released Container	TARGET=SchedulerApp	RESULT=SUCCESS	APPID=application_1457932032699_0002	CONTAINERID=container_1457932032699_0002_01_000001
2016-03-14 00:22:46,518 INFO org.apache.hadoop.yarn.server.resourcemanager.scheduler.SchedulerNode: Released container container_1457932032699_0002_01_000001 of capacity <memory:2048, vCores:1> on host vishal-VirtualBox:33502, which currently has 0 containers, <memory:0, vCores:0> used and <memory:8192, vCores:8> available, release resources=true
2016-03-14 00:22:46,519 INFO org.apache.hadoop.yarn.server.resourcemanager.scheduler.capacity.LeafQueue: default used=<memory:0, vCores:0> numContainers=0 user=vishal user-resources=<memory:0, vCores:0>
2016-03-14 00:22:46,519 INFO org.apache.hadoop.yarn.server.resourcemanager.scheduler.capacity.LeafQueue: completedContainer container=Container: [ContainerId: container_1457932032699_0002_01_000001, NodeId: vishal-VirtualBox:33502, NodeHttpAddress: vishal-VirtualBox:8042, Resource: <memory:2048, vCores:1>, Priority: 0, Token: Token { kind: ContainerToken, service: 127.0.1.1:33502 }, ] queue=default: capacity=1.0, absoluteCapacity=1.0, usedResources=<memory:0, vCores:0>, usedCapacity=0.0, absoluteUsedCapacity=0.0, numApps=1, numContainers=0 cluster=<memory:8192, vCores:8>
2016-03-14 00:22:46,519 INFO org.apache.hadoop.yarn.server.resourcemanager.scheduler.capacity.ParentQueue: completedContainer queue=root usedCapacity=0.0 absoluteUsedCapacity=0.0 used=<memory:0, vCores:0> cluster=<memory:8192, vCores:8>
2016-03-14 00:22:46,519 INFO org.apache.hadoop.yarn.server.resourcemanager.scheduler.capacity.ParentQueue: Re-sorting completed queue: root.default stats: default: capacity=1.0, absoluteCapacity=1.0, usedResources=<memory:0, vCores:0>, usedCapacity=0.0, absoluteUsedCapacity=0.0, numApps=1, numContainers=0
2016-03-14 00:22:46,519 INFO org.apache.hadoop.yarn.server.resourcemanager.scheduler.capacity.CapacityScheduler: Application attempt appattempt_1457932032699_0002_000001 released container container_1457932032699_0002_01_000001 on node: host: vishal-VirtualBox:33502 #containers=0 available=<memory:8192, vCores:8> used=<memory:0, vCores:0> with event: FINISHED
2016-03-14 00:22:46,520 INFO org.apache.hadoop.yarn.server.resourcemanager.ApplicationMasterService: Unregistering app attempt : appattempt_1457932032699_0002_000001
2016-03-14 00:22:46,521 INFO org.apache.hadoop.yarn.server.resourcemanager.security.AMRMTokenSecretManager: Application finished, removing password for appattempt_1457932032699_0002_000001
2016-03-14 00:22:46,521 INFO org.apache.hadoop.yarn.server.resourcemanager.rmapp.attempt.RMAppAttemptImpl: appattempt_1457932032699_0002_000001 State change from FINISHING to FINISHED
2016-03-14 00:22:46,521 INFO org.apache.hadoop.yarn.server.resourcemanager.rmapp.RMAppImpl: application_1457932032699_0002 State change from FINISHING to FINISHED
2016-03-14 00:22:46,521 INFO org.apache.hadoop.yarn.server.resourcemanager.RMAuditLogger: USER=vishal	OPERATION=Application Finished - Succeeded	TARGET=RMAppManager	RESULT=SUCCESS	APPID=application_1457932032699_0002
2016-03-14 00:22:46,521 INFO org.apache.hadoop.yarn.server.resourcemanager.RMAppManager$ApplicationSummary: appId=application_1457932032699_0002,name=word count,user=vishal,queue=default,state=FINISHED,trackingUrl=http://vishal-VirtualBox:8088/proxy/application_1457932032699_0002/,appMasterHost=vishal-VirtualBox,startTime=1457932931294,finishTime=1457932959943,finalStatus=SUCCEEDED,memorySeconds=86994,vcoreSeconds=49,preemptedAMContainers=0,preemptedNonAMContainers=0,preemptedResources=<memory:0\, vCores:0>,applicationType=MAPREDUCE
2016-03-14 00:22:46,522 INFO org.apache.hadoop.yarn.server.resourcemanager.scheduler.capacity.CapacityScheduler: Application Attempt appattempt_1457932032699_0002_000001 is done. finalState=FINISHED
2016-03-14 00:22:46,522 INFO org.apache.hadoop.yarn.server.resourcemanager.scheduler.AppSchedulingInfo: Application application_1457932032699_0002 requests cleared
2016-03-14 00:22:46,522 INFO org.apache.hadoop.yarn.server.resourcemanager.scheduler.capacity.LeafQueue: Application removed - appId: application_1457932032699_0002 user: vishal queue: default #user-pending-applications: 0 #user-active-applications: 0 #queue-pending-applications: 0 #queue-active-applications: 0
2016-03-14 00:22:46,522 INFO org.apache.hadoop.yarn.server.resourcemanager.scheduler.capacity.ParentQueue: Application removed - appId: application_1457932032699_0002 user: vishal leaf-queue of parent: root #applications: 0
2016-03-14 00:22:46,524 INFO org.apache.hadoop.yarn.server.resourcemanager.amlauncher.AMLauncher: Cleaning master appattempt_1457932032699_0002_000001
2016-03-14 00:22:47,572 INFO org.apache.hadoop.yarn.server.resourcemanager.scheduler.capacity.CapacityScheduler: Null container completed...
2016-03-14 00:50:48,787 ERROR org.apache.hadoop.yarn.server.resourcemanager.ResourceManager: RECEIVED SIGNAL 15: SIGTERM
2016-03-14 00:50:48,863 ERROR org.apache.hadoop.security.token.delegation.AbstractDelegationTokenSecretManager: ExpiredTokenRemover received java.lang.InterruptedException: sleep interrupted
2016-03-14 00:50:48,864 INFO org.mortbay.log: Stopped HttpServer2$SelectChannelConnectorWithSafeStartup@0.0.0.0:8088
2016-03-14 00:50:48,864 WARN org.apache.hadoop.http.HttpServer2: HttpServer Acceptor: isRunning is false. Rechecking.
2016-03-14 00:50:48,868 WARN org.apache.hadoop.http.HttpServer2: HttpServer Acceptor: isRunning is false
2016-03-14 00:50:48,871 INFO org.apache.hadoop.ipc.Server: Stopping server on 8032
2016-03-14 00:50:48,876 INFO org.apache.hadoop.ipc.Server: Stopping IPC Server listener on 8032
2016-03-14 00:50:48,876 INFO org.apache.hadoop.ipc.Server: Stopping IPC Server Responder
2016-03-14 00:50:48,876 INFO org.apache.hadoop.ipc.Server: Stopping server on 8033
2016-03-14 00:50:48,877 INFO org.apache.hadoop.ipc.Server: Stopping IPC Server listener on 8033
2016-03-14 00:50:48,878 INFO org.apache.hadoop.ipc.Server: Stopping IPC Server Responder
2016-03-14 00:50:48,878 INFO org.apache.hadoop.yarn.server.resourcemanager.ResourceManager: Transitioning to standby state
2016-03-14 00:50:48,879 WARN org.apache.hadoop.yarn.server.resourcemanager.amlauncher.ApplicationMasterLauncher: org.apache.hadoop.yarn.server.resourcemanager.amlauncher.ApplicationMasterLauncher$LauncherThread interrupted. Returning.
2016-03-14 00:50:48,879 INFO org.apache.hadoop.ipc.Server: Stopping server on 8030
2016-03-14 00:50:48,885 INFO org.apache.hadoop.ipc.Server: Stopping IPC Server listener on 8030
2016-03-14 00:50:48,885 INFO org.apache.hadoop.ipc.Server: Stopping IPC Server Responder
2016-03-14 00:50:48,885 INFO org.apache.hadoop.ipc.Server: Stopping server on 8031
2016-03-14 00:50:48,890 INFO org.apache.hadoop.ipc.Server: Stopping IPC Server listener on 8031
2016-03-14 00:50:48,891 INFO org.apache.hadoop.ipc.Server: Stopping IPC Server Responder
2016-03-14 00:50:48,891 INFO org.apache.hadoop.yarn.util.AbstractLivelinessMonitor: NMLivelinessMonitor thread interrupted
2016-03-14 00:50:48,891 ERROR org.apache.hadoop.yarn.server.resourcemanager.ResourceManager: Returning, interrupted : java.lang.InterruptedException
2016-03-14 00:50:48,891 INFO org.apache.hadoop.yarn.event.AsyncDispatcher: AsyncDispatcher is draining to stop, igonring any new events.
2016-03-14 00:50:48,892 INFO org.apache.hadoop.yarn.util.AbstractLivelinessMonitor: AMLivelinessMonitor thread interrupted
2016-03-14 00:50:48,892 INFO org.apache.hadoop.yarn.util.AbstractLivelinessMonitor: AMLivelinessMonitor thread interrupted
2016-03-14 00:50:48,892 INFO org.apache.hadoop.yarn.util.AbstractLivelinessMonitor: org.apache.hadoop.yarn.server.resourcemanager.rmcontainer.ContainerAllocationExpirer thread interrupted
2016-03-14 00:50:48,892 ERROR org.apache.hadoop.security.token.delegation.AbstractDelegationTokenSecretManager: ExpiredTokenRemover received java.lang.InterruptedException: sleep interrupted
2016-03-14 00:50:48,893 INFO org.apache.hadoop.metrics2.impl.MetricsSystemImpl: Stopping ResourceManager metrics system...
2016-03-14 00:50:48,894 INFO org.apache.hadoop.metrics2.impl.MetricsSystemImpl: ResourceManager metrics system stopped.
2016-03-14 00:50:48,895 INFO org.apache.hadoop.metrics2.impl.MetricsSystemImpl: ResourceManager metrics system shutdown complete.
2016-03-14 00:50:48,895 INFO org.apache.hadoop.yarn.event.AsyncDispatcher: AsyncDispatcher is draining to stop, igonring any new events.
2016-03-14 00:50:48,895 INFO org.apache.hadoop.yarn.server.resourcemanager.ResourceManager: Transitioned to standby state
2016-03-14 00:50:48,895 INFO org.apache.hadoop.yarn.server.resourcemanager.ResourceManager: SHUTDOWN_MSG: 
/************************************************************
SHUTDOWN_MSG: Shutting down ResourceManager at vishal-VirtualBox/127.0.1.1
************************************************************/
2016-03-18 16:38:11,409 INFO org.apache.hadoop.yarn.server.resourcemanager.ResourceManager: STARTUP_MSG: 
/************************************************************
STARTUP_MSG: Starting ResourceManager
STARTUP_MSG:   host = vishal-VirtualBox/127.0.1.1
STARTUP_MSG:   args = []
STARTUP_MSG:   version = 2.7.2
STARTUP_MSG:   build = https://git-wip-us.apache.org/repos/asf/hadoop.git -r b165c4fe8a74265c792ce23f546c64604acf0e41; compiled by 'jenkins' on 2016-01-26T00:08Z
STARTUP_MSG:   java = 1.8.0_74
************************************************************/
2016-03-18 16:38:11,520 INFO org.apache.hadoop.yarn.server.resourcemanager.ResourceManager: registered UNIX signal handlers for [TERM, HUP, INT]
2016-03-18 16:38:12,696 INFO org.apache.hadoop.conf.Configuration: found resource core-site.xml at file:/usr/local/hadoop/etc/hadoop/core-site.xml
2016-03-18 16:38:12,927 WARN org.apache.hadoop.util.NativeCodeLoader: Unable to load native-hadoop library for your platform... using builtin-java classes where applicable
2016-03-18 16:38:13,121 INFO org.apache.hadoop.security.Groups: clearing userToGroupsMap cache
2016-03-18 16:38:13,446 INFO org.apache.hadoop.conf.Configuration: found resource yarn-site.xml at file:/usr/local/hadoop/etc/hadoop/yarn-site.xml
2016-03-18 16:38:14,082 INFO org.apache.hadoop.yarn.event.AsyncDispatcher: Registering class org.apache.hadoop.yarn.server.resourcemanager.RMFatalEventType for class org.apache.hadoop.yarn.server.resourcemanager.ResourceManager$RMFatalEventDispatcher
2016-03-18 16:38:14,906 INFO org.apache.hadoop.yarn.server.resourcemanager.security.NMTokenSecretManagerInRM: NMTokenKeyRollingInterval: 86400000ms and NMTokenKeyActivationDelay: 900000ms
2016-03-18 16:38:14,955 INFO org.apache.hadoop.yarn.server.resourcemanager.security.RMContainerTokenSecretManager: ContainerTokenKeyRollingInterval: 86400000ms and ContainerTokenKeyActivationDelay: 900000ms
2016-03-18 16:38:14,997 INFO org.apache.hadoop.yarn.server.resourcemanager.security.AMRMTokenSecretManager: AMRMTokenKeyRollingInterval: 86400000ms and AMRMTokenKeyActivationDelay: 900000 ms
2016-03-18 16:38:15,203 INFO org.apache.hadoop.yarn.event.AsyncDispatcher: Registering class org.apache.hadoop.yarn.server.resourcemanager.recovery.RMStateStoreEventType for class org.apache.hadoop.yarn.server.resourcemanager.recovery.RMStateStore$ForwardingEventHandler
2016-03-18 16:38:15,205 INFO org.apache.hadoop.yarn.event.AsyncDispatcher: Registering class org.apache.hadoop.yarn.server.resourcemanager.NodesListManagerEventType for class org.apache.hadoop.yarn.server.resourcemanager.NodesListManager
2016-03-18 16:38:15,205 INFO org.apache.hadoop.yarn.server.resourcemanager.ResourceManager: Using Scheduler: org.apache.hadoop.yarn.server.resourcemanager.scheduler.capacity.CapacityScheduler
2016-03-18 16:38:15,302 INFO org.apache.hadoop.yarn.event.AsyncDispatcher: Registering class org.apache.hadoop.yarn.server.resourcemanager.scheduler.event.SchedulerEventType for class org.apache.hadoop.yarn.server.resourcemanager.ResourceManager$SchedulerEventDispatcher
2016-03-18 16:38:15,303 INFO org.apache.hadoop.yarn.event.AsyncDispatcher: Registering class org.apache.hadoop.yarn.server.resourcemanager.rmapp.RMAppEventType for class org.apache.hadoop.yarn.server.resourcemanager.ResourceManager$ApplicationEventDispatcher
2016-03-18 16:38:15,304 INFO org.apache.hadoop.yarn.event.AsyncDispatcher: Registering class org.apache.hadoop.yarn.server.resourcemanager.rmapp.attempt.RMAppAttemptEventType for class org.apache.hadoop.yarn.server.resourcemanager.ResourceManager$ApplicationAttemptEventDispatcher
2016-03-18 16:38:15,311 INFO org.apache.hadoop.yarn.event.AsyncDispatcher: Registering class org.apache.hadoop.yarn.server.resourcemanager.rmnode.RMNodeEventType for class org.apache.hadoop.yarn.server.resourcemanager.ResourceManager$NodeEventDispatcher
2016-03-18 16:38:15,688 INFO org.apache.hadoop.metrics2.impl.MetricsConfig: loaded properties from hadoop-metrics2.properties
2016-03-18 16:38:16,063 INFO org.apache.hadoop.metrics2.impl.MetricsSystemImpl: Scheduled snapshot period at 10 second(s).
2016-03-18 16:38:16,063 INFO org.apache.hadoop.metrics2.impl.MetricsSystemImpl: ResourceManager metrics system started
2016-03-18 16:38:16,105 INFO org.apache.hadoop.yarn.event.AsyncDispatcher: Registering class org.apache.hadoop.yarn.server.resourcemanager.RMAppManagerEventType for class org.apache.hadoop.yarn.server.resourcemanager.RMAppManager
2016-03-18 16:38:16,133 INFO org.apache.hadoop.yarn.event.AsyncDispatcher: Registering class org.apache.hadoop.yarn.server.resourcemanager.amlauncher.AMLauncherEventType for class org.apache.hadoop.yarn.server.resourcemanager.amlauncher.ApplicationMasterLauncher
2016-03-18 16:38:16,135 INFO org.apache.hadoop.yarn.server.resourcemanager.RMNMInfo: Registered RMNMInfo MBean
2016-03-18 16:38:16,142 INFO org.apache.hadoop.yarn.security.YarnAuthorizationProvider: org.apache.hadoop.yarn.security.ConfiguredYarnAuthorizer is instiantiated.
2016-03-18 16:38:16,143 INFO org.apache.hadoop.util.HostsFileReader: Refreshing hosts (include/exclude) list
2016-03-18 16:38:16,167 INFO org.apache.hadoop.conf.Configuration: found resource capacity-scheduler.xml at file:/usr/local/hadoop/etc/hadoop/capacity-scheduler.xml
2016-03-18 16:38:16,393 INFO org.apache.hadoop.yarn.server.resourcemanager.scheduler.capacity.CapacitySchedulerConfiguration: max alloc mb per queue for root is undefined
2016-03-18 16:38:16,394 INFO org.apache.hadoop.yarn.server.resourcemanager.scheduler.capacity.CapacitySchedulerConfiguration: max alloc vcore per queue for root is undefined
2016-03-18 16:38:16,406 INFO org.apache.hadoop.yarn.server.resourcemanager.scheduler.capacity.ParentQueue: root, capacity=1.0, asboluteCapacity=1.0, maxCapacity=1.0, asboluteMaxCapacity=1.0, state=RUNNING, acls=SUBMIT_APP:*ADMINISTER_QUEUE:*, labels=*,
, reservationsContinueLooking=true
2016-03-18 16:38:16,406 INFO org.apache.hadoop.yarn.server.resourcemanager.scheduler.capacity.ParentQueue: Initialized parent-queue root name=root, fullname=root
2016-03-18 16:38:16,447 INFO org.apache.hadoop.yarn.server.resourcemanager.scheduler.capacity.CapacitySchedulerConfiguration: max alloc mb per queue for root.default is undefined
2016-03-18 16:38:16,448 INFO org.apache.hadoop.yarn.server.resourcemanager.scheduler.capacity.CapacitySchedulerConfiguration: max alloc vcore per queue for root.default is undefined
2016-03-18 16:38:16,449 INFO org.apache.hadoop.yarn.server.resourcemanager.scheduler.capacity.LeafQueue: Initializing default
capacity = 1.0 [= (float) configuredCapacity / 100 ]
asboluteCapacity = 1.0 [= parentAbsoluteCapacity * capacity ]
maxCapacity = 1.0 [= configuredMaxCapacity ]
absoluteMaxCapacity = 1.0 [= 1.0 maximumCapacity undefined, (parentAbsoluteMaxCapacity * maximumCapacity) / 100 otherwise ]
userLimit = 100 [= configuredUserLimit ]
userLimitFactor = 1.0 [= configuredUserLimitFactor ]
maxApplications = 10000 [= configuredMaximumSystemApplicationsPerQueue or (int)(configuredMaximumSystemApplications * absoluteCapacity)]
maxApplicationsPerUser = 10000 [= (int)(maxApplications * (userLimit / 100.0f) * userLimitFactor) ]
usedCapacity = 0.0 [= usedResourcesMemory / (clusterResourceMemory * absoluteCapacity)]
absoluteUsedCapacity = 0.0 [= usedResourcesMemory / clusterResourceMemory]
maxAMResourcePerQueuePercent = 0.1 [= configuredMaximumAMResourcePercent ]
minimumAllocationFactor = 0.875 [= (float)(maximumAllocationMemory - minimumAllocationMemory) / maximumAllocationMemory ]
maximumAllocation = <memory:8192, vCores:32> [= configuredMaxAllocation ]
numContainers = 0 [= currentNumContainers ]
state = RUNNING [= configuredState ]
acls = SUBMIT_APP:*ADMINISTER_QUEUE:* [= configuredAcls ]
nodeLocalityDelay = 40
labels=*,
nodeLocalityDelay = 40
reservationsContinueLooking = true
preemptionDisabled = true

2016-03-18 16:38:16,449 INFO org.apache.hadoop.yarn.server.resourcemanager.scheduler.capacity.CapacityScheduler: Initialized queue: default: capacity=1.0, absoluteCapacity=1.0, usedResources=<memory:0, vCores:0>, usedCapacity=0.0, absoluteUsedCapacity=0.0, numApps=0, numContainers=0
2016-03-18 16:38:16,450 INFO org.apache.hadoop.yarn.server.resourcemanager.scheduler.capacity.CapacityScheduler: Initialized queue: root: numChildQueue= 1, capacity=1.0, absoluteCapacity=1.0, usedResources=<memory:0, vCores:0>usedCapacity=0.0, numApps=0, numContainers=0
2016-03-18 16:38:16,463 INFO org.apache.hadoop.yarn.server.resourcemanager.scheduler.capacity.CapacityScheduler: Initialized root queue root: numChildQueue= 1, capacity=1.0, absoluteCapacity=1.0, usedResources=<memory:0, vCores:0>usedCapacity=0.0, numApps=0, numContainers=0
2016-03-18 16:38:16,463 INFO org.apache.hadoop.yarn.server.resourcemanager.scheduler.capacity.CapacityScheduler: Initialized queue mappings, override: false
2016-03-18 16:38:16,463 INFO org.apache.hadoop.yarn.server.resourcemanager.scheduler.capacity.CapacityScheduler: Initialized CapacityScheduler with calculator=class org.apache.hadoop.yarn.util.resource.DefaultResourceCalculator, minimumAllocation=<<memory:1024, vCores:1>>, maximumAllocation=<<memory:8192, vCores:32>>, asynchronousScheduling=false, asyncScheduleInterval=5ms
2016-03-18 16:38:16,520 INFO org.apache.hadoop.yarn.server.resourcemanager.metrics.SystemMetricsPublisher: YARN system metrics publishing service is not enabled
2016-03-18 16:38:16,520 INFO org.apache.hadoop.yarn.server.resourcemanager.ResourceManager: Transitioning to active state
2016-03-18 16:38:16,607 INFO org.apache.hadoop.yarn.server.resourcemanager.recovery.RMStateStore: Updating AMRMToken
2016-03-18 16:38:16,607 INFO org.apache.hadoop.yarn.server.resourcemanager.security.RMContainerTokenSecretManager: Rolling master-key for container-tokens
2016-03-18 16:38:16,608 INFO org.apache.hadoop.yarn.server.resourcemanager.security.NMTokenSecretManagerInRM: Rolling master-key for nm-tokens
2016-03-18 16:38:16,608 INFO org.apache.hadoop.security.token.delegation.AbstractDelegationTokenSecretManager: Updating the current master key for generating delegation tokens
2016-03-18 16:38:16,613 INFO org.apache.hadoop.yarn.server.resourcemanager.security.RMDelegationTokenSecretManager: storing master key with keyID 1
2016-03-18 16:38:16,613 INFO org.apache.hadoop.yarn.server.resourcemanager.recovery.RMStateStore: Storing RMDTMasterKey.
2016-03-18 16:38:16,657 INFO org.apache.hadoop.yarn.event.AsyncDispatcher: Registering class org.apache.hadoop.yarn.nodelabels.event.NodeLabelsStoreEventType for class org.apache.hadoop.yarn.nodelabels.CommonNodeLabelsManager$ForwardingEventHandler
2016-03-18 16:38:16,662 INFO org.apache.hadoop.security.token.delegation.AbstractDelegationTokenSecretManager: Starting expired delegation token remover thread, tokenRemoverScanInterval=60 min(s)
2016-03-18 16:38:16,674 INFO org.apache.hadoop.security.token.delegation.AbstractDelegationTokenSecretManager: Updating the current master key for generating delegation tokens
2016-03-18 16:38:16,675 INFO org.apache.hadoop.yarn.server.resourcemanager.security.RMDelegationTokenSecretManager: storing master key with keyID 2
2016-03-18 16:38:16,677 INFO org.apache.hadoop.yarn.server.resourcemanager.recovery.RMStateStore: Storing RMDTMasterKey.
2016-03-18 16:38:16,798 INFO org.apache.hadoop.ipc.CallQueueManager: Using callQueue class java.util.concurrent.LinkedBlockingQueue
2016-03-18 16:38:16,856 INFO org.apache.hadoop.ipc.Server: Starting Socket Reader #1 for port 8031
2016-03-18 16:38:16,921 INFO org.apache.hadoop.yarn.factories.impl.pb.RpcServerFactoryPBImpl: Adding protocol org.apache.hadoop.yarn.server.api.ResourceTrackerPB to the server
2016-03-18 16:38:16,926 INFO org.apache.hadoop.ipc.Server: IPC Server Responder: starting
2016-03-18 16:38:16,927 INFO org.apache.hadoop.ipc.Server: IPC Server listener on 8031: starting
2016-03-18 16:38:17,178 INFO org.apache.hadoop.ipc.CallQueueManager: Using callQueue class java.util.concurrent.LinkedBlockingQueue
2016-03-18 16:38:17,188 INFO org.apache.hadoop.ipc.Server: Starting Socket Reader #1 for port 8030
2016-03-18 16:38:17,212 INFO org.apache.hadoop.yarn.factories.impl.pb.RpcServerFactoryPBImpl: Adding protocol org.apache.hadoop.yarn.api.ApplicationMasterProtocolPB to the server
2016-03-18 16:38:17,222 INFO org.apache.hadoop.ipc.Server: IPC Server listener on 8030: starting
2016-03-18 16:38:17,223 INFO org.apache.hadoop.ipc.Server: IPC Server Responder: starting
2016-03-18 16:38:17,546 INFO org.apache.hadoop.ipc.CallQueueManager: Using callQueue class java.util.concurrent.LinkedBlockingQueue
2016-03-18 16:38:17,549 INFO org.apache.hadoop.ipc.Server: Starting Socket Reader #1 for port 8032
2016-03-18 16:38:17,559 INFO org.apache.hadoop.yarn.factories.impl.pb.RpcServerFactoryPBImpl: Adding protocol org.apache.hadoop.yarn.api.ApplicationClientProtocolPB to the server
2016-03-18 16:38:17,574 INFO org.apache.hadoop.ipc.Server: IPC Server Responder: starting
2016-03-18 16:38:17,578 INFO org.apache.hadoop.ipc.Server: IPC Server listener on 8032: starting
2016-03-18 16:38:17,643 INFO org.apache.hadoop.yarn.server.resourcemanager.ResourceManager: Transitioned to active state
2016-03-18 16:38:18,227 INFO org.mortbay.log: Logging to org.slf4j.impl.Log4jLoggerAdapter(org.mortbay.log) via org.mortbay.log.Slf4jLog
2016-03-18 16:38:18,273 INFO org.apache.hadoop.security.authentication.server.AuthenticationFilter: Unable to initialize FileSignerSecretProvider, falling back to use random secrets.
2016-03-18 16:38:18,293 INFO org.apache.hadoop.http.HttpRequestLog: Http request log for http.requests.resourcemanager is not defined
2016-03-18 16:38:18,333 INFO org.apache.hadoop.http.HttpServer2: Added global filter 'safety' (class=org.apache.hadoop.http.HttpServer2$QuotingInputFilter)
2016-03-18 16:38:18,387 INFO org.apache.hadoop.http.HttpServer2: Added filter RMAuthenticationFilter (class=org.apache.hadoop.yarn.server.security.http.RMAuthenticationFilter) to context cluster
2016-03-18 16:38:18,387 INFO org.apache.hadoop.http.HttpServer2: Added filter RMAuthenticationFilter (class=org.apache.hadoop.yarn.server.security.http.RMAuthenticationFilter) to context logs
2016-03-18 16:38:18,387 INFO org.apache.hadoop.http.HttpServer2: Added filter RMAuthenticationFilter (class=org.apache.hadoop.yarn.server.security.http.RMAuthenticationFilter) to context static
2016-03-18 16:38:18,387 INFO org.apache.hadoop.http.HttpServer2: Added filter static_user_filter (class=org.apache.hadoop.http.lib.StaticUserWebFilter$StaticUserFilter) to context cluster
2016-03-18 16:38:18,388 INFO org.apache.hadoop.http.HttpServer2: Added filter static_user_filter (class=org.apache.hadoop.http.lib.StaticUserWebFilter$StaticUserFilter) to context logs
2016-03-18 16:38:18,388 INFO org.apache.hadoop.http.HttpServer2: Added filter static_user_filter (class=org.apache.hadoop.http.lib.StaticUserWebFilter$StaticUserFilter) to context static
2016-03-18 16:38:18,392 INFO org.apache.hadoop.http.HttpServer2: adding path spec: /cluster/*
2016-03-18 16:38:18,392 INFO org.apache.hadoop.http.HttpServer2: adding path spec: /ws/*
2016-03-18 16:38:20,106 INFO org.apache.hadoop.yarn.webapp.WebApps: Registered webapp guice modules
2016-03-18 16:38:20,109 INFO org.apache.hadoop.http.HttpServer2: Jetty bound to port 8088
2016-03-18 16:38:20,109 INFO org.mortbay.log: jetty-6.1.26
2016-03-18 16:38:20,218 INFO org.mortbay.log: Extract jar:file:/usr/local/hadoop/share/hadoop/yarn/hadoop-yarn-common-2.7.2.jar!/webapps/cluster to /tmp/Jetty_0_0_0_0_8088_cluster____u0rgz3/webapp
2016-03-18 16:38:20,898 INFO org.apache.hadoop.security.token.delegation.AbstractDelegationTokenSecretManager: Updating the current master key for generating delegation tokens
2016-03-18 16:38:20,909 INFO org.apache.hadoop.security.token.delegation.AbstractDelegationTokenSecretManager: Starting expired delegation token remover thread, tokenRemoverScanInterval=60 min(s)
2016-03-18 16:38:20,918 INFO org.apache.hadoop.security.token.delegation.AbstractDelegationTokenSecretManager: Updating the current master key for generating delegation tokens
2016-03-18 16:38:25,740 INFO org.mortbay.log: Started HttpServer2$SelectChannelConnectorWithSafeStartup@0.0.0.0:8088
2016-03-18 16:38:25,740 INFO org.apache.hadoop.yarn.webapp.WebApps: Web app cluster started at 8088
2016-03-18 16:38:26,026 INFO org.apache.hadoop.ipc.CallQueueManager: Using callQueue class java.util.concurrent.LinkedBlockingQueue
2016-03-18 16:38:26,034 INFO org.apache.hadoop.ipc.Server: Starting Socket Reader #1 for port 8033
2016-03-18 16:38:26,035 INFO org.apache.hadoop.yarn.factories.impl.pb.RpcServerFactoryPBImpl: Adding protocol org.apache.hadoop.yarn.server.api.ResourceManagerAdministrationProtocolPB to the server
2016-03-18 16:38:26,044 INFO org.apache.hadoop.ipc.Server: IPC Server listener on 8033: starting
2016-03-18 16:38:26,045 INFO org.apache.hadoop.ipc.Server: IPC Server Responder: starting
2016-03-18 16:38:26,720 INFO org.apache.hadoop.yarn.util.RackResolver: Resolved vishal-VirtualBox to /default-rack
2016-03-18 16:38:26,752 INFO org.apache.hadoop.yarn.server.resourcemanager.rmnode.RMNodeImpl: vishal-VirtualBox:43965 Node Transitioned from NEW to RUNNING
2016-03-18 16:38:26,761 INFO org.apache.hadoop.yarn.server.resourcemanager.ResourceTrackerService: NodeManager from node vishal-VirtualBox(cmPort: 43965 httpPort: 8042) registered with capability: <memory:8192, vCores:8>, assigned nodeId vishal-VirtualBox:43965
2016-03-18 16:38:26,769 INFO org.apache.hadoop.yarn.server.resourcemanager.scheduler.capacity.CapacityScheduler: Added node vishal-VirtualBox:43965 clusterResource: <memory:8192, vCores:8>
2016-03-18 16:48:16,168 INFO org.apache.hadoop.yarn.server.resourcemanager.scheduler.AbstractYarnScheduler: Release request cache is cleaned up
2016-03-18 20:02:08,519 INFO org.apache.hadoop.yarn.server.resourcemanager.ClientRMService: Allocated new applicationId: 1
2016-03-18 20:02:11,712 INFO org.apache.hadoop.yarn.server.resourcemanager.rmapp.RMAppImpl: Storing application with id application_1458337096528_0001
2016-03-18 20:02:11,719 INFO org.apache.hadoop.yarn.server.resourcemanager.ClientRMService: Application with id 1 submitted by user vishal
2016-03-18 20:02:11,724 INFO org.apache.hadoop.yarn.server.resourcemanager.RMAuditLogger: USER=vishal	IP=127.0.0.1	OPERATION=Submit Application Request	TARGET=ClientRMService	RESULT=SUCCESS	APPID=application_1458337096528_0001
2016-03-18 20:02:11,743 INFO org.apache.hadoop.yarn.server.resourcemanager.recovery.RMStateStore: Storing info for app: application_1458337096528_0001
2016-03-18 20:02:11,743 INFO org.apache.hadoop.yarn.server.resourcemanager.rmapp.RMAppImpl: application_1458337096528_0001 State change from NEW to NEW_SAVING
2016-03-18 20:02:11,743 INFO org.apache.hadoop.yarn.server.resourcemanager.rmapp.RMAppImpl: application_1458337096528_0001 State change from NEW_SAVING to SUBMITTED
2016-03-18 20:02:11,745 INFO org.apache.hadoop.yarn.server.resourcemanager.scheduler.capacity.ParentQueue: Application added - appId: application_1458337096528_0001 user: vishal leaf-queue of parent: root #applications: 1
2016-03-18 20:02:11,745 INFO org.apache.hadoop.yarn.server.resourcemanager.scheduler.capacity.CapacityScheduler: Accepted application application_1458337096528_0001 from user: vishal, in queue: default
2016-03-18 20:02:11,783 INFO org.apache.hadoop.yarn.server.resourcemanager.rmapp.RMAppImpl: application_1458337096528_0001 State change from SUBMITTED to ACCEPTED
2016-03-18 20:02:11,828 INFO org.apache.hadoop.yarn.server.resourcemanager.ApplicationMasterService: Registering app attempt : appattempt_1458337096528_0001_000001
2016-03-18 20:02:11,831 INFO org.apache.hadoop.yarn.server.resourcemanager.rmapp.attempt.RMAppAttemptImpl: appattempt_1458337096528_0001_000001 State change from NEW to SUBMITTED
2016-03-18 20:02:11,866 WARN org.apache.hadoop.yarn.server.resourcemanager.scheduler.capacity.LeafQueue: maximum-am-resource-percent is insufficient to start a single application in queue, it is likely set too low. skipping enforcement to allow at least one application to start
2016-03-18 20:02:11,866 WARN org.apache.hadoop.yarn.server.resourcemanager.scheduler.capacity.LeafQueue: maximum-am-resource-percent is insufficient to start a single application in queue for user, it is likely set too low. skipping enforcement to allow at least one application to start
2016-03-18 20:02:11,867 INFO org.apache.hadoop.yarn.server.resourcemanager.scheduler.capacity.LeafQueue: Application application_1458337096528_0001 from user: vishal activated in queue: default
2016-03-18 20:02:11,867 INFO org.apache.hadoop.yarn.server.resourcemanager.scheduler.capacity.LeafQueue: Application added - appId: application_1458337096528_0001 user: org.apache.hadoop.yarn.server.resourcemanager.scheduler.capacity.LeafQueue$User@7f08eb2e, leaf-queue: default #user-pending-applications: 0 #user-active-applications: 1 #queue-pending-applications: 0 #queue-active-applications: 1
2016-03-18 20:02:11,872 INFO org.apache.hadoop.yarn.server.resourcemanager.scheduler.capacity.CapacityScheduler: Added Application Attempt appattempt_1458337096528_0001_000001 to scheduler from user vishal in queue default
2016-03-18 20:02:11,874 INFO org.apache.hadoop.yarn.server.resourcemanager.rmapp.attempt.RMAppAttemptImpl: appattempt_1458337096528_0001_000001 State change from SUBMITTED to SCHEDULED
2016-03-18 20:02:12,354 INFO org.apache.hadoop.yarn.server.resourcemanager.rmcontainer.RMContainerImpl: container_1458337096528_0001_01_000001 Container Transitioned from NEW to ALLOCATED
2016-03-18 20:02:12,355 INFO org.apache.hadoop.yarn.server.resourcemanager.RMAuditLogger: USER=vishal	OPERATION=AM Allocated Container	TARGET=SchedulerApp	RESULT=SUCCESS	APPID=application_1458337096528_0001	CONTAINERID=container_1458337096528_0001_01_000001
2016-03-18 20:02:12,355 INFO org.apache.hadoop.yarn.server.resourcemanager.scheduler.SchedulerNode: Assigned container container_1458337096528_0001_01_000001 of capacity <memory:2048, vCores:1> on host vishal-VirtualBox:43965, which has 1 containers, <memory:2048, vCores:1> used and <memory:6144, vCores:7> available after allocation
2016-03-18 20:02:12,356 INFO org.apache.hadoop.yarn.server.resourcemanager.scheduler.capacity.LeafQueue: assignedContainer application attempt=appattempt_1458337096528_0001_000001 container=Container: [ContainerId: container_1458337096528_0001_01_000001, NodeId: vishal-VirtualBox:43965, NodeHttpAddress: vishal-VirtualBox:8042, Resource: <memory:2048, vCores:1>, Priority: 0, Token: null, ] queue=default: capacity=1.0, absoluteCapacity=1.0, usedResources=<memory:0, vCores:0>, usedCapacity=0.0, absoluteUsedCapacity=0.0, numApps=1, numContainers=0 clusterResource=<memory:8192, vCores:8>
2016-03-18 20:02:12,362 INFO org.apache.hadoop.yarn.server.resourcemanager.scheduler.capacity.ParentQueue: Re-sorting assigned queue: root.default stats: default: capacity=1.0, absoluteCapacity=1.0, usedResources=<memory:2048, vCores:1>, usedCapacity=0.25, absoluteUsedCapacity=0.25, numApps=1, numContainers=1
2016-03-18 20:02:12,362 INFO org.apache.hadoop.yarn.server.resourcemanager.scheduler.capacity.ParentQueue: assignedContainer queue=root usedCapacity=0.25 absoluteUsedCapacity=0.25 used=<memory:2048, vCores:1> cluster=<memory:8192, vCores:8>
2016-03-18 20:02:12,393 INFO org.apache.hadoop.yarn.server.resourcemanager.security.NMTokenSecretManagerInRM: Sending NMToken for nodeId : vishal-VirtualBox:43965 for container : container_1458337096528_0001_01_000001
2016-03-18 20:02:12,413 INFO org.apache.hadoop.yarn.server.resourcemanager.rmcontainer.RMContainerImpl: container_1458337096528_0001_01_000001 Container Transitioned from ALLOCATED to ACQUIRED
2016-03-18 20:02:12,414 INFO org.apache.hadoop.yarn.server.resourcemanager.security.NMTokenSecretManagerInRM: Clear node set for appattempt_1458337096528_0001_000001
2016-03-18 20:02:12,417 INFO org.apache.hadoop.yarn.server.resourcemanager.rmapp.attempt.RMAppAttemptImpl: Storing attempt: AppId: application_1458337096528_0001 AttemptId: appattempt_1458337096528_0001_000001 MasterContainer: Container: [ContainerId: container_1458337096528_0001_01_000001, NodeId: vishal-VirtualBox:43965, NodeHttpAddress: vishal-VirtualBox:8042, Resource: <memory:2048, vCores:1>, Priority: 0, Token: Token { kind: ContainerToken, service: 127.0.1.1:43965 }, ]
2016-03-18 20:02:12,448 INFO org.apache.hadoop.yarn.server.resourcemanager.rmapp.attempt.RMAppAttemptImpl: appattempt_1458337096528_0001_000001 State change from SCHEDULED to ALLOCATED_SAVING
2016-03-18 20:02:12,458 INFO org.apache.hadoop.yarn.server.resourcemanager.rmapp.attempt.RMAppAttemptImpl: appattempt_1458337096528_0001_000001 State change from ALLOCATED_SAVING to ALLOCATED
2016-03-18 20:02:12,462 INFO org.apache.hadoop.yarn.server.resourcemanager.amlauncher.AMLauncher: Launching masterappattempt_1458337096528_0001_000001
2016-03-18 20:02:12,499 INFO org.apache.hadoop.yarn.server.resourcemanager.amlauncher.AMLauncher: Setting up container Container: [ContainerId: container_1458337096528_0001_01_000001, NodeId: vishal-VirtualBox:43965, NodeHttpAddress: vishal-VirtualBox:8042, Resource: <memory:2048, vCores:1>, Priority: 0, Token: Token { kind: ContainerToken, service: 127.0.1.1:43965 }, ] for AM appattempt_1458337096528_0001_000001
2016-03-18 20:02:12,499 INFO org.apache.hadoop.yarn.server.resourcemanager.amlauncher.AMLauncher: Command to launch container container_1458337096528_0001_01_000001 : $JAVA_HOME/bin/java -Djava.io.tmpdir=$PWD/tmp -Dlog4j.configuration=container-log4j.properties -Dyarn.app.container.log.dir=<LOG_DIR> -Dyarn.app.container.log.filesize=0 -Dhadoop.root.logger=INFO,CLA -Dhadoop.root.logfile=syslog  -Xmx1024m org.apache.hadoop.mapreduce.v2.app.MRAppMaster 1><LOG_DIR>/stdout 2><LOG_DIR>/stderr 
2016-03-18 20:02:12,502 INFO org.apache.hadoop.yarn.server.resourcemanager.security.AMRMTokenSecretManager: Create AMRMToken for ApplicationAttempt: appattempt_1458337096528_0001_000001
2016-03-18 20:02:12,506 INFO org.apache.hadoop.yarn.server.resourcemanager.security.AMRMTokenSecretManager: Creating password for appattempt_1458337096528_0001_000001
2016-03-18 20:02:13,057 INFO org.apache.hadoop.yarn.server.resourcemanager.amlauncher.AMLauncher: Done launching container Container: [ContainerId: container_1458337096528_0001_01_000001, NodeId: vishal-VirtualBox:43965, NodeHttpAddress: vishal-VirtualBox:8042, Resource: <memory:2048, vCores:1>, Priority: 0, Token: Token { kind: ContainerToken, service: 127.0.1.1:43965 }, ] for AM appattempt_1458337096528_0001_000001
2016-03-18 20:02:13,061 INFO org.apache.hadoop.yarn.server.resourcemanager.rmapp.attempt.RMAppAttemptImpl: appattempt_1458337096528_0001_000001 State change from ALLOCATED to LAUNCHED
2016-03-18 20:02:13,326 INFO org.apache.hadoop.yarn.server.resourcemanager.rmcontainer.RMContainerImpl: container_1458337096528_0001_01_000001 Container Transitioned from ACQUIRED to RUNNING
2016-03-18 20:02:28,307 INFO SecurityLogger.org.apache.hadoop.ipc.Server: Auth successful for appattempt_1458337096528_0001_000001 (auth:SIMPLE)
2016-03-18 20:02:28,327 INFO org.apache.hadoop.yarn.server.resourcemanager.ApplicationMasterService: AM registration appattempt_1458337096528_0001_000001
2016-03-18 20:02:28,329 INFO org.apache.hadoop.yarn.server.resourcemanager.rmapp.attempt.RMAppAttemptImpl: appattempt_1458337096528_0001_000001 State change from LAUNCHED to RUNNING
2016-03-18 20:02:28,329 INFO org.apache.hadoop.yarn.server.resourcemanager.rmapp.RMAppImpl: application_1458337096528_0001 State change from ACCEPTED to RUNNING
2016-03-18 20:02:28,329 INFO org.apache.hadoop.yarn.server.resourcemanager.RMAuditLogger: USER=vishal	IP=127.0.0.1	OPERATION=Register App Master	TARGET=ApplicationMasterService	RESULT=SUCCESS	APPID=application_1458337096528_0001	APPATTEMPTID=appattempt_1458337096528_0001_000001
2016-03-18 20:02:30,376 INFO org.apache.hadoop.yarn.server.resourcemanager.rmcontainer.RMContainerImpl: container_1458337096528_0001_01_000002 Container Transitioned from NEW to ALLOCATED
2016-03-18 20:02:30,376 INFO org.apache.hadoop.yarn.server.resourcemanager.RMAuditLogger: USER=vishal	OPERATION=AM Allocated Container	TARGET=SchedulerApp	RESULT=SUCCESS	APPID=application_1458337096528_0001	CONTAINERID=container_1458337096528_0001_01_000002
2016-03-18 20:02:30,376 INFO org.apache.hadoop.yarn.server.resourcemanager.scheduler.SchedulerNode: Assigned container container_1458337096528_0001_01_000002 of capacity <memory:1024, vCores:1> on host vishal-VirtualBox:43965, which has 2 containers, <memory:3072, vCores:2> used and <memory:5120, vCores:6> available after allocation
2016-03-18 20:02:30,376 INFO org.apache.hadoop.yarn.server.resourcemanager.scheduler.capacity.LeafQueue: assignedContainer application attempt=appattempt_1458337096528_0001_000001 container=Container: [ContainerId: container_1458337096528_0001_01_000002, NodeId: vishal-VirtualBox:43965, NodeHttpAddress: vishal-VirtualBox:8042, Resource: <memory:1024, vCores:1>, Priority: 20, Token: null, ] queue=default: capacity=1.0, absoluteCapacity=1.0, usedResources=<memory:2048, vCores:1>, usedCapacity=0.25, absoluteUsedCapacity=0.25, numApps=1, numContainers=1 clusterResource=<memory:8192, vCores:8>
2016-03-18 20:02:30,376 INFO org.apache.hadoop.yarn.server.resourcemanager.scheduler.capacity.ParentQueue: Re-sorting assigned queue: root.default stats: default: capacity=1.0, absoluteCapacity=1.0, usedResources=<memory:3072, vCores:2>, usedCapacity=0.375, absoluteUsedCapacity=0.375, numApps=1, numContainers=2
2016-03-18 20:02:30,376 INFO org.apache.hadoop.yarn.server.resourcemanager.scheduler.capacity.ParentQueue: assignedContainer queue=root usedCapacity=0.375 absoluteUsedCapacity=0.375 used=<memory:3072, vCores:2> cluster=<memory:8192, vCores:8>
2016-03-18 20:02:30,377 INFO org.apache.hadoop.yarn.server.resourcemanager.rmcontainer.RMContainerImpl: container_1458337096528_0001_01_000003 Container Transitioned from NEW to ALLOCATED
2016-03-18 20:02:30,377 INFO org.apache.hadoop.yarn.server.resourcemanager.RMAuditLogger: USER=vishal	OPERATION=AM Allocated Container	TARGET=SchedulerApp	RESULT=SUCCESS	APPID=application_1458337096528_0001	CONTAINERID=container_1458337096528_0001_01_000003
2016-03-18 20:02:30,377 INFO org.apache.hadoop.yarn.server.resourcemanager.scheduler.SchedulerNode: Assigned container container_1458337096528_0001_01_000003 of capacity <memory:1024, vCores:1> on host vishal-VirtualBox:43965, which has 3 containers, <memory:4096, vCores:3> used and <memory:4096, vCores:5> available after allocation
2016-03-18 20:02:30,377 INFO org.apache.hadoop.yarn.server.resourcemanager.scheduler.capacity.LeafQueue: assignedContainer application attempt=appattempt_1458337096528_0001_000001 container=Container: [ContainerId: container_1458337096528_0001_01_000003, NodeId: vishal-VirtualBox:43965, NodeHttpAddress: vishal-VirtualBox:8042, Resource: <memory:1024, vCores:1>, Priority: 20, Token: null, ] queue=default: capacity=1.0, absoluteCapacity=1.0, usedResources=<memory:3072, vCores:2>, usedCapacity=0.375, absoluteUsedCapacity=0.375, numApps=1, numContainers=2 clusterResource=<memory:8192, vCores:8>
2016-03-18 20:02:30,377 INFO org.apache.hadoop.yarn.server.resourcemanager.scheduler.capacity.ParentQueue: Re-sorting assigned queue: root.default stats: default: capacity=1.0, absoluteCapacity=1.0, usedResources=<memory:4096, vCores:3>, usedCapacity=0.5, absoluteUsedCapacity=0.5, numApps=1, numContainers=3
2016-03-18 20:02:30,377 INFO org.apache.hadoop.yarn.server.resourcemanager.scheduler.capacity.ParentQueue: assignedContainer queue=root usedCapacity=0.5 absoluteUsedCapacity=0.5 used=<memory:4096, vCores:3> cluster=<memory:8192, vCores:8>
2016-03-18 20:02:30,459 INFO org.apache.hadoop.yarn.server.resourcemanager.security.NMTokenSecretManagerInRM: Sending NMToken for nodeId : vishal-VirtualBox:43965 for container : container_1458337096528_0001_01_000002
2016-03-18 20:02:30,463 INFO org.apache.hadoop.yarn.server.resourcemanager.rmcontainer.RMContainerImpl: container_1458337096528_0001_01_000002 Container Transitioned from ALLOCATED to ACQUIRED
2016-03-18 20:02:30,469 INFO org.apache.hadoop.yarn.server.resourcemanager.rmcontainer.RMContainerImpl: container_1458337096528_0001_01_000003 Container Transitioned from ALLOCATED to ACQUIRED
2016-03-18 20:02:31,380 INFO org.apache.hadoop.yarn.server.resourcemanager.rmcontainer.RMContainerImpl: container_1458337096528_0001_01_000002 Container Transitioned from ACQUIRED to RUNNING
2016-03-18 20:02:31,381 INFO org.apache.hadoop.yarn.server.resourcemanager.rmcontainer.RMContainerImpl: container_1458337096528_0001_01_000003 Container Transitioned from ACQUIRED to RUNNING
2016-03-18 20:02:31,542 INFO org.apache.hadoop.yarn.server.resourcemanager.scheduler.AppSchedulingInfo: checking for deactivate of application :application_1458337096528_0001
2016-03-18 20:02:41,896 INFO org.apache.hadoop.yarn.server.resourcemanager.rmcontainer.RMContainerImpl: container_1458337096528_0001_01_000002 Container Transitioned from RUNNING to COMPLETED
2016-03-18 20:02:41,896 INFO org.apache.hadoop.yarn.server.resourcemanager.scheduler.common.fica.FiCaSchedulerApp: Completed container: container_1458337096528_0001_01_000002 in state: COMPLETED event:FINISHED
2016-03-18 20:02:41,896 INFO org.apache.hadoop.yarn.server.resourcemanager.RMAuditLogger: USER=vishal	OPERATION=AM Released Container	TARGET=SchedulerApp	RESULT=SUCCESS	APPID=application_1458337096528_0001	CONTAINERID=container_1458337096528_0001_01_000002
2016-03-18 20:02:41,897 INFO org.apache.hadoop.yarn.server.resourcemanager.scheduler.SchedulerNode: Released container container_1458337096528_0001_01_000002 of capacity <memory:1024, vCores:1> on host vishal-VirtualBox:43965, which currently has 2 containers, <memory:3072, vCores:2> used and <memory:5120, vCores:6> available, release resources=true
2016-03-18 20:02:41,897 INFO org.apache.hadoop.yarn.server.resourcemanager.scheduler.capacity.LeafQueue: default used=<memory:3072, vCores:2> numContainers=2 user=vishal user-resources=<memory:3072, vCores:2>
2016-03-18 20:02:41,904 INFO org.apache.hadoop.yarn.server.resourcemanager.scheduler.capacity.LeafQueue: completedContainer container=Container: [ContainerId: container_1458337096528_0001_01_000002, NodeId: vishal-VirtualBox:43965, NodeHttpAddress: vishal-VirtualBox:8042, Resource: <memory:1024, vCores:1>, Priority: 20, Token: Token { kind: ContainerToken, service: 127.0.1.1:43965 }, ] queue=default: capacity=1.0, absoluteCapacity=1.0, usedResources=<memory:3072, vCores:2>, usedCapacity=0.375, absoluteUsedCapacity=0.375, numApps=1, numContainers=2 cluster=<memory:8192, vCores:8>
2016-03-18 20:02:41,905 INFO org.apache.hadoop.yarn.server.resourcemanager.scheduler.capacity.ParentQueue: completedContainer queue=root usedCapacity=0.375 absoluteUsedCapacity=0.375 used=<memory:3072, vCores:2> cluster=<memory:8192, vCores:8>
2016-03-18 20:02:41,905 INFO org.apache.hadoop.yarn.server.resourcemanager.scheduler.capacity.ParentQueue: Re-sorting completed queue: root.default stats: default: capacity=1.0, absoluteCapacity=1.0, usedResources=<memory:3072, vCores:2>, usedCapacity=0.375, absoluteUsedCapacity=0.375, numApps=1, numContainers=2
2016-03-18 20:02:41,905 INFO org.apache.hadoop.yarn.server.resourcemanager.scheduler.capacity.CapacityScheduler: Application attempt appattempt_1458337096528_0001_000001 released container container_1458337096528_0001_01_000002 on node: host: vishal-VirtualBox:43965 #containers=2 available=<memory:5120, vCores:6> used=<memory:3072, vCores:2> with event: FINISHED
2016-03-18 20:02:41,910 INFO org.apache.hadoop.yarn.server.resourcemanager.rmcontainer.RMContainerImpl: container_1458337096528_0001_01_000003 Container Transitioned from RUNNING to COMPLETED
2016-03-18 20:02:41,910 INFO org.apache.hadoop.yarn.server.resourcemanager.scheduler.common.fica.FiCaSchedulerApp: Completed container: container_1458337096528_0001_01_000003 in state: COMPLETED event:FINISHED
2016-03-18 20:02:41,911 INFO org.apache.hadoop.yarn.server.resourcemanager.RMAuditLogger: USER=vishal	OPERATION=AM Released Container	TARGET=SchedulerApp	RESULT=SUCCESS	APPID=application_1458337096528_0001	CONTAINERID=container_1458337096528_0001_01_000003
2016-03-18 20:02:41,911 INFO org.apache.hadoop.yarn.server.resourcemanager.scheduler.SchedulerNode: Released container container_1458337096528_0001_01_000003 of capacity <memory:1024, vCores:1> on host vishal-VirtualBox:43965, which currently has 1 containers, <memory:2048, vCores:1> used and <memory:6144, vCores:7> available, release resources=true
2016-03-18 20:02:41,911 INFO org.apache.hadoop.yarn.server.resourcemanager.scheduler.capacity.LeafQueue: default used=<memory:2048, vCores:1> numContainers=1 user=vishal user-resources=<memory:2048, vCores:1>
2016-03-18 20:02:41,912 INFO org.apache.hadoop.yarn.server.resourcemanager.scheduler.capacity.LeafQueue: completedContainer container=Container: [ContainerId: container_1458337096528_0001_01_000003, NodeId: vishal-VirtualBox:43965, NodeHttpAddress: vishal-VirtualBox:8042, Resource: <memory:1024, vCores:1>, Priority: 20, Token: Token { kind: ContainerToken, service: 127.0.1.1:43965 }, ] queue=default: capacity=1.0, absoluteCapacity=1.0, usedResources=<memory:2048, vCores:1>, usedCapacity=0.25, absoluteUsedCapacity=0.25, numApps=1, numContainers=1 cluster=<memory:8192, vCores:8>
2016-03-18 20:02:41,912 INFO org.apache.hadoop.yarn.server.resourcemanager.scheduler.capacity.ParentQueue: completedContainer queue=root usedCapacity=0.25 absoluteUsedCapacity=0.25 used=<memory:2048, vCores:1> cluster=<memory:8192, vCores:8>
2016-03-18 20:02:41,912 INFO org.apache.hadoop.yarn.server.resourcemanager.scheduler.capacity.ParentQueue: Re-sorting completed queue: root.default stats: default: capacity=1.0, absoluteCapacity=1.0, usedResources=<memory:2048, vCores:1>, usedCapacity=0.25, absoluteUsedCapacity=0.25, numApps=1, numContainers=1
2016-03-18 20:02:41,912 INFO org.apache.hadoop.yarn.server.resourcemanager.scheduler.capacity.CapacityScheduler: Application attempt appattempt_1458337096528_0001_000001 released container container_1458337096528_0001_01_000003 on node: host: vishal-VirtualBox:43965 #containers=1 available=<memory:6144, vCores:7> used=<memory:2048, vCores:1> with event: FINISHED
2016-03-18 20:02:42,907 INFO org.apache.hadoop.yarn.server.resourcemanager.rmcontainer.RMContainerImpl: container_1458337096528_0001_01_000004 Container Transitioned from NEW to ALLOCATED
2016-03-18 20:02:42,907 INFO org.apache.hadoop.yarn.server.resourcemanager.RMAuditLogger: USER=vishal	OPERATION=AM Allocated Container	TARGET=SchedulerApp	RESULT=SUCCESS	APPID=application_1458337096528_0001	CONTAINERID=container_1458337096528_0001_01_000004
2016-03-18 20:02:42,912 INFO org.apache.hadoop.yarn.server.resourcemanager.scheduler.SchedulerNode: Assigned container container_1458337096528_0001_01_000004 of capacity <memory:1024, vCores:1> on host vishal-VirtualBox:43965, which has 2 containers, <memory:3072, vCores:2> used and <memory:5120, vCores:6> available after allocation
2016-03-18 20:02:42,912 INFO org.apache.hadoop.yarn.server.resourcemanager.scheduler.capacity.LeafQueue: assignedContainer application attempt=appattempt_1458337096528_0001_000001 container=Container: [ContainerId: container_1458337096528_0001_01_000004, NodeId: vishal-VirtualBox:43965, NodeHttpAddress: vishal-VirtualBox:8042, Resource: <memory:1024, vCores:1>, Priority: 10, Token: null, ] queue=default: capacity=1.0, absoluteCapacity=1.0, usedResources=<memory:2048, vCores:1>, usedCapacity=0.25, absoluteUsedCapacity=0.25, numApps=1, numContainers=1 clusterResource=<memory:8192, vCores:8>
2016-03-18 20:02:42,913 INFO org.apache.hadoop.yarn.server.resourcemanager.scheduler.capacity.ParentQueue: Re-sorting assigned queue: root.default stats: default: capacity=1.0, absoluteCapacity=1.0, usedResources=<memory:3072, vCores:2>, usedCapacity=0.375, absoluteUsedCapacity=0.375, numApps=1, numContainers=2
2016-03-18 20:02:42,913 INFO org.apache.hadoop.yarn.server.resourcemanager.scheduler.capacity.ParentQueue: assignedContainer queue=root usedCapacity=0.375 absoluteUsedCapacity=0.375 used=<memory:3072, vCores:2> cluster=<memory:8192, vCores:8>
2016-03-18 20:02:43,620 INFO org.apache.hadoop.yarn.server.resourcemanager.rmcontainer.RMContainerImpl: container_1458337096528_0001_01_000004 Container Transitioned from ALLOCATED to ACQUIRED
2016-03-18 20:02:43,909 INFO org.apache.hadoop.yarn.server.resourcemanager.rmcontainer.RMContainerImpl: container_1458337096528_0001_01_000004 Container Transitioned from ACQUIRED to RUNNING
2016-03-18 20:02:44,633 INFO org.apache.hadoop.yarn.server.resourcemanager.scheduler.AppSchedulingInfo: checking for deactivate of application :application_1458337096528_0001
2016-03-18 20:02:49,941 INFO org.apache.hadoop.yarn.server.resourcemanager.rmapp.attempt.RMAppAttemptImpl: Updating application attempt appattempt_1458337096528_0001_000001 with final state: FINISHING, and exit status: -1000
2016-03-18 20:02:49,942 INFO org.apache.hadoop.yarn.server.resourcemanager.rmapp.attempt.RMAppAttemptImpl: appattempt_1458337096528_0001_000001 State change from RUNNING to FINAL_SAVING
2016-03-18 20:02:49,942 INFO org.apache.hadoop.yarn.server.resourcemanager.rmapp.attempt.RMAppAttemptImpl: appattempt_1458337096528_0001_000001 State change from FINAL_SAVING to FINISHING
2016-03-18 20:02:49,942 INFO org.apache.hadoop.yarn.server.resourcemanager.rmapp.RMAppImpl: Updating application application_1458337096528_0001 with final state: FINISHING
2016-03-18 20:02:49,948 INFO org.apache.hadoop.yarn.server.resourcemanager.recovery.RMStateStore: Updating info for app: application_1458337096528_0001
2016-03-18 20:02:49,948 INFO org.apache.hadoop.yarn.server.resourcemanager.rmapp.RMAppImpl: application_1458337096528_0001 State change from RUNNING to FINAL_SAVING
2016-03-18 20:02:49,948 INFO org.apache.hadoop.yarn.server.resourcemanager.rmapp.RMAppImpl: application_1458337096528_0001 State change from FINAL_SAVING to FINISHING
2016-03-18 20:02:50,430 INFO org.apache.hadoop.yarn.server.resourcemanager.rmcontainer.RMContainerImpl: container_1458337096528_0001_01_000004 Container Transitioned from RUNNING to COMPLETED
2016-03-18 20:02:50,431 INFO org.apache.hadoop.yarn.server.resourcemanager.scheduler.common.fica.FiCaSchedulerApp: Completed container: container_1458337096528_0001_01_000004 in state: COMPLETED event:FINISHED
2016-03-18 20:02:50,431 INFO org.apache.hadoop.yarn.server.resourcemanager.RMAuditLogger: USER=vishal	OPERATION=AM Released Container	TARGET=SchedulerApp	RESULT=SUCCESS	APPID=application_1458337096528_0001	CONTAINERID=container_1458337096528_0001_01_000004
2016-03-18 20:02:50,431 INFO org.apache.hadoop.yarn.server.resourcemanager.scheduler.SchedulerNode: Released container container_1458337096528_0001_01_000004 of capacity <memory:1024, vCores:1> on host vishal-VirtualBox:43965, which currently has 1 containers, <memory:2048, vCores:1> used and <memory:6144, vCores:7> available, release resources=true
2016-03-18 20:02:50,431 INFO org.apache.hadoop.yarn.server.resourcemanager.scheduler.capacity.LeafQueue: default used=<memory:2048, vCores:1> numContainers=1 user=vishal user-resources=<memory:2048, vCores:1>
2016-03-18 20:02:50,434 INFO org.apache.hadoop.yarn.server.resourcemanager.scheduler.capacity.LeafQueue: completedContainer container=Container: [ContainerId: container_1458337096528_0001_01_000004, NodeId: vishal-VirtualBox:43965, NodeHttpAddress: vishal-VirtualBox:8042, Resource: <memory:1024, vCores:1>, Priority: 10, Token: Token { kind: ContainerToken, service: 127.0.1.1:43965 }, ] queue=default: capacity=1.0, absoluteCapacity=1.0, usedResources=<memory:2048, vCores:1>, usedCapacity=0.25, absoluteUsedCapacity=0.25, numApps=1, numContainers=1 cluster=<memory:8192, vCores:8>
2016-03-18 20:02:50,434 INFO org.apache.hadoop.yarn.server.resourcemanager.scheduler.capacity.ParentQueue: completedContainer queue=root usedCapacity=0.25 absoluteUsedCapacity=0.25 used=<memory:2048, vCores:1> cluster=<memory:8192, vCores:8>
2016-03-18 20:02:50,435 INFO org.apache.hadoop.yarn.server.resourcemanager.scheduler.capacity.ParentQueue: Re-sorting completed queue: root.default stats: default: capacity=1.0, absoluteCapacity=1.0, usedResources=<memory:2048, vCores:1>, usedCapacity=0.25, absoluteUsedCapacity=0.25, numApps=1, numContainers=1
2016-03-18 20:02:50,435 INFO org.apache.hadoop.yarn.server.resourcemanager.scheduler.capacity.CapacityScheduler: Application attempt appattempt_1458337096528_0001_000001 released container container_1458337096528_0001_01_000004 on node: host: vishal-VirtualBox:43965 #containers=1 available=<memory:6144, vCores:7> used=<memory:2048, vCores:1> with event: FINISHED
2016-03-18 20:02:50,949 INFO org.apache.hadoop.yarn.server.resourcemanager.ApplicationMasterService: application_1458337096528_0001 unregistered successfully. 
2016-03-18 20:02:56,450 INFO org.apache.hadoop.yarn.server.resourcemanager.rmcontainer.RMContainerImpl: container_1458337096528_0001_01_000001 Container Transitioned from RUNNING to COMPLETED
2016-03-18 20:02:56,451 INFO org.apache.hadoop.yarn.server.resourcemanager.scheduler.common.fica.FiCaSchedulerApp: Completed container: container_1458337096528_0001_01_000001 in state: COMPLETED event:FINISHED
2016-03-18 20:02:56,451 INFO org.apache.hadoop.yarn.server.resourcemanager.RMAuditLogger: USER=vishal	OPERATION=AM Released Container	TARGET=SchedulerApp	RESULT=SUCCESS	APPID=application_1458337096528_0001	CONTAINERID=container_1458337096528_0001_01_000001
2016-03-18 20:02:56,451 INFO org.apache.hadoop.yarn.server.resourcemanager.scheduler.SchedulerNode: Released container container_1458337096528_0001_01_000001 of capacity <memory:2048, vCores:1> on host vishal-VirtualBox:43965, which currently has 0 containers, <memory:0, vCores:0> used and <memory:8192, vCores:8> available, release resources=true
2016-03-18 20:02:56,451 INFO org.apache.hadoop.yarn.server.resourcemanager.scheduler.capacity.LeafQueue: default used=<memory:0, vCores:0> numContainers=0 user=vishal user-resources=<memory:0, vCores:0>
2016-03-18 20:02:56,451 INFO org.apache.hadoop.yarn.server.resourcemanager.scheduler.capacity.LeafQueue: completedContainer container=Container: [ContainerId: container_1458337096528_0001_01_000001, NodeId: vishal-VirtualBox:43965, NodeHttpAddress: vishal-VirtualBox:8042, Resource: <memory:2048, vCores:1>, Priority: 0, Token: Token { kind: ContainerToken, service: 127.0.1.1:43965 }, ] queue=default: capacity=1.0, absoluteCapacity=1.0, usedResources=<memory:0, vCores:0>, usedCapacity=0.0, absoluteUsedCapacity=0.0, numApps=1, numContainers=0 cluster=<memory:8192, vCores:8>
2016-03-18 20:02:56,452 INFO org.apache.hadoop.yarn.server.resourcemanager.scheduler.capacity.ParentQueue: completedContainer queue=root usedCapacity=0.0 absoluteUsedCapacity=0.0 used=<memory:0, vCores:0> cluster=<memory:8192, vCores:8>
2016-03-18 20:02:56,452 INFO org.apache.hadoop.yarn.server.resourcemanager.scheduler.capacity.ParentQueue: Re-sorting completed queue: root.default stats: default: capacity=1.0, absoluteCapacity=1.0, usedResources=<memory:0, vCores:0>, usedCapacity=0.0, absoluteUsedCapacity=0.0, numApps=1, numContainers=0
2016-03-18 20:02:56,452 INFO org.apache.hadoop.yarn.server.resourcemanager.scheduler.capacity.CapacityScheduler: Application attempt appattempt_1458337096528_0001_000001 released container container_1458337096528_0001_01_000001 on node: host: vishal-VirtualBox:43965 #containers=0 available=<memory:8192, vCores:8> used=<memory:0, vCores:0> with event: FINISHED
2016-03-18 20:02:56,453 INFO org.apache.hadoop.yarn.server.resourcemanager.ApplicationMasterService: Unregistering app attempt : appattempt_1458337096528_0001_000001
2016-03-18 20:02:56,498 INFO org.apache.hadoop.yarn.server.resourcemanager.security.AMRMTokenSecretManager: Application finished, removing password for appattempt_1458337096528_0001_000001
2016-03-18 20:02:56,498 INFO org.apache.hadoop.yarn.server.resourcemanager.rmapp.attempt.RMAppAttemptImpl: appattempt_1458337096528_0001_000001 State change from FINISHING to FINISHED
2016-03-18 20:02:56,504 INFO org.apache.hadoop.yarn.server.resourcemanager.rmapp.RMAppImpl: application_1458337096528_0001 State change from FINISHING to FINISHED
2016-03-18 20:02:56,504 INFO org.apache.hadoop.yarn.server.resourcemanager.scheduler.capacity.CapacityScheduler: Application Attempt appattempt_1458337096528_0001_000001 is done. finalState=FINISHED
2016-03-18 20:02:56,504 INFO org.apache.hadoop.yarn.server.resourcemanager.scheduler.AppSchedulingInfo: Application application_1458337096528_0001 requests cleared
2016-03-18 20:02:56,505 INFO org.apache.hadoop.yarn.server.resourcemanager.scheduler.capacity.LeafQueue: Application removed - appId: application_1458337096528_0001 user: vishal queue: default #user-pending-applications: 0 #user-active-applications: 0 #queue-pending-applications: 0 #queue-active-applications: 0
2016-03-18 20:02:56,512 INFO org.apache.hadoop.yarn.server.resourcemanager.scheduler.capacity.ParentQueue: Application removed - appId: application_1458337096528_0001 user: vishal leaf-queue of parent: root #applications: 0
2016-03-18 20:02:56,511 INFO org.apache.hadoop.yarn.server.resourcemanager.amlauncher.AMLauncher: Cleaning master appattempt_1458337096528_0001_000001
2016-03-18 20:02:56,518 INFO org.apache.hadoop.yarn.server.resourcemanager.RMAuditLogger: USER=vishal	OPERATION=Application Finished - Succeeded	TARGET=RMAppManager	RESULT=SUCCESS	APPID=application_1458337096528_0001
2016-03-18 20:02:56,531 INFO org.apache.hadoop.yarn.server.resourcemanager.RMAppManager$ApplicationSummary: appId=application_1458337096528_0001,name=WordCount,user=vishal,queue=default,state=FINISHED,trackingUrl=http://vishal-VirtualBox:8088/proxy/application_1458337096528_0001/,appMasterHost=vishal-VirtualBox,startTime=1458349331710,finishTime=1458349369942,finalStatus=SUCCEEDED,memorySeconds=121625,vcoreSeconds=73,preemptedAMContainers=0,preemptedNonAMContainers=0,preemptedResources=<memory:0\, vCores:0>,applicationType=MAPREDUCE
2016-03-18 20:02:57,566 INFO org.apache.hadoop.yarn.server.resourcemanager.scheduler.capacity.CapacityScheduler: Null container completed...
2016-03-18 20:13:37,854 INFO org.apache.hadoop.yarn.server.resourcemanager.ClientRMService: Allocated new applicationId: 2
2016-03-18 20:14:53,593 INFO org.apache.hadoop.yarn.server.resourcemanager.ClientRMService: Allocated new applicationId: 3
2016-03-19 09:31:56,358 ERROR org.apache.hadoop.yarn.server.resourcemanager.ResourceManager: RECEIVED SIGNAL 15: SIGTERM
2016-03-19 09:31:56,496 ERROR org.apache.hadoop.security.token.delegation.AbstractDelegationTokenSecretManager: ExpiredTokenRemover received java.lang.InterruptedException: sleep interrupted
2016-03-19 09:31:56,497 INFO org.mortbay.log: Stopped HttpServer2$SelectChannelConnectorWithSafeStartup@0.0.0.0:8088
2016-03-19 09:31:56,503 WARN org.apache.hadoop.http.HttpServer2: HttpServer Acceptor: isRunning is false. Rechecking.
2016-03-19 09:31:56,504 WARN org.apache.hadoop.http.HttpServer2: HttpServer Acceptor: isRunning is false
2016-03-19 09:31:56,506 INFO org.apache.hadoop.ipc.Server: Stopping server on 8032
2016-03-19 09:31:56,532 INFO org.apache.hadoop.ipc.Server: Stopping IPC Server listener on 8032
2016-03-19 09:31:56,534 INFO org.apache.hadoop.ipc.Server: Stopping server on 8033
2016-03-19 09:31:56,534 INFO org.apache.hadoop.ipc.Server: Stopping IPC Server Responder
2016-03-19 09:31:56,535 INFO org.apache.hadoop.ipc.Server: Stopping IPC Server listener on 8033
2016-03-19 09:31:56,536 INFO org.apache.hadoop.yarn.server.resourcemanager.ResourceManager: Transitioning to standby state
2016-03-19 09:31:56,536 WARN org.apache.hadoop.yarn.server.resourcemanager.amlauncher.ApplicationMasterLauncher: org.apache.hadoop.yarn.server.resourcemanager.amlauncher.ApplicationMasterLauncher$LauncherThread interrupted. Returning.
2016-03-19 09:31:56,537 INFO org.apache.hadoop.ipc.Server: Stopping server on 8030
2016-03-19 09:31:56,546 INFO org.apache.hadoop.ipc.Server: Stopping IPC Server Responder
2016-03-19 09:31:56,549 INFO org.apache.hadoop.ipc.Server: Stopping IPC Server listener on 8030
2016-03-19 09:31:56,549 INFO org.apache.hadoop.ipc.Server: Stopping server on 8031
2016-03-19 09:31:56,558 INFO org.apache.hadoop.ipc.Server: Stopping IPC Server Responder
2016-03-19 09:31:56,560 INFO org.apache.hadoop.ipc.Server: Stopping IPC Server Responder
2016-03-19 09:31:56,559 INFO org.apache.hadoop.ipc.Server: Stopping IPC Server listener on 8031
2016-03-19 09:31:56,562 INFO org.apache.hadoop.yarn.util.AbstractLivelinessMonitor: NMLivelinessMonitor thread interrupted
2016-03-19 09:31:56,563 ERROR org.apache.hadoop.yarn.server.resourcemanager.ResourceManager: Returning, interrupted : java.lang.InterruptedException
2016-03-19 09:31:56,563 INFO org.apache.hadoop.yarn.event.AsyncDispatcher: AsyncDispatcher is draining to stop, igonring any new events.
2016-03-19 09:31:56,563 INFO org.apache.hadoop.yarn.util.AbstractLivelinessMonitor: AMLivelinessMonitor thread interrupted
2016-03-19 09:31:56,564 INFO org.apache.hadoop.yarn.util.AbstractLivelinessMonitor: AMLivelinessMonitor thread interrupted
2016-03-19 09:31:56,564 INFO org.apache.hadoop.yarn.util.AbstractLivelinessMonitor: org.apache.hadoop.yarn.server.resourcemanager.rmcontainer.ContainerAllocationExpirer thread interrupted
2016-03-19 09:31:56,564 ERROR org.apache.hadoop.security.token.delegation.AbstractDelegationTokenSecretManager: ExpiredTokenRemover received java.lang.InterruptedException: sleep interrupted
2016-03-19 09:31:56,564 INFO org.apache.hadoop.metrics2.impl.MetricsSystemImpl: Stopping ResourceManager metrics system...
2016-03-19 09:31:56,565 INFO org.apache.hadoop.metrics2.impl.MetricsSystemImpl: ResourceManager metrics system stopped.
2016-03-19 09:31:56,565 INFO org.apache.hadoop.metrics2.impl.MetricsSystemImpl: ResourceManager metrics system shutdown complete.
2016-03-19 09:31:56,565 INFO org.apache.hadoop.yarn.event.AsyncDispatcher: AsyncDispatcher is draining to stop, igonring any new events.
2016-03-19 09:31:56,566 INFO org.apache.hadoop.yarn.server.resourcemanager.ResourceManager: Transitioned to standby state
2016-03-19 09:31:56,566 INFO org.apache.hadoop.yarn.server.resourcemanager.ResourceManager: SHUTDOWN_MSG: 
/************************************************************
SHUTDOWN_MSG: Shutting down ResourceManager at vishal-VirtualBox/127.0.1.1
************************************************************/
2016-03-19 18:49:45,466 INFO org.apache.hadoop.yarn.server.resourcemanager.ResourceManager: STARTUP_MSG: 
/************************************************************
STARTUP_MSG: Starting ResourceManager
STARTUP_MSG:   host = vishal-VirtualBox/127.0.1.1
STARTUP_MSG:   args = []
STARTUP_MSG:   version = 2.7.2
STARTUP_MSG:   build = https://git-wip-us.apache.org/repos/asf/hadoop.git -r b165c4fe8a74265c792ce23f546c64604acf0e41; compiled by 'jenkins' on 2016-01-26T00:08Z
STARTUP_MSG:   java = 1.8.0_74
************************************************************/
2016-03-19 18:49:45,542 INFO org.apache.hadoop.yarn.server.resourcemanager.ResourceManager: registered UNIX signal handlers for [TERM, HUP, INT]
2016-03-19 18:49:46,954 INFO org.apache.hadoop.conf.Configuration: found resource core-site.xml at file:/usr/local/hadoop/etc/hadoop/core-site.xml
2016-03-19 18:49:47,285 WARN org.apache.hadoop.util.NativeCodeLoader: Unable to load native-hadoop library for your platform... using builtin-java classes where applicable
2016-03-19 18:49:47,407 INFO org.apache.hadoop.security.Groups: clearing userToGroupsMap cache
2016-03-19 18:49:47,764 INFO org.apache.hadoop.conf.Configuration: found resource yarn-site.xml at file:/usr/local/hadoop/etc/hadoop/yarn-site.xml
2016-03-19 18:49:48,437 INFO org.apache.hadoop.yarn.event.AsyncDispatcher: Registering class org.apache.hadoop.yarn.server.resourcemanager.RMFatalEventType for class org.apache.hadoop.yarn.server.resourcemanager.ResourceManager$RMFatalEventDispatcher
2016-03-19 18:49:49,343 INFO org.apache.hadoop.yarn.server.resourcemanager.security.NMTokenSecretManagerInRM: NMTokenKeyRollingInterval: 86400000ms and NMTokenKeyActivationDelay: 900000ms
2016-03-19 18:49:49,386 INFO org.apache.hadoop.yarn.server.resourcemanager.security.RMContainerTokenSecretManager: ContainerTokenKeyRollingInterval: 86400000ms and ContainerTokenKeyActivationDelay: 900000ms
2016-03-19 18:49:49,417 INFO org.apache.hadoop.yarn.server.resourcemanager.security.AMRMTokenSecretManager: AMRMTokenKeyRollingInterval: 86400000ms and AMRMTokenKeyActivationDelay: 900000 ms
2016-03-19 18:49:49,615 INFO org.apache.hadoop.yarn.event.AsyncDispatcher: Registering class org.apache.hadoop.yarn.server.resourcemanager.recovery.RMStateStoreEventType for class org.apache.hadoop.yarn.server.resourcemanager.recovery.RMStateStore$ForwardingEventHandler
2016-03-19 18:49:49,619 INFO org.apache.hadoop.yarn.event.AsyncDispatcher: Registering class org.apache.hadoop.yarn.server.resourcemanager.NodesListManagerEventType for class org.apache.hadoop.yarn.server.resourcemanager.NodesListManager
2016-03-19 18:49:49,620 INFO org.apache.hadoop.yarn.server.resourcemanager.ResourceManager: Using Scheduler: org.apache.hadoop.yarn.server.resourcemanager.scheduler.capacity.CapacityScheduler
2016-03-19 18:49:49,740 INFO org.apache.hadoop.yarn.event.AsyncDispatcher: Registering class org.apache.hadoop.yarn.server.resourcemanager.scheduler.event.SchedulerEventType for class org.apache.hadoop.yarn.server.resourcemanager.ResourceManager$SchedulerEventDispatcher
2016-03-19 18:49:49,741 INFO org.apache.hadoop.yarn.event.AsyncDispatcher: Registering class org.apache.hadoop.yarn.server.resourcemanager.rmapp.RMAppEventType for class org.apache.hadoop.yarn.server.resourcemanager.ResourceManager$ApplicationEventDispatcher
2016-03-19 18:49:49,742 INFO org.apache.hadoop.yarn.event.AsyncDispatcher: Registering class org.apache.hadoop.yarn.server.resourcemanager.rmapp.attempt.RMAppAttemptEventType for class org.apache.hadoop.yarn.server.resourcemanager.ResourceManager$ApplicationAttemptEventDispatcher
2016-03-19 18:49:49,754 INFO org.apache.hadoop.yarn.event.AsyncDispatcher: Registering class org.apache.hadoop.yarn.server.resourcemanager.rmnode.RMNodeEventType for class org.apache.hadoop.yarn.server.resourcemanager.ResourceManager$NodeEventDispatcher
2016-03-19 18:49:50,048 INFO org.apache.hadoop.metrics2.impl.MetricsConfig: loaded properties from hadoop-metrics2.properties
2016-03-19 18:49:50,312 INFO org.apache.hadoop.metrics2.impl.MetricsSystemImpl: Scheduled snapshot period at 10 second(s).
2016-03-19 18:49:50,313 INFO org.apache.hadoop.metrics2.impl.MetricsSystemImpl: ResourceManager metrics system started
2016-03-19 18:49:50,359 INFO org.apache.hadoop.yarn.event.AsyncDispatcher: Registering class org.apache.hadoop.yarn.server.resourcemanager.RMAppManagerEventType for class org.apache.hadoop.yarn.server.resourcemanager.RMAppManager
2016-03-19 18:49:50,398 INFO org.apache.hadoop.yarn.event.AsyncDispatcher: Registering class org.apache.hadoop.yarn.server.resourcemanager.amlauncher.AMLauncherEventType for class org.apache.hadoop.yarn.server.resourcemanager.amlauncher.ApplicationMasterLauncher
2016-03-19 18:49:50,402 INFO org.apache.hadoop.yarn.server.resourcemanager.RMNMInfo: Registered RMNMInfo MBean
2016-03-19 18:49:50,408 INFO org.apache.hadoop.yarn.security.YarnAuthorizationProvider: org.apache.hadoop.yarn.security.ConfiguredYarnAuthorizer is instiantiated.
2016-03-19 18:49:50,408 INFO org.apache.hadoop.util.HostsFileReader: Refreshing hosts (include/exclude) list
2016-03-19 18:49:50,437 INFO org.apache.hadoop.conf.Configuration: found resource capacity-scheduler.xml at file:/usr/local/hadoop/etc/hadoop/capacity-scheduler.xml
2016-03-19 18:49:50,697 INFO org.apache.hadoop.yarn.server.resourcemanager.scheduler.capacity.CapacitySchedulerConfiguration: max alloc mb per queue for root is undefined
2016-03-19 18:49:50,697 INFO org.apache.hadoop.yarn.server.resourcemanager.scheduler.capacity.CapacitySchedulerConfiguration: max alloc vcore per queue for root is undefined
2016-03-19 18:49:50,721 INFO org.apache.hadoop.yarn.server.resourcemanager.scheduler.capacity.ParentQueue: root, capacity=1.0, asboluteCapacity=1.0, maxCapacity=1.0, asboluteMaxCapacity=1.0, state=RUNNING, acls=SUBMIT_APP:*ADMINISTER_QUEUE:*, labels=*,
, reservationsContinueLooking=true
2016-03-19 18:49:50,721 INFO org.apache.hadoop.yarn.server.resourcemanager.scheduler.capacity.ParentQueue: Initialized parent-queue root name=root, fullname=root
2016-03-19 18:49:50,759 INFO org.apache.hadoop.yarn.server.resourcemanager.scheduler.capacity.CapacitySchedulerConfiguration: max alloc mb per queue for root.default is undefined
2016-03-19 18:49:50,759 INFO org.apache.hadoop.yarn.server.resourcemanager.scheduler.capacity.CapacitySchedulerConfiguration: max alloc vcore per queue for root.default is undefined
2016-03-19 18:49:50,760 INFO org.apache.hadoop.yarn.server.resourcemanager.scheduler.capacity.LeafQueue: Initializing default
capacity = 1.0 [= (float) configuredCapacity / 100 ]
asboluteCapacity = 1.0 [= parentAbsoluteCapacity * capacity ]
maxCapacity = 1.0 [= configuredMaxCapacity ]
absoluteMaxCapacity = 1.0 [= 1.0 maximumCapacity undefined, (parentAbsoluteMaxCapacity * maximumCapacity) / 100 otherwise ]
userLimit = 100 [= configuredUserLimit ]
userLimitFactor = 1.0 [= configuredUserLimitFactor ]
maxApplications = 10000 [= configuredMaximumSystemApplicationsPerQueue or (int)(configuredMaximumSystemApplications * absoluteCapacity)]
maxApplicationsPerUser = 10000 [= (int)(maxApplications * (userLimit / 100.0f) * userLimitFactor) ]
usedCapacity = 0.0 [= usedResourcesMemory / (clusterResourceMemory * absoluteCapacity)]
absoluteUsedCapacity = 0.0 [= usedResourcesMemory / clusterResourceMemory]
maxAMResourcePerQueuePercent = 0.1 [= configuredMaximumAMResourcePercent ]
minimumAllocationFactor = 0.875 [= (float)(maximumAllocationMemory - minimumAllocationMemory) / maximumAllocationMemory ]
maximumAllocation = <memory:8192, vCores:32> [= configuredMaxAllocation ]
numContainers = 0 [= currentNumContainers ]
state = RUNNING [= configuredState ]
acls = SUBMIT_APP:*ADMINISTER_QUEUE:* [= configuredAcls ]
nodeLocalityDelay = 40
labels=*,
nodeLocalityDelay = 40
reservationsContinueLooking = true
preemptionDisabled = true

2016-03-19 18:49:50,761 INFO org.apache.hadoop.yarn.server.resourcemanager.scheduler.capacity.CapacityScheduler: Initialized queue: default: capacity=1.0, absoluteCapacity=1.0, usedResources=<memory:0, vCores:0>, usedCapacity=0.0, absoluteUsedCapacity=0.0, numApps=0, numContainers=0
2016-03-19 18:49:50,761 INFO org.apache.hadoop.yarn.server.resourcemanager.scheduler.capacity.CapacityScheduler: Initialized queue: root: numChildQueue= 1, capacity=1.0, absoluteCapacity=1.0, usedResources=<memory:0, vCores:0>usedCapacity=0.0, numApps=0, numContainers=0
2016-03-19 18:49:50,762 INFO org.apache.hadoop.yarn.server.resourcemanager.scheduler.capacity.CapacityScheduler: Initialized root queue root: numChildQueue= 1, capacity=1.0, absoluteCapacity=1.0, usedResources=<memory:0, vCores:0>usedCapacity=0.0, numApps=0, numContainers=0
2016-03-19 18:49:50,762 INFO org.apache.hadoop.yarn.server.resourcemanager.scheduler.capacity.CapacityScheduler: Initialized queue mappings, override: false
2016-03-19 18:49:50,762 INFO org.apache.hadoop.yarn.server.resourcemanager.scheduler.capacity.CapacityScheduler: Initialized CapacityScheduler with calculator=class org.apache.hadoop.yarn.util.resource.DefaultResourceCalculator, minimumAllocation=<<memory:1024, vCores:1>>, maximumAllocation=<<memory:8192, vCores:32>>, asynchronousScheduling=false, asyncScheduleInterval=5ms
2016-03-19 18:49:50,823 INFO org.apache.hadoop.yarn.server.resourcemanager.metrics.SystemMetricsPublisher: YARN system metrics publishing service is not enabled
2016-03-19 18:49:50,823 INFO org.apache.hadoop.yarn.server.resourcemanager.ResourceManager: Transitioning to active state
2016-03-19 18:49:50,897 INFO org.apache.hadoop.yarn.server.resourcemanager.recovery.RMStateStore: Updating AMRMToken
2016-03-19 18:49:50,897 INFO org.apache.hadoop.yarn.server.resourcemanager.security.RMContainerTokenSecretManager: Rolling master-key for container-tokens
2016-03-19 18:49:50,904 INFO org.apache.hadoop.yarn.server.resourcemanager.security.NMTokenSecretManagerInRM: Rolling master-key for nm-tokens
2016-03-19 18:49:50,904 INFO org.apache.hadoop.security.token.delegation.AbstractDelegationTokenSecretManager: Updating the current master key for generating delegation tokens
2016-03-19 18:49:50,906 INFO org.apache.hadoop.yarn.server.resourcemanager.security.RMDelegationTokenSecretManager: storing master key with keyID 1
2016-03-19 18:49:50,906 INFO org.apache.hadoop.yarn.server.resourcemanager.recovery.RMStateStore: Storing RMDTMasterKey.
2016-03-19 18:49:50,920 INFO org.apache.hadoop.security.token.delegation.AbstractDelegationTokenSecretManager: Starting expired delegation token remover thread, tokenRemoverScanInterval=60 min(s)
2016-03-19 18:49:50,945 INFO org.apache.hadoop.security.token.delegation.AbstractDelegationTokenSecretManager: Updating the current master key for generating delegation tokens
2016-03-19 18:49:50,946 INFO org.apache.hadoop.yarn.server.resourcemanager.security.RMDelegationTokenSecretManager: storing master key with keyID 2
2016-03-19 18:49:50,946 INFO org.apache.hadoop.yarn.server.resourcemanager.recovery.RMStateStore: Storing RMDTMasterKey.
2016-03-19 18:49:50,946 INFO org.apache.hadoop.yarn.event.AsyncDispatcher: Registering class org.apache.hadoop.yarn.nodelabels.event.NodeLabelsStoreEventType for class org.apache.hadoop.yarn.nodelabels.CommonNodeLabelsManager$ForwardingEventHandler
2016-03-19 18:49:51,094 INFO org.apache.hadoop.ipc.CallQueueManager: Using callQueue class java.util.concurrent.LinkedBlockingQueue
2016-03-19 18:49:51,156 INFO org.apache.hadoop.ipc.Server: Starting Socket Reader #1 for port 8031
2016-03-19 18:49:51,213 INFO org.apache.hadoop.yarn.factories.impl.pb.RpcServerFactoryPBImpl: Adding protocol org.apache.hadoop.yarn.server.api.ResourceTrackerPB to the server
2016-03-19 18:49:51,213 INFO org.apache.hadoop.ipc.Server: IPC Server Responder: starting
2016-03-19 18:49:51,256 INFO org.apache.hadoop.ipc.Server: IPC Server listener on 8031: starting
2016-03-19 18:49:51,378 INFO org.apache.hadoop.ipc.CallQueueManager: Using callQueue class java.util.concurrent.LinkedBlockingQueue
2016-03-19 18:49:51,392 INFO org.apache.hadoop.ipc.Server: Starting Socket Reader #1 for port 8030
2016-03-19 18:49:51,438 INFO org.apache.hadoop.yarn.factories.impl.pb.RpcServerFactoryPBImpl: Adding protocol org.apache.hadoop.yarn.api.ApplicationMasterProtocolPB to the server
2016-03-19 18:49:51,438 INFO org.apache.hadoop.ipc.Server: IPC Server Responder: starting
2016-03-19 18:49:51,487 INFO org.apache.hadoop.ipc.Server: IPC Server listener on 8030: starting
2016-03-19 18:49:51,757 INFO org.apache.hadoop.ipc.CallQueueManager: Using callQueue class java.util.concurrent.LinkedBlockingQueue
2016-03-19 18:49:51,764 INFO org.apache.hadoop.ipc.Server: Starting Socket Reader #1 for port 8032
2016-03-19 18:49:51,766 INFO org.apache.hadoop.yarn.factories.impl.pb.RpcServerFactoryPBImpl: Adding protocol org.apache.hadoop.yarn.api.ApplicationClientProtocolPB to the server
2016-03-19 18:49:51,786 INFO org.apache.hadoop.ipc.Server: IPC Server listener on 8032: starting
2016-03-19 18:49:51,812 INFO org.apache.hadoop.ipc.Server: IPC Server Responder: starting
2016-03-19 18:49:51,836 INFO org.apache.hadoop.yarn.server.resourcemanager.ResourceManager: Transitioned to active state
2016-03-19 18:49:52,210 INFO org.mortbay.log: Logging to org.slf4j.impl.Log4jLoggerAdapter(org.mortbay.log) via org.mortbay.log.Slf4jLog
2016-03-19 18:49:52,252 INFO org.apache.hadoop.security.authentication.server.AuthenticationFilter: Unable to initialize FileSignerSecretProvider, falling back to use random secrets.
2016-03-19 18:49:52,271 INFO org.apache.hadoop.http.HttpRequestLog: Http request log for http.requests.resourcemanager is not defined
2016-03-19 18:49:52,318 INFO org.apache.hadoop.http.HttpServer2: Added global filter 'safety' (class=org.apache.hadoop.http.HttpServer2$QuotingInputFilter)
2016-03-19 18:49:52,333 INFO org.apache.hadoop.http.HttpServer2: Added filter RMAuthenticationFilter (class=org.apache.hadoop.yarn.server.security.http.RMAuthenticationFilter) to context cluster
2016-03-19 18:49:52,339 INFO org.apache.hadoop.http.HttpServer2: Added filter RMAuthenticationFilter (class=org.apache.hadoop.yarn.server.security.http.RMAuthenticationFilter) to context logs
2016-03-19 18:49:52,339 INFO org.apache.hadoop.http.HttpServer2: Added filter RMAuthenticationFilter (class=org.apache.hadoop.yarn.server.security.http.RMAuthenticationFilter) to context static
2016-03-19 18:49:52,350 INFO org.apache.hadoop.http.HttpServer2: Added filter static_user_filter (class=org.apache.hadoop.http.lib.StaticUserWebFilter$StaticUserFilter) to context cluster
2016-03-19 18:49:52,350 INFO org.apache.hadoop.http.HttpServer2: Added filter static_user_filter (class=org.apache.hadoop.http.lib.StaticUserWebFilter$StaticUserFilter) to context logs
2016-03-19 18:49:52,350 INFO org.apache.hadoop.http.HttpServer2: Added filter static_user_filter (class=org.apache.hadoop.http.lib.StaticUserWebFilter$StaticUserFilter) to context static
2016-03-19 18:49:52,365 INFO org.apache.hadoop.http.HttpServer2: adding path spec: /cluster/*
2016-03-19 18:49:52,365 INFO org.apache.hadoop.http.HttpServer2: adding path spec: /ws/*
2016-03-19 18:49:53,870 INFO org.apache.hadoop.yarn.webapp.WebApps: Registered webapp guice modules
2016-03-19 18:49:53,881 INFO org.apache.hadoop.http.HttpServer2: Jetty bound to port 8088
2016-03-19 18:49:53,881 INFO org.mortbay.log: jetty-6.1.26
2016-03-19 18:49:53,941 INFO org.mortbay.log: Extract jar:file:/usr/local/hadoop/share/hadoop/yarn/hadoop-yarn-common-2.7.2.jar!/webapps/cluster to /tmp/Jetty_0_0_0_0_8088_cluster____u0rgz3/webapp
2016-03-19 18:49:54,734 INFO org.apache.hadoop.security.token.delegation.AbstractDelegationTokenSecretManager: Updating the current master key for generating delegation tokens
2016-03-19 18:49:54,738 INFO org.apache.hadoop.security.token.delegation.AbstractDelegationTokenSecretManager: Starting expired delegation token remover thread, tokenRemoverScanInterval=60 min(s)
2016-03-19 18:49:54,740 INFO org.apache.hadoop.security.token.delegation.AbstractDelegationTokenSecretManager: Updating the current master key for generating delegation tokens
2016-03-19 18:49:58,953 INFO org.mortbay.log: Started HttpServer2$SelectChannelConnectorWithSafeStartup@0.0.0.0:8088
2016-03-19 18:49:58,953 INFO org.apache.hadoop.yarn.webapp.WebApps: Web app cluster started at 8088
2016-03-19 18:49:59,148 INFO org.apache.hadoop.ipc.CallQueueManager: Using callQueue class java.util.concurrent.LinkedBlockingQueue
2016-03-19 18:49:59,159 INFO org.apache.hadoop.ipc.Server: Starting Socket Reader #1 for port 8033
2016-03-19 18:49:59,165 INFO org.apache.hadoop.yarn.factories.impl.pb.RpcServerFactoryPBImpl: Adding protocol org.apache.hadoop.yarn.server.api.ResourceManagerAdministrationProtocolPB to the server
2016-03-19 18:49:59,168 INFO org.apache.hadoop.ipc.Server: IPC Server Responder: starting
2016-03-19 18:49:59,168 INFO org.apache.hadoop.ipc.Server: IPC Server listener on 8033: starting
2016-03-19 18:49:59,817 INFO org.apache.hadoop.yarn.util.RackResolver: Resolved vishal-VirtualBox to /default-rack
2016-03-19 18:49:59,826 INFO org.apache.hadoop.yarn.server.resourcemanager.rmnode.RMNodeImpl: vishal-VirtualBox:43256 Node Transitioned from NEW to RUNNING
2016-03-19 18:49:59,830 INFO org.apache.hadoop.yarn.server.resourcemanager.scheduler.capacity.CapacityScheduler: Added node vishal-VirtualBox:43256 clusterResource: <memory:8192, vCores:8>
2016-03-19 18:49:59,831 INFO org.apache.hadoop.yarn.server.resourcemanager.ResourceTrackerService: NodeManager from node vishal-VirtualBox(cmPort: 43256 httpPort: 8042) registered with capability: <memory:8192, vCores:8>, assigned nodeId vishal-VirtualBox:43256
2016-03-19 18:59:50,437 INFO org.apache.hadoop.yarn.server.resourcemanager.scheduler.AbstractYarnScheduler: Release request cache is cleaned up
2016-03-19 19:04:24,710 ERROR org.apache.hadoop.yarn.server.resourcemanager.ResourceManager: RECEIVED SIGNAL 15: SIGTERM
2016-03-19 19:04:24,820 ERROR org.apache.hadoop.security.token.delegation.AbstractDelegationTokenSecretManager: ExpiredTokenRemover received java.lang.InterruptedException: sleep interrupted
2016-03-19 19:04:24,834 INFO org.mortbay.log: Stopped HttpServer2$SelectChannelConnectorWithSafeStartup@0.0.0.0:8088
2016-03-19 19:04:24,839 INFO org.apache.hadoop.ipc.Server: Stopping server on 8032
2016-03-19 19:04:24,854 INFO org.apache.hadoop.ipc.Server: Stopping IPC Server Responder
2016-03-19 19:04:24,855 INFO org.apache.hadoop.ipc.Server: Stopping IPC Server listener on 8032
2016-03-19 19:04:24,855 INFO org.apache.hadoop.ipc.Server: Stopping server on 8033
2016-03-19 19:04:24,856 INFO org.apache.hadoop.ipc.Server: Stopping IPC Server listener on 8033
2016-03-19 19:04:24,857 INFO org.apache.hadoop.yarn.server.resourcemanager.ResourceManager: Transitioning to standby state
2016-03-19 19:04:24,857 WARN org.apache.hadoop.yarn.server.resourcemanager.amlauncher.ApplicationMasterLauncher: org.apache.hadoop.yarn.server.resourcemanager.amlauncher.ApplicationMasterLauncher$LauncherThread interrupted. Returning.
2016-03-19 19:04:24,857 INFO org.apache.hadoop.ipc.Server: Stopping server on 8030
2016-03-19 19:04:24,862 INFO org.apache.hadoop.ipc.Server: Stopping IPC Server Responder
2016-03-19 19:04:24,863 INFO org.apache.hadoop.ipc.Server: Stopping server on 8031
2016-03-19 19:04:24,863 INFO org.apache.hadoop.ipc.Server: Stopping IPC Server Responder
2016-03-19 19:04:24,867 INFO org.apache.hadoop.ipc.Server: Stopping IPC Server listener on 8030
2016-03-19 19:04:24,870 INFO org.apache.hadoop.ipc.Server: Stopping IPC Server listener on 8031
2016-03-19 19:04:24,870 INFO org.apache.hadoop.ipc.Server: Stopping IPC Server Responder
2016-03-19 19:04:24,870 INFO org.apache.hadoop.yarn.util.AbstractLivelinessMonitor: NMLivelinessMonitor thread interrupted
2016-03-19 19:04:24,870 ERROR org.apache.hadoop.yarn.server.resourcemanager.ResourceManager: Returning, interrupted : java.lang.InterruptedException
2016-03-19 19:04:24,871 INFO org.apache.hadoop.yarn.event.AsyncDispatcher: AsyncDispatcher is draining to stop, igonring any new events.
2016-03-19 19:04:24,872 ERROR org.apache.hadoop.security.token.delegation.AbstractDelegationTokenSecretManager: ExpiredTokenRemover received java.lang.InterruptedException: sleep interrupted
2016-03-19 19:04:24,872 INFO org.apache.hadoop.metrics2.impl.MetricsSystemImpl: Stopping ResourceManager metrics system...
2016-03-19 19:04:24,872 INFO org.apache.hadoop.yarn.util.AbstractLivelinessMonitor: AMLivelinessMonitor thread interrupted
2016-03-19 19:04:24,872 INFO org.apache.hadoop.yarn.util.AbstractLivelinessMonitor: AMLivelinessMonitor thread interrupted
2016-03-19 19:04:24,872 INFO org.apache.hadoop.yarn.util.AbstractLivelinessMonitor: org.apache.hadoop.yarn.server.resourcemanager.rmcontainer.ContainerAllocationExpirer thread interrupted
2016-03-19 19:04:24,874 INFO org.apache.hadoop.metrics2.impl.MetricsSystemImpl: ResourceManager metrics system stopped.
2016-03-19 19:04:24,874 INFO org.apache.hadoop.metrics2.impl.MetricsSystemImpl: ResourceManager metrics system shutdown complete.
2016-03-19 19:04:24,874 INFO org.apache.hadoop.yarn.event.AsyncDispatcher: AsyncDispatcher is draining to stop, igonring any new events.
2016-03-19 19:04:24,874 INFO org.apache.hadoop.yarn.server.resourcemanager.ResourceManager: Transitioned to standby state
2016-03-19 19:04:24,874 INFO org.apache.hadoop.yarn.server.resourcemanager.ResourceManager: SHUTDOWN_MSG: 
/************************************************************
SHUTDOWN_MSG: Shutting down ResourceManager at vishal-VirtualBox/127.0.1.1
************************************************************/
2016-03-19 19:10:52,058 INFO org.apache.hadoop.yarn.server.resourcemanager.ResourceManager: STARTUP_MSG: 
/************************************************************
STARTUP_MSG: Starting ResourceManager
STARTUP_MSG:   host = vishal-VirtualBox/127.0.1.1
STARTUP_MSG:   args = []
STARTUP_MSG:   version = 2.7.2
STARTUP_MSG:   build = https://git-wip-us.apache.org/repos/asf/hadoop.git -r b165c4fe8a74265c792ce23f546c64604acf0e41; compiled by 'jenkins' on 2016-01-26T00:08Z
STARTUP_MSG:   java = 1.8.0_74
************************************************************/
2016-03-19 19:10:52,180 INFO org.apache.hadoop.yarn.server.resourcemanager.ResourceManager: registered UNIX signal handlers for [TERM, HUP, INT]
2016-03-19 19:10:53,864 INFO org.apache.hadoop.conf.Configuration: found resource core-site.xml at file:/usr/local/hadoop/etc/hadoop/core-site.xml
2016-03-19 19:10:54,235 WARN org.apache.hadoop.util.NativeCodeLoader: Unable to load native-hadoop library for your platform... using builtin-java classes where applicable
2016-03-19 19:10:54,352 INFO org.apache.hadoop.security.Groups: clearing userToGroupsMap cache
2016-03-19 19:10:54,785 INFO org.apache.hadoop.conf.Configuration: found resource yarn-site.xml at file:/usr/local/hadoop/etc/hadoop/yarn-site.xml
2016-03-19 19:10:55,757 INFO org.apache.hadoop.yarn.event.AsyncDispatcher: Registering class org.apache.hadoop.yarn.server.resourcemanager.RMFatalEventType for class org.apache.hadoop.yarn.server.resourcemanager.ResourceManager$RMFatalEventDispatcher
2016-03-19 19:10:57,185 INFO org.apache.hadoop.yarn.server.resourcemanager.security.NMTokenSecretManagerInRM: NMTokenKeyRollingInterval: 86400000ms and NMTokenKeyActivationDelay: 900000ms
2016-03-19 19:10:57,247 INFO org.apache.hadoop.yarn.server.resourcemanager.security.RMContainerTokenSecretManager: ContainerTokenKeyRollingInterval: 86400000ms and ContainerTokenKeyActivationDelay: 900000ms
2016-03-19 19:10:57,280 INFO org.apache.hadoop.yarn.server.resourcemanager.security.AMRMTokenSecretManager: AMRMTokenKeyRollingInterval: 86400000ms and AMRMTokenKeyActivationDelay: 900000 ms
2016-03-19 19:10:57,696 INFO org.apache.hadoop.yarn.event.AsyncDispatcher: Registering class org.apache.hadoop.yarn.server.resourcemanager.recovery.RMStateStoreEventType for class org.apache.hadoop.yarn.server.resourcemanager.recovery.RMStateStore$ForwardingEventHandler
2016-03-19 19:10:57,719 INFO org.apache.hadoop.yarn.event.AsyncDispatcher: Registering class org.apache.hadoop.yarn.server.resourcemanager.NodesListManagerEventType for class org.apache.hadoop.yarn.server.resourcemanager.NodesListManager
2016-03-19 19:10:57,719 INFO org.apache.hadoop.yarn.server.resourcemanager.ResourceManager: Using Scheduler: org.apache.hadoop.yarn.server.resourcemanager.scheduler.capacity.CapacityScheduler
2016-03-19 19:10:57,913 INFO org.apache.hadoop.yarn.event.AsyncDispatcher: Registering class org.apache.hadoop.yarn.server.resourcemanager.scheduler.event.SchedulerEventType for class org.apache.hadoop.yarn.server.resourcemanager.ResourceManager$SchedulerEventDispatcher
2016-03-19 19:10:57,914 INFO org.apache.hadoop.yarn.event.AsyncDispatcher: Registering class org.apache.hadoop.yarn.server.resourcemanager.rmapp.RMAppEventType for class org.apache.hadoop.yarn.server.resourcemanager.ResourceManager$ApplicationEventDispatcher
2016-03-19 19:10:57,916 INFO org.apache.hadoop.yarn.event.AsyncDispatcher: Registering class org.apache.hadoop.yarn.server.resourcemanager.rmapp.attempt.RMAppAttemptEventType for class org.apache.hadoop.yarn.server.resourcemanager.ResourceManager$ApplicationAttemptEventDispatcher
2016-03-19 19:10:57,928 INFO org.apache.hadoop.yarn.event.AsyncDispatcher: Registering class org.apache.hadoop.yarn.server.resourcemanager.rmnode.RMNodeEventType for class org.apache.hadoop.yarn.server.resourcemanager.ResourceManager$NodeEventDispatcher
2016-03-19 19:10:58,371 INFO org.apache.hadoop.metrics2.impl.MetricsConfig: loaded properties from hadoop-metrics2.properties
2016-03-19 19:10:58,868 INFO org.apache.hadoop.metrics2.impl.MetricsSystemImpl: Scheduled snapshot period at 10 second(s).
2016-03-19 19:10:58,868 INFO org.apache.hadoop.metrics2.impl.MetricsSystemImpl: ResourceManager metrics system started
2016-03-19 19:10:58,999 INFO org.apache.hadoop.yarn.event.AsyncDispatcher: Registering class org.apache.hadoop.yarn.server.resourcemanager.RMAppManagerEventType for class org.apache.hadoop.yarn.server.resourcemanager.RMAppManager
2016-03-19 19:10:59,047 INFO org.apache.hadoop.yarn.event.AsyncDispatcher: Registering class org.apache.hadoop.yarn.server.resourcemanager.amlauncher.AMLauncherEventType for class org.apache.hadoop.yarn.server.resourcemanager.amlauncher.ApplicationMasterLauncher
2016-03-19 19:10:59,059 INFO org.apache.hadoop.yarn.server.resourcemanager.RMNMInfo: Registered RMNMInfo MBean
2016-03-19 19:10:59,070 INFO org.apache.hadoop.yarn.security.YarnAuthorizationProvider: org.apache.hadoop.yarn.security.ConfiguredYarnAuthorizer is instiantiated.
2016-03-19 19:10:59,076 INFO org.apache.hadoop.util.HostsFileReader: Refreshing hosts (include/exclude) list
2016-03-19 19:10:59,133 INFO org.apache.hadoop.conf.Configuration: found resource capacity-scheduler.xml at file:/usr/local/hadoop/etc/hadoop/capacity-scheduler.xml
2016-03-19 19:10:59,643 INFO org.apache.hadoop.yarn.server.resourcemanager.scheduler.capacity.CapacitySchedulerConfiguration: max alloc mb per queue for root is undefined
2016-03-19 19:10:59,643 INFO org.apache.hadoop.yarn.server.resourcemanager.scheduler.capacity.CapacitySchedulerConfiguration: max alloc vcore per queue for root is undefined
2016-03-19 19:10:59,718 INFO org.apache.hadoop.yarn.server.resourcemanager.scheduler.capacity.ParentQueue: root, capacity=1.0, asboluteCapacity=1.0, maxCapacity=1.0, asboluteMaxCapacity=1.0, state=RUNNING, acls=SUBMIT_APP:*ADMINISTER_QUEUE:*, labels=*,
, reservationsContinueLooking=true
2016-03-19 19:10:59,718 INFO org.apache.hadoop.yarn.server.resourcemanager.scheduler.capacity.ParentQueue: Initialized parent-queue root name=root, fullname=root
2016-03-19 19:10:59,774 INFO org.apache.hadoop.yarn.server.resourcemanager.scheduler.capacity.CapacitySchedulerConfiguration: max alloc mb per queue for root.default is undefined
2016-03-19 19:10:59,774 INFO org.apache.hadoop.yarn.server.resourcemanager.scheduler.capacity.CapacitySchedulerConfiguration: max alloc vcore per queue for root.default is undefined
2016-03-19 19:10:59,776 INFO org.apache.hadoop.yarn.server.resourcemanager.scheduler.capacity.LeafQueue: Initializing default
capacity = 1.0 [= (float) configuredCapacity / 100 ]
asboluteCapacity = 1.0 [= parentAbsoluteCapacity * capacity ]
maxCapacity = 1.0 [= configuredMaxCapacity ]
absoluteMaxCapacity = 1.0 [= 1.0 maximumCapacity undefined, (parentAbsoluteMaxCapacity * maximumCapacity) / 100 otherwise ]
userLimit = 100 [= configuredUserLimit ]
userLimitFactor = 1.0 [= configuredUserLimitFactor ]
maxApplications = 10000 [= configuredMaximumSystemApplicationsPerQueue or (int)(configuredMaximumSystemApplications * absoluteCapacity)]
maxApplicationsPerUser = 10000 [= (int)(maxApplications * (userLimit / 100.0f) * userLimitFactor) ]
usedCapacity = 0.0 [= usedResourcesMemory / (clusterResourceMemory * absoluteCapacity)]
absoluteUsedCapacity = 0.0 [= usedResourcesMemory / clusterResourceMemory]
maxAMResourcePerQueuePercent = 0.1 [= configuredMaximumAMResourcePercent ]
minimumAllocationFactor = 0.875 [= (float)(maximumAllocationMemory - minimumAllocationMemory) / maximumAllocationMemory ]
maximumAllocation = <memory:8192, vCores:32> [= configuredMaxAllocation ]
numContainers = 0 [= currentNumContainers ]
state = RUNNING [= configuredState ]
acls = SUBMIT_APP:*ADMINISTER_QUEUE:* [= configuredAcls ]
nodeLocalityDelay = 40
labels=*,
nodeLocalityDelay = 40
reservationsContinueLooking = true
preemptionDisabled = true

2016-03-19 19:10:59,776 INFO org.apache.hadoop.yarn.server.resourcemanager.scheduler.capacity.CapacityScheduler: Initialized queue: default: capacity=1.0, absoluteCapacity=1.0, usedResources=<memory:0, vCores:0>, usedCapacity=0.0, absoluteUsedCapacity=0.0, numApps=0, numContainers=0
2016-03-19 19:10:59,776 INFO org.apache.hadoop.yarn.server.resourcemanager.scheduler.capacity.CapacityScheduler: Initialized queue: root: numChildQueue= 1, capacity=1.0, absoluteCapacity=1.0, usedResources=<memory:0, vCores:0>usedCapacity=0.0, numApps=0, numContainers=0
2016-03-19 19:10:59,777 INFO org.apache.hadoop.yarn.server.resourcemanager.scheduler.capacity.CapacityScheduler: Initialized root queue root: numChildQueue= 1, capacity=1.0, absoluteCapacity=1.0, usedResources=<memory:0, vCores:0>usedCapacity=0.0, numApps=0, numContainers=0
2016-03-19 19:10:59,777 INFO org.apache.hadoop.yarn.server.resourcemanager.scheduler.capacity.CapacityScheduler: Initialized queue mappings, override: false
2016-03-19 19:10:59,785 INFO org.apache.hadoop.yarn.server.resourcemanager.scheduler.capacity.CapacityScheduler: Initialized CapacityScheduler with calculator=class org.apache.hadoop.yarn.util.resource.DefaultResourceCalculator, minimumAllocation=<<memory:1024, vCores:1>>, maximumAllocation=<<memory:8192, vCores:32>>, asynchronousScheduling=false, asyncScheduleInterval=5ms
2016-03-19 19:10:59,848 INFO org.apache.hadoop.yarn.server.resourcemanager.metrics.SystemMetricsPublisher: YARN system metrics publishing service is not enabled
2016-03-19 19:10:59,849 INFO org.apache.hadoop.yarn.server.resourcemanager.ResourceManager: Transitioning to active state
2016-03-19 19:10:59,968 INFO org.apache.hadoop.yarn.server.resourcemanager.recovery.RMStateStore: Updating AMRMToken
2016-03-19 19:10:59,970 INFO org.apache.hadoop.yarn.server.resourcemanager.security.RMContainerTokenSecretManager: Rolling master-key for container-tokens
2016-03-19 19:10:59,971 INFO org.apache.hadoop.yarn.server.resourcemanager.security.NMTokenSecretManagerInRM: Rolling master-key for nm-tokens
2016-03-19 19:10:59,971 INFO org.apache.hadoop.security.token.delegation.AbstractDelegationTokenSecretManager: Updating the current master key for generating delegation tokens
2016-03-19 19:10:59,975 INFO org.apache.hadoop.yarn.server.resourcemanager.security.RMDelegationTokenSecretManager: storing master key with keyID 1
2016-03-19 19:10:59,977 INFO org.apache.hadoop.yarn.server.resourcemanager.recovery.RMStateStore: Storing RMDTMasterKey.
2016-03-19 19:10:59,998 INFO org.apache.hadoop.security.token.delegation.AbstractDelegationTokenSecretManager: Starting expired delegation token remover thread, tokenRemoverScanInterval=60 min(s)
2016-03-19 19:11:00,002 INFO org.apache.hadoop.yarn.event.AsyncDispatcher: Registering class org.apache.hadoop.yarn.nodelabels.event.NodeLabelsStoreEventType for class org.apache.hadoop.yarn.nodelabels.CommonNodeLabelsManager$ForwardingEventHandler
2016-03-19 19:11:00,044 INFO org.apache.hadoop.security.token.delegation.AbstractDelegationTokenSecretManager: Updating the current master key for generating delegation tokens
2016-03-19 19:11:00,049 INFO org.apache.hadoop.yarn.server.resourcemanager.security.RMDelegationTokenSecretManager: storing master key with keyID 2
2016-03-19 19:11:00,049 INFO org.apache.hadoop.yarn.server.resourcemanager.recovery.RMStateStore: Storing RMDTMasterKey.
2016-03-19 19:11:00,173 INFO org.apache.hadoop.ipc.CallQueueManager: Using callQueue class java.util.concurrent.LinkedBlockingQueue
2016-03-19 19:11:00,292 INFO org.apache.hadoop.ipc.Server: Starting Socket Reader #1 for port 8031
2016-03-19 19:11:00,416 INFO org.apache.hadoop.yarn.factories.impl.pb.RpcServerFactoryPBImpl: Adding protocol org.apache.hadoop.yarn.server.api.ResourceTrackerPB to the server
2016-03-19 19:11:00,424 INFO org.apache.hadoop.ipc.Server: IPC Server Responder: starting
2016-03-19 19:11:00,495 INFO org.apache.hadoop.ipc.Server: IPC Server listener on 8031: starting
2016-03-19 19:11:00,714 INFO org.apache.hadoop.ipc.CallQueueManager: Using callQueue class java.util.concurrent.LinkedBlockingQueue
2016-03-19 19:11:00,729 INFO org.apache.hadoop.ipc.Server: Starting Socket Reader #1 for port 8030
2016-03-19 19:11:00,789 INFO org.apache.hadoop.yarn.factories.impl.pb.RpcServerFactoryPBImpl: Adding protocol org.apache.hadoop.yarn.api.ApplicationMasterProtocolPB to the server
2016-03-19 19:11:00,790 INFO org.apache.hadoop.ipc.Server: IPC Server Responder: starting
2016-03-19 19:11:00,801 INFO org.apache.hadoop.ipc.Server: IPC Server listener on 8030: starting
2016-03-19 19:11:01,498 INFO org.apache.hadoop.ipc.CallQueueManager: Using callQueue class java.util.concurrent.LinkedBlockingQueue
2016-03-19 19:11:01,499 INFO org.apache.hadoop.ipc.Server: Starting Socket Reader #1 for port 8032
2016-03-19 19:11:01,526 INFO org.apache.hadoop.yarn.factories.impl.pb.RpcServerFactoryPBImpl: Adding protocol org.apache.hadoop.yarn.api.ApplicationClientProtocolPB to the server
2016-03-19 19:11:01,526 INFO org.apache.hadoop.ipc.Server: IPC Server Responder: starting
2016-03-19 19:11:01,600 INFO org.apache.hadoop.ipc.Server: IPC Server listener on 8032: starting
2016-03-19 19:11:01,650 INFO org.apache.hadoop.yarn.server.resourcemanager.ResourceManager: Transitioned to active state
2016-03-19 19:11:02,407 INFO org.mortbay.log: Logging to org.slf4j.impl.Log4jLoggerAdapter(org.mortbay.log) via org.mortbay.log.Slf4jLog
2016-03-19 19:11:02,476 INFO org.apache.hadoop.security.authentication.server.AuthenticationFilter: Unable to initialize FileSignerSecretProvider, falling back to use random secrets.
2016-03-19 19:11:02,514 INFO org.apache.hadoop.http.HttpRequestLog: Http request log for http.requests.resourcemanager is not defined
2016-03-19 19:11:02,569 INFO org.apache.hadoop.http.HttpServer2: Added global filter 'safety' (class=org.apache.hadoop.http.HttpServer2$QuotingInputFilter)
2016-03-19 19:11:02,602 INFO org.apache.hadoop.http.HttpServer2: Added filter RMAuthenticationFilter (class=org.apache.hadoop.yarn.server.security.http.RMAuthenticationFilter) to context cluster
2016-03-19 19:11:02,602 INFO org.apache.hadoop.http.HttpServer2: Added filter RMAuthenticationFilter (class=org.apache.hadoop.yarn.server.security.http.RMAuthenticationFilter) to context logs
2016-03-19 19:11:02,603 INFO org.apache.hadoop.http.HttpServer2: Added filter RMAuthenticationFilter (class=org.apache.hadoop.yarn.server.security.http.RMAuthenticationFilter) to context static
2016-03-19 19:11:02,607 INFO org.apache.hadoop.http.HttpServer2: Added filter static_user_filter (class=org.apache.hadoop.http.lib.StaticUserWebFilter$StaticUserFilter) to context cluster
2016-03-19 19:11:02,607 INFO org.apache.hadoop.http.HttpServer2: Added filter static_user_filter (class=org.apache.hadoop.http.lib.StaticUserWebFilter$StaticUserFilter) to context logs
2016-03-19 19:11:02,607 INFO org.apache.hadoop.http.HttpServer2: Added filter static_user_filter (class=org.apache.hadoop.http.lib.StaticUserWebFilter$StaticUserFilter) to context static
2016-03-19 19:11:02,634 INFO org.apache.hadoop.http.HttpServer2: adding path spec: /cluster/*
2016-03-19 19:11:02,635 INFO org.apache.hadoop.http.HttpServer2: adding path spec: /ws/*
2016-03-19 19:11:04,861 INFO org.apache.hadoop.yarn.webapp.WebApps: Registered webapp guice modules
2016-03-19 19:11:04,864 INFO org.apache.hadoop.http.HttpServer2: Jetty bound to port 8088
2016-03-19 19:11:04,865 INFO org.mortbay.log: jetty-6.1.26
2016-03-19 19:11:05,047 INFO org.mortbay.log: Extract jar:file:/usr/local/hadoop/share/hadoop/yarn/hadoop-yarn-common-2.7.2.jar!/webapps/cluster to /tmp/Jetty_0_0_0_0_8088_cluster____u0rgz3/webapp
2016-03-19 19:11:06,508 INFO org.apache.hadoop.security.token.delegation.AbstractDelegationTokenSecretManager: Updating the current master key for generating delegation tokens
2016-03-19 19:11:06,517 INFO org.apache.hadoop.security.token.delegation.AbstractDelegationTokenSecretManager: Starting expired delegation token remover thread, tokenRemoverScanInterval=60 min(s)
2016-03-19 19:11:06,536 INFO org.apache.hadoop.security.token.delegation.AbstractDelegationTokenSecretManager: Updating the current master key for generating delegation tokens
2016-03-19 19:11:14,046 INFO org.mortbay.log: Started HttpServer2$SelectChannelConnectorWithSafeStartup@0.0.0.0:8088
2016-03-19 19:11:14,047 INFO org.apache.hadoop.yarn.webapp.WebApps: Web app cluster started at 8088
2016-03-19 19:11:14,368 INFO org.apache.hadoop.ipc.CallQueueManager: Using callQueue class java.util.concurrent.LinkedBlockingQueue
2016-03-19 19:11:14,380 INFO org.apache.hadoop.ipc.Server: Starting Socket Reader #1 for port 8033
2016-03-19 19:11:14,394 INFO org.apache.hadoop.yarn.factories.impl.pb.RpcServerFactoryPBImpl: Adding protocol org.apache.hadoop.yarn.server.api.ResourceManagerAdministrationProtocolPB to the server
2016-03-19 19:11:14,395 INFO org.apache.hadoop.ipc.Server: IPC Server Responder: starting
2016-03-19 19:11:14,395 INFO org.apache.hadoop.ipc.Server: IPC Server listener on 8033: starting
2016-03-19 19:11:15,631 INFO org.apache.hadoop.yarn.util.RackResolver: Resolved vishal-VirtualBox to /default-rack
2016-03-19 19:11:15,658 INFO org.apache.hadoop.yarn.server.resourcemanager.rmnode.RMNodeImpl: vishal-VirtualBox:34179 Node Transitioned from NEW to RUNNING
2016-03-19 19:11:15,667 INFO org.apache.hadoop.yarn.server.resourcemanager.scheduler.capacity.CapacityScheduler: Added node vishal-VirtualBox:34179 clusterResource: <memory:8192, vCores:8>
2016-03-19 19:11:15,671 INFO org.apache.hadoop.yarn.server.resourcemanager.ResourceTrackerService: NodeManager from node vishal-VirtualBox(cmPort: 34179 httpPort: 8042) registered with capability: <memory:8192, vCores:8>, assigned nodeId vishal-VirtualBox:34179
2016-03-19 19:15:26,656 ERROR org.apache.hadoop.yarn.server.resourcemanager.ResourceManager: RECEIVED SIGNAL 15: SIGTERM
2016-03-19 19:15:26,718 ERROR org.apache.hadoop.security.token.delegation.AbstractDelegationTokenSecretManager: ExpiredTokenRemover received java.lang.InterruptedException: sleep interrupted
2016-03-19 19:15:26,734 INFO org.mortbay.log: Stopped HttpServer2$SelectChannelConnectorWithSafeStartup@0.0.0.0:8088
2016-03-19 19:15:26,740 INFO org.apache.hadoop.ipc.Server: Stopping server on 8032
2016-03-19 19:15:26,754 INFO org.apache.hadoop.ipc.Server: Stopping IPC Server Responder
2016-03-19 19:15:26,757 INFO org.apache.hadoop.ipc.Server: Stopping IPC Server listener on 8032
2016-03-19 19:15:26,758 INFO org.apache.hadoop.ipc.Server: Stopping server on 8033
2016-03-19 19:15:26,762 INFO org.apache.hadoop.ipc.Server: Stopping IPC Server listener on 8033
2016-03-19 19:15:26,762 INFO org.apache.hadoop.ipc.Server: Stopping IPC Server Responder
2016-03-19 19:15:26,769 INFO org.apache.hadoop.yarn.server.resourcemanager.ResourceManager: Transitioning to standby state
2016-03-19 19:15:26,769 WARN org.apache.hadoop.yarn.server.resourcemanager.amlauncher.ApplicationMasterLauncher: org.apache.hadoop.yarn.server.resourcemanager.amlauncher.ApplicationMasterLauncher$LauncherThread interrupted. Returning.
2016-03-19 19:15:26,770 INFO org.apache.hadoop.ipc.Server: Stopping server on 8030
2016-03-19 19:15:26,775 INFO org.apache.hadoop.ipc.Server: Stopping server on 8031
2016-03-19 19:15:26,775 INFO org.apache.hadoop.ipc.Server: Stopping IPC Server Responder
2016-03-19 19:15:26,779 INFO org.apache.hadoop.ipc.Server: Stopping IPC Server listener on 8030
2016-03-19 19:15:26,780 INFO org.apache.hadoop.ipc.Server: Stopping IPC Server listener on 8031
2016-03-19 19:15:26,780 INFO org.apache.hadoop.ipc.Server: Stopping IPC Server Responder
2016-03-19 19:15:26,780 INFO org.apache.hadoop.yarn.util.AbstractLivelinessMonitor: NMLivelinessMonitor thread interrupted
2016-03-19 19:15:26,781 ERROR org.apache.hadoop.yarn.server.resourcemanager.ResourceManager: Returning, interrupted : java.lang.InterruptedException
2016-03-19 19:15:26,782 INFO org.apache.hadoop.yarn.event.AsyncDispatcher: AsyncDispatcher is draining to stop, igonring any new events.
2016-03-19 19:15:26,783 ERROR org.apache.hadoop.security.token.delegation.AbstractDelegationTokenSecretManager: ExpiredTokenRemover received java.lang.InterruptedException: sleep interrupted
2016-03-19 19:15:26,783 INFO org.apache.hadoop.metrics2.impl.MetricsSystemImpl: Stopping ResourceManager metrics system...
2016-03-19 19:15:26,783 INFO org.apache.hadoop.yarn.util.AbstractLivelinessMonitor: AMLivelinessMonitor thread interrupted
2016-03-19 19:15:26,783 INFO org.apache.hadoop.yarn.util.AbstractLivelinessMonitor: AMLivelinessMonitor thread interrupted
2016-03-19 19:15:26,783 INFO org.apache.hadoop.yarn.util.AbstractLivelinessMonitor: org.apache.hadoop.yarn.server.resourcemanager.rmcontainer.ContainerAllocationExpirer thread interrupted
2016-03-19 19:15:26,786 INFO org.apache.hadoop.metrics2.impl.MetricsSystemImpl: ResourceManager metrics system stopped.
2016-03-19 19:15:26,786 INFO org.apache.hadoop.metrics2.impl.MetricsSystemImpl: ResourceManager metrics system shutdown complete.
2016-03-19 19:15:26,786 INFO org.apache.hadoop.yarn.event.AsyncDispatcher: AsyncDispatcher is draining to stop, igonring any new events.
2016-03-19 19:15:26,786 INFO org.apache.hadoop.yarn.server.resourcemanager.ResourceManager: Transitioned to standby state
2016-03-19 19:15:26,786 INFO org.apache.hadoop.yarn.server.resourcemanager.ResourceManager: SHUTDOWN_MSG: 
/************************************************************
SHUTDOWN_MSG: Shutting down ResourceManager at vishal-VirtualBox/127.0.1.1
************************************************************/
2016-03-19 19:16:04,907 INFO org.apache.hadoop.yarn.server.resourcemanager.ResourceManager: STARTUP_MSG: 
/************************************************************
STARTUP_MSG: Starting ResourceManager
STARTUP_MSG:   host = vishal-VirtualBox/127.0.1.1
STARTUP_MSG:   args = []
STARTUP_MSG:   version = 2.7.2
STARTUP_MSG:   build = https://git-wip-us.apache.org/repos/asf/hadoop.git -r b165c4fe8a74265c792ce23f546c64604acf0e41; compiled by 'jenkins' on 2016-01-26T00:08Z
STARTUP_MSG:   java = 1.8.0_74
************************************************************/
2016-03-19 19:16:04,930 INFO org.apache.hadoop.yarn.server.resourcemanager.ResourceManager: registered UNIX signal handlers for [TERM, HUP, INT]
2016-03-19 19:16:06,596 INFO org.apache.hadoop.conf.Configuration: found resource core-site.xml at file:/usr/local/hadoop/etc/hadoop/core-site.xml
2016-03-19 19:16:06,913 WARN org.apache.hadoop.util.NativeCodeLoader: Unable to load native-hadoop library for your platform... using builtin-java classes where applicable
2016-03-19 19:16:07,052 INFO org.apache.hadoop.security.Groups: clearing userToGroupsMap cache
2016-03-19 19:16:07,437 INFO org.apache.hadoop.conf.Configuration: found resource yarn-site.xml at file:/usr/local/hadoop/etc/hadoop/yarn-site.xml
2016-03-19 19:16:08,194 INFO org.apache.hadoop.yarn.event.AsyncDispatcher: Registering class org.apache.hadoop.yarn.server.resourcemanager.RMFatalEventType for class org.apache.hadoop.yarn.server.resourcemanager.ResourceManager$RMFatalEventDispatcher
2016-03-19 19:16:09,177 INFO org.apache.hadoop.yarn.server.resourcemanager.security.NMTokenSecretManagerInRM: NMTokenKeyRollingInterval: 86400000ms and NMTokenKeyActivationDelay: 900000ms
2016-03-19 19:16:09,210 INFO org.apache.hadoop.yarn.server.resourcemanager.security.RMContainerTokenSecretManager: ContainerTokenKeyRollingInterval: 86400000ms and ContainerTokenKeyActivationDelay: 900000ms
2016-03-19 19:16:09,229 INFO org.apache.hadoop.yarn.server.resourcemanager.security.AMRMTokenSecretManager: AMRMTokenKeyRollingInterval: 86400000ms and AMRMTokenKeyActivationDelay: 900000 ms
2016-03-19 19:16:09,506 INFO org.apache.hadoop.yarn.event.AsyncDispatcher: Registering class org.apache.hadoop.yarn.server.resourcemanager.recovery.RMStateStoreEventType for class org.apache.hadoop.yarn.server.resourcemanager.recovery.RMStateStore$ForwardingEventHandler
2016-03-19 19:16:09,508 INFO org.apache.hadoop.yarn.event.AsyncDispatcher: Registering class org.apache.hadoop.yarn.server.resourcemanager.NodesListManagerEventType for class org.apache.hadoop.yarn.server.resourcemanager.NodesListManager
2016-03-19 19:16:09,508 INFO org.apache.hadoop.yarn.server.resourcemanager.ResourceManager: Using Scheduler: org.apache.hadoop.yarn.server.resourcemanager.scheduler.capacity.CapacityScheduler
2016-03-19 19:16:09,675 INFO org.apache.hadoop.yarn.event.AsyncDispatcher: Registering class org.apache.hadoop.yarn.server.resourcemanager.scheduler.event.SchedulerEventType for class org.apache.hadoop.yarn.server.resourcemanager.ResourceManager$SchedulerEventDispatcher
2016-03-19 19:16:09,684 INFO org.apache.hadoop.yarn.event.AsyncDispatcher: Registering class org.apache.hadoop.yarn.server.resourcemanager.rmapp.RMAppEventType for class org.apache.hadoop.yarn.server.resourcemanager.ResourceManager$ApplicationEventDispatcher
2016-03-19 19:16:09,686 INFO org.apache.hadoop.yarn.event.AsyncDispatcher: Registering class org.apache.hadoop.yarn.server.resourcemanager.rmapp.attempt.RMAppAttemptEventType for class org.apache.hadoop.yarn.server.resourcemanager.ResourceManager$ApplicationAttemptEventDispatcher
2016-03-19 19:16:09,687 INFO org.apache.hadoop.yarn.event.AsyncDispatcher: Registering class org.apache.hadoop.yarn.server.resourcemanager.rmnode.RMNodeEventType for class org.apache.hadoop.yarn.server.resourcemanager.ResourceManager$NodeEventDispatcher
2016-03-19 19:16:10,037 INFO org.apache.hadoop.metrics2.impl.MetricsConfig: loaded properties from hadoop-metrics2.properties
2016-03-19 19:16:10,518 INFO org.apache.hadoop.metrics2.impl.MetricsSystemImpl: Scheduled snapshot period at 10 second(s).
2016-03-19 19:16:10,519 INFO org.apache.hadoop.metrics2.impl.MetricsSystemImpl: ResourceManager metrics system started
2016-03-19 19:16:10,624 INFO org.apache.hadoop.yarn.event.AsyncDispatcher: Registering class org.apache.hadoop.yarn.server.resourcemanager.RMAppManagerEventType for class org.apache.hadoop.yarn.server.resourcemanager.RMAppManager
2016-03-19 19:16:10,650 INFO org.apache.hadoop.yarn.event.AsyncDispatcher: Registering class org.apache.hadoop.yarn.server.resourcemanager.amlauncher.AMLauncherEventType for class org.apache.hadoop.yarn.server.resourcemanager.amlauncher.ApplicationMasterLauncher
2016-03-19 19:16:10,652 INFO org.apache.hadoop.yarn.server.resourcemanager.RMNMInfo: Registered RMNMInfo MBean
2016-03-19 19:16:10,664 INFO org.apache.hadoop.yarn.security.YarnAuthorizationProvider: org.apache.hadoop.yarn.security.ConfiguredYarnAuthorizer is instiantiated.
2016-03-19 19:16:10,665 INFO org.apache.hadoop.util.HostsFileReader: Refreshing hosts (include/exclude) list
2016-03-19 19:16:10,714 INFO org.apache.hadoop.conf.Configuration: found resource capacity-scheduler.xml at file:/usr/local/hadoop/etc/hadoop/capacity-scheduler.xml
2016-03-19 19:16:11,230 INFO org.apache.hadoop.yarn.server.resourcemanager.scheduler.capacity.CapacitySchedulerConfiguration: max alloc mb per queue for root is undefined
2016-03-19 19:16:11,230 INFO org.apache.hadoop.yarn.server.resourcemanager.scheduler.capacity.CapacitySchedulerConfiguration: max alloc vcore per queue for root is undefined
2016-03-19 19:16:11,251 INFO org.apache.hadoop.yarn.server.resourcemanager.scheduler.capacity.ParentQueue: root, capacity=1.0, asboluteCapacity=1.0, maxCapacity=1.0, asboluteMaxCapacity=1.0, state=RUNNING, acls=SUBMIT_APP:*ADMINISTER_QUEUE:*, labels=*,
, reservationsContinueLooking=true
2016-03-19 19:16:11,251 INFO org.apache.hadoop.yarn.server.resourcemanager.scheduler.capacity.ParentQueue: Initialized parent-queue root name=root, fullname=root
2016-03-19 19:16:11,314 INFO org.apache.hadoop.yarn.server.resourcemanager.scheduler.capacity.CapacitySchedulerConfiguration: max alloc mb per queue for root.default is undefined
2016-03-19 19:16:11,314 INFO org.apache.hadoop.yarn.server.resourcemanager.scheduler.capacity.CapacitySchedulerConfiguration: max alloc vcore per queue for root.default is undefined
2016-03-19 19:16:11,315 INFO org.apache.hadoop.yarn.server.resourcemanager.scheduler.capacity.LeafQueue: Initializing default
capacity = 1.0 [= (float) configuredCapacity / 100 ]
asboluteCapacity = 1.0 [= parentAbsoluteCapacity * capacity ]
maxCapacity = 1.0 [= configuredMaxCapacity ]
absoluteMaxCapacity = 1.0 [= 1.0 maximumCapacity undefined, (parentAbsoluteMaxCapacity * maximumCapacity) / 100 otherwise ]
userLimit = 100 [= configuredUserLimit ]
userLimitFactor = 1.0 [= configuredUserLimitFactor ]
maxApplications = 10000 [= configuredMaximumSystemApplicationsPerQueue or (int)(configuredMaximumSystemApplications * absoluteCapacity)]
maxApplicationsPerUser = 10000 [= (int)(maxApplications * (userLimit / 100.0f) * userLimitFactor) ]
usedCapacity = 0.0 [= usedResourcesMemory / (clusterResourceMemory * absoluteCapacity)]
absoluteUsedCapacity = 0.0 [= usedResourcesMemory / clusterResourceMemory]
maxAMResourcePerQueuePercent = 0.1 [= configuredMaximumAMResourcePercent ]
minimumAllocationFactor = 0.875 [= (float)(maximumAllocationMemory - minimumAllocationMemory) / maximumAllocationMemory ]
maximumAllocation = <memory:8192, vCores:32> [= configuredMaxAllocation ]
numContainers = 0 [= currentNumContainers ]
state = RUNNING [= configuredState ]
acls = SUBMIT_APP:*ADMINISTER_QUEUE:* [= configuredAcls ]
nodeLocalityDelay = 40
labels=*,
nodeLocalityDelay = 40
reservationsContinueLooking = true
preemptionDisabled = true

2016-03-19 19:16:11,316 INFO org.apache.hadoop.yarn.server.resourcemanager.scheduler.capacity.CapacityScheduler: Initialized queue: default: capacity=1.0, absoluteCapacity=1.0, usedResources=<memory:0, vCores:0>, usedCapacity=0.0, absoluteUsedCapacity=0.0, numApps=0, numContainers=0
2016-03-19 19:16:11,316 INFO org.apache.hadoop.yarn.server.resourcemanager.scheduler.capacity.CapacityScheduler: Initialized queue: root: numChildQueue= 1, capacity=1.0, absoluteCapacity=1.0, usedResources=<memory:0, vCores:0>usedCapacity=0.0, numApps=0, numContainers=0
2016-03-19 19:16:11,317 INFO org.apache.hadoop.yarn.server.resourcemanager.scheduler.capacity.CapacityScheduler: Initialized root queue root: numChildQueue= 1, capacity=1.0, absoluteCapacity=1.0, usedResources=<memory:0, vCores:0>usedCapacity=0.0, numApps=0, numContainers=0
2016-03-19 19:16:11,317 INFO org.apache.hadoop.yarn.server.resourcemanager.scheduler.capacity.CapacityScheduler: Initialized queue mappings, override: false
2016-03-19 19:16:11,322 INFO org.apache.hadoop.yarn.server.resourcemanager.scheduler.capacity.CapacityScheduler: Initialized CapacityScheduler with calculator=class org.apache.hadoop.yarn.util.resource.DefaultResourceCalculator, minimumAllocation=<<memory:1024, vCores:1>>, maximumAllocation=<<memory:8192, vCores:32>>, asynchronousScheduling=false, asyncScheduleInterval=5ms
2016-03-19 19:16:11,403 INFO org.apache.hadoop.yarn.server.resourcemanager.metrics.SystemMetricsPublisher: YARN system metrics publishing service is not enabled
2016-03-19 19:16:11,403 INFO org.apache.hadoop.yarn.server.resourcemanager.ResourceManager: Transitioning to active state
2016-03-19 19:16:11,530 INFO org.apache.hadoop.yarn.server.resourcemanager.recovery.RMStateStore: Updating AMRMToken
2016-03-19 19:16:11,530 INFO org.apache.hadoop.yarn.server.resourcemanager.security.RMContainerTokenSecretManager: Rolling master-key for container-tokens
2016-03-19 19:16:11,531 INFO org.apache.hadoop.yarn.server.resourcemanager.security.NMTokenSecretManagerInRM: Rolling master-key for nm-tokens
2016-03-19 19:16:11,531 INFO org.apache.hadoop.security.token.delegation.AbstractDelegationTokenSecretManager: Updating the current master key for generating delegation tokens
2016-03-19 19:16:11,534 INFO org.apache.hadoop.yarn.server.resourcemanager.security.RMDelegationTokenSecretManager: storing master key with keyID 1
2016-03-19 19:16:11,535 INFO org.apache.hadoop.yarn.server.resourcemanager.recovery.RMStateStore: Storing RMDTMasterKey.
2016-03-19 19:16:11,552 INFO org.apache.hadoop.security.token.delegation.AbstractDelegationTokenSecretManager: Starting expired delegation token remover thread, tokenRemoverScanInterval=60 min(s)
2016-03-19 19:16:11,575 INFO org.apache.hadoop.security.token.delegation.AbstractDelegationTokenSecretManager: Updating the current master key for generating delegation tokens
2016-03-19 19:16:11,575 INFO org.apache.hadoop.yarn.server.resourcemanager.security.RMDelegationTokenSecretManager: storing master key with keyID 2
2016-03-19 19:16:11,575 INFO org.apache.hadoop.yarn.server.resourcemanager.recovery.RMStateStore: Storing RMDTMasterKey.
2016-03-19 19:16:11,563 INFO org.apache.hadoop.yarn.event.AsyncDispatcher: Registering class org.apache.hadoop.yarn.nodelabels.event.NodeLabelsStoreEventType for class org.apache.hadoop.yarn.nodelabels.CommonNodeLabelsManager$ForwardingEventHandler
2016-03-19 19:16:11,776 INFO org.apache.hadoop.ipc.CallQueueManager: Using callQueue class java.util.concurrent.LinkedBlockingQueue
2016-03-19 19:16:11,872 INFO org.apache.hadoop.ipc.Server: Starting Socket Reader #1 for port 8031
2016-03-19 19:16:11,984 INFO org.apache.hadoop.yarn.factories.impl.pb.RpcServerFactoryPBImpl: Adding protocol org.apache.hadoop.yarn.server.api.ResourceTrackerPB to the server
2016-03-19 19:16:11,990 INFO org.apache.hadoop.ipc.Server: IPC Server Responder: starting
2016-03-19 19:16:12,028 INFO org.apache.hadoop.ipc.Server: IPC Server listener on 8031: starting
2016-03-19 19:16:12,198 INFO org.apache.hadoop.ipc.CallQueueManager: Using callQueue class java.util.concurrent.LinkedBlockingQueue
2016-03-19 19:16:12,218 INFO org.apache.hadoop.ipc.Server: Starting Socket Reader #1 for port 8030
2016-03-19 19:16:12,263 INFO org.apache.hadoop.yarn.factories.impl.pb.RpcServerFactoryPBImpl: Adding protocol org.apache.hadoop.yarn.api.ApplicationMasterProtocolPB to the server
2016-03-19 19:16:12,263 INFO org.apache.hadoop.ipc.Server: IPC Server Responder: starting
2016-03-19 19:16:12,357 INFO org.apache.hadoop.ipc.Server: IPC Server listener on 8030: starting
2016-03-19 19:16:12,714 INFO org.apache.hadoop.ipc.CallQueueManager: Using callQueue class java.util.concurrent.LinkedBlockingQueue
2016-03-19 19:16:12,721 INFO org.apache.hadoop.ipc.Server: Starting Socket Reader #1 for port 8032
2016-03-19 19:16:12,724 INFO org.apache.hadoop.yarn.factories.impl.pb.RpcServerFactoryPBImpl: Adding protocol org.apache.hadoop.yarn.api.ApplicationClientProtocolPB to the server
2016-03-19 19:16:12,745 INFO org.apache.hadoop.ipc.Server: IPC Server listener on 8032: starting
2016-03-19 19:16:12,859 INFO org.apache.hadoop.yarn.server.resourcemanager.ResourceManager: Transitioned to active state
2016-03-19 19:16:12,869 INFO org.apache.hadoop.ipc.Server: IPC Server Responder: starting
2016-03-19 19:16:13,545 INFO org.mortbay.log: Logging to org.slf4j.impl.Log4jLoggerAdapter(org.mortbay.log) via org.mortbay.log.Slf4jLog
2016-03-19 19:16:13,613 INFO org.apache.hadoop.security.authentication.server.AuthenticationFilter: Unable to initialize FileSignerSecretProvider, falling back to use random secrets.
2016-03-19 19:16:13,641 INFO org.apache.hadoop.http.HttpRequestLog: Http request log for http.requests.resourcemanager is not defined
2016-03-19 19:16:13,702 INFO org.apache.hadoop.http.HttpServer2: Added global filter 'safety' (class=org.apache.hadoop.http.HttpServer2$QuotingInputFilter)
2016-03-19 19:16:13,720 INFO org.apache.hadoop.http.HttpServer2: Added filter RMAuthenticationFilter (class=org.apache.hadoop.yarn.server.security.http.RMAuthenticationFilter) to context cluster
2016-03-19 19:16:13,735 INFO org.apache.hadoop.http.HttpServer2: Added filter RMAuthenticationFilter (class=org.apache.hadoop.yarn.server.security.http.RMAuthenticationFilter) to context logs
2016-03-19 19:16:13,735 INFO org.apache.hadoop.http.HttpServer2: Added filter RMAuthenticationFilter (class=org.apache.hadoop.yarn.server.security.http.RMAuthenticationFilter) to context static
2016-03-19 19:16:13,740 INFO org.apache.hadoop.http.HttpServer2: Added filter static_user_filter (class=org.apache.hadoop.http.lib.StaticUserWebFilter$StaticUserFilter) to context cluster
2016-03-19 19:16:13,745 INFO org.apache.hadoop.http.HttpServer2: Added filter static_user_filter (class=org.apache.hadoop.http.lib.StaticUserWebFilter$StaticUserFilter) to context logs
2016-03-19 19:16:13,750 INFO org.apache.hadoop.http.HttpServer2: Added filter static_user_filter (class=org.apache.hadoop.http.lib.StaticUserWebFilter$StaticUserFilter) to context static
2016-03-19 19:16:13,768 INFO org.apache.hadoop.http.HttpServer2: adding path spec: /cluster/*
2016-03-19 19:16:13,768 INFO org.apache.hadoop.http.HttpServer2: adding path spec: /ws/*
2016-03-19 19:16:16,999 INFO org.apache.hadoop.yarn.webapp.WebApps: Registered webapp guice modules
2016-03-19 19:16:17,015 INFO org.apache.hadoop.http.HttpServer2: Jetty bound to port 8088
2016-03-19 19:16:17,015 INFO org.mortbay.log: jetty-6.1.26
2016-03-19 19:16:17,276 INFO org.mortbay.log: Extract jar:file:/usr/local/hadoop/share/hadoop/yarn/hadoop-yarn-common-2.7.2.jar!/webapps/cluster to /tmp/Jetty_0_0_0_0_8088_cluster____u0rgz3/webapp
2016-03-19 19:16:18,830 INFO org.apache.hadoop.security.token.delegation.AbstractDelegationTokenSecretManager: Updating the current master key for generating delegation tokens
2016-03-19 19:16:18,845 INFO org.apache.hadoop.security.token.delegation.AbstractDelegationTokenSecretManager: Starting expired delegation token remover thread, tokenRemoverScanInterval=60 min(s)
2016-03-19 19:16:18,845 INFO org.apache.hadoop.security.token.delegation.AbstractDelegationTokenSecretManager: Updating the current master key for generating delegation tokens
2016-03-19 19:16:27,578 INFO org.mortbay.log: Started HttpServer2$SelectChannelConnectorWithSafeStartup@0.0.0.0:8088
2016-03-19 19:16:27,578 INFO org.apache.hadoop.yarn.webapp.WebApps: Web app cluster started at 8088
2016-03-19 19:16:27,771 INFO org.apache.hadoop.ipc.CallQueueManager: Using callQueue class java.util.concurrent.LinkedBlockingQueue
2016-03-19 19:16:27,771 INFO org.apache.hadoop.ipc.Server: Starting Socket Reader #1 for port 8033
2016-03-19 19:16:27,794 INFO org.apache.hadoop.yarn.factories.impl.pb.RpcServerFactoryPBImpl: Adding protocol org.apache.hadoop.yarn.server.api.ResourceManagerAdministrationProtocolPB to the server
2016-03-19 19:16:27,805 INFO org.apache.hadoop.ipc.Server: IPC Server Responder: starting
2016-03-19 19:16:27,815 INFO org.apache.hadoop.ipc.Server: IPC Server listener on 8033: starting
2016-03-19 19:16:29,788 INFO org.apache.hadoop.yarn.util.RackResolver: Resolved vishal-VirtualBox to /default-rack
2016-03-19 19:16:29,798 INFO org.apache.hadoop.yarn.server.resourcemanager.rmnode.RMNodeImpl: vishal-VirtualBox:42309 Node Transitioned from NEW to RUNNING
2016-03-19 19:16:29,803 INFO org.apache.hadoop.yarn.server.resourcemanager.ResourceTrackerService: NodeManager from node vishal-VirtualBox(cmPort: 42309 httpPort: 8042) registered with capability: <memory:8192, vCores:8>, assigned nodeId vishal-VirtualBox:42309
2016-03-19 19:16:29,808 INFO org.apache.hadoop.yarn.server.resourcemanager.scheduler.capacity.CapacityScheduler: Added node vishal-VirtualBox:42309 clusterResource: <memory:8192, vCores:8>
2016-03-19 19:17:31,651 ERROR org.apache.hadoop.yarn.server.resourcemanager.ResourceManager: RECEIVED SIGNAL 15: SIGTERM
2016-03-19 19:17:31,749 ERROR org.apache.hadoop.security.token.delegation.AbstractDelegationTokenSecretManager: ExpiredTokenRemover received java.lang.InterruptedException: sleep interrupted
2016-03-19 19:17:31,762 INFO org.mortbay.log: Stopped HttpServer2$SelectChannelConnectorWithSafeStartup@0.0.0.0:8088
2016-03-19 19:17:31,769 INFO org.apache.hadoop.ipc.Server: Stopping server on 8032
2016-03-19 19:17:31,782 INFO org.apache.hadoop.ipc.Server: Stopping IPC Server Responder
2016-03-19 19:17:31,783 INFO org.apache.hadoop.ipc.Server: Stopping IPC Server listener on 8032
2016-03-19 19:17:31,785 INFO org.apache.hadoop.ipc.Server: Stopping server on 8033
2016-03-19 19:17:31,788 INFO org.apache.hadoop.ipc.Server: Stopping IPC Server listener on 8033
2016-03-19 19:17:31,788 INFO org.apache.hadoop.ipc.Server: Stopping IPC Server Responder
2016-03-19 19:17:31,793 INFO org.apache.hadoop.yarn.server.resourcemanager.ResourceManager: Transitioning to standby state
2016-03-19 19:17:31,793 WARN org.apache.hadoop.yarn.server.resourcemanager.amlauncher.ApplicationMasterLauncher: org.apache.hadoop.yarn.server.resourcemanager.amlauncher.ApplicationMasterLauncher$LauncherThread interrupted. Returning.
2016-03-19 19:17:31,794 INFO org.apache.hadoop.ipc.Server: Stopping server on 8030
2016-03-19 19:17:31,805 INFO org.apache.hadoop.ipc.Server: Stopping server on 8031
2016-03-19 19:17:31,805 INFO org.apache.hadoop.ipc.Server: Stopping IPC Server Responder
2016-03-19 19:17:31,811 INFO org.apache.hadoop.ipc.Server: Stopping IPC Server listener on 8030
2016-03-19 19:17:31,811 INFO org.apache.hadoop.ipc.Server: Stopping IPC Server listener on 8031
2016-03-19 19:17:31,811 INFO org.apache.hadoop.ipc.Server: Stopping IPC Server Responder
2016-03-19 19:17:31,812 INFO org.apache.hadoop.yarn.util.AbstractLivelinessMonitor: NMLivelinessMonitor thread interrupted
2016-03-19 19:17:31,812 ERROR org.apache.hadoop.yarn.server.resourcemanager.ResourceManager: Returning, interrupted : java.lang.InterruptedException
2016-03-19 19:17:31,813 INFO org.apache.hadoop.yarn.event.AsyncDispatcher: AsyncDispatcher is draining to stop, igonring any new events.
2016-03-19 19:17:31,814 ERROR org.apache.hadoop.security.token.delegation.AbstractDelegationTokenSecretManager: ExpiredTokenRemover received java.lang.InterruptedException: sleep interrupted
2016-03-19 19:17:31,814 INFO org.apache.hadoop.metrics2.impl.MetricsSystemImpl: Stopping ResourceManager metrics system...
2016-03-19 19:17:31,814 INFO org.apache.hadoop.yarn.util.AbstractLivelinessMonitor: AMLivelinessMonitor thread interrupted
2016-03-19 19:17:31,814 INFO org.apache.hadoop.yarn.util.AbstractLivelinessMonitor: AMLivelinessMonitor thread interrupted
2016-03-19 19:17:31,814 INFO org.apache.hadoop.yarn.util.AbstractLivelinessMonitor: org.apache.hadoop.yarn.server.resourcemanager.rmcontainer.ContainerAllocationExpirer thread interrupted
2016-03-19 19:17:31,817 INFO org.apache.hadoop.metrics2.impl.MetricsSystemImpl: ResourceManager metrics system stopped.
2016-03-19 19:17:31,817 INFO org.apache.hadoop.metrics2.impl.MetricsSystemImpl: ResourceManager metrics system shutdown complete.
2016-03-19 19:17:31,817 INFO org.apache.hadoop.yarn.event.AsyncDispatcher: AsyncDispatcher is draining to stop, igonring any new events.
2016-03-19 19:17:31,819 INFO org.apache.hadoop.yarn.server.resourcemanager.ResourceManager: Transitioned to standby state
2016-03-19 19:17:31,819 INFO org.apache.hadoop.yarn.server.resourcemanager.ResourceManager: SHUTDOWN_MSG: 
/************************************************************
SHUTDOWN_MSG: Shutting down ResourceManager at vishal-VirtualBox/127.0.1.1
************************************************************/
2016-03-19 19:20:49,228 INFO org.apache.hadoop.yarn.server.resourcemanager.ResourceManager: STARTUP_MSG: 
/************************************************************
STARTUP_MSG: Starting ResourceManager
STARTUP_MSG:   host = vishal-VirtualBox/127.0.1.1
STARTUP_MSG:   args = []
STARTUP_MSG:   version = 2.7.2
STARTUP_MSG:   build = https://git-wip-us.apache.org/repos/asf/hadoop.git -r b165c4fe8a74265c792ce23f546c64604acf0e41; compiled by 'jenkins' on 2016-01-26T00:08Z
STARTUP_MSG:   java = 1.8.0_74
************************************************************/
2016-03-19 19:20:49,286 INFO org.apache.hadoop.yarn.server.resourcemanager.ResourceManager: registered UNIX signal handlers for [TERM, HUP, INT]
2016-03-19 19:20:51,314 INFO org.apache.hadoop.conf.Configuration: found resource core-site.xml at file:/usr/local/hadoop/etc/hadoop/core-site.xml
2016-03-19 19:20:51,650 WARN org.apache.hadoop.util.NativeCodeLoader: Unable to load native-hadoop library for your platform... using builtin-java classes where applicable
2016-03-19 19:20:51,796 INFO org.apache.hadoop.security.Groups: clearing userToGroupsMap cache
2016-03-19 19:20:52,438 INFO org.apache.hadoop.conf.Configuration: found resource yarn-site.xml at file:/usr/local/hadoop/etc/hadoop/yarn-site.xml
2016-03-19 19:20:53,513 INFO org.apache.hadoop.yarn.event.AsyncDispatcher: Registering class org.apache.hadoop.yarn.server.resourcemanager.RMFatalEventType for class org.apache.hadoop.yarn.server.resourcemanager.ResourceManager$RMFatalEventDispatcher
2016-03-19 19:20:54,467 INFO org.apache.hadoop.yarn.server.resourcemanager.security.NMTokenSecretManagerInRM: NMTokenKeyRollingInterval: 86400000ms and NMTokenKeyActivationDelay: 900000ms
2016-03-19 19:20:54,486 INFO org.apache.hadoop.yarn.server.resourcemanager.security.RMContainerTokenSecretManager: ContainerTokenKeyRollingInterval: 86400000ms and ContainerTokenKeyActivationDelay: 900000ms
2016-03-19 19:20:54,517 INFO org.apache.hadoop.yarn.server.resourcemanager.security.AMRMTokenSecretManager: AMRMTokenKeyRollingInterval: 86400000ms and AMRMTokenKeyActivationDelay: 900000 ms
2016-03-19 19:20:54,714 INFO org.apache.hadoop.yarn.event.AsyncDispatcher: Registering class org.apache.hadoop.yarn.server.resourcemanager.recovery.RMStateStoreEventType for class org.apache.hadoop.yarn.server.resourcemanager.recovery.RMStateStore$ForwardingEventHandler
2016-03-19 19:20:54,716 INFO org.apache.hadoop.yarn.event.AsyncDispatcher: Registering class org.apache.hadoop.yarn.server.resourcemanager.NodesListManagerEventType for class org.apache.hadoop.yarn.server.resourcemanager.NodesListManager
2016-03-19 19:20:54,716 INFO org.apache.hadoop.yarn.server.resourcemanager.ResourceManager: Using Scheduler: org.apache.hadoop.yarn.server.resourcemanager.scheduler.capacity.CapacityScheduler
2016-03-19 19:20:54,833 INFO org.apache.hadoop.yarn.event.AsyncDispatcher: Registering class org.apache.hadoop.yarn.server.resourcemanager.scheduler.event.SchedulerEventType for class org.apache.hadoop.yarn.server.resourcemanager.ResourceManager$SchedulerEventDispatcher
2016-03-19 19:20:54,834 INFO org.apache.hadoop.yarn.event.AsyncDispatcher: Registering class org.apache.hadoop.yarn.server.resourcemanager.rmapp.RMAppEventType for class org.apache.hadoop.yarn.server.resourcemanager.ResourceManager$ApplicationEventDispatcher
2016-03-19 19:20:54,834 INFO org.apache.hadoop.yarn.event.AsyncDispatcher: Registering class org.apache.hadoop.yarn.server.resourcemanager.rmapp.attempt.RMAppAttemptEventType for class org.apache.hadoop.yarn.server.resourcemanager.ResourceManager$ApplicationAttemptEventDispatcher
2016-03-19 19:20:54,839 INFO org.apache.hadoop.yarn.event.AsyncDispatcher: Registering class org.apache.hadoop.yarn.server.resourcemanager.rmnode.RMNodeEventType for class org.apache.hadoop.yarn.server.resourcemanager.ResourceManager$NodeEventDispatcher
2016-03-19 19:20:55,193 INFO org.apache.hadoop.metrics2.impl.MetricsConfig: loaded properties from hadoop-metrics2.properties
2016-03-19 19:20:55,498 INFO org.apache.hadoop.metrics2.impl.MetricsSystemImpl: Scheduled snapshot period at 10 second(s).
2016-03-19 19:20:55,499 INFO org.apache.hadoop.metrics2.impl.MetricsSystemImpl: ResourceManager metrics system started
2016-03-19 19:20:55,593 INFO org.apache.hadoop.yarn.event.AsyncDispatcher: Registering class org.apache.hadoop.yarn.server.resourcemanager.RMAppManagerEventType for class org.apache.hadoop.yarn.server.resourcemanager.RMAppManager
2016-03-19 19:20:55,614 INFO org.apache.hadoop.yarn.event.AsyncDispatcher: Registering class org.apache.hadoop.yarn.server.resourcemanager.amlauncher.AMLauncherEventType for class org.apache.hadoop.yarn.server.resourcemanager.amlauncher.ApplicationMasterLauncher
2016-03-19 19:20:55,616 INFO org.apache.hadoop.yarn.server.resourcemanager.RMNMInfo: Registered RMNMInfo MBean
2016-03-19 19:20:55,622 INFO org.apache.hadoop.yarn.security.YarnAuthorizationProvider: org.apache.hadoop.yarn.security.ConfiguredYarnAuthorizer is instiantiated.
2016-03-19 19:20:55,623 INFO org.apache.hadoop.util.HostsFileReader: Refreshing hosts (include/exclude) list
2016-03-19 19:20:55,658 INFO org.apache.hadoop.conf.Configuration: found resource capacity-scheduler.xml at file:/usr/local/hadoop/etc/hadoop/capacity-scheduler.xml
2016-03-19 19:20:56,012 INFO org.apache.hadoop.yarn.server.resourcemanager.scheduler.capacity.CapacitySchedulerConfiguration: max alloc mb per queue for root is undefined
2016-03-19 19:20:56,012 INFO org.apache.hadoop.yarn.server.resourcemanager.scheduler.capacity.CapacitySchedulerConfiguration: max alloc vcore per queue for root is undefined
2016-03-19 19:20:56,028 INFO org.apache.hadoop.yarn.server.resourcemanager.scheduler.capacity.ParentQueue: root, capacity=1.0, asboluteCapacity=1.0, maxCapacity=1.0, asboluteMaxCapacity=1.0, state=RUNNING, acls=SUBMIT_APP:*ADMINISTER_QUEUE:*, labels=*,
, reservationsContinueLooking=true
2016-03-19 19:20:56,028 INFO org.apache.hadoop.yarn.server.resourcemanager.scheduler.capacity.ParentQueue: Initialized parent-queue root name=root, fullname=root
2016-03-19 19:20:56,063 INFO org.apache.hadoop.yarn.server.resourcemanager.scheduler.capacity.CapacitySchedulerConfiguration: max alloc mb per queue for root.default is undefined
2016-03-19 19:20:56,063 INFO org.apache.hadoop.yarn.server.resourcemanager.scheduler.capacity.CapacitySchedulerConfiguration: max alloc vcore per queue for root.default is undefined
2016-03-19 19:20:56,064 INFO org.apache.hadoop.yarn.server.resourcemanager.scheduler.capacity.LeafQueue: Initializing default
capacity = 1.0 [= (float) configuredCapacity / 100 ]
asboluteCapacity = 1.0 [= parentAbsoluteCapacity * capacity ]
maxCapacity = 1.0 [= configuredMaxCapacity ]
absoluteMaxCapacity = 1.0 [= 1.0 maximumCapacity undefined, (parentAbsoluteMaxCapacity * maximumCapacity) / 100 otherwise ]
userLimit = 100 [= configuredUserLimit ]
userLimitFactor = 1.0 [= configuredUserLimitFactor ]
maxApplications = 10000 [= configuredMaximumSystemApplicationsPerQueue or (int)(configuredMaximumSystemApplications * absoluteCapacity)]
maxApplicationsPerUser = 10000 [= (int)(maxApplications * (userLimit / 100.0f) * userLimitFactor) ]
usedCapacity = 0.0 [= usedResourcesMemory / (clusterResourceMemory * absoluteCapacity)]
absoluteUsedCapacity = 0.0 [= usedResourcesMemory / clusterResourceMemory]
maxAMResourcePerQueuePercent = 0.1 [= configuredMaximumAMResourcePercent ]
minimumAllocationFactor = 0.875 [= (float)(maximumAllocationMemory - minimumAllocationMemory) / maximumAllocationMemory ]
maximumAllocation = <memory:8192, vCores:32> [= configuredMaxAllocation ]
numContainers = 0 [= currentNumContainers ]
state = RUNNING [= configuredState ]
acls = SUBMIT_APP:*ADMINISTER_QUEUE:* [= configuredAcls ]
nodeLocalityDelay = 40
labels=*,
nodeLocalityDelay = 40
reservationsContinueLooking = true
preemptionDisabled = true

2016-03-19 19:20:56,069 INFO org.apache.hadoop.yarn.server.resourcemanager.scheduler.capacity.CapacityScheduler: Initialized queue: default: capacity=1.0, absoluteCapacity=1.0, usedResources=<memory:0, vCores:0>, usedCapacity=0.0, absoluteUsedCapacity=0.0, numApps=0, numContainers=0
2016-03-19 19:20:56,069 INFO org.apache.hadoop.yarn.server.resourcemanager.scheduler.capacity.CapacityScheduler: Initialized queue: root: numChildQueue= 1, capacity=1.0, absoluteCapacity=1.0, usedResources=<memory:0, vCores:0>usedCapacity=0.0, numApps=0, numContainers=0
2016-03-19 19:20:56,070 INFO org.apache.hadoop.yarn.server.resourcemanager.scheduler.capacity.CapacityScheduler: Initialized root queue root: numChildQueue= 1, capacity=1.0, absoluteCapacity=1.0, usedResources=<memory:0, vCores:0>usedCapacity=0.0, numApps=0, numContainers=0
2016-03-19 19:20:56,070 INFO org.apache.hadoop.yarn.server.resourcemanager.scheduler.capacity.CapacityScheduler: Initialized queue mappings, override: false
2016-03-19 19:20:56,070 INFO org.apache.hadoop.yarn.server.resourcemanager.scheduler.capacity.CapacityScheduler: Initialized CapacityScheduler with calculator=class org.apache.hadoop.yarn.util.resource.DefaultResourceCalculator, minimumAllocation=<<memory:1024, vCores:1>>, maximumAllocation=<<memory:8192, vCores:32>>, asynchronousScheduling=false, asyncScheduleInterval=5ms
2016-03-19 19:20:56,127 INFO org.apache.hadoop.yarn.server.resourcemanager.metrics.SystemMetricsPublisher: YARN system metrics publishing service is not enabled
2016-03-19 19:20:56,127 INFO org.apache.hadoop.yarn.server.resourcemanager.ResourceManager: Transitioning to active state
2016-03-19 19:20:56,203 INFO org.apache.hadoop.yarn.server.resourcemanager.recovery.RMStateStore: Updating AMRMToken
2016-03-19 19:20:56,217 INFO org.apache.hadoop.yarn.server.resourcemanager.security.RMContainerTokenSecretManager: Rolling master-key for container-tokens
2016-03-19 19:20:56,225 INFO org.apache.hadoop.yarn.server.resourcemanager.security.NMTokenSecretManagerInRM: Rolling master-key for nm-tokens
2016-03-19 19:20:56,225 INFO org.apache.hadoop.security.token.delegation.AbstractDelegationTokenSecretManager: Updating the current master key for generating delegation tokens
2016-03-19 19:20:56,227 INFO org.apache.hadoop.yarn.server.resourcemanager.security.RMDelegationTokenSecretManager: storing master key with keyID 1
2016-03-19 19:20:56,227 INFO org.apache.hadoop.yarn.server.resourcemanager.recovery.RMStateStore: Storing RMDTMasterKey.
2016-03-19 19:20:56,262 INFO org.apache.hadoop.yarn.event.AsyncDispatcher: Registering class org.apache.hadoop.yarn.nodelabels.event.NodeLabelsStoreEventType for class org.apache.hadoop.yarn.nodelabels.CommonNodeLabelsManager$ForwardingEventHandler
2016-03-19 19:20:56,260 INFO org.apache.hadoop.security.token.delegation.AbstractDelegationTokenSecretManager: Starting expired delegation token remover thread, tokenRemoverScanInterval=60 min(s)
2016-03-19 19:20:56,280 INFO org.apache.hadoop.security.token.delegation.AbstractDelegationTokenSecretManager: Updating the current master key for generating delegation tokens
2016-03-19 19:20:56,280 INFO org.apache.hadoop.yarn.server.resourcemanager.security.RMDelegationTokenSecretManager: storing master key with keyID 2
2016-03-19 19:20:56,280 INFO org.apache.hadoop.yarn.server.resourcemanager.recovery.RMStateStore: Storing RMDTMasterKey.
2016-03-19 19:20:56,459 INFO org.apache.hadoop.ipc.CallQueueManager: Using callQueue class java.util.concurrent.LinkedBlockingQueue
2016-03-19 19:20:56,506 INFO org.apache.hadoop.ipc.Server: Starting Socket Reader #1 for port 8031
2016-03-19 19:20:56,571 INFO org.apache.hadoop.yarn.factories.impl.pb.RpcServerFactoryPBImpl: Adding protocol org.apache.hadoop.yarn.server.api.ResourceTrackerPB to the server
2016-03-19 19:20:56,577 INFO org.apache.hadoop.ipc.Server: IPC Server Responder: starting
2016-03-19 19:20:56,578 INFO org.apache.hadoop.ipc.Server: IPC Server listener on 8031: starting
2016-03-19 19:20:56,762 INFO org.apache.hadoop.ipc.CallQueueManager: Using callQueue class java.util.concurrent.LinkedBlockingQueue
2016-03-19 19:20:56,777 INFO org.apache.hadoop.ipc.Server: Starting Socket Reader #1 for port 8030
2016-03-19 19:20:56,803 INFO org.apache.hadoop.yarn.factories.impl.pb.RpcServerFactoryPBImpl: Adding protocol org.apache.hadoop.yarn.api.ApplicationMasterProtocolPB to the server
2016-03-19 19:20:56,803 INFO org.apache.hadoop.ipc.Server: IPC Server Responder: starting
2016-03-19 19:20:56,804 INFO org.apache.hadoop.ipc.Server: IPC Server listener on 8030: starting
2016-03-19 19:20:57,154 INFO org.apache.hadoop.ipc.CallQueueManager: Using callQueue class java.util.concurrent.LinkedBlockingQueue
2016-03-19 19:20:57,161 INFO org.apache.hadoop.ipc.Server: Starting Socket Reader #1 for port 8032
2016-03-19 19:20:57,163 INFO org.apache.hadoop.yarn.factories.impl.pb.RpcServerFactoryPBImpl: Adding protocol org.apache.hadoop.yarn.api.ApplicationClientProtocolPB to the server
2016-03-19 19:20:57,171 INFO org.apache.hadoop.ipc.Server: IPC Server Responder: starting
2016-03-19 19:20:57,173 INFO org.apache.hadoop.ipc.Server: IPC Server listener on 8032: starting
2016-03-19 19:20:57,253 INFO org.apache.hadoop.yarn.server.resourcemanager.ResourceManager: Transitioned to active state
2016-03-19 19:20:57,618 INFO org.mortbay.log: Logging to org.slf4j.impl.Log4jLoggerAdapter(org.mortbay.log) via org.mortbay.log.Slf4jLog
2016-03-19 19:20:57,637 INFO org.apache.hadoop.security.authentication.server.AuthenticationFilter: Unable to initialize FileSignerSecretProvider, falling back to use random secrets.
2016-03-19 19:20:57,652 INFO org.apache.hadoop.http.HttpRequestLog: Http request log for http.requests.resourcemanager is not defined
2016-03-19 19:20:57,682 INFO org.apache.hadoop.http.HttpServer2: Added global filter 'safety' (class=org.apache.hadoop.http.HttpServer2$QuotingInputFilter)
2016-03-19 19:20:57,696 INFO org.apache.hadoop.http.HttpServer2: Added filter RMAuthenticationFilter (class=org.apache.hadoop.yarn.server.security.http.RMAuthenticationFilter) to context cluster
2016-03-19 19:20:57,696 INFO org.apache.hadoop.http.HttpServer2: Added filter RMAuthenticationFilter (class=org.apache.hadoop.yarn.server.security.http.RMAuthenticationFilter) to context logs
2016-03-19 19:20:57,697 INFO org.apache.hadoop.http.HttpServer2: Added filter RMAuthenticationFilter (class=org.apache.hadoop.yarn.server.security.http.RMAuthenticationFilter) to context static
2016-03-19 19:20:57,700 INFO org.apache.hadoop.http.HttpServer2: Added filter static_user_filter (class=org.apache.hadoop.http.lib.StaticUserWebFilter$StaticUserFilter) to context cluster
2016-03-19 19:20:57,700 INFO org.apache.hadoop.http.HttpServer2: Added filter static_user_filter (class=org.apache.hadoop.http.lib.StaticUserWebFilter$StaticUserFilter) to context logs
2016-03-19 19:20:57,700 INFO org.apache.hadoop.http.HttpServer2: Added filter static_user_filter (class=org.apache.hadoop.http.lib.StaticUserWebFilter$StaticUserFilter) to context static
2016-03-19 19:20:57,707 INFO org.apache.hadoop.http.HttpServer2: adding path spec: /cluster/*
2016-03-19 19:20:57,707 INFO org.apache.hadoop.http.HttpServer2: adding path spec: /ws/*
2016-03-19 19:20:59,372 INFO org.apache.hadoop.yarn.webapp.WebApps: Registered webapp guice modules
2016-03-19 19:20:59,381 INFO org.apache.hadoop.http.HttpServer2: Jetty bound to port 8088
2016-03-19 19:20:59,381 INFO org.mortbay.log: jetty-6.1.26
2016-03-19 19:20:59,509 INFO org.mortbay.log: Extract jar:file:/usr/local/hadoop/share/hadoop/yarn/hadoop-yarn-common-2.7.2.jar!/webapps/cluster to /tmp/Jetty_0_0_0_0_8088_cluster____u0rgz3/webapp
2016-03-19 19:21:00,490 INFO org.apache.hadoop.security.token.delegation.AbstractDelegationTokenSecretManager: Updating the current master key for generating delegation tokens
2016-03-19 19:21:00,494 INFO org.apache.hadoop.security.token.delegation.AbstractDelegationTokenSecretManager: Starting expired delegation token remover thread, tokenRemoverScanInterval=60 min(s)
2016-03-19 19:21:00,495 INFO org.apache.hadoop.security.token.delegation.AbstractDelegationTokenSecretManager: Updating the current master key for generating delegation tokens
2016-03-19 19:21:05,564 INFO org.mortbay.log: Started HttpServer2$SelectChannelConnectorWithSafeStartup@0.0.0.0:8088
2016-03-19 19:21:05,565 INFO org.apache.hadoop.yarn.webapp.WebApps: Web app cluster started at 8088
2016-03-19 19:21:05,766 INFO org.apache.hadoop.ipc.CallQueueManager: Using callQueue class java.util.concurrent.LinkedBlockingQueue
2016-03-19 19:21:05,771 INFO org.apache.hadoop.ipc.Server: Starting Socket Reader #1 for port 8033
2016-03-19 19:21:05,779 INFO org.apache.hadoop.yarn.factories.impl.pb.RpcServerFactoryPBImpl: Adding protocol org.apache.hadoop.yarn.server.api.ResourceManagerAdministrationProtocolPB to the server
2016-03-19 19:21:05,793 INFO org.apache.hadoop.ipc.Server: IPC Server listener on 8033: starting
2016-03-19 19:21:05,815 INFO org.apache.hadoop.ipc.Server: IPC Server Responder: starting
2016-03-19 19:21:06,623 INFO org.apache.hadoop.yarn.util.RackResolver: Resolved vishal-VirtualBox to /default-rack
2016-03-19 19:21:06,639 INFO org.apache.hadoop.yarn.server.resourcemanager.rmnode.RMNodeImpl: vishal-VirtualBox:37633 Node Transitioned from NEW to RUNNING
2016-03-19 19:21:06,643 INFO org.apache.hadoop.yarn.server.resourcemanager.ResourceTrackerService: NodeManager from node vishal-VirtualBox(cmPort: 37633 httpPort: 8042) registered with capability: <memory:8192, vCores:8>, assigned nodeId vishal-VirtualBox:37633
2016-03-19 19:21:06,648 INFO org.apache.hadoop.yarn.server.resourcemanager.scheduler.capacity.CapacityScheduler: Added node vishal-VirtualBox:37633 clusterResource: <memory:8192, vCores:8>
2016-03-19 19:26:07,595 ERROR org.apache.hadoop.yarn.server.resourcemanager.ResourceManager: RECEIVED SIGNAL 15: SIGTERM
2016-03-19 19:26:07,665 ERROR org.apache.hadoop.security.token.delegation.AbstractDelegationTokenSecretManager: ExpiredTokenRemover received java.lang.InterruptedException: sleep interrupted
2016-03-19 19:26:07,692 INFO org.mortbay.log: Stopped HttpServer2$SelectChannelConnectorWithSafeStartup@0.0.0.0:8088
2016-03-19 19:26:07,700 INFO org.apache.hadoop.ipc.Server: Stopping server on 8032
2016-03-19 19:26:07,726 INFO org.apache.hadoop.ipc.Server: Stopping IPC Server Responder
2016-03-19 19:26:07,727 INFO org.apache.hadoop.ipc.Server: Stopping IPC Server listener on 8032
2016-03-19 19:26:07,728 INFO org.apache.hadoop.ipc.Server: Stopping server on 8033
2016-03-19 19:26:07,730 INFO org.apache.hadoop.ipc.Server: Stopping IPC Server listener on 8033
2016-03-19 19:26:07,730 INFO org.apache.hadoop.ipc.Server: Stopping IPC Server Responder
2016-03-19 19:26:07,732 INFO org.apache.hadoop.yarn.server.resourcemanager.ResourceManager: Transitioning to standby state
2016-03-19 19:26:07,733 WARN org.apache.hadoop.yarn.server.resourcemanager.amlauncher.ApplicationMasterLauncher: org.apache.hadoop.yarn.server.resourcemanager.amlauncher.ApplicationMasterLauncher$LauncherThread interrupted. Returning.
2016-03-19 19:26:07,733 INFO org.apache.hadoop.ipc.Server: Stopping server on 8030
2016-03-19 19:26:07,745 INFO org.apache.hadoop.ipc.Server: Stopping server on 8031
2016-03-19 19:26:07,746 INFO org.apache.hadoop.ipc.Server: Stopping IPC Server Responder
2016-03-19 19:26:07,758 INFO org.apache.hadoop.ipc.Server: Stopping IPC Server listener on 8030
2016-03-19 19:26:07,759 INFO org.apache.hadoop.ipc.Server: Stopping IPC Server listener on 8031
2016-03-19 19:26:07,759 INFO org.apache.hadoop.ipc.Server: Stopping IPC Server Responder
2016-03-19 19:26:07,759 INFO org.apache.hadoop.yarn.util.AbstractLivelinessMonitor: NMLivelinessMonitor thread interrupted
2016-03-19 19:26:07,760 ERROR org.apache.hadoop.yarn.server.resourcemanager.ResourceManager: Returning, interrupted : java.lang.InterruptedException
2016-03-19 19:26:07,761 INFO org.apache.hadoop.yarn.event.AsyncDispatcher: AsyncDispatcher is draining to stop, igonring any new events.
2016-03-19 19:26:07,763 ERROR org.apache.hadoop.security.token.delegation.AbstractDelegationTokenSecretManager: ExpiredTokenRemover received java.lang.InterruptedException: sleep interrupted
2016-03-19 19:26:07,764 INFO org.apache.hadoop.metrics2.impl.MetricsSystemImpl: Stopping ResourceManager metrics system...
2016-03-19 19:26:07,763 INFO org.apache.hadoop.yarn.util.AbstractLivelinessMonitor: AMLivelinessMonitor thread interrupted
2016-03-19 19:26:07,763 INFO org.apache.hadoop.yarn.util.AbstractLivelinessMonitor: AMLivelinessMonitor thread interrupted
2016-03-19 19:26:07,763 INFO org.apache.hadoop.yarn.util.AbstractLivelinessMonitor: org.apache.hadoop.yarn.server.resourcemanager.rmcontainer.ContainerAllocationExpirer thread interrupted
2016-03-19 19:26:07,770 INFO org.apache.hadoop.metrics2.impl.MetricsSystemImpl: ResourceManager metrics system stopped.
2016-03-19 19:26:07,770 INFO org.apache.hadoop.metrics2.impl.MetricsSystemImpl: ResourceManager metrics system shutdown complete.
2016-03-19 19:26:07,770 INFO org.apache.hadoop.yarn.event.AsyncDispatcher: AsyncDispatcher is draining to stop, igonring any new events.
2016-03-19 19:26:07,771 INFO org.apache.hadoop.yarn.server.resourcemanager.ResourceManager: Transitioned to standby state
2016-03-19 19:26:07,771 INFO org.apache.hadoop.yarn.server.resourcemanager.ResourceManager: SHUTDOWN_MSG: 
/************************************************************
SHUTDOWN_MSG: Shutting down ResourceManager at vishal-VirtualBox/127.0.1.1
************************************************************/
2016-03-19 19:30:42,188 INFO org.apache.hadoop.yarn.server.resourcemanager.ResourceManager: STARTUP_MSG: 
/************************************************************
STARTUP_MSG: Starting ResourceManager
STARTUP_MSG:   host = vishal-VirtualBox/127.0.1.1
STARTUP_MSG:   args = []
STARTUP_MSG:   version = 2.7.2
STARTUP_MSG:   build = https://git-wip-us.apache.org/repos/asf/hadoop.git -r b165c4fe8a74265c792ce23f546c64604acf0e41; compiled by 'jenkins' on 2016-01-26T00:08Z
STARTUP_MSG:   java = 1.8.0_74
************************************************************/
2016-03-19 19:30:42,274 INFO org.apache.hadoop.yarn.server.resourcemanager.ResourceManager: registered UNIX signal handlers for [TERM, HUP, INT]
2016-03-19 19:30:43,869 INFO org.apache.hadoop.conf.Configuration: found resource core-site.xml at file:/usr/local/hadoop/etc/hadoop/core-site.xml
2016-03-19 19:30:44,182 WARN org.apache.hadoop.util.NativeCodeLoader: Unable to load native-hadoop library for your platform... using builtin-java classes where applicable
2016-03-19 19:30:44,309 INFO org.apache.hadoop.security.Groups: clearing userToGroupsMap cache
2016-03-19 19:30:44,861 INFO org.apache.hadoop.conf.Configuration: found resource yarn-site.xml at file:/usr/local/hadoop/etc/hadoop/yarn-site.xml
2016-03-19 19:30:47,015 INFO org.apache.hadoop.yarn.event.AsyncDispatcher: Registering class org.apache.hadoop.yarn.server.resourcemanager.RMFatalEventType for class org.apache.hadoop.yarn.server.resourcemanager.ResourceManager$RMFatalEventDispatcher
2016-03-19 19:30:48,613 INFO org.apache.hadoop.yarn.server.resourcemanager.security.NMTokenSecretManagerInRM: NMTokenKeyRollingInterval: 86400000ms and NMTokenKeyActivationDelay: 900000ms
2016-03-19 19:30:48,654 INFO org.apache.hadoop.yarn.server.resourcemanager.security.RMContainerTokenSecretManager: ContainerTokenKeyRollingInterval: 86400000ms and ContainerTokenKeyActivationDelay: 900000ms
2016-03-19 19:30:48,695 INFO org.apache.hadoop.yarn.server.resourcemanager.security.AMRMTokenSecretManager: AMRMTokenKeyRollingInterval: 86400000ms and AMRMTokenKeyActivationDelay: 900000 ms
2016-03-19 19:30:48,984 INFO org.apache.hadoop.yarn.event.AsyncDispatcher: Registering class org.apache.hadoop.yarn.server.resourcemanager.recovery.RMStateStoreEventType for class org.apache.hadoop.yarn.server.resourcemanager.recovery.RMStateStore$ForwardingEventHandler
2016-03-19 19:30:49,001 INFO org.apache.hadoop.yarn.event.AsyncDispatcher: Registering class org.apache.hadoop.yarn.server.resourcemanager.NodesListManagerEventType for class org.apache.hadoop.yarn.server.resourcemanager.NodesListManager
2016-03-19 19:30:49,001 INFO org.apache.hadoop.yarn.server.resourcemanager.ResourceManager: Using Scheduler: org.apache.hadoop.yarn.server.resourcemanager.scheduler.capacity.CapacityScheduler
2016-03-19 19:30:49,185 INFO org.apache.hadoop.yarn.event.AsyncDispatcher: Registering class org.apache.hadoop.yarn.server.resourcemanager.scheduler.event.SchedulerEventType for class org.apache.hadoop.yarn.server.resourcemanager.ResourceManager$SchedulerEventDispatcher
2016-03-19 19:30:49,186 INFO org.apache.hadoop.yarn.event.AsyncDispatcher: Registering class org.apache.hadoop.yarn.server.resourcemanager.rmapp.RMAppEventType for class org.apache.hadoop.yarn.server.resourcemanager.ResourceManager$ApplicationEventDispatcher
2016-03-19 19:30:49,187 INFO org.apache.hadoop.yarn.event.AsyncDispatcher: Registering class org.apache.hadoop.yarn.server.resourcemanager.rmapp.attempt.RMAppAttemptEventType for class org.apache.hadoop.yarn.server.resourcemanager.ResourceManager$ApplicationAttemptEventDispatcher
2016-03-19 19:30:49,205 INFO org.apache.hadoop.yarn.event.AsyncDispatcher: Registering class org.apache.hadoop.yarn.server.resourcemanager.rmnode.RMNodeEventType for class org.apache.hadoop.yarn.server.resourcemanager.ResourceManager$NodeEventDispatcher
2016-03-19 19:30:49,649 INFO org.apache.hadoop.metrics2.impl.MetricsConfig: loaded properties from hadoop-metrics2.properties
2016-03-19 19:30:50,460 INFO org.apache.hadoop.metrics2.impl.MetricsSystemImpl: Scheduled snapshot period at 10 second(s).
2016-03-19 19:30:50,460 INFO org.apache.hadoop.metrics2.impl.MetricsSystemImpl: ResourceManager metrics system started
2016-03-19 19:30:50,598 INFO org.apache.hadoop.yarn.event.AsyncDispatcher: Registering class org.apache.hadoop.yarn.server.resourcemanager.RMAppManagerEventType for class org.apache.hadoop.yarn.server.resourcemanager.RMAppManager
2016-03-19 19:30:50,645 INFO org.apache.hadoop.yarn.event.AsyncDispatcher: Registering class org.apache.hadoop.yarn.server.resourcemanager.amlauncher.AMLauncherEventType for class org.apache.hadoop.yarn.server.resourcemanager.amlauncher.ApplicationMasterLauncher
2016-03-19 19:30:50,647 INFO org.apache.hadoop.yarn.server.resourcemanager.RMNMInfo: Registered RMNMInfo MBean
2016-03-19 19:30:50,660 INFO org.apache.hadoop.yarn.security.YarnAuthorizationProvider: org.apache.hadoop.yarn.security.ConfiguredYarnAuthorizer is instiantiated.
2016-03-19 19:30:50,661 INFO org.apache.hadoop.util.HostsFileReader: Refreshing hosts (include/exclude) list
2016-03-19 19:30:50,717 INFO org.apache.hadoop.conf.Configuration: found resource capacity-scheduler.xml at file:/usr/local/hadoop/etc/hadoop/capacity-scheduler.xml
2016-03-19 19:30:51,162 INFO org.apache.hadoop.yarn.server.resourcemanager.scheduler.capacity.CapacitySchedulerConfiguration: max alloc mb per queue for root is undefined
2016-03-19 19:30:51,162 INFO org.apache.hadoop.yarn.server.resourcemanager.scheduler.capacity.CapacitySchedulerConfiguration: max alloc vcore per queue for root is undefined
2016-03-19 19:30:51,209 INFO org.apache.hadoop.yarn.server.resourcemanager.scheduler.capacity.ParentQueue: root, capacity=1.0, asboluteCapacity=1.0, maxCapacity=1.0, asboluteMaxCapacity=1.0, state=RUNNING, acls=SUBMIT_APP:*ADMINISTER_QUEUE:*, labels=*,
, reservationsContinueLooking=true
2016-03-19 19:30:51,209 INFO org.apache.hadoop.yarn.server.resourcemanager.scheduler.capacity.ParentQueue: Initialized parent-queue root name=root, fullname=root
2016-03-19 19:30:51,291 INFO org.apache.hadoop.yarn.server.resourcemanager.scheduler.capacity.CapacitySchedulerConfiguration: max alloc mb per queue for root.default is undefined
2016-03-19 19:30:51,291 INFO org.apache.hadoop.yarn.server.resourcemanager.scheduler.capacity.CapacitySchedulerConfiguration: max alloc vcore per queue for root.default is undefined
2016-03-19 19:30:51,300 INFO org.apache.hadoop.yarn.server.resourcemanager.scheduler.capacity.LeafQueue: Initializing default
capacity = 1.0 [= (float) configuredCapacity / 100 ]
asboluteCapacity = 1.0 [= parentAbsoluteCapacity * capacity ]
maxCapacity = 1.0 [= configuredMaxCapacity ]
absoluteMaxCapacity = 1.0 [= 1.0 maximumCapacity undefined, (parentAbsoluteMaxCapacity * maximumCapacity) / 100 otherwise ]
userLimit = 100 [= configuredUserLimit ]
userLimitFactor = 1.0 [= configuredUserLimitFactor ]
maxApplications = 10000 [= configuredMaximumSystemApplicationsPerQueue or (int)(configuredMaximumSystemApplications * absoluteCapacity)]
maxApplicationsPerUser = 10000 [= (int)(maxApplications * (userLimit / 100.0f) * userLimitFactor) ]
usedCapacity = 0.0 [= usedResourcesMemory / (clusterResourceMemory * absoluteCapacity)]
absoluteUsedCapacity = 0.0 [= usedResourcesMemory / clusterResourceMemory]
maxAMResourcePerQueuePercent = 0.1 [= configuredMaximumAMResourcePercent ]
minimumAllocationFactor = 0.875 [= (float)(maximumAllocationMemory - minimumAllocationMemory) / maximumAllocationMemory ]
maximumAllocation = <memory:8192, vCores:32> [= configuredMaxAllocation ]
numContainers = 0 [= currentNumContainers ]
state = RUNNING [= configuredState ]
acls = SUBMIT_APP:*ADMINISTER_QUEUE:* [= configuredAcls ]
nodeLocalityDelay = 40
labels=*,
nodeLocalityDelay = 40
reservationsContinueLooking = true
preemptionDisabled = true

2016-03-19 19:30:51,301 INFO org.apache.hadoop.yarn.server.resourcemanager.scheduler.capacity.CapacityScheduler: Initialized queue: default: capacity=1.0, absoluteCapacity=1.0, usedResources=<memory:0, vCores:0>, usedCapacity=0.0, absoluteUsedCapacity=0.0, numApps=0, numContainers=0
2016-03-19 19:30:51,301 INFO org.apache.hadoop.yarn.server.resourcemanager.scheduler.capacity.CapacityScheduler: Initialized queue: root: numChildQueue= 1, capacity=1.0, absoluteCapacity=1.0, usedResources=<memory:0, vCores:0>usedCapacity=0.0, numApps=0, numContainers=0
2016-03-19 19:30:51,302 INFO org.apache.hadoop.yarn.server.resourcemanager.scheduler.capacity.CapacityScheduler: Initialized root queue root: numChildQueue= 1, capacity=1.0, absoluteCapacity=1.0, usedResources=<memory:0, vCores:0>usedCapacity=0.0, numApps=0, numContainers=0
2016-03-19 19:30:51,302 INFO org.apache.hadoop.yarn.server.resourcemanager.scheduler.capacity.CapacityScheduler: Initialized queue mappings, override: false
2016-03-19 19:30:51,302 INFO org.apache.hadoop.yarn.server.resourcemanager.scheduler.capacity.CapacityScheduler: Initialized CapacityScheduler with calculator=class org.apache.hadoop.yarn.util.resource.DefaultResourceCalculator, minimumAllocation=<<memory:1024, vCores:1>>, maximumAllocation=<<memory:8192, vCores:32>>, asynchronousScheduling=false, asyncScheduleInterval=5ms
2016-03-19 19:30:51,424 INFO org.apache.hadoop.yarn.server.resourcemanager.metrics.SystemMetricsPublisher: YARN system metrics publishing service is not enabled
2016-03-19 19:30:51,424 INFO org.apache.hadoop.yarn.server.resourcemanager.ResourceManager: Transitioning to active state
2016-03-19 19:30:51,531 INFO org.apache.hadoop.yarn.server.resourcemanager.recovery.RMStateStore: Updating AMRMToken
2016-03-19 19:30:51,539 INFO org.apache.hadoop.yarn.server.resourcemanager.security.RMContainerTokenSecretManager: Rolling master-key for container-tokens
2016-03-19 19:30:51,539 INFO org.apache.hadoop.yarn.server.resourcemanager.security.NMTokenSecretManagerInRM: Rolling master-key for nm-tokens
2016-03-19 19:30:51,540 INFO org.apache.hadoop.security.token.delegation.AbstractDelegationTokenSecretManager: Updating the current master key for generating delegation tokens
2016-03-19 19:30:51,549 INFO org.apache.hadoop.yarn.server.resourcemanager.security.RMDelegationTokenSecretManager: storing master key with keyID 1
2016-03-19 19:30:51,549 INFO org.apache.hadoop.yarn.server.resourcemanager.recovery.RMStateStore: Storing RMDTMasterKey.
2016-03-19 19:30:51,568 INFO org.apache.hadoop.security.token.delegation.AbstractDelegationTokenSecretManager: Starting expired delegation token remover thread, tokenRemoverScanInterval=60 min(s)
2016-03-19 19:30:51,592 INFO org.apache.hadoop.security.token.delegation.AbstractDelegationTokenSecretManager: Updating the current master key for generating delegation tokens
2016-03-19 19:30:51,592 INFO org.apache.hadoop.yarn.server.resourcemanager.security.RMDelegationTokenSecretManager: storing master key with keyID 2
2016-03-19 19:30:51,593 INFO org.apache.hadoop.yarn.server.resourcemanager.recovery.RMStateStore: Storing RMDTMasterKey.
2016-03-19 19:30:51,593 INFO org.apache.hadoop.yarn.event.AsyncDispatcher: Registering class org.apache.hadoop.yarn.nodelabels.event.NodeLabelsStoreEventType for class org.apache.hadoop.yarn.nodelabels.CommonNodeLabelsManager$ForwardingEventHandler
2016-03-19 19:30:51,826 INFO org.apache.hadoop.ipc.CallQueueManager: Using callQueue class java.util.concurrent.LinkedBlockingQueue
2016-03-19 19:30:51,950 INFO org.apache.hadoop.ipc.Server: Starting Socket Reader #1 for port 8031
2016-03-19 19:30:52,058 INFO org.apache.hadoop.yarn.factories.impl.pb.RpcServerFactoryPBImpl: Adding protocol org.apache.hadoop.yarn.server.api.ResourceTrackerPB to the server
2016-03-19 19:30:52,064 INFO org.apache.hadoop.ipc.Server: IPC Server Responder: starting
2016-03-19 19:30:52,190 INFO org.apache.hadoop.ipc.Server: IPC Server listener on 8031: starting
2016-03-19 19:30:52,291 INFO org.apache.hadoop.ipc.CallQueueManager: Using callQueue class java.util.concurrent.LinkedBlockingQueue
2016-03-19 19:30:52,322 INFO org.apache.hadoop.ipc.Server: Starting Socket Reader #1 for port 8030
2016-03-19 19:30:52,375 INFO org.apache.hadoop.yarn.factories.impl.pb.RpcServerFactoryPBImpl: Adding protocol org.apache.hadoop.yarn.api.ApplicationMasterProtocolPB to the server
2016-03-19 19:30:52,382 INFO org.apache.hadoop.ipc.Server: IPC Server Responder: starting
2016-03-19 19:30:52,475 INFO org.apache.hadoop.ipc.Server: IPC Server listener on 8030: starting
2016-03-19 19:30:53,007 INFO org.apache.hadoop.ipc.CallQueueManager: Using callQueue class java.util.concurrent.LinkedBlockingQueue
2016-03-19 19:30:53,008 INFO org.apache.hadoop.ipc.Server: Starting Socket Reader #1 for port 8032
2016-03-19 19:30:53,023 INFO org.apache.hadoop.yarn.factories.impl.pb.RpcServerFactoryPBImpl: Adding protocol org.apache.hadoop.yarn.api.ApplicationClientProtocolPB to the server
2016-03-19 19:30:53,051 INFO org.apache.hadoop.ipc.Server: IPC Server Responder: starting
2016-03-19 19:30:53,060 INFO org.apache.hadoop.ipc.Server: IPC Server listener on 8032: starting
2016-03-19 19:30:53,165 INFO org.apache.hadoop.yarn.server.resourcemanager.ResourceManager: Transitioned to active state
2016-03-19 19:30:53,803 INFO org.mortbay.log: Logging to org.slf4j.impl.Log4jLoggerAdapter(org.mortbay.log) via org.mortbay.log.Slf4jLog
2016-03-19 19:30:53,883 INFO org.apache.hadoop.security.authentication.server.AuthenticationFilter: Unable to initialize FileSignerSecretProvider, falling back to use random secrets.
2016-03-19 19:30:53,912 INFO org.apache.hadoop.http.HttpRequestLog: Http request log for http.requests.resourcemanager is not defined
2016-03-19 19:30:53,981 INFO org.apache.hadoop.http.HttpServer2: Added global filter 'safety' (class=org.apache.hadoop.http.HttpServer2$QuotingInputFilter)
2016-03-19 19:30:54,031 INFO org.apache.hadoop.http.HttpServer2: Added filter RMAuthenticationFilter (class=org.apache.hadoop.yarn.server.security.http.RMAuthenticationFilter) to context cluster
2016-03-19 19:30:54,031 INFO org.apache.hadoop.http.HttpServer2: Added filter RMAuthenticationFilter (class=org.apache.hadoop.yarn.server.security.http.RMAuthenticationFilter) to context logs
2016-03-19 19:30:54,032 INFO org.apache.hadoop.http.HttpServer2: Added filter RMAuthenticationFilter (class=org.apache.hadoop.yarn.server.security.http.RMAuthenticationFilter) to context static
2016-03-19 19:30:54,032 INFO org.apache.hadoop.http.HttpServer2: Added filter static_user_filter (class=org.apache.hadoop.http.lib.StaticUserWebFilter$StaticUserFilter) to context cluster
2016-03-19 19:30:54,033 INFO org.apache.hadoop.http.HttpServer2: Added filter static_user_filter (class=org.apache.hadoop.http.lib.StaticUserWebFilter$StaticUserFilter) to context logs
2016-03-19 19:30:54,033 INFO org.apache.hadoop.http.HttpServer2: Added filter static_user_filter (class=org.apache.hadoop.http.lib.StaticUserWebFilter$StaticUserFilter) to context static
2016-03-19 19:30:54,051 INFO org.apache.hadoop.http.HttpServer2: adding path spec: /cluster/*
2016-03-19 19:30:54,051 INFO org.apache.hadoop.http.HttpServer2: adding path spec: /ws/*
2016-03-19 19:30:55,752 INFO org.apache.hadoop.yarn.webapp.WebApps: Registered webapp guice modules
2016-03-19 19:30:55,758 INFO org.apache.hadoop.http.HttpServer2: Jetty bound to port 8088
2016-03-19 19:30:55,758 INFO org.mortbay.log: jetty-6.1.26
2016-03-19 19:30:55,821 INFO org.mortbay.log: Extract jar:file:/usr/local/hadoop/share/hadoop/yarn/hadoop-yarn-common-2.7.2.jar!/webapps/cluster to /tmp/Jetty_0_0_0_0_8088_cluster____u0rgz3/webapp
2016-03-19 19:30:56,276 INFO org.apache.hadoop.security.token.delegation.AbstractDelegationTokenSecretManager: Updating the current master key for generating delegation tokens
2016-03-19 19:30:56,281 INFO org.apache.hadoop.security.token.delegation.AbstractDelegationTokenSecretManager: Starting expired delegation token remover thread, tokenRemoverScanInterval=60 min(s)
2016-03-19 19:30:56,282 INFO org.apache.hadoop.security.token.delegation.AbstractDelegationTokenSecretManager: Updating the current master key for generating delegation tokens
2016-03-19 19:30:59,955 INFO org.mortbay.log: Started HttpServer2$SelectChannelConnectorWithSafeStartup@0.0.0.0:8088
2016-03-19 19:30:59,956 INFO org.apache.hadoop.yarn.webapp.WebApps: Web app cluster started at 8088
2016-03-19 19:31:00,199 INFO org.apache.hadoop.ipc.CallQueueManager: Using callQueue class java.util.concurrent.LinkedBlockingQueue
2016-03-19 19:31:00,199 INFO org.apache.hadoop.ipc.Server: Starting Socket Reader #1 for port 8033
2016-03-19 19:31:00,208 INFO org.apache.hadoop.yarn.factories.impl.pb.RpcServerFactoryPBImpl: Adding protocol org.apache.hadoop.yarn.server.api.ResourceManagerAdministrationProtocolPB to the server
2016-03-19 19:31:00,217 INFO org.apache.hadoop.ipc.Server: IPC Server Responder: starting
2016-03-19 19:31:00,232 INFO org.apache.hadoop.ipc.Server: IPC Server listener on 8033: starting
2016-03-19 19:31:04,701 INFO org.apache.hadoop.yarn.util.RackResolver: Resolved vishal-VirtualBox to /default-rack
2016-03-19 19:31:04,711 INFO org.apache.hadoop.yarn.server.resourcemanager.rmnode.RMNodeImpl: vishal-VirtualBox:40685 Node Transitioned from NEW to RUNNING
2016-03-19 19:31:04,712 INFO org.apache.hadoop.yarn.server.resourcemanager.ResourceTrackerService: NodeManager from node vishal-VirtualBox(cmPort: 40685 httpPort: 8042) registered with capability: <memory:8192, vCores:8>, assigned nodeId vishal-VirtualBox:40685
2016-03-19 19:31:04,731 INFO org.apache.hadoop.yarn.server.resourcemanager.scheduler.capacity.CapacityScheduler: Added node vishal-VirtualBox:40685 clusterResource: <memory:8192, vCores:8>
2016-03-19 19:31:29,364 INFO org.apache.hadoop.yarn.server.resourcemanager.ClientRMService: Allocated new applicationId: 1
2016-03-19 19:32:06,251 INFO org.apache.hadoop.yarn.server.resourcemanager.ClientRMService: Allocated new applicationId: 2
2016-03-19 19:32:17,978 INFO org.apache.hadoop.yarn.server.resourcemanager.ClientRMService: Allocated new applicationId: 3
2016-03-19 19:40:50,717 INFO org.apache.hadoop.yarn.server.resourcemanager.scheduler.AbstractYarnScheduler: Release request cache is cleaned up
2016-03-19 19:41:14,101 INFO org.apache.hadoop.yarn.server.resourcemanager.ClientRMService: Allocated new applicationId: 4
2016-03-19 19:51:04,050 INFO org.apache.hadoop.yarn.server.resourcemanager.ResourceManager: STARTUP_MSG: 
/************************************************************
STARTUP_MSG: Starting ResourceManager
STARTUP_MSG:   host = vishal-VirtualBox/127.0.1.1
STARTUP_MSG:   args = []
STARTUP_MSG:   version = 2.7.2
STARTUP_MSG:   build = https://git-wip-us.apache.org/repos/asf/hadoop.git -r b165c4fe8a74265c792ce23f546c64604acf0e41; compiled by 'jenkins' on 2016-01-26T00:08Z
STARTUP_MSG:   java = 1.8.0_74
************************************************************/
2016-03-19 19:51:04,080 INFO org.apache.hadoop.yarn.server.resourcemanager.ResourceManager: registered UNIX signal handlers for [TERM, HUP, INT]
2016-03-19 19:51:05,724 INFO org.apache.hadoop.conf.Configuration: found resource core-site.xml at file:/usr/local/hadoop/etc/hadoop/core-site.xml
2016-03-19 19:51:06,032 WARN org.apache.hadoop.util.NativeCodeLoader: Unable to load native-hadoop library for your platform... using builtin-java classes where applicable
2016-03-19 19:51:06,164 INFO org.apache.hadoop.security.Groups: clearing userToGroupsMap cache
2016-03-19 19:51:06,536 INFO org.apache.hadoop.conf.Configuration: found resource yarn-site.xml at file:/usr/local/hadoop/etc/hadoop/yarn-site.xml
2016-03-19 19:51:07,382 INFO org.apache.hadoop.yarn.event.AsyncDispatcher: Registering class org.apache.hadoop.yarn.server.resourcemanager.RMFatalEventType for class org.apache.hadoop.yarn.server.resourcemanager.ResourceManager$RMFatalEventDispatcher
2016-03-19 19:51:08,810 INFO org.apache.hadoop.yarn.server.resourcemanager.security.NMTokenSecretManagerInRM: NMTokenKeyRollingInterval: 86400000ms and NMTokenKeyActivationDelay: 900000ms
2016-03-19 19:51:08,900 INFO org.apache.hadoop.yarn.server.resourcemanager.security.RMContainerTokenSecretManager: ContainerTokenKeyRollingInterval: 86400000ms and ContainerTokenKeyActivationDelay: 900000ms
2016-03-19 19:51:08,982 INFO org.apache.hadoop.yarn.server.resourcemanager.security.AMRMTokenSecretManager: AMRMTokenKeyRollingInterval: 86400000ms and AMRMTokenKeyActivationDelay: 900000 ms
2016-03-19 19:51:09,399 INFO org.apache.hadoop.yarn.event.AsyncDispatcher: Registering class org.apache.hadoop.yarn.server.resourcemanager.recovery.RMStateStoreEventType for class org.apache.hadoop.yarn.server.resourcemanager.recovery.RMStateStore$ForwardingEventHandler
2016-03-19 19:51:09,428 INFO org.apache.hadoop.yarn.event.AsyncDispatcher: Registering class org.apache.hadoop.yarn.server.resourcemanager.NodesListManagerEventType for class org.apache.hadoop.yarn.server.resourcemanager.NodesListManager
2016-03-19 19:51:09,428 INFO org.apache.hadoop.yarn.server.resourcemanager.ResourceManager: Using Scheduler: org.apache.hadoop.yarn.server.resourcemanager.scheduler.capacity.CapacityScheduler
2016-03-19 19:51:09,530 INFO org.apache.hadoop.yarn.event.AsyncDispatcher: Registering class org.apache.hadoop.yarn.server.resourcemanager.scheduler.event.SchedulerEventType for class org.apache.hadoop.yarn.server.resourcemanager.ResourceManager$SchedulerEventDispatcher
2016-03-19 19:51:09,531 INFO org.apache.hadoop.yarn.event.AsyncDispatcher: Registering class org.apache.hadoop.yarn.server.resourcemanager.rmapp.RMAppEventType for class org.apache.hadoop.yarn.server.resourcemanager.ResourceManager$ApplicationEventDispatcher
2016-03-19 19:51:09,532 INFO org.apache.hadoop.yarn.event.AsyncDispatcher: Registering class org.apache.hadoop.yarn.server.resourcemanager.rmapp.attempt.RMAppAttemptEventType for class org.apache.hadoop.yarn.server.resourcemanager.ResourceManager$ApplicationAttemptEventDispatcher
2016-03-19 19:51:09,539 INFO org.apache.hadoop.yarn.event.AsyncDispatcher: Registering class org.apache.hadoop.yarn.server.resourcemanager.rmnode.RMNodeEventType for class org.apache.hadoop.yarn.server.resourcemanager.ResourceManager$NodeEventDispatcher
2016-03-19 19:51:09,816 INFO org.apache.hadoop.metrics2.impl.MetricsConfig: loaded properties from hadoop-metrics2.properties
2016-03-19 19:51:10,138 INFO org.apache.hadoop.metrics2.impl.MetricsSystemImpl: Scheduled snapshot period at 10 second(s).
2016-03-19 19:51:10,139 INFO org.apache.hadoop.metrics2.impl.MetricsSystemImpl: ResourceManager metrics system started
2016-03-19 19:51:10,228 INFO org.apache.hadoop.yarn.event.AsyncDispatcher: Registering class org.apache.hadoop.yarn.server.resourcemanager.RMAppManagerEventType for class org.apache.hadoop.yarn.server.resourcemanager.RMAppManager
2016-03-19 19:51:10,272 INFO org.apache.hadoop.yarn.event.AsyncDispatcher: Registering class org.apache.hadoop.yarn.server.resourcemanager.amlauncher.AMLauncherEventType for class org.apache.hadoop.yarn.server.resourcemanager.amlauncher.ApplicationMasterLauncher
2016-03-19 19:51:10,281 INFO org.apache.hadoop.yarn.server.resourcemanager.RMNMInfo: Registered RMNMInfo MBean
2016-03-19 19:51:10,284 INFO org.apache.hadoop.yarn.security.YarnAuthorizationProvider: org.apache.hadoop.yarn.security.ConfiguredYarnAuthorizer is instiantiated.
2016-03-19 19:51:10,292 INFO org.apache.hadoop.util.HostsFileReader: Refreshing hosts (include/exclude) list
2016-03-19 19:51:10,325 INFO org.apache.hadoop.conf.Configuration: found resource capacity-scheduler.xml at file:/usr/local/hadoop/etc/hadoop/capacity-scheduler.xml
2016-03-19 19:51:10,677 INFO org.apache.hadoop.yarn.server.resourcemanager.scheduler.capacity.CapacitySchedulerConfiguration: max alloc mb per queue for root is undefined
2016-03-19 19:51:10,677 INFO org.apache.hadoop.yarn.server.resourcemanager.scheduler.capacity.CapacitySchedulerConfiguration: max alloc vcore per queue for root is undefined
2016-03-19 19:51:10,680 INFO org.apache.hadoop.yarn.server.resourcemanager.scheduler.capacity.ParentQueue: root, capacity=1.0, asboluteCapacity=1.0, maxCapacity=1.0, asboluteMaxCapacity=1.0, state=RUNNING, acls=SUBMIT_APP:*ADMINISTER_QUEUE:*, labels=*,
, reservationsContinueLooking=true
2016-03-19 19:51:10,680 INFO org.apache.hadoop.yarn.server.resourcemanager.scheduler.capacity.ParentQueue: Initialized parent-queue root name=root, fullname=root
2016-03-19 19:51:10,723 INFO org.apache.hadoop.yarn.server.resourcemanager.scheduler.capacity.CapacitySchedulerConfiguration: max alloc mb per queue for root.default is undefined
2016-03-19 19:51:10,723 INFO org.apache.hadoop.yarn.server.resourcemanager.scheduler.capacity.CapacitySchedulerConfiguration: max alloc vcore per queue for root.default is undefined
2016-03-19 19:51:10,724 INFO org.apache.hadoop.yarn.server.resourcemanager.scheduler.capacity.LeafQueue: Initializing default
capacity = 1.0 [= (float) configuredCapacity / 100 ]
asboluteCapacity = 1.0 [= parentAbsoluteCapacity * capacity ]
maxCapacity = 1.0 [= configuredMaxCapacity ]
absoluteMaxCapacity = 1.0 [= 1.0 maximumCapacity undefined, (parentAbsoluteMaxCapacity * maximumCapacity) / 100 otherwise ]
userLimit = 100 [= configuredUserLimit ]
userLimitFactor = 1.0 [= configuredUserLimitFactor ]
maxApplications = 10000 [= configuredMaximumSystemApplicationsPerQueue or (int)(configuredMaximumSystemApplications * absoluteCapacity)]
maxApplicationsPerUser = 10000 [= (int)(maxApplications * (userLimit / 100.0f) * userLimitFactor) ]
usedCapacity = 0.0 [= usedResourcesMemory / (clusterResourceMemory * absoluteCapacity)]
absoluteUsedCapacity = 0.0 [= usedResourcesMemory / clusterResourceMemory]
maxAMResourcePerQueuePercent = 0.1 [= configuredMaximumAMResourcePercent ]
minimumAllocationFactor = 0.875 [= (float)(maximumAllocationMemory - minimumAllocationMemory) / maximumAllocationMemory ]
maximumAllocation = <memory:8192, vCores:32> [= configuredMaxAllocation ]
numContainers = 0 [= currentNumContainers ]
state = RUNNING [= configuredState ]
acls = SUBMIT_APP:*ADMINISTER_QUEUE:* [= configuredAcls ]
nodeLocalityDelay = 40
labels=*,
nodeLocalityDelay = 40
reservationsContinueLooking = true
preemptionDisabled = true

2016-03-19 19:51:10,725 INFO org.apache.hadoop.yarn.server.resourcemanager.scheduler.capacity.CapacityScheduler: Initialized queue: default: capacity=1.0, absoluteCapacity=1.0, usedResources=<memory:0, vCores:0>, usedCapacity=0.0, absoluteUsedCapacity=0.0, numApps=0, numContainers=0
2016-03-19 19:51:10,725 INFO org.apache.hadoop.yarn.server.resourcemanager.scheduler.capacity.CapacityScheduler: Initialized queue: root: numChildQueue= 1, capacity=1.0, absoluteCapacity=1.0, usedResources=<memory:0, vCores:0>usedCapacity=0.0, numApps=0, numContainers=0
2016-03-19 19:51:10,726 INFO org.apache.hadoop.yarn.server.resourcemanager.scheduler.capacity.CapacityScheduler: Initialized root queue root: numChildQueue= 1, capacity=1.0, absoluteCapacity=1.0, usedResources=<memory:0, vCores:0>usedCapacity=0.0, numApps=0, numContainers=0
2016-03-19 19:51:10,726 INFO org.apache.hadoop.yarn.server.resourcemanager.scheduler.capacity.CapacityScheduler: Initialized queue mappings, override: false
2016-03-19 19:51:10,730 INFO org.apache.hadoop.yarn.server.resourcemanager.scheduler.capacity.CapacityScheduler: Initialized CapacityScheduler with calculator=class org.apache.hadoop.yarn.util.resource.DefaultResourceCalculator, minimumAllocation=<<memory:1024, vCores:1>>, maximumAllocation=<<memory:8192, vCores:32>>, asynchronousScheduling=false, asyncScheduleInterval=5ms
2016-03-19 19:51:10,771 INFO org.apache.hadoop.yarn.server.resourcemanager.metrics.SystemMetricsPublisher: YARN system metrics publishing service is not enabled
2016-03-19 19:51:10,771 INFO org.apache.hadoop.yarn.server.resourcemanager.ResourceManager: Transitioning to active state
2016-03-19 19:51:10,843 INFO org.apache.hadoop.yarn.server.resourcemanager.recovery.RMStateStore: Updating AMRMToken
2016-03-19 19:51:10,849 INFO org.apache.hadoop.yarn.server.resourcemanager.security.RMContainerTokenSecretManager: Rolling master-key for container-tokens
2016-03-19 19:51:10,849 INFO org.apache.hadoop.yarn.server.resourcemanager.security.NMTokenSecretManagerInRM: Rolling master-key for nm-tokens
2016-03-19 19:51:10,849 INFO org.apache.hadoop.security.token.delegation.AbstractDelegationTokenSecretManager: Updating the current master key for generating delegation tokens
2016-03-19 19:51:10,851 INFO org.apache.hadoop.yarn.server.resourcemanager.security.RMDelegationTokenSecretManager: storing master key with keyID 1
2016-03-19 19:51:10,852 INFO org.apache.hadoop.yarn.server.resourcemanager.recovery.RMStateStore: Storing RMDTMasterKey.
2016-03-19 19:51:10,860 INFO org.apache.hadoop.security.token.delegation.AbstractDelegationTokenSecretManager: Starting expired delegation token remover thread, tokenRemoverScanInterval=60 min(s)
2016-03-19 19:51:10,868 INFO org.apache.hadoop.yarn.event.AsyncDispatcher: Registering class org.apache.hadoop.yarn.nodelabels.event.NodeLabelsStoreEventType for class org.apache.hadoop.yarn.nodelabels.CommonNodeLabelsManager$ForwardingEventHandler
2016-03-19 19:51:10,874 INFO org.apache.hadoop.security.token.delegation.AbstractDelegationTokenSecretManager: Updating the current master key for generating delegation tokens
2016-03-19 19:51:10,886 INFO org.apache.hadoop.yarn.server.resourcemanager.security.RMDelegationTokenSecretManager: storing master key with keyID 2
2016-03-19 19:51:10,891 INFO org.apache.hadoop.yarn.server.resourcemanager.recovery.RMStateStore: Storing RMDTMasterKey.
2016-03-19 19:51:11,015 INFO org.apache.hadoop.ipc.CallQueueManager: Using callQueue class java.util.concurrent.LinkedBlockingQueue
2016-03-19 19:51:11,093 INFO org.apache.hadoop.service.AbstractService: Service org.apache.hadoop.yarn.server.resourcemanager.ResourceTrackerService failed in state STARTED; cause: org.apache.hadoop.yarn.exceptions.YarnRuntimeException: java.net.BindException: Problem binding to [0.0.0.0:8031] java.net.BindException: Address already in use; For more details see:  http://wiki.apache.org/hadoop/BindException
org.apache.hadoop.yarn.exceptions.YarnRuntimeException: java.net.BindException: Problem binding to [0.0.0.0:8031] java.net.BindException: Address already in use; For more details see:  http://wiki.apache.org/hadoop/BindException
	at org.apache.hadoop.yarn.factories.impl.pb.RpcServerFactoryPBImpl.getServer(RpcServerFactoryPBImpl.java:139)
	at org.apache.hadoop.yarn.ipc.HadoopYarnProtoRPC.getServer(HadoopYarnProtoRPC.java:65)
	at org.apache.hadoop.yarn.ipc.YarnRPC.getServer(YarnRPC.java:54)
	at org.apache.hadoop.yarn.server.resourcemanager.ResourceTrackerService.serviceStart(ResourceTrackerService.java:162)
	at org.apache.hadoop.service.AbstractService.start(AbstractService.java:193)
	at org.apache.hadoop.service.CompositeService.serviceStart(CompositeService.java:120)
	at org.apache.hadoop.yarn.server.resourcemanager.ResourceManager$RMActiveServices.serviceStart(ResourceManager.java:579)
	at org.apache.hadoop.service.AbstractService.start(AbstractService.java:193)
	at org.apache.hadoop.yarn.server.resourcemanager.ResourceManager.startActiveServices(ResourceManager.java:964)
	at org.apache.hadoop.yarn.server.resourcemanager.ResourceManager$1.run(ResourceManager.java:1005)
	at org.apache.hadoop.yarn.server.resourcemanager.ResourceManager$1.run(ResourceManager.java:1001)
	at java.security.AccessController.doPrivileged(Native Method)
	at javax.security.auth.Subject.doAs(Subject.java:422)
	at org.apache.hadoop.security.UserGroupInformation.doAs(UserGroupInformation.java:1657)
	at org.apache.hadoop.yarn.server.resourcemanager.ResourceManager.transitionToActive(ResourceManager.java:1001)
	at org.apache.hadoop.yarn.server.resourcemanager.ResourceManager.serviceStart(ResourceManager.java:1041)
	at org.apache.hadoop.service.AbstractService.start(AbstractService.java:193)
	at org.apache.hadoop.yarn.server.resourcemanager.ResourceManager.main(ResourceManager.java:1178)
Caused by: java.net.BindException: Problem binding to [0.0.0.0:8031] java.net.BindException: Address already in use; For more details see:  http://wiki.apache.org/hadoop/BindException
	at sun.reflect.NativeConstructorAccessorImpl.newInstance0(Native Method)
	at sun.reflect.NativeConstructorAccessorImpl.newInstance(NativeConstructorAccessorImpl.java:62)
	at sun.reflect.DelegatingConstructorAccessorImpl.newInstance(DelegatingConstructorAccessorImpl.java:45)
	at java.lang.reflect.Constructor.newInstance(Constructor.java:423)
	at org.apache.hadoop.net.NetUtils.wrapWithMessage(NetUtils.java:792)
	at org.apache.hadoop.net.NetUtils.wrapException(NetUtils.java:721)
	at org.apache.hadoop.ipc.Server.bind(Server.java:425)
	at org.apache.hadoop.ipc.Server$Listener.<init>(Server.java:574)
	at org.apache.hadoop.ipc.Server.<init>(Server.java:2215)
	at org.apache.hadoop.ipc.RPC$Server.<init>(RPC.java:938)
	at org.apache.hadoop.ipc.ProtobufRpcEngine$Server.<init>(ProtobufRpcEngine.java:534)
	at org.apache.hadoop.ipc.ProtobufRpcEngine.getServer(ProtobufRpcEngine.java:509)
	at org.apache.hadoop.ipc.RPC$Builder.build(RPC.java:783)
	at org.apache.hadoop.yarn.factories.impl.pb.RpcServerFactoryPBImpl.createServer(RpcServerFactoryPBImpl.java:169)
	at org.apache.hadoop.yarn.factories.impl.pb.RpcServerFactoryPBImpl.getServer(RpcServerFactoryPBImpl.java:132)
	... 17 more
Caused by: java.net.BindException: Address already in use
	at sun.nio.ch.Net.bind0(Native Method)
	at sun.nio.ch.Net.bind(Net.java:433)
	at sun.nio.ch.Net.bind(Net.java:425)
	at sun.nio.ch.ServerSocketChannelImpl.bind(ServerSocketChannelImpl.java:223)
	at sun.nio.ch.ServerSocketAdaptor.bind(ServerSocketAdaptor.java:74)
	at org.apache.hadoop.ipc.Server.bind(Server.java:408)
	... 25 more
2016-03-19 19:51:11,096 INFO org.apache.hadoop.service.AbstractService: Service RMActiveServices failed in state STARTED; cause: org.apache.hadoop.yarn.exceptions.YarnRuntimeException: java.net.BindException: Problem binding to [0.0.0.0:8031] java.net.BindException: Address already in use; For more details see:  http://wiki.apache.org/hadoop/BindException
org.apache.hadoop.yarn.exceptions.YarnRuntimeException: java.net.BindException: Problem binding to [0.0.0.0:8031] java.net.BindException: Address already in use; For more details see:  http://wiki.apache.org/hadoop/BindException
	at org.apache.hadoop.yarn.factories.impl.pb.RpcServerFactoryPBImpl.getServer(RpcServerFactoryPBImpl.java:139)
	at org.apache.hadoop.yarn.ipc.HadoopYarnProtoRPC.getServer(HadoopYarnProtoRPC.java:65)
	at org.apache.hadoop.yarn.ipc.YarnRPC.getServer(YarnRPC.java:54)
	at org.apache.hadoop.yarn.server.resourcemanager.ResourceTrackerService.serviceStart(ResourceTrackerService.java:162)
	at org.apache.hadoop.service.AbstractService.start(AbstractService.java:193)
	at org.apache.hadoop.service.CompositeService.serviceStart(CompositeService.java:120)
	at org.apache.hadoop.yarn.server.resourcemanager.ResourceManager$RMActiveServices.serviceStart(ResourceManager.java:579)
	at org.apache.hadoop.service.AbstractService.start(AbstractService.java:193)
	at org.apache.hadoop.yarn.server.resourcemanager.ResourceManager.startActiveServices(ResourceManager.java:964)
	at org.apache.hadoop.yarn.server.resourcemanager.ResourceManager$1.run(ResourceManager.java:1005)
	at org.apache.hadoop.yarn.server.resourcemanager.ResourceManager$1.run(ResourceManager.java:1001)
	at java.security.AccessController.doPrivileged(Native Method)
	at javax.security.auth.Subject.doAs(Subject.java:422)
	at org.apache.hadoop.security.UserGroupInformation.doAs(UserGroupInformation.java:1657)
	at org.apache.hadoop.yarn.server.resourcemanager.ResourceManager.transitionToActive(ResourceManager.java:1001)
	at org.apache.hadoop.yarn.server.resourcemanager.ResourceManager.serviceStart(ResourceManager.java:1041)
	at org.apache.hadoop.service.AbstractService.start(AbstractService.java:193)
	at org.apache.hadoop.yarn.server.resourcemanager.ResourceManager.main(ResourceManager.java:1178)
Caused by: java.net.BindException: Problem binding to [0.0.0.0:8031] java.net.BindException: Address already in use; For more details see:  http://wiki.apache.org/hadoop/BindException
	at sun.reflect.NativeConstructorAccessorImpl.newInstance0(Native Method)
	at sun.reflect.NativeConstructorAccessorImpl.newInstance(NativeConstructorAccessorImpl.java:62)
	at sun.reflect.DelegatingConstructorAccessorImpl.newInstance(DelegatingConstructorAccessorImpl.java:45)
	at java.lang.reflect.Constructor.newInstance(Constructor.java:423)
	at org.apache.hadoop.net.NetUtils.wrapWithMessage(NetUtils.java:792)
	at org.apache.hadoop.net.NetUtils.wrapException(NetUtils.java:721)
	at org.apache.hadoop.ipc.Server.bind(Server.java:425)
	at org.apache.hadoop.ipc.Server$Listener.<init>(Server.java:574)
	at org.apache.hadoop.ipc.Server.<init>(Server.java:2215)
	at org.apache.hadoop.ipc.RPC$Server.<init>(RPC.java:938)
	at org.apache.hadoop.ipc.ProtobufRpcEngine$Server.<init>(ProtobufRpcEngine.java:534)
	at org.apache.hadoop.ipc.ProtobufRpcEngine.getServer(ProtobufRpcEngine.java:509)
	at org.apache.hadoop.ipc.RPC$Builder.build(RPC.java:783)
	at org.apache.hadoop.yarn.factories.impl.pb.RpcServerFactoryPBImpl.createServer(RpcServerFactoryPBImpl.java:169)
	at org.apache.hadoop.yarn.factories.impl.pb.RpcServerFactoryPBImpl.getServer(RpcServerFactoryPBImpl.java:132)
	... 17 more
Caused by: java.net.BindException: Address already in use
	at sun.nio.ch.Net.bind0(Native Method)
	at sun.nio.ch.Net.bind(Net.java:433)
	at sun.nio.ch.Net.bind(Net.java:425)
	at sun.nio.ch.ServerSocketChannelImpl.bind(ServerSocketChannelImpl.java:223)
	at sun.nio.ch.ServerSocketAdaptor.bind(ServerSocketAdaptor.java:74)
	at org.apache.hadoop.ipc.Server.bind(Server.java:408)
	... 25 more
2016-03-19 19:51:11,110 INFO org.apache.hadoop.yarn.util.AbstractLivelinessMonitor: NMLivelinessMonitor thread interrupted
2016-03-19 19:51:11,111 ERROR org.apache.hadoop.yarn.server.resourcemanager.ResourceManager: Returning, interrupted : java.lang.InterruptedException
2016-03-19 19:51:11,111 INFO org.apache.hadoop.yarn.event.AsyncDispatcher: AsyncDispatcher is draining to stop, igonring any new events.
2016-03-19 19:51:11,111 INFO org.apache.hadoop.yarn.util.AbstractLivelinessMonitor: AMLivelinessMonitor thread interrupted
2016-03-19 19:51:11,112 INFO org.apache.hadoop.yarn.util.AbstractLivelinessMonitor: AMLivelinessMonitor thread interrupted
2016-03-19 19:51:11,113 INFO org.apache.hadoop.yarn.util.AbstractLivelinessMonitor: org.apache.hadoop.yarn.server.resourcemanager.rmcontainer.ContainerAllocationExpirer thread interrupted
2016-03-19 19:51:11,114 ERROR org.apache.hadoop.security.token.delegation.AbstractDelegationTokenSecretManager: ExpiredTokenRemover received java.lang.InterruptedException: sleep interrupted
2016-03-19 19:51:11,117 INFO org.apache.hadoop.metrics2.impl.MetricsSystemImpl: Stopping ResourceManager metrics system...
2016-03-19 19:51:11,118 INFO org.apache.hadoop.metrics2.impl.MetricsSystemImpl: ResourceManager metrics system stopped.
2016-03-19 19:51:11,118 INFO org.apache.hadoop.metrics2.impl.MetricsSystemImpl: ResourceManager metrics system shutdown complete.
2016-03-19 19:51:11,120 INFO org.apache.hadoop.yarn.event.AsyncDispatcher: AsyncDispatcher is draining to stop, igonring any new events.
2016-03-19 19:51:11,124 INFO org.apache.hadoop.yarn.event.AsyncDispatcher: Registering class org.apache.hadoop.yarn.server.resourcemanager.RMFatalEventType for class org.apache.hadoop.yarn.server.resourcemanager.ResourceManager$RMFatalEventDispatcher
2016-03-19 19:51:11,127 INFO org.apache.hadoop.yarn.server.resourcemanager.security.NMTokenSecretManagerInRM: NMTokenKeyRollingInterval: 86400000ms and NMTokenKeyActivationDelay: 900000ms
2016-03-19 19:51:11,134 INFO org.apache.hadoop.yarn.server.resourcemanager.security.RMContainerTokenSecretManager: ContainerTokenKeyRollingInterval: 86400000ms and ContainerTokenKeyActivationDelay: 900000ms
2016-03-19 19:51:11,135 INFO org.apache.hadoop.yarn.server.resourcemanager.security.AMRMTokenSecretManager: AMRMTokenKeyRollingInterval: 86400000ms and AMRMTokenKeyActivationDelay: 900000 ms
2016-03-19 19:51:11,135 INFO org.apache.hadoop.yarn.event.AsyncDispatcher: Registering class org.apache.hadoop.yarn.server.resourcemanager.recovery.RMStateStoreEventType for class org.apache.hadoop.yarn.server.resourcemanager.recovery.RMStateStore$ForwardingEventHandler
2016-03-19 19:51:11,135 INFO org.apache.hadoop.yarn.event.AsyncDispatcher: Registering class org.apache.hadoop.yarn.server.resourcemanager.NodesListManagerEventType for class org.apache.hadoop.yarn.server.resourcemanager.NodesListManager
2016-03-19 19:51:11,135 INFO org.apache.hadoop.yarn.server.resourcemanager.ResourceManager: Using Scheduler: org.apache.hadoop.yarn.server.resourcemanager.scheduler.capacity.CapacityScheduler
2016-03-19 19:51:11,135 INFO org.apache.hadoop.yarn.event.AsyncDispatcher: Registering class org.apache.hadoop.yarn.server.resourcemanager.scheduler.event.SchedulerEventType for class org.apache.hadoop.yarn.server.resourcemanager.ResourceManager$SchedulerEventDispatcher
2016-03-19 19:51:11,136 INFO org.apache.hadoop.yarn.event.AsyncDispatcher: Registering class org.apache.hadoop.yarn.server.resourcemanager.rmapp.RMAppEventType for class org.apache.hadoop.yarn.server.resourcemanager.ResourceManager$ApplicationEventDispatcher
2016-03-19 19:51:11,136 INFO org.apache.hadoop.yarn.event.AsyncDispatcher: Registering class org.apache.hadoop.yarn.server.resourcemanager.rmapp.attempt.RMAppAttemptEventType for class org.apache.hadoop.yarn.server.resourcemanager.ResourceManager$ApplicationAttemptEventDispatcher
2016-03-19 19:51:11,136 INFO org.apache.hadoop.yarn.event.AsyncDispatcher: Registering class org.apache.hadoop.yarn.server.resourcemanager.rmnode.RMNodeEventType for class org.apache.hadoop.yarn.server.resourcemanager.ResourceManager$NodeEventDispatcher
2016-03-19 19:51:11,143 INFO org.apache.hadoop.metrics2.impl.MetricsConfig: loaded properties from hadoop-metrics2.properties
2016-03-19 19:51:11,145 INFO org.apache.hadoop.metrics2.impl.MetricsSystemImpl: Scheduled snapshot period at 10 second(s).
2016-03-19 19:51:11,151 INFO org.apache.hadoop.metrics2.impl.MetricsSystemImpl: ResourceManager metrics system started
2016-03-19 19:51:11,152 INFO org.apache.hadoop.yarn.event.AsyncDispatcher: Registering class org.apache.hadoop.yarn.server.resourcemanager.RMAppManagerEventType for class org.apache.hadoop.yarn.server.resourcemanager.RMAppManager
2016-03-19 19:51:11,153 INFO org.apache.hadoop.yarn.event.AsyncDispatcher: Registering class org.apache.hadoop.yarn.server.resourcemanager.amlauncher.AMLauncherEventType for class org.apache.hadoop.yarn.server.resourcemanager.amlauncher.ApplicationMasterLauncher
2016-03-19 19:51:11,153 WARN org.apache.hadoop.metrics2.util.MBeans: Failed to register MBean "Hadoop:service=ResourceManager,name=RMNMInfo": Instance already exists.
2016-03-19 19:51:11,153 INFO org.apache.hadoop.yarn.server.resourcemanager.RMNMInfo: Registered RMNMInfo MBean
2016-03-19 19:51:11,153 INFO org.apache.hadoop.util.HostsFileReader: Refreshing hosts (include/exclude) list
2016-03-19 19:51:11,155 INFO org.apache.hadoop.conf.Configuration: found resource capacity-scheduler.xml at file:/usr/local/hadoop/etc/hadoop/capacity-scheduler.xml
2016-03-19 19:51:11,306 INFO org.apache.hadoop.yarn.server.resourcemanager.scheduler.capacity.CapacitySchedulerConfiguration: max alloc mb per queue for root is undefined
2016-03-19 19:51:11,306 INFO org.apache.hadoop.yarn.server.resourcemanager.scheduler.capacity.CapacitySchedulerConfiguration: max alloc vcore per queue for root is undefined
2016-03-19 19:51:11,306 INFO org.apache.hadoop.yarn.server.resourcemanager.scheduler.capacity.ParentQueue: root, capacity=1.0, asboluteCapacity=1.0, maxCapacity=1.0, asboluteMaxCapacity=1.0, state=RUNNING, acls=SUBMIT_APP:*ADMINISTER_QUEUE:*, labels=*,
, reservationsContinueLooking=true
2016-03-19 19:51:11,306 INFO org.apache.hadoop.yarn.server.resourcemanager.scheduler.capacity.ParentQueue: Initialized parent-queue root name=root, fullname=root
2016-03-19 19:51:11,335 INFO org.apache.hadoop.yarn.server.resourcemanager.scheduler.capacity.CapacitySchedulerConfiguration: max alloc mb per queue for root.default is undefined
2016-03-19 19:51:11,335 INFO org.apache.hadoop.yarn.server.resourcemanager.scheduler.capacity.CapacitySchedulerConfiguration: max alloc vcore per queue for root.default is undefined
2016-03-19 19:51:11,337 INFO org.apache.hadoop.yarn.server.resourcemanager.scheduler.capacity.LeafQueue: Initializing default
capacity = 1.0 [= (float) configuredCapacity / 100 ]
asboluteCapacity = 1.0 [= parentAbsoluteCapacity * capacity ]
maxCapacity = 1.0 [= configuredMaxCapacity ]
absoluteMaxCapacity = 1.0 [= 1.0 maximumCapacity undefined, (parentAbsoluteMaxCapacity * maximumCapacity) / 100 otherwise ]
userLimit = 100 [= configuredUserLimit ]
userLimitFactor = 1.0 [= configuredUserLimitFactor ]
maxApplications = 10000 [= configuredMaximumSystemApplicationsPerQueue or (int)(configuredMaximumSystemApplications * absoluteCapacity)]
maxApplicationsPerUser = 10000 [= (int)(maxApplications * (userLimit / 100.0f) * userLimitFactor) ]
usedCapacity = 0.0 [= usedResourcesMemory / (clusterResourceMemory * absoluteCapacity)]
absoluteUsedCapacity = 0.0 [= usedResourcesMemory / clusterResourceMemory]
maxAMResourcePerQueuePercent = 0.1 [= configuredMaximumAMResourcePercent ]
minimumAllocationFactor = 0.875 [= (float)(maximumAllocationMemory - minimumAllocationMemory) / maximumAllocationMemory ]
maximumAllocation = <memory:8192, vCores:32> [= configuredMaxAllocation ]
numContainers = 0 [= currentNumContainers ]
state = RUNNING [= configuredState ]
acls = SUBMIT_APP:*ADMINISTER_QUEUE:* [= configuredAcls ]
nodeLocalityDelay = 40
labels=*,
nodeLocalityDelay = 40
reservationsContinueLooking = true
preemptionDisabled = true

2016-03-19 19:51:11,337 INFO org.apache.hadoop.yarn.server.resourcemanager.scheduler.capacity.CapacityScheduler: Initialized queue: default: capacity=1.0, absoluteCapacity=1.0, usedResources=<memory:0, vCores:0>, usedCapacity=0.0, absoluteUsedCapacity=0.0, numApps=0, numContainers=0
2016-03-19 19:51:11,338 INFO org.apache.hadoop.yarn.server.resourcemanager.scheduler.capacity.CapacityScheduler: Initialized queue: root: numChildQueue= 1, capacity=1.0, absoluteCapacity=1.0, usedResources=<memory:0, vCores:0>usedCapacity=0.0, numApps=0, numContainers=0
2016-03-19 19:51:11,338 INFO org.apache.hadoop.yarn.server.resourcemanager.scheduler.capacity.CapacityScheduler: Initialized root queue root: numChildQueue= 1, capacity=1.0, absoluteCapacity=1.0, usedResources=<memory:0, vCores:0>usedCapacity=0.0, numApps=0, numContainers=0
2016-03-19 19:51:11,338 INFO org.apache.hadoop.yarn.server.resourcemanager.scheduler.capacity.CapacityScheduler: Initialized queue mappings, override: false
2016-03-19 19:51:11,342 INFO org.apache.hadoop.yarn.server.resourcemanager.scheduler.capacity.CapacityScheduler: Initialized CapacityScheduler with calculator=class org.apache.hadoop.yarn.util.resource.DefaultResourceCalculator, minimumAllocation=<<memory:1024, vCores:1>>, maximumAllocation=<<memory:8192, vCores:32>>, asynchronousScheduling=false, asyncScheduleInterval=5ms
2016-03-19 19:51:11,342 INFO org.apache.hadoop.service.AbstractService: Service ResourceManager failed in state STARTED; cause: org.apache.hadoop.yarn.exceptions.YarnRuntimeException: java.net.BindException: Problem binding to [0.0.0.0:8031] java.net.BindException: Address already in use; For more details see:  http://wiki.apache.org/hadoop/BindException
org.apache.hadoop.yarn.exceptions.YarnRuntimeException: java.net.BindException: Problem binding to [0.0.0.0:8031] java.net.BindException: Address already in use; For more details see:  http://wiki.apache.org/hadoop/BindException
	at org.apache.hadoop.yarn.factories.impl.pb.RpcServerFactoryPBImpl.getServer(RpcServerFactoryPBImpl.java:139)
	at org.apache.hadoop.yarn.ipc.HadoopYarnProtoRPC.getServer(HadoopYarnProtoRPC.java:65)
	at org.apache.hadoop.yarn.ipc.YarnRPC.getServer(YarnRPC.java:54)
	at org.apache.hadoop.yarn.server.resourcemanager.ResourceTrackerService.serviceStart(ResourceTrackerService.java:162)
	at org.apache.hadoop.service.AbstractService.start(AbstractService.java:193)
	at org.apache.hadoop.service.CompositeService.serviceStart(CompositeService.java:120)
	at org.apache.hadoop.yarn.server.resourcemanager.ResourceManager$RMActiveServices.serviceStart(ResourceManager.java:579)
	at org.apache.hadoop.service.AbstractService.start(AbstractService.java:193)
	at org.apache.hadoop.yarn.server.resourcemanager.ResourceManager.startActiveServices(ResourceManager.java:964)
	at org.apache.hadoop.yarn.server.resourcemanager.ResourceManager$1.run(ResourceManager.java:1005)
	at org.apache.hadoop.yarn.server.resourcemanager.ResourceManager$1.run(ResourceManager.java:1001)
	at java.security.AccessController.doPrivileged(Native Method)
	at javax.security.auth.Subject.doAs(Subject.java:422)
	at org.apache.hadoop.security.UserGroupInformation.doAs(UserGroupInformation.java:1657)
	at org.apache.hadoop.yarn.server.resourcemanager.ResourceManager.transitionToActive(ResourceManager.java:1001)
	at org.apache.hadoop.yarn.server.resourcemanager.ResourceManager.serviceStart(ResourceManager.java:1041)
	at org.apache.hadoop.service.AbstractService.start(AbstractService.java:193)
	at org.apache.hadoop.yarn.server.resourcemanager.ResourceManager.main(ResourceManager.java:1178)
Caused by: java.net.BindException: Problem binding to [0.0.0.0:8031] java.net.BindException: Address already in use; For more details see:  http://wiki.apache.org/hadoop/BindException
	at sun.reflect.NativeConstructorAccessorImpl.newInstance0(Native Method)
	at sun.reflect.NativeConstructorAccessorImpl.newInstance(NativeConstructorAccessorImpl.java:62)
	at sun.reflect.DelegatingConstructorAccessorImpl.newInstance(DelegatingConstructorAccessorImpl.java:45)
	at java.lang.reflect.Constructor.newInstance(Constructor.java:423)
	at org.apache.hadoop.net.NetUtils.wrapWithMessage(NetUtils.java:792)
	at org.apache.hadoop.net.NetUtils.wrapException(NetUtils.java:721)
	at org.apache.hadoop.ipc.Server.bind(Server.java:425)
	at org.apache.hadoop.ipc.Server$Listener.<init>(Server.java:574)
	at org.apache.hadoop.ipc.Server.<init>(Server.java:2215)
	at org.apache.hadoop.ipc.RPC$Server.<init>(RPC.java:938)
	at org.apache.hadoop.ipc.ProtobufRpcEngine$Server.<init>(ProtobufRpcEngine.java:534)
	at org.apache.hadoop.ipc.ProtobufRpcEngine.getServer(ProtobufRpcEngine.java:509)
	at org.apache.hadoop.ipc.RPC$Builder.build(RPC.java:783)
	at org.apache.hadoop.yarn.factories.impl.pb.RpcServerFactoryPBImpl.createServer(RpcServerFactoryPBImpl.java:169)
	at org.apache.hadoop.yarn.factories.impl.pb.RpcServerFactoryPBImpl.getServer(RpcServerFactoryPBImpl.java:132)
	... 17 more
Caused by: java.net.BindException: Address already in use
	at sun.nio.ch.Net.bind0(Native Method)
	at sun.nio.ch.Net.bind(Net.java:433)
	at sun.nio.ch.Net.bind(Net.java:425)
	at sun.nio.ch.ServerSocketChannelImpl.bind(ServerSocketChannelImpl.java:223)
	at sun.nio.ch.ServerSocketAdaptor.bind(ServerSocketAdaptor.java:74)
	at org.apache.hadoop.ipc.Server.bind(Server.java:408)
	... 25 more
2016-03-19 19:51:11,353 INFO org.apache.hadoop.yarn.server.resourcemanager.ResourceManager: Transitioning to standby state
2016-03-19 19:51:11,353 INFO org.apache.hadoop.yarn.server.resourcemanager.ResourceManager: Transitioned to standby state
2016-03-19 19:51:11,353 FATAL org.apache.hadoop.yarn.server.resourcemanager.ResourceManager: Error starting ResourceManager
org.apache.hadoop.yarn.exceptions.YarnRuntimeException: java.net.BindException: Problem binding to [0.0.0.0:8031] java.net.BindException: Address already in use; For more details see:  http://wiki.apache.org/hadoop/BindException
	at org.apache.hadoop.yarn.factories.impl.pb.RpcServerFactoryPBImpl.getServer(RpcServerFactoryPBImpl.java:139)
	at org.apache.hadoop.yarn.ipc.HadoopYarnProtoRPC.getServer(HadoopYarnProtoRPC.java:65)
	at org.apache.hadoop.yarn.ipc.YarnRPC.getServer(YarnRPC.java:54)
	at org.apache.hadoop.yarn.server.resourcemanager.ResourceTrackerService.serviceStart(ResourceTrackerService.java:162)
	at org.apache.hadoop.service.AbstractService.start(AbstractService.java:193)
	at org.apache.hadoop.service.CompositeService.serviceStart(CompositeService.java:120)
	at org.apache.hadoop.yarn.server.resourcemanager.ResourceManager$RMActiveServices.serviceStart(ResourceManager.java:579)
	at org.apache.hadoop.service.AbstractService.start(AbstractService.java:193)
	at org.apache.hadoop.yarn.server.resourcemanager.ResourceManager.startActiveServices(ResourceManager.java:964)
	at org.apache.hadoop.yarn.server.resourcemanager.ResourceManager$1.run(ResourceManager.java:1005)
	at org.apache.hadoop.yarn.server.resourcemanager.ResourceManager$1.run(ResourceManager.java:1001)
	at java.security.AccessController.doPrivileged(Native Method)
	at javax.security.auth.Subject.doAs(Subject.java:422)
	at org.apache.hadoop.security.UserGroupInformation.doAs(UserGroupInformation.java:1657)
	at org.apache.hadoop.yarn.server.resourcemanager.ResourceManager.transitionToActive(ResourceManager.java:1001)
	at org.apache.hadoop.yarn.server.resourcemanager.ResourceManager.serviceStart(ResourceManager.java:1041)
	at org.apache.hadoop.service.AbstractService.start(AbstractService.java:193)
	at org.apache.hadoop.yarn.server.resourcemanager.ResourceManager.main(ResourceManager.java:1178)
Caused by: java.net.BindException: Problem binding to [0.0.0.0:8031] java.net.BindException: Address already in use; For more details see:  http://wiki.apache.org/hadoop/BindException
	at sun.reflect.NativeConstructorAccessorImpl.newInstance0(Native Method)
	at sun.reflect.NativeConstructorAccessorImpl.newInstance(NativeConstructorAccessorImpl.java:62)
	at sun.reflect.DelegatingConstructorAccessorImpl.newInstance(DelegatingConstructorAccessorImpl.java:45)
	at java.lang.reflect.Constructor.newInstance(Constructor.java:423)
	at org.apache.hadoop.net.NetUtils.wrapWithMessage(NetUtils.java:792)
	at org.apache.hadoop.net.NetUtils.wrapException(NetUtils.java:721)
	at org.apache.hadoop.ipc.Server.bind(Server.java:425)
	at org.apache.hadoop.ipc.Server$Listener.<init>(Server.java:574)
	at org.apache.hadoop.ipc.Server.<init>(Server.java:2215)
	at org.apache.hadoop.ipc.RPC$Server.<init>(RPC.java:938)
	at org.apache.hadoop.ipc.ProtobufRpcEngine$Server.<init>(ProtobufRpcEngine.java:534)
	at org.apache.hadoop.ipc.ProtobufRpcEngine.getServer(ProtobufRpcEngine.java:509)
	at org.apache.hadoop.ipc.RPC$Builder.build(RPC.java:783)
	at org.apache.hadoop.yarn.factories.impl.pb.RpcServerFactoryPBImpl.createServer(RpcServerFactoryPBImpl.java:169)
	at org.apache.hadoop.yarn.factories.impl.pb.RpcServerFactoryPBImpl.getServer(RpcServerFactoryPBImpl.java:132)
	... 17 more
Caused by: java.net.BindException: Address already in use
	at sun.nio.ch.Net.bind0(Native Method)
	at sun.nio.ch.Net.bind(Net.java:433)
	at sun.nio.ch.Net.bind(Net.java:425)
	at sun.nio.ch.ServerSocketChannelImpl.bind(ServerSocketChannelImpl.java:223)
	at sun.nio.ch.ServerSocketAdaptor.bind(ServerSocketAdaptor.java:74)
	at org.apache.hadoop.ipc.Server.bind(Server.java:408)
	... 25 more
2016-03-19 19:51:11,361 INFO org.apache.hadoop.yarn.server.resourcemanager.ResourceManager: SHUTDOWN_MSG: 
/************************************************************
SHUTDOWN_MSG: Shutting down ResourceManager at vishal-VirtualBox/127.0.1.1
************************************************************/
2016-03-19 19:52:01,670 INFO org.apache.hadoop.yarn.server.resourcemanager.ResourceManager: STARTUP_MSG: 
/************************************************************
STARTUP_MSG: Starting ResourceManager
STARTUP_MSG:   host = vishal-VirtualBox/127.0.1.1
STARTUP_MSG:   args = []
STARTUP_MSG:   version = 2.7.2
STARTUP_MSG:   build = https://git-wip-us.apache.org/repos/asf/hadoop.git -r b165c4fe8a74265c792ce23f546c64604acf0e41; compiled by 'jenkins' on 2016-01-26T00:08Z
STARTUP_MSG:   java = 1.8.0_74
************************************************************/
2016-03-19 19:52:01,699 INFO org.apache.hadoop.yarn.server.resourcemanager.ResourceManager: registered UNIX signal handlers for [TERM, HUP, INT]
2016-03-19 19:52:03,117 INFO org.apache.hadoop.conf.Configuration: found resource core-site.xml at file:/usr/local/hadoop/etc/hadoop/core-site.xml
2016-03-19 19:52:03,570 WARN org.apache.hadoop.util.NativeCodeLoader: Unable to load native-hadoop library for your platform... using builtin-java classes where applicable
2016-03-19 19:52:03,724 INFO org.apache.hadoop.security.Groups: clearing userToGroupsMap cache
2016-03-19 19:52:04,064 INFO org.apache.hadoop.conf.Configuration: found resource yarn-site.xml at file:/usr/local/hadoop/etc/hadoop/yarn-site.xml
2016-03-19 19:52:05,754 INFO org.apache.hadoop.yarn.event.AsyncDispatcher: Registering class org.apache.hadoop.yarn.server.resourcemanager.RMFatalEventType for class org.apache.hadoop.yarn.server.resourcemanager.ResourceManager$RMFatalEventDispatcher
2016-03-19 19:52:06,649 INFO org.apache.hadoop.yarn.server.resourcemanager.security.NMTokenSecretManagerInRM: NMTokenKeyRollingInterval: 86400000ms and NMTokenKeyActivationDelay: 900000ms
2016-03-19 19:52:06,673 INFO org.apache.hadoop.yarn.server.resourcemanager.security.RMContainerTokenSecretManager: ContainerTokenKeyRollingInterval: 86400000ms and ContainerTokenKeyActivationDelay: 900000ms
2016-03-19 19:52:06,697 INFO org.apache.hadoop.yarn.server.resourcemanager.security.AMRMTokenSecretManager: AMRMTokenKeyRollingInterval: 86400000ms and AMRMTokenKeyActivationDelay: 900000 ms
2016-03-19 19:52:06,888 INFO org.apache.hadoop.yarn.event.AsyncDispatcher: Registering class org.apache.hadoop.yarn.server.resourcemanager.recovery.RMStateStoreEventType for class org.apache.hadoop.yarn.server.resourcemanager.recovery.RMStateStore$ForwardingEventHandler
2016-03-19 19:52:06,903 INFO org.apache.hadoop.yarn.event.AsyncDispatcher: Registering class org.apache.hadoop.yarn.server.resourcemanager.NodesListManagerEventType for class org.apache.hadoop.yarn.server.resourcemanager.NodesListManager
2016-03-19 19:52:06,903 INFO org.apache.hadoop.yarn.server.resourcemanager.ResourceManager: Using Scheduler: org.apache.hadoop.yarn.server.resourcemanager.scheduler.capacity.CapacityScheduler
2016-03-19 19:52:07,017 INFO org.apache.hadoop.yarn.event.AsyncDispatcher: Registering class org.apache.hadoop.yarn.server.resourcemanager.scheduler.event.SchedulerEventType for class org.apache.hadoop.yarn.server.resourcemanager.ResourceManager$SchedulerEventDispatcher
2016-03-19 19:52:07,019 INFO org.apache.hadoop.yarn.event.AsyncDispatcher: Registering class org.apache.hadoop.yarn.server.resourcemanager.rmapp.RMAppEventType for class org.apache.hadoop.yarn.server.resourcemanager.ResourceManager$ApplicationEventDispatcher
2016-03-19 19:52:07,033 INFO org.apache.hadoop.yarn.event.AsyncDispatcher: Registering class org.apache.hadoop.yarn.server.resourcemanager.rmapp.attempt.RMAppAttemptEventType for class org.apache.hadoop.yarn.server.resourcemanager.ResourceManager$ApplicationAttemptEventDispatcher
2016-03-19 19:52:07,034 INFO org.apache.hadoop.yarn.event.AsyncDispatcher: Registering class org.apache.hadoop.yarn.server.resourcemanager.rmnode.RMNodeEventType for class org.apache.hadoop.yarn.server.resourcemanager.ResourceManager$NodeEventDispatcher
2016-03-19 19:52:07,418 INFO org.apache.hadoop.metrics2.impl.MetricsConfig: loaded properties from hadoop-metrics2.properties
2016-03-19 19:52:07,708 INFO org.apache.hadoop.metrics2.impl.MetricsSystemImpl: Scheduled snapshot period at 10 second(s).
2016-03-19 19:52:07,708 INFO org.apache.hadoop.metrics2.impl.MetricsSystemImpl: ResourceManager metrics system started
2016-03-19 19:52:07,752 INFO org.apache.hadoop.yarn.event.AsyncDispatcher: Registering class org.apache.hadoop.yarn.server.resourcemanager.RMAppManagerEventType for class org.apache.hadoop.yarn.server.resourcemanager.RMAppManager
2016-03-19 19:52:07,767 INFO org.apache.hadoop.yarn.event.AsyncDispatcher: Registering class org.apache.hadoop.yarn.server.resourcemanager.amlauncher.AMLauncherEventType for class org.apache.hadoop.yarn.server.resourcemanager.amlauncher.ApplicationMasterLauncher
2016-03-19 19:52:07,770 INFO org.apache.hadoop.yarn.server.resourcemanager.RMNMInfo: Registered RMNMInfo MBean
2016-03-19 19:52:07,772 INFO org.apache.hadoop.yarn.security.YarnAuthorizationProvider: org.apache.hadoop.yarn.security.ConfiguredYarnAuthorizer is instiantiated.
2016-03-19 19:52:07,780 INFO org.apache.hadoop.util.HostsFileReader: Refreshing hosts (include/exclude) list
2016-03-19 19:52:07,808 INFO org.apache.hadoop.conf.Configuration: found resource capacity-scheduler.xml at file:/usr/local/hadoop/etc/hadoop/capacity-scheduler.xml
2016-03-19 19:52:08,100 INFO org.apache.hadoop.yarn.server.resourcemanager.scheduler.capacity.CapacitySchedulerConfiguration: max alloc mb per queue for root is undefined
2016-03-19 19:52:08,100 INFO org.apache.hadoop.yarn.server.resourcemanager.scheduler.capacity.CapacitySchedulerConfiguration: max alloc vcore per queue for root is undefined
2016-03-19 19:52:08,115 INFO org.apache.hadoop.yarn.server.resourcemanager.scheduler.capacity.ParentQueue: root, capacity=1.0, asboluteCapacity=1.0, maxCapacity=1.0, asboluteMaxCapacity=1.0, state=RUNNING, acls=SUBMIT_APP:*ADMINISTER_QUEUE:*, labels=*,
, reservationsContinueLooking=true
2016-03-19 19:52:08,115 INFO org.apache.hadoop.yarn.server.resourcemanager.scheduler.capacity.ParentQueue: Initialized parent-queue root name=root, fullname=root
2016-03-19 19:52:08,150 INFO org.apache.hadoop.yarn.server.resourcemanager.scheduler.capacity.CapacitySchedulerConfiguration: max alloc mb per queue for root.default is undefined
2016-03-19 19:52:08,150 INFO org.apache.hadoop.yarn.server.resourcemanager.scheduler.capacity.CapacitySchedulerConfiguration: max alloc vcore per queue for root.default is undefined
2016-03-19 19:52:08,151 INFO org.apache.hadoop.yarn.server.resourcemanager.scheduler.capacity.LeafQueue: Initializing default
capacity = 1.0 [= (float) configuredCapacity / 100 ]
asboluteCapacity = 1.0 [= parentAbsoluteCapacity * capacity ]
maxCapacity = 1.0 [= configuredMaxCapacity ]
absoluteMaxCapacity = 1.0 [= 1.0 maximumCapacity undefined, (parentAbsoluteMaxCapacity * maximumCapacity) / 100 otherwise ]
userLimit = 100 [= configuredUserLimit ]
userLimitFactor = 1.0 [= configuredUserLimitFactor ]
maxApplications = 10000 [= configuredMaximumSystemApplicationsPerQueue or (int)(configuredMaximumSystemApplications * absoluteCapacity)]
maxApplicationsPerUser = 10000 [= (int)(maxApplications * (userLimit / 100.0f) * userLimitFactor) ]
usedCapacity = 0.0 [= usedResourcesMemory / (clusterResourceMemory * absoluteCapacity)]
absoluteUsedCapacity = 0.0 [= usedResourcesMemory / clusterResourceMemory]
maxAMResourcePerQueuePercent = 0.1 [= configuredMaximumAMResourcePercent ]
minimumAllocationFactor = 0.875 [= (float)(maximumAllocationMemory - minimumAllocationMemory) / maximumAllocationMemory ]
maximumAllocation = <memory:8192, vCores:32> [= configuredMaxAllocation ]
numContainers = 0 [= currentNumContainers ]
state = RUNNING [= configuredState ]
acls = SUBMIT_APP:*ADMINISTER_QUEUE:* [= configuredAcls ]
nodeLocalityDelay = 40
labels=*,
nodeLocalityDelay = 40
reservationsContinueLooking = true
preemptionDisabled = true

2016-03-19 19:52:08,152 INFO org.apache.hadoop.yarn.server.resourcemanager.scheduler.capacity.CapacityScheduler: Initialized queue: default: capacity=1.0, absoluteCapacity=1.0, usedResources=<memory:0, vCores:0>, usedCapacity=0.0, absoluteUsedCapacity=0.0, numApps=0, numContainers=0
2016-03-19 19:52:08,152 INFO org.apache.hadoop.yarn.server.resourcemanager.scheduler.capacity.CapacityScheduler: Initialized queue: root: numChildQueue= 1, capacity=1.0, absoluteCapacity=1.0, usedResources=<memory:0, vCores:0>usedCapacity=0.0, numApps=0, numContainers=0
2016-03-19 19:52:08,157 INFO org.apache.hadoop.yarn.server.resourcemanager.scheduler.capacity.CapacityScheduler: Initialized root queue root: numChildQueue= 1, capacity=1.0, absoluteCapacity=1.0, usedResources=<memory:0, vCores:0>usedCapacity=0.0, numApps=0, numContainers=0
2016-03-19 19:52:08,157 INFO org.apache.hadoop.yarn.server.resourcemanager.scheduler.capacity.CapacityScheduler: Initialized queue mappings, override: false
2016-03-19 19:52:08,157 INFO org.apache.hadoop.yarn.server.resourcemanager.scheduler.capacity.CapacityScheduler: Initialized CapacityScheduler with calculator=class org.apache.hadoop.yarn.util.resource.DefaultResourceCalculator, minimumAllocation=<<memory:1024, vCores:1>>, maximumAllocation=<<memory:8192, vCores:32>>, asynchronousScheduling=false, asyncScheduleInterval=5ms
2016-03-19 19:52:08,203 INFO org.apache.hadoop.yarn.server.resourcemanager.metrics.SystemMetricsPublisher: YARN system metrics publishing service is not enabled
2016-03-19 19:52:08,203 INFO org.apache.hadoop.yarn.server.resourcemanager.ResourceManager: Transitioning to active state
2016-03-19 19:52:08,264 INFO org.apache.hadoop.yarn.server.resourcemanager.recovery.RMStateStore: Updating AMRMToken
2016-03-19 19:52:08,268 INFO org.apache.hadoop.yarn.server.resourcemanager.security.RMContainerTokenSecretManager: Rolling master-key for container-tokens
2016-03-19 19:52:08,269 INFO org.apache.hadoop.yarn.server.resourcemanager.security.NMTokenSecretManagerInRM: Rolling master-key for nm-tokens
2016-03-19 19:52:08,269 INFO org.apache.hadoop.security.token.delegation.AbstractDelegationTokenSecretManager: Updating the current master key for generating delegation tokens
2016-03-19 19:52:08,272 INFO org.apache.hadoop.yarn.server.resourcemanager.security.RMDelegationTokenSecretManager: storing master key with keyID 1
2016-03-19 19:52:08,273 INFO org.apache.hadoop.yarn.server.resourcemanager.recovery.RMStateStore: Storing RMDTMasterKey.
2016-03-19 19:52:08,282 INFO org.apache.hadoop.security.token.delegation.AbstractDelegationTokenSecretManager: Starting expired delegation token remover thread, tokenRemoverScanInterval=60 min(s)
2016-03-19 19:52:08,291 INFO org.apache.hadoop.yarn.event.AsyncDispatcher: Registering class org.apache.hadoop.yarn.nodelabels.event.NodeLabelsStoreEventType for class org.apache.hadoop.yarn.nodelabels.CommonNodeLabelsManager$ForwardingEventHandler
2016-03-19 19:52:08,307 INFO org.apache.hadoop.security.token.delegation.AbstractDelegationTokenSecretManager: Updating the current master key for generating delegation tokens
2016-03-19 19:52:08,310 INFO org.apache.hadoop.yarn.server.resourcemanager.security.RMDelegationTokenSecretManager: storing master key with keyID 2
2016-03-19 19:52:08,310 INFO org.apache.hadoop.yarn.server.resourcemanager.recovery.RMStateStore: Storing RMDTMasterKey.
2016-03-19 19:52:08,398 INFO org.apache.hadoop.ipc.CallQueueManager: Using callQueue class java.util.concurrent.LinkedBlockingQueue
2016-03-19 19:52:08,444 INFO org.apache.hadoop.service.AbstractService: Service org.apache.hadoop.yarn.server.resourcemanager.ResourceTrackerService failed in state STARTED; cause: org.apache.hadoop.yarn.exceptions.YarnRuntimeException: java.net.BindException: Problem binding to [0.0.0.0:8031] java.net.BindException: Address already in use; For more details see:  http://wiki.apache.org/hadoop/BindException
org.apache.hadoop.yarn.exceptions.YarnRuntimeException: java.net.BindException: Problem binding to [0.0.0.0:8031] java.net.BindException: Address already in use; For more details see:  http://wiki.apache.org/hadoop/BindException
	at org.apache.hadoop.yarn.factories.impl.pb.RpcServerFactoryPBImpl.getServer(RpcServerFactoryPBImpl.java:139)
	at org.apache.hadoop.yarn.ipc.HadoopYarnProtoRPC.getServer(HadoopYarnProtoRPC.java:65)
	at org.apache.hadoop.yarn.ipc.YarnRPC.getServer(YarnRPC.java:54)
	at org.apache.hadoop.yarn.server.resourcemanager.ResourceTrackerService.serviceStart(ResourceTrackerService.java:162)
	at org.apache.hadoop.service.AbstractService.start(AbstractService.java:193)
	at org.apache.hadoop.service.CompositeService.serviceStart(CompositeService.java:120)
	at org.apache.hadoop.yarn.server.resourcemanager.ResourceManager$RMActiveServices.serviceStart(ResourceManager.java:579)
	at org.apache.hadoop.service.AbstractService.start(AbstractService.java:193)
	at org.apache.hadoop.yarn.server.resourcemanager.ResourceManager.startActiveServices(ResourceManager.java:964)
	at org.apache.hadoop.yarn.server.resourcemanager.ResourceManager$1.run(ResourceManager.java:1005)
	at org.apache.hadoop.yarn.server.resourcemanager.ResourceManager$1.run(ResourceManager.java:1001)
	at java.security.AccessController.doPrivileged(Native Method)
	at javax.security.auth.Subject.doAs(Subject.java:422)
	at org.apache.hadoop.security.UserGroupInformation.doAs(UserGroupInformation.java:1657)
	at org.apache.hadoop.yarn.server.resourcemanager.ResourceManager.transitionToActive(ResourceManager.java:1001)
	at org.apache.hadoop.yarn.server.resourcemanager.ResourceManager.serviceStart(ResourceManager.java:1041)
	at org.apache.hadoop.service.AbstractService.start(AbstractService.java:193)
	at org.apache.hadoop.yarn.server.resourcemanager.ResourceManager.main(ResourceManager.java:1178)
Caused by: java.net.BindException: Problem binding to [0.0.0.0:8031] java.net.BindException: Address already in use; For more details see:  http://wiki.apache.org/hadoop/BindException
	at sun.reflect.NativeConstructorAccessorImpl.newInstance0(Native Method)
	at sun.reflect.NativeConstructorAccessorImpl.newInstance(NativeConstructorAccessorImpl.java:62)
	at sun.reflect.DelegatingConstructorAccessorImpl.newInstance(DelegatingConstructorAccessorImpl.java:45)
	at java.lang.reflect.Constructor.newInstance(Constructor.java:423)
	at org.apache.hadoop.net.NetUtils.wrapWithMessage(NetUtils.java:792)
	at org.apache.hadoop.net.NetUtils.wrapException(NetUtils.java:721)
	at org.apache.hadoop.ipc.Server.bind(Server.java:425)
	at org.apache.hadoop.ipc.Server$Listener.<init>(Server.java:574)
	at org.apache.hadoop.ipc.Server.<init>(Server.java:2215)
	at org.apache.hadoop.ipc.RPC$Server.<init>(RPC.java:938)
	at org.apache.hadoop.ipc.ProtobufRpcEngine$Server.<init>(ProtobufRpcEngine.java:534)
	at org.apache.hadoop.ipc.ProtobufRpcEngine.getServer(ProtobufRpcEngine.java:509)
	at org.apache.hadoop.ipc.RPC$Builder.build(RPC.java:783)
	at org.apache.hadoop.yarn.factories.impl.pb.RpcServerFactoryPBImpl.createServer(RpcServerFactoryPBImpl.java:169)
	at org.apache.hadoop.yarn.factories.impl.pb.RpcServerFactoryPBImpl.getServer(RpcServerFactoryPBImpl.java:132)
	... 17 more
Caused by: java.net.BindException: Address already in use
	at sun.nio.ch.Net.bind0(Native Method)
	at sun.nio.ch.Net.bind(Net.java:433)
	at sun.nio.ch.Net.bind(Net.java:425)
	at sun.nio.ch.ServerSocketChannelImpl.bind(ServerSocketChannelImpl.java:223)
	at sun.nio.ch.ServerSocketAdaptor.bind(ServerSocketAdaptor.java:74)
	at org.apache.hadoop.ipc.Server.bind(Server.java:408)
	... 25 more
2016-03-19 19:52:08,457 INFO org.apache.hadoop.service.AbstractService: Service RMActiveServices failed in state STARTED; cause: org.apache.hadoop.yarn.exceptions.YarnRuntimeException: java.net.BindException: Problem binding to [0.0.0.0:8031] java.net.BindException: Address already in use; For more details see:  http://wiki.apache.org/hadoop/BindException
org.apache.hadoop.yarn.exceptions.YarnRuntimeException: java.net.BindException: Problem binding to [0.0.0.0:8031] java.net.BindException: Address already in use; For more details see:  http://wiki.apache.org/hadoop/BindException
	at org.apache.hadoop.yarn.factories.impl.pb.RpcServerFactoryPBImpl.getServer(RpcServerFactoryPBImpl.java:139)
	at org.apache.hadoop.yarn.ipc.HadoopYarnProtoRPC.getServer(HadoopYarnProtoRPC.java:65)
	at org.apache.hadoop.yarn.ipc.YarnRPC.getServer(YarnRPC.java:54)
	at org.apache.hadoop.yarn.server.resourcemanager.ResourceTrackerService.serviceStart(ResourceTrackerService.java:162)
	at org.apache.hadoop.service.AbstractService.start(AbstractService.java:193)
	at org.apache.hadoop.service.CompositeService.serviceStart(CompositeService.java:120)
	at org.apache.hadoop.yarn.server.resourcemanager.ResourceManager$RMActiveServices.serviceStart(ResourceManager.java:579)
	at org.apache.hadoop.service.AbstractService.start(AbstractService.java:193)
	at org.apache.hadoop.yarn.server.resourcemanager.ResourceManager.startActiveServices(ResourceManager.java:964)
	at org.apache.hadoop.yarn.server.resourcemanager.ResourceManager$1.run(ResourceManager.java:1005)
	at org.apache.hadoop.yarn.server.resourcemanager.ResourceManager$1.run(ResourceManager.java:1001)
	at java.security.AccessController.doPrivileged(Native Method)
	at javax.security.auth.Subject.doAs(Subject.java:422)
	at org.apache.hadoop.security.UserGroupInformation.doAs(UserGroupInformation.java:1657)
	at org.apache.hadoop.yarn.server.resourcemanager.ResourceManager.transitionToActive(ResourceManager.java:1001)
	at org.apache.hadoop.yarn.server.resourcemanager.ResourceManager.serviceStart(ResourceManager.java:1041)
	at org.apache.hadoop.service.AbstractService.start(AbstractService.java:193)
	at org.apache.hadoop.yarn.server.resourcemanager.ResourceManager.main(ResourceManager.java:1178)
Caused by: java.net.BindException: Problem binding to [0.0.0.0:8031] java.net.BindException: Address already in use; For more details see:  http://wiki.apache.org/hadoop/BindException
	at sun.reflect.NativeConstructorAccessorImpl.newInstance0(Native Method)
	at sun.reflect.NativeConstructorAccessorImpl.newInstance(NativeConstructorAccessorImpl.java:62)
	at sun.reflect.DelegatingConstructorAccessorImpl.newInstance(DelegatingConstructorAccessorImpl.java:45)
	at java.lang.reflect.Constructor.newInstance(Constructor.java:423)
	at org.apache.hadoop.net.NetUtils.wrapWithMessage(NetUtils.java:792)
	at org.apache.hadoop.net.NetUtils.wrapException(NetUtils.java:721)
	at org.apache.hadoop.ipc.Server.bind(Server.java:425)
	at org.apache.hadoop.ipc.Server$Listener.<init>(Server.java:574)
	at org.apache.hadoop.ipc.Server.<init>(Server.java:2215)
	at org.apache.hadoop.ipc.RPC$Server.<init>(RPC.java:938)
	at org.apache.hadoop.ipc.ProtobufRpcEngine$Server.<init>(ProtobufRpcEngine.java:534)
	at org.apache.hadoop.ipc.ProtobufRpcEngine.getServer(ProtobufRpcEngine.java:509)
	at org.apache.hadoop.ipc.RPC$Builder.build(RPC.java:783)
	at org.apache.hadoop.yarn.factories.impl.pb.RpcServerFactoryPBImpl.createServer(RpcServerFactoryPBImpl.java:169)
	at org.apache.hadoop.yarn.factories.impl.pb.RpcServerFactoryPBImpl.getServer(RpcServerFactoryPBImpl.java:132)
	... 17 more
Caused by: java.net.BindException: Address already in use
	at sun.nio.ch.Net.bind0(Native Method)
	at sun.nio.ch.Net.bind(Net.java:433)
	at sun.nio.ch.Net.bind(Net.java:425)
	at sun.nio.ch.ServerSocketChannelImpl.bind(ServerSocketChannelImpl.java:223)
	at sun.nio.ch.ServerSocketAdaptor.bind(ServerSocketAdaptor.java:74)
	at org.apache.hadoop.ipc.Server.bind(Server.java:408)
	... 25 more
2016-03-19 19:52:08,464 INFO org.apache.hadoop.yarn.util.AbstractLivelinessMonitor: NMLivelinessMonitor thread interrupted
2016-03-19 19:52:08,465 ERROR org.apache.hadoop.yarn.server.resourcemanager.ResourceManager: Returning, interrupted : java.lang.InterruptedException
2016-03-19 19:52:08,465 INFO org.apache.hadoop.yarn.event.AsyncDispatcher: AsyncDispatcher is draining to stop, igonring any new events.
2016-03-19 19:52:08,466 INFO org.apache.hadoop.yarn.util.AbstractLivelinessMonitor: AMLivelinessMonitor thread interrupted
2016-03-19 19:52:08,467 INFO org.apache.hadoop.yarn.util.AbstractLivelinessMonitor: AMLivelinessMonitor thread interrupted
2016-03-19 19:52:08,467 INFO org.apache.hadoop.yarn.util.AbstractLivelinessMonitor: org.apache.hadoop.yarn.server.resourcemanager.rmcontainer.ContainerAllocationExpirer thread interrupted
2016-03-19 19:52:08,472 ERROR org.apache.hadoop.security.token.delegation.AbstractDelegationTokenSecretManager: ExpiredTokenRemover received java.lang.InterruptedException: sleep interrupted
2016-03-19 19:52:08,472 INFO org.apache.hadoop.metrics2.impl.MetricsSystemImpl: Stopping ResourceManager metrics system...
2016-03-19 19:52:08,473 INFO org.apache.hadoop.metrics2.impl.MetricsSystemImpl: ResourceManager metrics system stopped.
2016-03-19 19:52:08,473 INFO org.apache.hadoop.metrics2.impl.MetricsSystemImpl: ResourceManager metrics system shutdown complete.
2016-03-19 19:52:08,473 INFO org.apache.hadoop.yarn.event.AsyncDispatcher: AsyncDispatcher is draining to stop, igonring any new events.
2016-03-19 19:52:08,478 INFO org.apache.hadoop.yarn.event.AsyncDispatcher: Registering class org.apache.hadoop.yarn.server.resourcemanager.RMFatalEventType for class org.apache.hadoop.yarn.server.resourcemanager.ResourceManager$RMFatalEventDispatcher
2016-03-19 19:52:08,480 INFO org.apache.hadoop.yarn.server.resourcemanager.security.NMTokenSecretManagerInRM: NMTokenKeyRollingInterval: 86400000ms and NMTokenKeyActivationDelay: 900000ms
2016-03-19 19:52:08,481 INFO org.apache.hadoop.yarn.server.resourcemanager.security.RMContainerTokenSecretManager: ContainerTokenKeyRollingInterval: 86400000ms and ContainerTokenKeyActivationDelay: 900000ms
2016-03-19 19:52:08,481 INFO org.apache.hadoop.yarn.server.resourcemanager.security.AMRMTokenSecretManager: AMRMTokenKeyRollingInterval: 86400000ms and AMRMTokenKeyActivationDelay: 900000 ms
2016-03-19 19:52:08,482 INFO org.apache.hadoop.yarn.event.AsyncDispatcher: Registering class org.apache.hadoop.yarn.server.resourcemanager.recovery.RMStateStoreEventType for class org.apache.hadoop.yarn.server.resourcemanager.recovery.RMStateStore$ForwardingEventHandler
2016-03-19 19:52:08,482 INFO org.apache.hadoop.yarn.event.AsyncDispatcher: Registering class org.apache.hadoop.yarn.server.resourcemanager.NodesListManagerEventType for class org.apache.hadoop.yarn.server.resourcemanager.NodesListManager
2016-03-19 19:52:08,482 INFO org.apache.hadoop.yarn.server.resourcemanager.ResourceManager: Using Scheduler: org.apache.hadoop.yarn.server.resourcemanager.scheduler.capacity.CapacityScheduler
2016-03-19 19:52:08,482 INFO org.apache.hadoop.yarn.event.AsyncDispatcher: Registering class org.apache.hadoop.yarn.server.resourcemanager.scheduler.event.SchedulerEventType for class org.apache.hadoop.yarn.server.resourcemanager.ResourceManager$SchedulerEventDispatcher
2016-03-19 19:52:08,482 INFO org.apache.hadoop.yarn.event.AsyncDispatcher: Registering class org.apache.hadoop.yarn.server.resourcemanager.rmapp.RMAppEventType for class org.apache.hadoop.yarn.server.resourcemanager.ResourceManager$ApplicationEventDispatcher
2016-03-19 19:52:08,482 INFO org.apache.hadoop.yarn.event.AsyncDispatcher: Registering class org.apache.hadoop.yarn.server.resourcemanager.rmapp.attempt.RMAppAttemptEventType for class org.apache.hadoop.yarn.server.resourcemanager.ResourceManager$ApplicationAttemptEventDispatcher
2016-03-19 19:52:08,482 INFO org.apache.hadoop.yarn.event.AsyncDispatcher: Registering class org.apache.hadoop.yarn.server.resourcemanager.rmnode.RMNodeEventType for class org.apache.hadoop.yarn.server.resourcemanager.ResourceManager$NodeEventDispatcher
2016-03-19 19:52:08,484 INFO org.apache.hadoop.metrics2.impl.MetricsConfig: loaded properties from hadoop-metrics2.properties
2016-03-19 19:52:08,514 INFO org.apache.hadoop.metrics2.impl.MetricsSystemImpl: Scheduled snapshot period at 10 second(s).
2016-03-19 19:52:08,514 INFO org.apache.hadoop.metrics2.impl.MetricsSystemImpl: ResourceManager metrics system started
2016-03-19 19:52:08,515 INFO org.apache.hadoop.yarn.event.AsyncDispatcher: Registering class org.apache.hadoop.yarn.server.resourcemanager.RMAppManagerEventType for class org.apache.hadoop.yarn.server.resourcemanager.RMAppManager
2016-03-19 19:52:08,515 INFO org.apache.hadoop.yarn.event.AsyncDispatcher: Registering class org.apache.hadoop.yarn.server.resourcemanager.amlauncher.AMLauncherEventType for class org.apache.hadoop.yarn.server.resourcemanager.amlauncher.ApplicationMasterLauncher
2016-03-19 19:52:08,515 WARN org.apache.hadoop.metrics2.util.MBeans: Failed to register MBean "Hadoop:service=ResourceManager,name=RMNMInfo": Instance already exists.
2016-03-19 19:52:08,515 INFO org.apache.hadoop.yarn.server.resourcemanager.RMNMInfo: Registered RMNMInfo MBean
2016-03-19 19:52:08,516 INFO org.apache.hadoop.util.HostsFileReader: Refreshing hosts (include/exclude) list
2016-03-19 19:52:08,529 INFO org.apache.hadoop.conf.Configuration: found resource capacity-scheduler.xml at file:/usr/local/hadoop/etc/hadoop/capacity-scheduler.xml
2016-03-19 19:52:08,694 INFO org.apache.hadoop.yarn.server.resourcemanager.scheduler.capacity.CapacitySchedulerConfiguration: max alloc mb per queue for root is undefined
2016-03-19 19:52:08,694 INFO org.apache.hadoop.yarn.server.resourcemanager.scheduler.capacity.CapacitySchedulerConfiguration: max alloc vcore per queue for root is undefined
2016-03-19 19:52:08,694 INFO org.apache.hadoop.yarn.server.resourcemanager.scheduler.capacity.ParentQueue: root, capacity=1.0, asboluteCapacity=1.0, maxCapacity=1.0, asboluteMaxCapacity=1.0, state=RUNNING, acls=SUBMIT_APP:*ADMINISTER_QUEUE:*, labels=*,
, reservationsContinueLooking=true
2016-03-19 19:52:08,694 INFO org.apache.hadoop.yarn.server.resourcemanager.scheduler.capacity.ParentQueue: Initialized parent-queue root name=root, fullname=root
2016-03-19 19:52:08,724 INFO org.apache.hadoop.yarn.server.resourcemanager.scheduler.capacity.CapacitySchedulerConfiguration: max alloc mb per queue for root.default is undefined
2016-03-19 19:52:08,724 INFO org.apache.hadoop.yarn.server.resourcemanager.scheduler.capacity.CapacitySchedulerConfiguration: max alloc vcore per queue for root.default is undefined
2016-03-19 19:52:08,725 INFO org.apache.hadoop.yarn.server.resourcemanager.scheduler.capacity.LeafQueue: Initializing default
capacity = 1.0 [= (float) configuredCapacity / 100 ]
asboluteCapacity = 1.0 [= parentAbsoluteCapacity * capacity ]
maxCapacity = 1.0 [= configuredMaxCapacity ]
absoluteMaxCapacity = 1.0 [= 1.0 maximumCapacity undefined, (parentAbsoluteMaxCapacity * maximumCapacity) / 100 otherwise ]
userLimit = 100 [= configuredUserLimit ]
userLimitFactor = 1.0 [= configuredUserLimitFactor ]
maxApplications = 10000 [= configuredMaximumSystemApplicationsPerQueue or (int)(configuredMaximumSystemApplications * absoluteCapacity)]
maxApplicationsPerUser = 10000 [= (int)(maxApplications * (userLimit / 100.0f) * userLimitFactor) ]
usedCapacity = 0.0 [= usedResourcesMemory / (clusterResourceMemory * absoluteCapacity)]
absoluteUsedCapacity = 0.0 [= usedResourcesMemory / clusterResourceMemory]
maxAMResourcePerQueuePercent = 0.1 [= configuredMaximumAMResourcePercent ]
minimumAllocationFactor = 0.875 [= (float)(maximumAllocationMemory - minimumAllocationMemory) / maximumAllocationMemory ]
maximumAllocation = <memory:8192, vCores:32> [= configuredMaxAllocation ]
numContainers = 0 [= currentNumContainers ]
state = RUNNING [= configuredState ]
acls = SUBMIT_APP:*ADMINISTER_QUEUE:* [= configuredAcls ]
nodeLocalityDelay = 40
labels=*,
nodeLocalityDelay = 40
reservationsContinueLooking = true
preemptionDisabled = true

2016-03-19 19:52:08,726 INFO org.apache.hadoop.yarn.server.resourcemanager.scheduler.capacity.CapacityScheduler: Initialized queue: default: capacity=1.0, absoluteCapacity=1.0, usedResources=<memory:0, vCores:0>, usedCapacity=0.0, absoluteUsedCapacity=0.0, numApps=0, numContainers=0
2016-03-19 19:52:08,726 INFO org.apache.hadoop.yarn.server.resourcemanager.scheduler.capacity.CapacityScheduler: Initialized queue: root: numChildQueue= 1, capacity=1.0, absoluteCapacity=1.0, usedResources=<memory:0, vCores:0>usedCapacity=0.0, numApps=0, numContainers=0
2016-03-19 19:52:08,726 INFO org.apache.hadoop.yarn.server.resourcemanager.scheduler.capacity.CapacityScheduler: Initialized root queue root: numChildQueue= 1, capacity=1.0, absoluteCapacity=1.0, usedResources=<memory:0, vCores:0>usedCapacity=0.0, numApps=0, numContainers=0
2016-03-19 19:52:08,726 INFO org.apache.hadoop.yarn.server.resourcemanager.scheduler.capacity.CapacityScheduler: Initialized queue mappings, override: false
2016-03-19 19:52:08,736 INFO org.apache.hadoop.yarn.server.resourcemanager.scheduler.capacity.CapacityScheduler: Initialized CapacityScheduler with calculator=class org.apache.hadoop.yarn.util.resource.DefaultResourceCalculator, minimumAllocation=<<memory:1024, vCores:1>>, maximumAllocation=<<memory:8192, vCores:32>>, asynchronousScheduling=false, asyncScheduleInterval=5ms
2016-03-19 19:52:08,740 INFO org.apache.hadoop.service.AbstractService: Service ResourceManager failed in state STARTED; cause: org.apache.hadoop.yarn.exceptions.YarnRuntimeException: java.net.BindException: Problem binding to [0.0.0.0:8031] java.net.BindException: Address already in use; For more details see:  http://wiki.apache.org/hadoop/BindException
org.apache.hadoop.yarn.exceptions.YarnRuntimeException: java.net.BindException: Problem binding to [0.0.0.0:8031] java.net.BindException: Address already in use; For more details see:  http://wiki.apache.org/hadoop/BindException
	at org.apache.hadoop.yarn.factories.impl.pb.RpcServerFactoryPBImpl.getServer(RpcServerFactoryPBImpl.java:139)
	at org.apache.hadoop.yarn.ipc.HadoopYarnProtoRPC.getServer(HadoopYarnProtoRPC.java:65)
	at org.apache.hadoop.yarn.ipc.YarnRPC.getServer(YarnRPC.java:54)
	at org.apache.hadoop.yarn.server.resourcemanager.ResourceTrackerService.serviceStart(ResourceTrackerService.java:162)
	at org.apache.hadoop.service.AbstractService.start(AbstractService.java:193)
	at org.apache.hadoop.service.CompositeService.serviceStart(CompositeService.java:120)
	at org.apache.hadoop.yarn.server.resourcemanager.ResourceManager$RMActiveServices.serviceStart(ResourceManager.java:579)
	at org.apache.hadoop.service.AbstractService.start(AbstractService.java:193)
	at org.apache.hadoop.yarn.server.resourcemanager.ResourceManager.startActiveServices(ResourceManager.java:964)
	at org.apache.hadoop.yarn.server.resourcemanager.ResourceManager$1.run(ResourceManager.java:1005)
	at org.apache.hadoop.yarn.server.resourcemanager.ResourceManager$1.run(ResourceManager.java:1001)
	at java.security.AccessController.doPrivileged(Native Method)
	at javax.security.auth.Subject.doAs(Subject.java:422)
	at org.apache.hadoop.security.UserGroupInformation.doAs(UserGroupInformation.java:1657)
	at org.apache.hadoop.yarn.server.resourcemanager.ResourceManager.transitionToActive(ResourceManager.java:1001)
	at org.apache.hadoop.yarn.server.resourcemanager.ResourceManager.serviceStart(ResourceManager.java:1041)
	at org.apache.hadoop.service.AbstractService.start(AbstractService.java:193)
	at org.apache.hadoop.yarn.server.resourcemanager.ResourceManager.main(ResourceManager.java:1178)
Caused by: java.net.BindException: Problem binding to [0.0.0.0:8031] java.net.BindException: Address already in use; For more details see:  http://wiki.apache.org/hadoop/BindException
	at sun.reflect.NativeConstructorAccessorImpl.newInstance0(Native Method)
	at sun.reflect.NativeConstructorAccessorImpl.newInstance(NativeConstructorAccessorImpl.java:62)
	at sun.reflect.DelegatingConstructorAccessorImpl.newInstance(DelegatingConstructorAccessorImpl.java:45)
	at java.lang.reflect.Constructor.newInstance(Constructor.java:423)
	at org.apache.hadoop.net.NetUtils.wrapWithMessage(NetUtils.java:792)
	at org.apache.hadoop.net.NetUtils.wrapException(NetUtils.java:721)
	at org.apache.hadoop.ipc.Server.bind(Server.java:425)
	at org.apache.hadoop.ipc.Server$Listener.<init>(Server.java:574)
	at org.apache.hadoop.ipc.Server.<init>(Server.java:2215)
	at org.apache.hadoop.ipc.RPC$Server.<init>(RPC.java:938)
	at org.apache.hadoop.ipc.ProtobufRpcEngine$Server.<init>(ProtobufRpcEngine.java:534)
	at org.apache.hadoop.ipc.ProtobufRpcEngine.getServer(ProtobufRpcEngine.java:509)
	at org.apache.hadoop.ipc.RPC$Builder.build(RPC.java:783)
	at org.apache.hadoop.yarn.factories.impl.pb.RpcServerFactoryPBImpl.createServer(RpcServerFactoryPBImpl.java:169)
	at org.apache.hadoop.yarn.factories.impl.pb.RpcServerFactoryPBImpl.getServer(RpcServerFactoryPBImpl.java:132)
	... 17 more
Caused by: java.net.BindException: Address already in use
	at sun.nio.ch.Net.bind0(Native Method)
	at sun.nio.ch.Net.bind(Net.java:433)
	at sun.nio.ch.Net.bind(Net.java:425)
	at sun.nio.ch.ServerSocketChannelImpl.bind(ServerSocketChannelImpl.java:223)
	at sun.nio.ch.ServerSocketAdaptor.bind(ServerSocketAdaptor.java:74)
	at org.apache.hadoop.ipc.Server.bind(Server.java:408)
	... 25 more
2016-03-19 19:52:08,751 INFO org.apache.hadoop.yarn.server.resourcemanager.ResourceManager: Transitioning to standby state
2016-03-19 19:52:08,752 INFO org.apache.hadoop.yarn.server.resourcemanager.ResourceManager: Transitioned to standby state
2016-03-19 19:52:08,752 FATAL org.apache.hadoop.yarn.server.resourcemanager.ResourceManager: Error starting ResourceManager
org.apache.hadoop.yarn.exceptions.YarnRuntimeException: java.net.BindException: Problem binding to [0.0.0.0:8031] java.net.BindException: Address already in use; For more details see:  http://wiki.apache.org/hadoop/BindException
	at org.apache.hadoop.yarn.factories.impl.pb.RpcServerFactoryPBImpl.getServer(RpcServerFactoryPBImpl.java:139)
	at org.apache.hadoop.yarn.ipc.HadoopYarnProtoRPC.getServer(HadoopYarnProtoRPC.java:65)
	at org.apache.hadoop.yarn.ipc.YarnRPC.getServer(YarnRPC.java:54)
	at org.apache.hadoop.yarn.server.resourcemanager.ResourceTrackerService.serviceStart(ResourceTrackerService.java:162)
	at org.apache.hadoop.service.AbstractService.start(AbstractService.java:193)
	at org.apache.hadoop.service.CompositeService.serviceStart(CompositeService.java:120)
	at org.apache.hadoop.yarn.server.resourcemanager.ResourceManager$RMActiveServices.serviceStart(ResourceManager.java:579)
	at org.apache.hadoop.service.AbstractService.start(AbstractService.java:193)
	at org.apache.hadoop.yarn.server.resourcemanager.ResourceManager.startActiveServices(ResourceManager.java:964)
	at org.apache.hadoop.yarn.server.resourcemanager.ResourceManager$1.run(ResourceManager.java:1005)
	at org.apache.hadoop.yarn.server.resourcemanager.ResourceManager$1.run(ResourceManager.java:1001)
	at java.security.AccessController.doPrivileged(Native Method)
	at javax.security.auth.Subject.doAs(Subject.java:422)
	at org.apache.hadoop.security.UserGroupInformation.doAs(UserGroupInformation.java:1657)
	at org.apache.hadoop.yarn.server.resourcemanager.ResourceManager.transitionToActive(ResourceManager.java:1001)
	at org.apache.hadoop.yarn.server.resourcemanager.ResourceManager.serviceStart(ResourceManager.java:1041)
	at org.apache.hadoop.service.AbstractService.start(AbstractService.java:193)
	at org.apache.hadoop.yarn.server.resourcemanager.ResourceManager.main(ResourceManager.java:1178)
Caused by: java.net.BindException: Problem binding to [0.0.0.0:8031] java.net.BindException: Address already in use; For more details see:  http://wiki.apache.org/hadoop/BindException
	at sun.reflect.NativeConstructorAccessorImpl.newInstance0(Native Method)
	at sun.reflect.NativeConstructorAccessorImpl.newInstance(NativeConstructorAccessorImpl.java:62)
	at sun.reflect.DelegatingConstructorAccessorImpl.newInstance(DelegatingConstructorAccessorImpl.java:45)
	at java.lang.reflect.Constructor.newInstance(Constructor.java:423)
	at org.apache.hadoop.net.NetUtils.wrapWithMessage(NetUtils.java:792)
	at org.apache.hadoop.net.NetUtils.wrapException(NetUtils.java:721)
	at org.apache.hadoop.ipc.Server.bind(Server.java:425)
	at org.apache.hadoop.ipc.Server$Listener.<init>(Server.java:574)
	at org.apache.hadoop.ipc.Server.<init>(Server.java:2215)
	at org.apache.hadoop.ipc.RPC$Server.<init>(RPC.java:938)
	at org.apache.hadoop.ipc.ProtobufRpcEngine$Server.<init>(ProtobufRpcEngine.java:534)
	at org.apache.hadoop.ipc.ProtobufRpcEngine.getServer(ProtobufRpcEngine.java:509)
	at org.apache.hadoop.ipc.RPC$Builder.build(RPC.java:783)
	at org.apache.hadoop.yarn.factories.impl.pb.RpcServerFactoryPBImpl.createServer(RpcServerFactoryPBImpl.java:169)
	at org.apache.hadoop.yarn.factories.impl.pb.RpcServerFactoryPBImpl.getServer(RpcServerFactoryPBImpl.java:132)
	... 17 more
Caused by: java.net.BindException: Address already in use
	at sun.nio.ch.Net.bind0(Native Method)
	at sun.nio.ch.Net.bind(Net.java:433)
	at sun.nio.ch.Net.bind(Net.java:425)
	at sun.nio.ch.ServerSocketChannelImpl.bind(ServerSocketChannelImpl.java:223)
	at sun.nio.ch.ServerSocketAdaptor.bind(ServerSocketAdaptor.java:74)
	at org.apache.hadoop.ipc.Server.bind(Server.java:408)
	... 25 more
2016-03-19 19:52:08,754 INFO org.apache.hadoop.yarn.server.resourcemanager.ResourceManager: SHUTDOWN_MSG: 
/************************************************************
SHUTDOWN_MSG: Shutting down ResourceManager at vishal-VirtualBox/127.0.1.1
************************************************************/
2016-03-19 19:54:19,287 INFO org.apache.hadoop.yarn.server.resourcemanager.ResourceManager: STARTUP_MSG: 
/************************************************************
STARTUP_MSG: Starting ResourceManager
STARTUP_MSG:   host = vishal-VirtualBox/127.0.1.1
STARTUP_MSG:   args = []
STARTUP_MSG:   version = 2.7.2
STARTUP_MSG:   build = https://git-wip-us.apache.org/repos/asf/hadoop.git -r b165c4fe8a74265c792ce23f546c64604acf0e41; compiled by 'jenkins' on 2016-01-26T00:08Z
STARTUP_MSG:   java = 1.8.0_74
************************************************************/
2016-03-19 19:54:19,373 INFO org.apache.hadoop.yarn.server.resourcemanager.ResourceManager: registered UNIX signal handlers for [TERM, HUP, INT]
2016-03-19 19:54:20,822 INFO org.apache.hadoop.conf.Configuration: found resource core-site.xml at file:/usr/local/hadoop/etc/hadoop/core-site.xml
2016-03-19 19:54:21,232 WARN org.apache.hadoop.util.NativeCodeLoader: Unable to load native-hadoop library for your platform... using builtin-java classes where applicable
2016-03-19 19:54:21,361 INFO org.apache.hadoop.security.Groups: clearing userToGroupsMap cache
2016-03-19 19:54:21,765 INFO org.apache.hadoop.conf.Configuration: found resource yarn-site.xml at file:/usr/local/hadoop/etc/hadoop/yarn-site.xml
2016-03-19 19:54:22,694 INFO org.apache.hadoop.yarn.event.AsyncDispatcher: Registering class org.apache.hadoop.yarn.server.resourcemanager.RMFatalEventType for class org.apache.hadoop.yarn.server.resourcemanager.ResourceManager$RMFatalEventDispatcher
2016-03-19 19:54:24,051 INFO org.apache.hadoop.yarn.server.resourcemanager.security.NMTokenSecretManagerInRM: NMTokenKeyRollingInterval: 86400000ms and NMTokenKeyActivationDelay: 900000ms
2016-03-19 19:54:24,116 INFO org.apache.hadoop.yarn.server.resourcemanager.security.RMContainerTokenSecretManager: ContainerTokenKeyRollingInterval: 86400000ms and ContainerTokenKeyActivationDelay: 900000ms
2016-03-19 19:54:24,163 INFO org.apache.hadoop.yarn.server.resourcemanager.security.AMRMTokenSecretManager: AMRMTokenKeyRollingInterval: 86400000ms and AMRMTokenKeyActivationDelay: 900000 ms
2016-03-19 19:54:24,735 INFO org.apache.hadoop.yarn.event.AsyncDispatcher: Registering class org.apache.hadoop.yarn.server.resourcemanager.recovery.RMStateStoreEventType for class org.apache.hadoop.yarn.server.resourcemanager.recovery.RMStateStore$ForwardingEventHandler
2016-03-19 19:54:24,737 INFO org.apache.hadoop.yarn.event.AsyncDispatcher: Registering class org.apache.hadoop.yarn.server.resourcemanager.NodesListManagerEventType for class org.apache.hadoop.yarn.server.resourcemanager.NodesListManager
2016-03-19 19:54:24,737 INFO org.apache.hadoop.yarn.server.resourcemanager.ResourceManager: Using Scheduler: org.apache.hadoop.yarn.server.resourcemanager.scheduler.capacity.CapacityScheduler
2016-03-19 19:54:24,973 INFO org.apache.hadoop.yarn.event.AsyncDispatcher: Registering class org.apache.hadoop.yarn.server.resourcemanager.scheduler.event.SchedulerEventType for class org.apache.hadoop.yarn.server.resourcemanager.ResourceManager$SchedulerEventDispatcher
2016-03-19 19:54:24,987 INFO org.apache.hadoop.yarn.event.AsyncDispatcher: Registering class org.apache.hadoop.yarn.server.resourcemanager.rmapp.RMAppEventType for class org.apache.hadoop.yarn.server.resourcemanager.ResourceManager$ApplicationEventDispatcher
2016-03-19 19:54:24,988 INFO org.apache.hadoop.yarn.event.AsyncDispatcher: Registering class org.apache.hadoop.yarn.server.resourcemanager.rmapp.attempt.RMAppAttemptEventType for class org.apache.hadoop.yarn.server.resourcemanager.ResourceManager$ApplicationAttemptEventDispatcher
2016-03-19 19:54:24,998 INFO org.apache.hadoop.yarn.event.AsyncDispatcher: Registering class org.apache.hadoop.yarn.server.resourcemanager.rmnode.RMNodeEventType for class org.apache.hadoop.yarn.server.resourcemanager.ResourceManager$NodeEventDispatcher
2016-03-19 19:54:25,333 INFO org.apache.hadoop.metrics2.impl.MetricsConfig: loaded properties from hadoop-metrics2.properties
2016-03-19 19:54:25,673 INFO org.apache.hadoop.metrics2.impl.MetricsSystemImpl: Scheduled snapshot period at 10 second(s).
2016-03-19 19:54:25,673 INFO org.apache.hadoop.metrics2.impl.MetricsSystemImpl: ResourceManager metrics system started
2016-03-19 19:54:25,726 INFO org.apache.hadoop.yarn.event.AsyncDispatcher: Registering class org.apache.hadoop.yarn.server.resourcemanager.RMAppManagerEventType for class org.apache.hadoop.yarn.server.resourcemanager.RMAppManager
2016-03-19 19:54:25,746 INFO org.apache.hadoop.yarn.event.AsyncDispatcher: Registering class org.apache.hadoop.yarn.server.resourcemanager.amlauncher.AMLauncherEventType for class org.apache.hadoop.yarn.server.resourcemanager.amlauncher.ApplicationMasterLauncher
2016-03-19 19:54:25,749 INFO org.apache.hadoop.yarn.server.resourcemanager.RMNMInfo: Registered RMNMInfo MBean
2016-03-19 19:54:25,751 INFO org.apache.hadoop.yarn.security.YarnAuthorizationProvider: org.apache.hadoop.yarn.security.ConfiguredYarnAuthorizer is instiantiated.
2016-03-19 19:54:25,757 INFO org.apache.hadoop.util.HostsFileReader: Refreshing hosts (include/exclude) list
2016-03-19 19:54:25,793 INFO org.apache.hadoop.conf.Configuration: found resource capacity-scheduler.xml at file:/usr/local/hadoop/etc/hadoop/capacity-scheduler.xml
2016-03-19 19:54:26,115 INFO org.apache.hadoop.yarn.server.resourcemanager.scheduler.capacity.CapacitySchedulerConfiguration: max alloc mb per queue for root is undefined
2016-03-19 19:54:26,115 INFO org.apache.hadoop.yarn.server.resourcemanager.scheduler.capacity.CapacitySchedulerConfiguration: max alloc vcore per queue for root is undefined
2016-03-19 19:54:26,136 INFO org.apache.hadoop.yarn.server.resourcemanager.scheduler.capacity.ParentQueue: root, capacity=1.0, asboluteCapacity=1.0, maxCapacity=1.0, asboluteMaxCapacity=1.0, state=RUNNING, acls=SUBMIT_APP:*ADMINISTER_QUEUE:*, labels=*,
, reservationsContinueLooking=true
2016-03-19 19:54:26,136 INFO org.apache.hadoop.yarn.server.resourcemanager.scheduler.capacity.ParentQueue: Initialized parent-queue root name=root, fullname=root
2016-03-19 19:54:26,167 INFO org.apache.hadoop.yarn.server.resourcemanager.scheduler.capacity.CapacitySchedulerConfiguration: max alloc mb per queue for root.default is undefined
2016-03-19 19:54:26,167 INFO org.apache.hadoop.yarn.server.resourcemanager.scheduler.capacity.CapacitySchedulerConfiguration: max alloc vcore per queue for root.default is undefined
2016-03-19 19:54:26,168 INFO org.apache.hadoop.yarn.server.resourcemanager.scheduler.capacity.LeafQueue: Initializing default
capacity = 1.0 [= (float) configuredCapacity / 100 ]
asboluteCapacity = 1.0 [= parentAbsoluteCapacity * capacity ]
maxCapacity = 1.0 [= configuredMaxCapacity ]
absoluteMaxCapacity = 1.0 [= 1.0 maximumCapacity undefined, (parentAbsoluteMaxCapacity * maximumCapacity) / 100 otherwise ]
userLimit = 100 [= configuredUserLimit ]
userLimitFactor = 1.0 [= configuredUserLimitFactor ]
maxApplications = 10000 [= configuredMaximumSystemApplicationsPerQueue or (int)(configuredMaximumSystemApplications * absoluteCapacity)]
maxApplicationsPerUser = 10000 [= (int)(maxApplications * (userLimit / 100.0f) * userLimitFactor) ]
usedCapacity = 0.0 [= usedResourcesMemory / (clusterResourceMemory * absoluteCapacity)]
absoluteUsedCapacity = 0.0 [= usedResourcesMemory / clusterResourceMemory]
maxAMResourcePerQueuePercent = 0.1 [= configuredMaximumAMResourcePercent ]
minimumAllocationFactor = 0.875 [= (float)(maximumAllocationMemory - minimumAllocationMemory) / maximumAllocationMemory ]
maximumAllocation = <memory:8192, vCores:32> [= configuredMaxAllocation ]
numContainers = 0 [= currentNumContainers ]
state = RUNNING [= configuredState ]
acls = SUBMIT_APP:*ADMINISTER_QUEUE:* [= configuredAcls ]
nodeLocalityDelay = 40
labels=*,
nodeLocalityDelay = 40
reservationsContinueLooking = true
preemptionDisabled = true

2016-03-19 19:54:26,169 INFO org.apache.hadoop.yarn.server.resourcemanager.scheduler.capacity.CapacityScheduler: Initialized queue: default: capacity=1.0, absoluteCapacity=1.0, usedResources=<memory:0, vCores:0>, usedCapacity=0.0, absoluteUsedCapacity=0.0, numApps=0, numContainers=0
2016-03-19 19:54:26,169 INFO org.apache.hadoop.yarn.server.resourcemanager.scheduler.capacity.CapacityScheduler: Initialized queue: root: numChildQueue= 1, capacity=1.0, absoluteCapacity=1.0, usedResources=<memory:0, vCores:0>usedCapacity=0.0, numApps=0, numContainers=0
2016-03-19 19:54:26,169 INFO org.apache.hadoop.yarn.server.resourcemanager.scheduler.capacity.CapacityScheduler: Initialized root queue root: numChildQueue= 1, capacity=1.0, absoluteCapacity=1.0, usedResources=<memory:0, vCores:0>usedCapacity=0.0, numApps=0, numContainers=0
2016-03-19 19:54:26,170 INFO org.apache.hadoop.yarn.server.resourcemanager.scheduler.capacity.CapacityScheduler: Initialized queue mappings, override: false
2016-03-19 19:54:26,170 INFO org.apache.hadoop.yarn.server.resourcemanager.scheduler.capacity.CapacityScheduler: Initialized CapacityScheduler with calculator=class org.apache.hadoop.yarn.util.resource.DefaultResourceCalculator, minimumAllocation=<<memory:1024, vCores:1>>, maximumAllocation=<<memory:8192, vCores:32>>, asynchronousScheduling=false, asyncScheduleInterval=5ms
2016-03-19 19:54:26,228 INFO org.apache.hadoop.yarn.server.resourcemanager.metrics.SystemMetricsPublisher: YARN system metrics publishing service is not enabled
2016-03-19 19:54:26,228 INFO org.apache.hadoop.yarn.server.resourcemanager.ResourceManager: Transitioning to active state
2016-03-19 19:54:26,304 INFO org.apache.hadoop.yarn.server.resourcemanager.recovery.RMStateStore: Updating AMRMToken
2016-03-19 19:54:26,307 INFO org.apache.hadoop.yarn.server.resourcemanager.security.RMContainerTokenSecretManager: Rolling master-key for container-tokens
2016-03-19 19:54:26,307 INFO org.apache.hadoop.yarn.server.resourcemanager.security.NMTokenSecretManagerInRM: Rolling master-key for nm-tokens
2016-03-19 19:54:26,307 INFO org.apache.hadoop.security.token.delegation.AbstractDelegationTokenSecretManager: Updating the current master key for generating delegation tokens
2016-03-19 19:54:26,313 INFO org.apache.hadoop.yarn.server.resourcemanager.security.RMDelegationTokenSecretManager: storing master key with keyID 1
2016-03-19 19:54:26,313 INFO org.apache.hadoop.yarn.server.resourcemanager.recovery.RMStateStore: Storing RMDTMasterKey.
2016-03-19 19:54:26,320 INFO org.apache.hadoop.security.token.delegation.AbstractDelegationTokenSecretManager: Starting expired delegation token remover thread, tokenRemoverScanInterval=60 min(s)
2016-03-19 19:54:26,328 INFO org.apache.hadoop.security.token.delegation.AbstractDelegationTokenSecretManager: Updating the current master key for generating delegation tokens
2016-03-19 19:54:26,329 INFO org.apache.hadoop.yarn.event.AsyncDispatcher: Registering class org.apache.hadoop.yarn.nodelabels.event.NodeLabelsStoreEventType for class org.apache.hadoop.yarn.nodelabels.CommonNodeLabelsManager$ForwardingEventHandler
2016-03-19 19:54:26,345 INFO org.apache.hadoop.yarn.server.resourcemanager.security.RMDelegationTokenSecretManager: storing master key with keyID 2
2016-03-19 19:54:26,345 INFO org.apache.hadoop.yarn.server.resourcemanager.recovery.RMStateStore: Storing RMDTMasterKey.
2016-03-19 19:54:26,527 INFO org.apache.hadoop.ipc.CallQueueManager: Using callQueue class java.util.concurrent.LinkedBlockingQueue
2016-03-19 19:54:26,575 INFO org.apache.hadoop.service.AbstractService: Service org.apache.hadoop.yarn.server.resourcemanager.ResourceTrackerService failed in state STARTED; cause: org.apache.hadoop.yarn.exceptions.YarnRuntimeException: java.net.BindException: Problem binding to [0.0.0.0:8031] java.net.BindException: Address already in use; For more details see:  http://wiki.apache.org/hadoop/BindException
org.apache.hadoop.yarn.exceptions.YarnRuntimeException: java.net.BindException: Problem binding to [0.0.0.0:8031] java.net.BindException: Address already in use; For more details see:  http://wiki.apache.org/hadoop/BindException
	at org.apache.hadoop.yarn.factories.impl.pb.RpcServerFactoryPBImpl.getServer(RpcServerFactoryPBImpl.java:139)
	at org.apache.hadoop.yarn.ipc.HadoopYarnProtoRPC.getServer(HadoopYarnProtoRPC.java:65)
	at org.apache.hadoop.yarn.ipc.YarnRPC.getServer(YarnRPC.java:54)
	at org.apache.hadoop.yarn.server.resourcemanager.ResourceTrackerService.serviceStart(ResourceTrackerService.java:162)
	at org.apache.hadoop.service.AbstractService.start(AbstractService.java:193)
	at org.apache.hadoop.service.CompositeService.serviceStart(CompositeService.java:120)
	at org.apache.hadoop.yarn.server.resourcemanager.ResourceManager$RMActiveServices.serviceStart(ResourceManager.java:579)
	at org.apache.hadoop.service.AbstractService.start(AbstractService.java:193)
	at org.apache.hadoop.yarn.server.resourcemanager.ResourceManager.startActiveServices(ResourceManager.java:964)
	at org.apache.hadoop.yarn.server.resourcemanager.ResourceManager$1.run(ResourceManager.java:1005)
	at org.apache.hadoop.yarn.server.resourcemanager.ResourceManager$1.run(ResourceManager.java:1001)
	at java.security.AccessController.doPrivileged(Native Method)
	at javax.security.auth.Subject.doAs(Subject.java:422)
	at org.apache.hadoop.security.UserGroupInformation.doAs(UserGroupInformation.java:1657)
	at org.apache.hadoop.yarn.server.resourcemanager.ResourceManager.transitionToActive(ResourceManager.java:1001)
	at org.apache.hadoop.yarn.server.resourcemanager.ResourceManager.serviceStart(ResourceManager.java:1041)
	at org.apache.hadoop.service.AbstractService.start(AbstractService.java:193)
	at org.apache.hadoop.yarn.server.resourcemanager.ResourceManager.main(ResourceManager.java:1178)
Caused by: java.net.BindException: Problem binding to [0.0.0.0:8031] java.net.BindException: Address already in use; For more details see:  http://wiki.apache.org/hadoop/BindException
	at sun.reflect.NativeConstructorAccessorImpl.newInstance0(Native Method)
	at sun.reflect.NativeConstructorAccessorImpl.newInstance(NativeConstructorAccessorImpl.java:62)
	at sun.reflect.DelegatingConstructorAccessorImpl.newInstance(DelegatingConstructorAccessorImpl.java:45)
	at java.lang.reflect.Constructor.newInstance(Constructor.java:423)
	at org.apache.hadoop.net.NetUtils.wrapWithMessage(NetUtils.java:792)
	at org.apache.hadoop.net.NetUtils.wrapException(NetUtils.java:721)
	at org.apache.hadoop.ipc.Server.bind(Server.java:425)
	at org.apache.hadoop.ipc.Server$Listener.<init>(Server.java:574)
	at org.apache.hadoop.ipc.Server.<init>(Server.java:2215)
	at org.apache.hadoop.ipc.RPC$Server.<init>(RPC.java:938)
	at org.apache.hadoop.ipc.ProtobufRpcEngine$Server.<init>(ProtobufRpcEngine.java:534)
	at org.apache.hadoop.ipc.ProtobufRpcEngine.getServer(ProtobufRpcEngine.java:509)
	at org.apache.hadoop.ipc.RPC$Builder.build(RPC.java:783)
	at org.apache.hadoop.yarn.factories.impl.pb.RpcServerFactoryPBImpl.createServer(RpcServerFactoryPBImpl.java:169)
	at org.apache.hadoop.yarn.factories.impl.pb.RpcServerFactoryPBImpl.getServer(RpcServerFactoryPBImpl.java:132)
	... 17 more
Caused by: java.net.BindException: Address already in use
	at sun.nio.ch.Net.bind0(Native Method)
	at sun.nio.ch.Net.bind(Net.java:433)
	at sun.nio.ch.Net.bind(Net.java:425)
	at sun.nio.ch.ServerSocketChannelImpl.bind(ServerSocketChannelImpl.java:223)
	at sun.nio.ch.ServerSocketAdaptor.bind(ServerSocketAdaptor.java:74)
	at org.apache.hadoop.ipc.Server.bind(Server.java:408)
	... 25 more
2016-03-19 19:54:26,593 INFO org.apache.hadoop.service.AbstractService: Service RMActiveServices failed in state STARTED; cause: org.apache.hadoop.yarn.exceptions.YarnRuntimeException: java.net.BindException: Problem binding to [0.0.0.0:8031] java.net.BindException: Address already in use; For more details see:  http://wiki.apache.org/hadoop/BindException
org.apache.hadoop.yarn.exceptions.YarnRuntimeException: java.net.BindException: Problem binding to [0.0.0.0:8031] java.net.BindException: Address already in use; For more details see:  http://wiki.apache.org/hadoop/BindException
	at org.apache.hadoop.yarn.factories.impl.pb.RpcServerFactoryPBImpl.getServer(RpcServerFactoryPBImpl.java:139)
	at org.apache.hadoop.yarn.ipc.HadoopYarnProtoRPC.getServer(HadoopYarnProtoRPC.java:65)
	at org.apache.hadoop.yarn.ipc.YarnRPC.getServer(YarnRPC.java:54)
	at org.apache.hadoop.yarn.server.resourcemanager.ResourceTrackerService.serviceStart(ResourceTrackerService.java:162)
	at org.apache.hadoop.service.AbstractService.start(AbstractService.java:193)
	at org.apache.hadoop.service.CompositeService.serviceStart(CompositeService.java:120)
	at org.apache.hadoop.yarn.server.resourcemanager.ResourceManager$RMActiveServices.serviceStart(ResourceManager.java:579)
	at org.apache.hadoop.service.AbstractService.start(AbstractService.java:193)
	at org.apache.hadoop.yarn.server.resourcemanager.ResourceManager.startActiveServices(ResourceManager.java:964)
	at org.apache.hadoop.yarn.server.resourcemanager.ResourceManager$1.run(ResourceManager.java:1005)
	at org.apache.hadoop.yarn.server.resourcemanager.ResourceManager$1.run(ResourceManager.java:1001)
	at java.security.AccessController.doPrivileged(Native Method)
	at javax.security.auth.Subject.doAs(Subject.java:422)
	at org.apache.hadoop.security.UserGroupInformation.doAs(UserGroupInformation.java:1657)
	at org.apache.hadoop.yarn.server.resourcemanager.ResourceManager.transitionToActive(ResourceManager.java:1001)
	at org.apache.hadoop.yarn.server.resourcemanager.ResourceManager.serviceStart(ResourceManager.java:1041)
	at org.apache.hadoop.service.AbstractService.start(AbstractService.java:193)
	at org.apache.hadoop.yarn.server.resourcemanager.ResourceManager.main(ResourceManager.java:1178)
Caused by: java.net.BindException: Problem binding to [0.0.0.0:8031] java.net.BindException: Address already in use; For more details see:  http://wiki.apache.org/hadoop/BindException
	at sun.reflect.NativeConstructorAccessorImpl.newInstance0(Native Method)
	at sun.reflect.NativeConstructorAccessorImpl.newInstance(NativeConstructorAccessorImpl.java:62)
	at sun.reflect.DelegatingConstructorAccessorImpl.newInstance(DelegatingConstructorAccessorImpl.java:45)
	at java.lang.reflect.Constructor.newInstance(Constructor.java:423)
	at org.apache.hadoop.net.NetUtils.wrapWithMessage(NetUtils.java:792)
	at org.apache.hadoop.net.NetUtils.wrapException(NetUtils.java:721)
	at org.apache.hadoop.ipc.Server.bind(Server.java:425)
	at org.apache.hadoop.ipc.Server$Listener.<init>(Server.java:574)
	at org.apache.hadoop.ipc.Server.<init>(Server.java:2215)
	at org.apache.hadoop.ipc.RPC$Server.<init>(RPC.java:938)
	at org.apache.hadoop.ipc.ProtobufRpcEngine$Server.<init>(ProtobufRpcEngine.java:534)
	at org.apache.hadoop.ipc.ProtobufRpcEngine.getServer(ProtobufRpcEngine.java:509)
	at org.apache.hadoop.ipc.RPC$Builder.build(RPC.java:783)
	at org.apache.hadoop.yarn.factories.impl.pb.RpcServerFactoryPBImpl.createServer(RpcServerFactoryPBImpl.java:169)
	at org.apache.hadoop.yarn.factories.impl.pb.RpcServerFactoryPBImpl.getServer(RpcServerFactoryPBImpl.java:132)
	... 17 more
Caused by: java.net.BindException: Address already in use
	at sun.nio.ch.Net.bind0(Native Method)
	at sun.nio.ch.Net.bind(Net.java:433)
	at sun.nio.ch.Net.bind(Net.java:425)
	at sun.nio.ch.ServerSocketChannelImpl.bind(ServerSocketChannelImpl.java:223)
	at sun.nio.ch.ServerSocketAdaptor.bind(ServerSocketAdaptor.java:74)
	at org.apache.hadoop.ipc.Server.bind(Server.java:408)
	... 25 more
2016-03-19 19:54:26,601 INFO org.apache.hadoop.yarn.util.AbstractLivelinessMonitor: NMLivelinessMonitor thread interrupted
2016-03-19 19:54:26,601 ERROR org.apache.hadoop.yarn.server.resourcemanager.ResourceManager: Returning, interrupted : java.lang.InterruptedException
2016-03-19 19:54:26,601 INFO org.apache.hadoop.yarn.event.AsyncDispatcher: AsyncDispatcher is draining to stop, igonring any new events.
2016-03-19 19:54:26,602 INFO org.apache.hadoop.yarn.util.AbstractLivelinessMonitor: AMLivelinessMonitor thread interrupted
2016-03-19 19:54:26,602 INFO org.apache.hadoop.yarn.util.AbstractLivelinessMonitor: AMLivelinessMonitor thread interrupted
2016-03-19 19:54:26,602 INFO org.apache.hadoop.yarn.util.AbstractLivelinessMonitor: org.apache.hadoop.yarn.server.resourcemanager.rmcontainer.ContainerAllocationExpirer thread interrupted
2016-03-19 19:54:26,602 ERROR org.apache.hadoop.security.token.delegation.AbstractDelegationTokenSecretManager: ExpiredTokenRemover received java.lang.InterruptedException: sleep interrupted
2016-03-19 19:54:26,603 INFO org.apache.hadoop.metrics2.impl.MetricsSystemImpl: Stopping ResourceManager metrics system...
2016-03-19 19:54:26,603 INFO org.apache.hadoop.metrics2.impl.MetricsSystemImpl: ResourceManager metrics system stopped.
2016-03-19 19:54:26,604 INFO org.apache.hadoop.metrics2.impl.MetricsSystemImpl: ResourceManager metrics system shutdown complete.
2016-03-19 19:54:26,604 INFO org.apache.hadoop.yarn.event.AsyncDispatcher: AsyncDispatcher is draining to stop, igonring any new events.
2016-03-19 19:54:26,604 INFO org.apache.hadoop.yarn.event.AsyncDispatcher: Registering class org.apache.hadoop.yarn.server.resourcemanager.RMFatalEventType for class org.apache.hadoop.yarn.server.resourcemanager.ResourceManager$RMFatalEventDispatcher
2016-03-19 19:54:26,610 INFO org.apache.hadoop.yarn.server.resourcemanager.security.NMTokenSecretManagerInRM: NMTokenKeyRollingInterval: 86400000ms and NMTokenKeyActivationDelay: 900000ms
2016-03-19 19:54:26,616 INFO org.apache.hadoop.yarn.server.resourcemanager.security.RMContainerTokenSecretManager: ContainerTokenKeyRollingInterval: 86400000ms and ContainerTokenKeyActivationDelay: 900000ms
2016-03-19 19:54:26,617 INFO org.apache.hadoop.yarn.server.resourcemanager.security.AMRMTokenSecretManager: AMRMTokenKeyRollingInterval: 86400000ms and AMRMTokenKeyActivationDelay: 900000 ms
2016-03-19 19:54:26,617 INFO org.apache.hadoop.yarn.event.AsyncDispatcher: Registering class org.apache.hadoop.yarn.server.resourcemanager.recovery.RMStateStoreEventType for class org.apache.hadoop.yarn.server.resourcemanager.recovery.RMStateStore$ForwardingEventHandler
2016-03-19 19:54:26,617 INFO org.apache.hadoop.yarn.event.AsyncDispatcher: Registering class org.apache.hadoop.yarn.server.resourcemanager.NodesListManagerEventType for class org.apache.hadoop.yarn.server.resourcemanager.NodesListManager
2016-03-19 19:54:26,617 INFO org.apache.hadoop.yarn.server.resourcemanager.ResourceManager: Using Scheduler: org.apache.hadoop.yarn.server.resourcemanager.scheduler.capacity.CapacityScheduler
2016-03-19 19:54:26,617 INFO org.apache.hadoop.yarn.event.AsyncDispatcher: Registering class org.apache.hadoop.yarn.server.resourcemanager.scheduler.event.SchedulerEventType for class org.apache.hadoop.yarn.server.resourcemanager.ResourceManager$SchedulerEventDispatcher
2016-03-19 19:54:26,617 INFO org.apache.hadoop.yarn.event.AsyncDispatcher: Registering class org.apache.hadoop.yarn.server.resourcemanager.rmapp.RMAppEventType for class org.apache.hadoop.yarn.server.resourcemanager.ResourceManager$ApplicationEventDispatcher
2016-03-19 19:54:26,617 INFO org.apache.hadoop.yarn.event.AsyncDispatcher: Registering class org.apache.hadoop.yarn.server.resourcemanager.rmapp.attempt.RMAppAttemptEventType for class org.apache.hadoop.yarn.server.resourcemanager.ResourceManager$ApplicationAttemptEventDispatcher
2016-03-19 19:54:26,617 INFO org.apache.hadoop.yarn.event.AsyncDispatcher: Registering class org.apache.hadoop.yarn.server.resourcemanager.rmnode.RMNodeEventType for class org.apache.hadoop.yarn.server.resourcemanager.ResourceManager$NodeEventDispatcher
2016-03-19 19:54:26,631 INFO org.apache.hadoop.metrics2.impl.MetricsConfig: loaded properties from hadoop-metrics2.properties
2016-03-19 19:54:26,637 INFO org.apache.hadoop.metrics2.impl.MetricsSystemImpl: Scheduled snapshot period at 10 second(s).
2016-03-19 19:54:26,638 INFO org.apache.hadoop.metrics2.impl.MetricsSystemImpl: ResourceManager metrics system started
2016-03-19 19:54:26,638 INFO org.apache.hadoop.yarn.event.AsyncDispatcher: Registering class org.apache.hadoop.yarn.server.resourcemanager.RMAppManagerEventType for class org.apache.hadoop.yarn.server.resourcemanager.RMAppManager
2016-03-19 19:54:26,639 INFO org.apache.hadoop.yarn.event.AsyncDispatcher: Registering class org.apache.hadoop.yarn.server.resourcemanager.amlauncher.AMLauncherEventType for class org.apache.hadoop.yarn.server.resourcemanager.amlauncher.ApplicationMasterLauncher
2016-03-19 19:54:26,639 WARN org.apache.hadoop.metrics2.util.MBeans: Failed to register MBean "Hadoop:service=ResourceManager,name=RMNMInfo": Instance already exists.
2016-03-19 19:54:26,639 INFO org.apache.hadoop.yarn.server.resourcemanager.RMNMInfo: Registered RMNMInfo MBean
2016-03-19 19:54:26,639 INFO org.apache.hadoop.util.HostsFileReader: Refreshing hosts (include/exclude) list
2016-03-19 19:54:26,651 INFO org.apache.hadoop.conf.Configuration: found resource capacity-scheduler.xml at file:/usr/local/hadoop/etc/hadoop/capacity-scheduler.xml
2016-03-19 19:54:26,803 INFO org.apache.hadoop.yarn.server.resourcemanager.scheduler.capacity.CapacitySchedulerConfiguration: max alloc mb per queue for root is undefined
2016-03-19 19:54:26,803 INFO org.apache.hadoop.yarn.server.resourcemanager.scheduler.capacity.CapacitySchedulerConfiguration: max alloc vcore per queue for root is undefined
2016-03-19 19:54:26,803 INFO org.apache.hadoop.yarn.server.resourcemanager.scheduler.capacity.ParentQueue: root, capacity=1.0, asboluteCapacity=1.0, maxCapacity=1.0, asboluteMaxCapacity=1.0, state=RUNNING, acls=SUBMIT_APP:*ADMINISTER_QUEUE:*, labels=*,
, reservationsContinueLooking=true
2016-03-19 19:54:26,803 INFO org.apache.hadoop.yarn.server.resourcemanager.scheduler.capacity.ParentQueue: Initialized parent-queue root name=root, fullname=root
2016-03-19 19:54:26,827 INFO org.apache.hadoop.yarn.server.resourcemanager.scheduler.capacity.CapacitySchedulerConfiguration: max alloc mb per queue for root.default is undefined
2016-03-19 19:54:26,827 INFO org.apache.hadoop.yarn.server.resourcemanager.scheduler.capacity.CapacitySchedulerConfiguration: max alloc vcore per queue for root.default is undefined
2016-03-19 19:54:26,828 INFO org.apache.hadoop.yarn.server.resourcemanager.scheduler.capacity.LeafQueue: Initializing default
capacity = 1.0 [= (float) configuredCapacity / 100 ]
asboluteCapacity = 1.0 [= parentAbsoluteCapacity * capacity ]
maxCapacity = 1.0 [= configuredMaxCapacity ]
absoluteMaxCapacity = 1.0 [= 1.0 maximumCapacity undefined, (parentAbsoluteMaxCapacity * maximumCapacity) / 100 otherwise ]
userLimit = 100 [= configuredUserLimit ]
userLimitFactor = 1.0 [= configuredUserLimitFactor ]
maxApplications = 10000 [= configuredMaximumSystemApplicationsPerQueue or (int)(configuredMaximumSystemApplications * absoluteCapacity)]
maxApplicationsPerUser = 10000 [= (int)(maxApplications * (userLimit / 100.0f) * userLimitFactor) ]
usedCapacity = 0.0 [= usedResourcesMemory / (clusterResourceMemory * absoluteCapacity)]
absoluteUsedCapacity = 0.0 [= usedResourcesMemory / clusterResourceMemory]
maxAMResourcePerQueuePercent = 0.1 [= configuredMaximumAMResourcePercent ]
minimumAllocationFactor = 0.875 [= (float)(maximumAllocationMemory - minimumAllocationMemory) / maximumAllocationMemory ]
maximumAllocation = <memory:8192, vCores:32> [= configuredMaxAllocation ]
numContainers = 0 [= currentNumContainers ]
state = RUNNING [= configuredState ]
acls = SUBMIT_APP:*ADMINISTER_QUEUE:* [= configuredAcls ]
nodeLocalityDelay = 40
labels=*,
nodeLocalityDelay = 40
reservationsContinueLooking = true
preemptionDisabled = true

2016-03-19 19:54:26,828 INFO org.apache.hadoop.yarn.server.resourcemanager.scheduler.capacity.CapacityScheduler: Initialized queue: default: capacity=1.0, absoluteCapacity=1.0, usedResources=<memory:0, vCores:0>, usedCapacity=0.0, absoluteUsedCapacity=0.0, numApps=0, numContainers=0
2016-03-19 19:54:26,829 INFO org.apache.hadoop.yarn.server.resourcemanager.scheduler.capacity.CapacityScheduler: Initialized queue: root: numChildQueue= 1, capacity=1.0, absoluteCapacity=1.0, usedResources=<memory:0, vCores:0>usedCapacity=0.0, numApps=0, numContainers=0
2016-03-19 19:54:26,839 INFO org.apache.hadoop.yarn.server.resourcemanager.scheduler.capacity.CapacityScheduler: Initialized root queue root: numChildQueue= 1, capacity=1.0, absoluteCapacity=1.0, usedResources=<memory:0, vCores:0>usedCapacity=0.0, numApps=0, numContainers=0
2016-03-19 19:54:26,840 INFO org.apache.hadoop.yarn.server.resourcemanager.scheduler.capacity.CapacityScheduler: Initialized queue mappings, override: false
2016-03-19 19:54:26,844 INFO org.apache.hadoop.yarn.server.resourcemanager.scheduler.capacity.CapacityScheduler: Initialized CapacityScheduler with calculator=class org.apache.hadoop.yarn.util.resource.DefaultResourceCalculator, minimumAllocation=<<memory:1024, vCores:1>>, maximumAllocation=<<memory:8192, vCores:32>>, asynchronousScheduling=false, asyncScheduleInterval=5ms
2016-03-19 19:54:26,844 INFO org.apache.hadoop.service.AbstractService: Service ResourceManager failed in state STARTED; cause: org.apache.hadoop.yarn.exceptions.YarnRuntimeException: java.net.BindException: Problem binding to [0.0.0.0:8031] java.net.BindException: Address already in use; For more details see:  http://wiki.apache.org/hadoop/BindException
org.apache.hadoop.yarn.exceptions.YarnRuntimeException: java.net.BindException: Problem binding to [0.0.0.0:8031] java.net.BindException: Address already in use; For more details see:  http://wiki.apache.org/hadoop/BindException
	at org.apache.hadoop.yarn.factories.impl.pb.RpcServerFactoryPBImpl.getServer(RpcServerFactoryPBImpl.java:139)
	at org.apache.hadoop.yarn.ipc.HadoopYarnProtoRPC.getServer(HadoopYarnProtoRPC.java:65)
	at org.apache.hadoop.yarn.ipc.YarnRPC.getServer(YarnRPC.java:54)
	at org.apache.hadoop.yarn.server.resourcemanager.ResourceTrackerService.serviceStart(ResourceTrackerService.java:162)
	at org.apache.hadoop.service.AbstractService.start(AbstractService.java:193)
	at org.apache.hadoop.service.CompositeService.serviceStart(CompositeService.java:120)
	at org.apache.hadoop.yarn.server.resourcemanager.ResourceManager$RMActiveServices.serviceStart(ResourceManager.java:579)
	at org.apache.hadoop.service.AbstractService.start(AbstractService.java:193)
	at org.apache.hadoop.yarn.server.resourcemanager.ResourceManager.startActiveServices(ResourceManager.java:964)
	at org.apache.hadoop.yarn.server.resourcemanager.ResourceManager$1.run(ResourceManager.java:1005)
	at org.apache.hadoop.yarn.server.resourcemanager.ResourceManager$1.run(ResourceManager.java:1001)
	at java.security.AccessController.doPrivileged(Native Method)
	at javax.security.auth.Subject.doAs(Subject.java:422)
	at org.apache.hadoop.security.UserGroupInformation.doAs(UserGroupInformation.java:1657)
	at org.apache.hadoop.yarn.server.resourcemanager.ResourceManager.transitionToActive(ResourceManager.java:1001)
	at org.apache.hadoop.yarn.server.resourcemanager.ResourceManager.serviceStart(ResourceManager.java:1041)
	at org.apache.hadoop.service.AbstractService.start(AbstractService.java:193)
	at org.apache.hadoop.yarn.server.resourcemanager.ResourceManager.main(ResourceManager.java:1178)
Caused by: java.net.BindException: Problem binding to [0.0.0.0:8031] java.net.BindException: Address already in use; For more details see:  http://wiki.apache.org/hadoop/BindException
	at sun.reflect.NativeConstructorAccessorImpl.newInstance0(Native Method)
	at sun.reflect.NativeConstructorAccessorImpl.newInstance(NativeConstructorAccessorImpl.java:62)
	at sun.reflect.DelegatingConstructorAccessorImpl.newInstance(DelegatingConstructorAccessorImpl.java:45)
	at java.lang.reflect.Constructor.newInstance(Constructor.java:423)
	at org.apache.hadoop.net.NetUtils.wrapWithMessage(NetUtils.java:792)
	at org.apache.hadoop.net.NetUtils.wrapException(NetUtils.java:721)
	at org.apache.hadoop.ipc.Server.bind(Server.java:425)
	at org.apache.hadoop.ipc.Server$Listener.<init>(Server.java:574)
	at org.apache.hadoop.ipc.Server.<init>(Server.java:2215)
	at org.apache.hadoop.ipc.RPC$Server.<init>(RPC.java:938)
	at org.apache.hadoop.ipc.ProtobufRpcEngine$Server.<init>(ProtobufRpcEngine.java:534)
	at org.apache.hadoop.ipc.ProtobufRpcEngine.getServer(ProtobufRpcEngine.java:509)
	at org.apache.hadoop.ipc.RPC$Builder.build(RPC.java:783)
	at org.apache.hadoop.yarn.factories.impl.pb.RpcServerFactoryPBImpl.createServer(RpcServerFactoryPBImpl.java:169)
	at org.apache.hadoop.yarn.factories.impl.pb.RpcServerFactoryPBImpl.getServer(RpcServerFactoryPBImpl.java:132)
	... 17 more
Caused by: java.net.BindException: Address already in use
	at sun.nio.ch.Net.bind0(Native Method)
	at sun.nio.ch.Net.bind(Net.java:433)
	at sun.nio.ch.Net.bind(Net.java:425)
	at sun.nio.ch.ServerSocketChannelImpl.bind(ServerSocketChannelImpl.java:223)
	at sun.nio.ch.ServerSocketAdaptor.bind(ServerSocketAdaptor.java:74)
	at org.apache.hadoop.ipc.Server.bind(Server.java:408)
	... 25 more
2016-03-19 19:54:26,855 INFO org.apache.hadoop.yarn.server.resourcemanager.ResourceManager: Transitioning to standby state
2016-03-19 19:54:26,855 INFO org.apache.hadoop.yarn.server.resourcemanager.ResourceManager: Transitioned to standby state
2016-03-19 19:54:26,855 FATAL org.apache.hadoop.yarn.server.resourcemanager.ResourceManager: Error starting ResourceManager
org.apache.hadoop.yarn.exceptions.YarnRuntimeException: java.net.BindException: Problem binding to [0.0.0.0:8031] java.net.BindException: Address already in use; For more details see:  http://wiki.apache.org/hadoop/BindException
	at org.apache.hadoop.yarn.factories.impl.pb.RpcServerFactoryPBImpl.getServer(RpcServerFactoryPBImpl.java:139)
	at org.apache.hadoop.yarn.ipc.HadoopYarnProtoRPC.getServer(HadoopYarnProtoRPC.java:65)
	at org.apache.hadoop.yarn.ipc.YarnRPC.getServer(YarnRPC.java:54)
	at org.apache.hadoop.yarn.server.resourcemanager.ResourceTrackerService.serviceStart(ResourceTrackerService.java:162)
	at org.apache.hadoop.service.AbstractService.start(AbstractService.java:193)
	at org.apache.hadoop.service.CompositeService.serviceStart(CompositeService.java:120)
	at org.apache.hadoop.yarn.server.resourcemanager.ResourceManager$RMActiveServices.serviceStart(ResourceManager.java:579)
	at org.apache.hadoop.service.AbstractService.start(AbstractService.java:193)
	at org.apache.hadoop.yarn.server.resourcemanager.ResourceManager.startActiveServices(ResourceManager.java:964)
	at org.apache.hadoop.yarn.server.resourcemanager.ResourceManager$1.run(ResourceManager.java:1005)
	at org.apache.hadoop.yarn.server.resourcemanager.ResourceManager$1.run(ResourceManager.java:1001)
	at java.security.AccessController.doPrivileged(Native Method)
	at javax.security.auth.Subject.doAs(Subject.java:422)
	at org.apache.hadoop.security.UserGroupInformation.doAs(UserGroupInformation.java:1657)
	at org.apache.hadoop.yarn.server.resourcemanager.ResourceManager.transitionToActive(ResourceManager.java:1001)
	at org.apache.hadoop.yarn.server.resourcemanager.ResourceManager.serviceStart(ResourceManager.java:1041)
	at org.apache.hadoop.service.AbstractService.start(AbstractService.java:193)
	at org.apache.hadoop.yarn.server.resourcemanager.ResourceManager.main(ResourceManager.java:1178)
Caused by: java.net.BindException: Problem binding to [0.0.0.0:8031] java.net.BindException: Address already in use; For more details see:  http://wiki.apache.org/hadoop/BindException
	at sun.reflect.NativeConstructorAccessorImpl.newInstance0(Native Method)
	at sun.reflect.NativeConstructorAccessorImpl.newInstance(NativeConstructorAccessorImpl.java:62)
	at sun.reflect.DelegatingConstructorAccessorImpl.newInstance(DelegatingConstructorAccessorImpl.java:45)
	at java.lang.reflect.Constructor.newInstance(Constructor.java:423)
	at org.apache.hadoop.net.NetUtils.wrapWithMessage(NetUtils.java:792)
	at org.apache.hadoop.net.NetUtils.wrapException(NetUtils.java:721)
	at org.apache.hadoop.ipc.Server.bind(Server.java:425)
	at org.apache.hadoop.ipc.Server$Listener.<init>(Server.java:574)
	at org.apache.hadoop.ipc.Server.<init>(Server.java:2215)
	at org.apache.hadoop.ipc.RPC$Server.<init>(RPC.java:938)
	at org.apache.hadoop.ipc.ProtobufRpcEngine$Server.<init>(ProtobufRpcEngine.java:534)
	at org.apache.hadoop.ipc.ProtobufRpcEngine.getServer(ProtobufRpcEngine.java:509)
	at org.apache.hadoop.ipc.RPC$Builder.build(RPC.java:783)
	at org.apache.hadoop.yarn.factories.impl.pb.RpcServerFactoryPBImpl.createServer(RpcServerFactoryPBImpl.java:169)
	at org.apache.hadoop.yarn.factories.impl.pb.RpcServerFactoryPBImpl.getServer(RpcServerFactoryPBImpl.java:132)
	... 17 more
Caused by: java.net.BindException: Address already in use
	at sun.nio.ch.Net.bind0(Native Method)
	at sun.nio.ch.Net.bind(Net.java:433)
	at sun.nio.ch.Net.bind(Net.java:425)
	at sun.nio.ch.ServerSocketChannelImpl.bind(ServerSocketChannelImpl.java:223)
	at sun.nio.ch.ServerSocketAdaptor.bind(ServerSocketAdaptor.java:74)
	at org.apache.hadoop.ipc.Server.bind(Server.java:408)
	... 25 more
2016-03-19 19:54:26,873 INFO org.apache.hadoop.yarn.server.resourcemanager.ResourceManager: SHUTDOWN_MSG: 
/************************************************************
SHUTDOWN_MSG: Shutting down ResourceManager at vishal-VirtualBox/127.0.1.1
************************************************************/
2016-03-19 19:55:21,757 INFO org.apache.hadoop.yarn.server.resourcemanager.ResourceManager: STARTUP_MSG: 
/************************************************************
STARTUP_MSG: Starting ResourceManager
STARTUP_MSG:   host = vishal-VirtualBox/127.0.1.1
STARTUP_MSG:   args = []
STARTUP_MSG:   version = 2.7.2
STARTUP_MSG:   build = https://git-wip-us.apache.org/repos/asf/hadoop.git -r b165c4fe8a74265c792ce23f546c64604acf0e41; compiled by 'jenkins' on 2016-01-26T00:08Z
STARTUP_MSG:   java = 1.8.0_74
************************************************************/
2016-03-19 19:55:21,786 INFO org.apache.hadoop.yarn.server.resourcemanager.ResourceManager: registered UNIX signal handlers for [TERM, HUP, INT]
2016-03-19 19:55:23,421 INFO org.apache.hadoop.conf.Configuration: found resource core-site.xml at file:/usr/local/hadoop/etc/hadoop/core-site.xml
2016-03-19 19:55:23,808 WARN org.apache.hadoop.util.NativeCodeLoader: Unable to load native-hadoop library for your platform... using builtin-java classes where applicable
2016-03-19 19:55:23,960 INFO org.apache.hadoop.security.Groups: clearing userToGroupsMap cache
2016-03-19 19:55:24,325 INFO org.apache.hadoop.conf.Configuration: found resource yarn-site.xml at file:/usr/local/hadoop/etc/hadoop/yarn-site.xml
2016-03-19 19:55:25,269 INFO org.apache.hadoop.yarn.event.AsyncDispatcher: Registering class org.apache.hadoop.yarn.server.resourcemanager.RMFatalEventType for class org.apache.hadoop.yarn.server.resourcemanager.ResourceManager$RMFatalEventDispatcher
2016-03-19 19:55:26,308 INFO org.apache.hadoop.yarn.server.resourcemanager.security.NMTokenSecretManagerInRM: NMTokenKeyRollingInterval: 86400000ms and NMTokenKeyActivationDelay: 900000ms
2016-03-19 19:55:26,333 INFO org.apache.hadoop.yarn.server.resourcemanager.security.RMContainerTokenSecretManager: ContainerTokenKeyRollingInterval: 86400000ms and ContainerTokenKeyActivationDelay: 900000ms
2016-03-19 19:55:26,352 INFO org.apache.hadoop.yarn.server.resourcemanager.security.AMRMTokenSecretManager: AMRMTokenKeyRollingInterval: 86400000ms and AMRMTokenKeyActivationDelay: 900000 ms
2016-03-19 19:55:26,523 INFO org.apache.hadoop.yarn.event.AsyncDispatcher: Registering class org.apache.hadoop.yarn.server.resourcemanager.recovery.RMStateStoreEventType for class org.apache.hadoop.yarn.server.resourcemanager.recovery.RMStateStore$ForwardingEventHandler
2016-03-19 19:55:26,532 INFO org.apache.hadoop.yarn.event.AsyncDispatcher: Registering class org.apache.hadoop.yarn.server.resourcemanager.NodesListManagerEventType for class org.apache.hadoop.yarn.server.resourcemanager.NodesListManager
2016-03-19 19:55:26,532 INFO org.apache.hadoop.yarn.server.resourcemanager.ResourceManager: Using Scheduler: org.apache.hadoop.yarn.server.resourcemanager.scheduler.capacity.CapacityScheduler
2016-03-19 19:55:26,653 INFO org.apache.hadoop.yarn.event.AsyncDispatcher: Registering class org.apache.hadoop.yarn.server.resourcemanager.scheduler.event.SchedulerEventType for class org.apache.hadoop.yarn.server.resourcemanager.ResourceManager$SchedulerEventDispatcher
2016-03-19 19:55:26,654 INFO org.apache.hadoop.yarn.event.AsyncDispatcher: Registering class org.apache.hadoop.yarn.server.resourcemanager.rmapp.RMAppEventType for class org.apache.hadoop.yarn.server.resourcemanager.ResourceManager$ApplicationEventDispatcher
2016-03-19 19:55:26,655 INFO org.apache.hadoop.yarn.event.AsyncDispatcher: Registering class org.apache.hadoop.yarn.server.resourcemanager.rmapp.attempt.RMAppAttemptEventType for class org.apache.hadoop.yarn.server.resourcemanager.ResourceManager$ApplicationAttemptEventDispatcher
2016-03-19 19:55:26,662 INFO org.apache.hadoop.yarn.event.AsyncDispatcher: Registering class org.apache.hadoop.yarn.server.resourcemanager.rmnode.RMNodeEventType for class org.apache.hadoop.yarn.server.resourcemanager.ResourceManager$NodeEventDispatcher
2016-03-19 19:55:27,069 INFO org.apache.hadoop.metrics2.impl.MetricsConfig: loaded properties from hadoop-metrics2.properties
2016-03-19 19:55:27,419 INFO org.apache.hadoop.metrics2.impl.MetricsSystemImpl: Scheduled snapshot period at 10 second(s).
2016-03-19 19:55:27,419 INFO org.apache.hadoop.metrics2.impl.MetricsSystemImpl: ResourceManager metrics system started
2016-03-19 19:55:27,517 INFO org.apache.hadoop.yarn.event.AsyncDispatcher: Registering class org.apache.hadoop.yarn.server.resourcemanager.RMAppManagerEventType for class org.apache.hadoop.yarn.server.resourcemanager.RMAppManager
2016-03-19 19:55:27,553 INFO org.apache.hadoop.yarn.event.AsyncDispatcher: Registering class org.apache.hadoop.yarn.server.resourcemanager.amlauncher.AMLauncherEventType for class org.apache.hadoop.yarn.server.resourcemanager.amlauncher.ApplicationMasterLauncher
2016-03-19 19:55:27,555 INFO org.apache.hadoop.yarn.server.resourcemanager.RMNMInfo: Registered RMNMInfo MBean
2016-03-19 19:55:27,565 INFO org.apache.hadoop.yarn.security.YarnAuthorizationProvider: org.apache.hadoop.yarn.security.ConfiguredYarnAuthorizer is instiantiated.
2016-03-19 19:55:27,565 INFO org.apache.hadoop.util.HostsFileReader: Refreshing hosts (include/exclude) list
2016-03-19 19:55:27,602 INFO org.apache.hadoop.conf.Configuration: found resource capacity-scheduler.xml at file:/usr/local/hadoop/etc/hadoop/capacity-scheduler.xml
2016-03-19 19:55:27,902 INFO org.apache.hadoop.yarn.server.resourcemanager.scheduler.capacity.CapacitySchedulerConfiguration: max alloc mb per queue for root is undefined
2016-03-19 19:55:27,902 INFO org.apache.hadoop.yarn.server.resourcemanager.scheduler.capacity.CapacitySchedulerConfiguration: max alloc vcore per queue for root is undefined
2016-03-19 19:55:27,910 INFO org.apache.hadoop.yarn.server.resourcemanager.scheduler.capacity.ParentQueue: root, capacity=1.0, asboluteCapacity=1.0, maxCapacity=1.0, asboluteMaxCapacity=1.0, state=RUNNING, acls=SUBMIT_APP:*ADMINISTER_QUEUE:*, labels=*,
, reservationsContinueLooking=true
2016-03-19 19:55:27,910 INFO org.apache.hadoop.yarn.server.resourcemanager.scheduler.capacity.ParentQueue: Initialized parent-queue root name=root, fullname=root
2016-03-19 19:55:27,953 INFO org.apache.hadoop.yarn.server.resourcemanager.scheduler.capacity.CapacitySchedulerConfiguration: max alloc mb per queue for root.default is undefined
2016-03-19 19:55:27,953 INFO org.apache.hadoop.yarn.server.resourcemanager.scheduler.capacity.CapacitySchedulerConfiguration: max alloc vcore per queue for root.default is undefined
2016-03-19 19:55:27,954 INFO org.apache.hadoop.yarn.server.resourcemanager.scheduler.capacity.LeafQueue: Initializing default
capacity = 1.0 [= (float) configuredCapacity / 100 ]
asboluteCapacity = 1.0 [= parentAbsoluteCapacity * capacity ]
maxCapacity = 1.0 [= configuredMaxCapacity ]
absoluteMaxCapacity = 1.0 [= 1.0 maximumCapacity undefined, (parentAbsoluteMaxCapacity * maximumCapacity) / 100 otherwise ]
userLimit = 100 [= configuredUserLimit ]
userLimitFactor = 1.0 [= configuredUserLimitFactor ]
maxApplications = 10000 [= configuredMaximumSystemApplicationsPerQueue or (int)(configuredMaximumSystemApplications * absoluteCapacity)]
maxApplicationsPerUser = 10000 [= (int)(maxApplications * (userLimit / 100.0f) * userLimitFactor) ]
usedCapacity = 0.0 [= usedResourcesMemory / (clusterResourceMemory * absoluteCapacity)]
absoluteUsedCapacity = 0.0 [= usedResourcesMemory / clusterResourceMemory]
maxAMResourcePerQueuePercent = 0.1 [= configuredMaximumAMResourcePercent ]
minimumAllocationFactor = 0.875 [= (float)(maximumAllocationMemory - minimumAllocationMemory) / maximumAllocationMemory ]
maximumAllocation = <memory:8192, vCores:32> [= configuredMaxAllocation ]
numContainers = 0 [= currentNumContainers ]
state = RUNNING [= configuredState ]
acls = SUBMIT_APP:*ADMINISTER_QUEUE:* [= configuredAcls ]
nodeLocalityDelay = 40
labels=*,
nodeLocalityDelay = 40
reservationsContinueLooking = true
preemptionDisabled = true

2016-03-19 19:55:27,955 INFO org.apache.hadoop.yarn.server.resourcemanager.scheduler.capacity.CapacityScheduler: Initialized queue: default: capacity=1.0, absoluteCapacity=1.0, usedResources=<memory:0, vCores:0>, usedCapacity=0.0, absoluteUsedCapacity=0.0, numApps=0, numContainers=0
2016-03-19 19:55:27,955 INFO org.apache.hadoop.yarn.server.resourcemanager.scheduler.capacity.CapacityScheduler: Initialized queue: root: numChildQueue= 1, capacity=1.0, absoluteCapacity=1.0, usedResources=<memory:0, vCores:0>usedCapacity=0.0, numApps=0, numContainers=0
2016-03-19 19:55:27,955 INFO org.apache.hadoop.yarn.server.resourcemanager.scheduler.capacity.CapacityScheduler: Initialized root queue root: numChildQueue= 1, capacity=1.0, absoluteCapacity=1.0, usedResources=<memory:0, vCores:0>usedCapacity=0.0, numApps=0, numContainers=0
2016-03-19 19:55:27,956 INFO org.apache.hadoop.yarn.server.resourcemanager.scheduler.capacity.CapacityScheduler: Initialized queue mappings, override: false
2016-03-19 19:55:27,956 INFO org.apache.hadoop.yarn.server.resourcemanager.scheduler.capacity.CapacityScheduler: Initialized CapacityScheduler with calculator=class org.apache.hadoop.yarn.util.resource.DefaultResourceCalculator, minimumAllocation=<<memory:1024, vCores:1>>, maximumAllocation=<<memory:8192, vCores:32>>, asynchronousScheduling=false, asyncScheduleInterval=5ms
2016-03-19 19:55:28,058 INFO org.apache.hadoop.yarn.server.resourcemanager.metrics.SystemMetricsPublisher: YARN system metrics publishing service is not enabled
2016-03-19 19:55:28,058 INFO org.apache.hadoop.yarn.server.resourcemanager.ResourceManager: Transitioning to active state
2016-03-19 19:55:28,142 INFO org.apache.hadoop.yarn.server.resourcemanager.recovery.RMStateStore: Updating AMRMToken
2016-03-19 19:55:28,142 INFO org.apache.hadoop.yarn.server.resourcemanager.security.RMContainerTokenSecretManager: Rolling master-key for container-tokens
2016-03-19 19:55:28,142 INFO org.apache.hadoop.yarn.server.resourcemanager.security.NMTokenSecretManagerInRM: Rolling master-key for nm-tokens
2016-03-19 19:55:28,153 INFO org.apache.hadoop.security.token.delegation.AbstractDelegationTokenSecretManager: Updating the current master key for generating delegation tokens
2016-03-19 19:55:28,157 INFO org.apache.hadoop.yarn.server.resourcemanager.security.RMDelegationTokenSecretManager: storing master key with keyID 1
2016-03-19 19:55:28,158 INFO org.apache.hadoop.yarn.server.resourcemanager.recovery.RMStateStore: Storing RMDTMasterKey.
2016-03-19 19:55:28,170 INFO org.apache.hadoop.security.token.delegation.AbstractDelegationTokenSecretManager: Starting expired delegation token remover thread, tokenRemoverScanInterval=60 min(s)
2016-03-19 19:55:28,198 INFO org.apache.hadoop.security.token.delegation.AbstractDelegationTokenSecretManager: Updating the current master key for generating delegation tokens
2016-03-19 19:55:28,199 INFO org.apache.hadoop.yarn.server.resourcemanager.security.RMDelegationTokenSecretManager: storing master key with keyID 2
2016-03-19 19:55:28,199 INFO org.apache.hadoop.yarn.server.resourcemanager.recovery.RMStateStore: Storing RMDTMasterKey.
2016-03-19 19:55:28,199 INFO org.apache.hadoop.yarn.event.AsyncDispatcher: Registering class org.apache.hadoop.yarn.nodelabels.event.NodeLabelsStoreEventType for class org.apache.hadoop.yarn.nodelabels.CommonNodeLabelsManager$ForwardingEventHandler
2016-03-19 19:55:29,345 INFO org.apache.hadoop.ipc.CallQueueManager: Using callQueue class java.util.concurrent.LinkedBlockingQueue
2016-03-19 19:55:29,502 INFO org.apache.hadoop.service.AbstractService: Service org.apache.hadoop.yarn.server.resourcemanager.ResourceTrackerService failed in state STARTED; cause: org.apache.hadoop.yarn.exceptions.YarnRuntimeException: java.net.BindException: Problem binding to [0.0.0.0:8031] java.net.BindException: Address already in use; For more details see:  http://wiki.apache.org/hadoop/BindException
org.apache.hadoop.yarn.exceptions.YarnRuntimeException: java.net.BindException: Problem binding to [0.0.0.0:8031] java.net.BindException: Address already in use; For more details see:  http://wiki.apache.org/hadoop/BindException
	at org.apache.hadoop.yarn.factories.impl.pb.RpcServerFactoryPBImpl.getServer(RpcServerFactoryPBImpl.java:139)
	at org.apache.hadoop.yarn.ipc.HadoopYarnProtoRPC.getServer(HadoopYarnProtoRPC.java:65)
	at org.apache.hadoop.yarn.ipc.YarnRPC.getServer(YarnRPC.java:54)
	at org.apache.hadoop.yarn.server.resourcemanager.ResourceTrackerService.serviceStart(ResourceTrackerService.java:162)
	at org.apache.hadoop.service.AbstractService.start(AbstractService.java:193)
	at org.apache.hadoop.service.CompositeService.serviceStart(CompositeService.java:120)
	at org.apache.hadoop.yarn.server.resourcemanager.ResourceManager$RMActiveServices.serviceStart(ResourceManager.java:579)
	at org.apache.hadoop.service.AbstractService.start(AbstractService.java:193)
	at org.apache.hadoop.yarn.server.resourcemanager.ResourceManager.startActiveServices(ResourceManager.java:964)
	at org.apache.hadoop.yarn.server.resourcemanager.ResourceManager$1.run(ResourceManager.java:1005)
	at org.apache.hadoop.yarn.server.resourcemanager.ResourceManager$1.run(ResourceManager.java:1001)
	at java.security.AccessController.doPrivileged(Native Method)
	at javax.security.auth.Subject.doAs(Subject.java:422)
	at org.apache.hadoop.security.UserGroupInformation.doAs(UserGroupInformation.java:1657)
	at org.apache.hadoop.yarn.server.resourcemanager.ResourceManager.transitionToActive(ResourceManager.java:1001)
	at org.apache.hadoop.yarn.server.resourcemanager.ResourceManager.serviceStart(ResourceManager.java:1041)
	at org.apache.hadoop.service.AbstractService.start(AbstractService.java:193)
	at org.apache.hadoop.yarn.server.resourcemanager.ResourceManager.main(ResourceManager.java:1178)
Caused by: java.net.BindException: Problem binding to [0.0.0.0:8031] java.net.BindException: Address already in use; For more details see:  http://wiki.apache.org/hadoop/BindException
	at sun.reflect.NativeConstructorAccessorImpl.newInstance0(Native Method)
	at sun.reflect.NativeConstructorAccessorImpl.newInstance(NativeConstructorAccessorImpl.java:62)
	at sun.reflect.DelegatingConstructorAccessorImpl.newInstance(DelegatingConstructorAccessorImpl.java:45)
	at java.lang.reflect.Constructor.newInstance(Constructor.java:423)
	at org.apache.hadoop.net.NetUtils.wrapWithMessage(NetUtils.java:792)
	at org.apache.hadoop.net.NetUtils.wrapException(NetUtils.java:721)
	at org.apache.hadoop.ipc.Server.bind(Server.java:425)
	at org.apache.hadoop.ipc.Server$Listener.<init>(Server.java:574)
	at org.apache.hadoop.ipc.Server.<init>(Server.java:2215)
	at org.apache.hadoop.ipc.RPC$Server.<init>(RPC.java:938)
	at org.apache.hadoop.ipc.ProtobufRpcEngine$Server.<init>(ProtobufRpcEngine.java:534)
	at org.apache.hadoop.ipc.ProtobufRpcEngine.getServer(ProtobufRpcEngine.java:509)
	at org.apache.hadoop.ipc.RPC$Builder.build(RPC.java:783)
	at org.apache.hadoop.yarn.factories.impl.pb.RpcServerFactoryPBImpl.createServer(RpcServerFactoryPBImpl.java:169)
	at org.apache.hadoop.yarn.factories.impl.pb.RpcServerFactoryPBImpl.getServer(RpcServerFactoryPBImpl.java:132)
	... 17 more
Caused by: java.net.BindException: Address already in use
	at sun.nio.ch.Net.bind0(Native Method)
	at sun.nio.ch.Net.bind(Net.java:433)
	at sun.nio.ch.Net.bind(Net.java:425)
	at sun.nio.ch.ServerSocketChannelImpl.bind(ServerSocketChannelImpl.java:223)
	at sun.nio.ch.ServerSocketAdaptor.bind(ServerSocketAdaptor.java:74)
	at org.apache.hadoop.ipc.Server.bind(Server.java:408)
	... 25 more
2016-03-19 19:55:29,534 INFO org.apache.hadoop.service.AbstractService: Service RMActiveServices failed in state STARTED; cause: org.apache.hadoop.yarn.exceptions.YarnRuntimeException: java.net.BindException: Problem binding to [0.0.0.0:8031] java.net.BindException: Address already in use; For more details see:  http://wiki.apache.org/hadoop/BindException
org.apache.hadoop.yarn.exceptions.YarnRuntimeException: java.net.BindException: Problem binding to [0.0.0.0:8031] java.net.BindException: Address already in use; For more details see:  http://wiki.apache.org/hadoop/BindException
	at org.apache.hadoop.yarn.factories.impl.pb.RpcServerFactoryPBImpl.getServer(RpcServerFactoryPBImpl.java:139)
	at org.apache.hadoop.yarn.ipc.HadoopYarnProtoRPC.getServer(HadoopYarnProtoRPC.java:65)
	at org.apache.hadoop.yarn.ipc.YarnRPC.getServer(YarnRPC.java:54)
	at org.apache.hadoop.yarn.server.resourcemanager.ResourceTrackerService.serviceStart(ResourceTrackerService.java:162)
	at org.apache.hadoop.service.AbstractService.start(AbstractService.java:193)
	at org.apache.hadoop.service.CompositeService.serviceStart(CompositeService.java:120)
	at org.apache.hadoop.yarn.server.resourcemanager.ResourceManager$RMActiveServices.serviceStart(ResourceManager.java:579)
	at org.apache.hadoop.service.AbstractService.start(AbstractService.java:193)
	at org.apache.hadoop.yarn.server.resourcemanager.ResourceManager.startActiveServices(ResourceManager.java:964)
	at org.apache.hadoop.yarn.server.resourcemanager.ResourceManager$1.run(ResourceManager.java:1005)
	at org.apache.hadoop.yarn.server.resourcemanager.ResourceManager$1.run(ResourceManager.java:1001)
	at java.security.AccessController.doPrivileged(Native Method)
	at javax.security.auth.Subject.doAs(Subject.java:422)
	at org.apache.hadoop.security.UserGroupInformation.doAs(UserGroupInformation.java:1657)
	at org.apache.hadoop.yarn.server.resourcemanager.ResourceManager.transitionToActive(ResourceManager.java:1001)
	at org.apache.hadoop.yarn.server.resourcemanager.ResourceManager.serviceStart(ResourceManager.java:1041)
	at org.apache.hadoop.service.AbstractService.start(AbstractService.java:193)
	at org.apache.hadoop.yarn.server.resourcemanager.ResourceManager.main(ResourceManager.java:1178)
Caused by: java.net.BindException: Problem binding to [0.0.0.0:8031] java.net.BindException: Address already in use; For more details see:  http://wiki.apache.org/hadoop/BindException
	at sun.reflect.NativeConstructorAccessorImpl.newInstance0(Native Method)
	at sun.reflect.NativeConstructorAccessorImpl.newInstance(NativeConstructorAccessorImpl.java:62)
	at sun.reflect.DelegatingConstructorAccessorImpl.newInstance(DelegatingConstructorAccessorImpl.java:45)
	at java.lang.reflect.Constructor.newInstance(Constructor.java:423)
	at org.apache.hadoop.net.NetUtils.wrapWithMessage(NetUtils.java:792)
	at org.apache.hadoop.net.NetUtils.wrapException(NetUtils.java:721)
	at org.apache.hadoop.ipc.Server.bind(Server.java:425)
	at org.apache.hadoop.ipc.Server$Listener.<init>(Server.java:574)
	at org.apache.hadoop.ipc.Server.<init>(Server.java:2215)
	at org.apache.hadoop.ipc.RPC$Server.<init>(RPC.java:938)
	at org.apache.hadoop.ipc.ProtobufRpcEngine$Server.<init>(ProtobufRpcEngine.java:534)
	at org.apache.hadoop.ipc.ProtobufRpcEngine.getServer(ProtobufRpcEngine.java:509)
	at org.apache.hadoop.ipc.RPC$Builder.build(RPC.java:783)
	at org.apache.hadoop.yarn.factories.impl.pb.RpcServerFactoryPBImpl.createServer(RpcServerFactoryPBImpl.java:169)
	at org.apache.hadoop.yarn.factories.impl.pb.RpcServerFactoryPBImpl.getServer(RpcServerFactoryPBImpl.java:132)
	... 17 more
Caused by: java.net.BindException: Address already in use
	at sun.nio.ch.Net.bind0(Native Method)
	at sun.nio.ch.Net.bind(Net.java:433)
	at sun.nio.ch.Net.bind(Net.java:425)
	at sun.nio.ch.ServerSocketChannelImpl.bind(ServerSocketChannelImpl.java:223)
	at sun.nio.ch.ServerSocketAdaptor.bind(ServerSocketAdaptor.java:74)
	at org.apache.hadoop.ipc.Server.bind(Server.java:408)
	... 25 more
2016-03-19 19:55:29,547 INFO org.apache.hadoop.yarn.util.AbstractLivelinessMonitor: NMLivelinessMonitor thread interrupted
2016-03-19 19:55:29,547 ERROR org.apache.hadoop.yarn.server.resourcemanager.ResourceManager: Returning, interrupted : java.lang.InterruptedException
2016-03-19 19:55:29,549 INFO org.apache.hadoop.yarn.event.AsyncDispatcher: AsyncDispatcher is draining to stop, igonring any new events.
2016-03-19 19:55:29,550 INFO org.apache.hadoop.yarn.util.AbstractLivelinessMonitor: AMLivelinessMonitor thread interrupted
2016-03-19 19:55:29,553 INFO org.apache.hadoop.yarn.util.AbstractLivelinessMonitor: AMLivelinessMonitor thread interrupted
2016-03-19 19:55:29,553 INFO org.apache.hadoop.yarn.util.AbstractLivelinessMonitor: org.apache.hadoop.yarn.server.resourcemanager.rmcontainer.ContainerAllocationExpirer thread interrupted
2016-03-19 19:55:29,553 ERROR org.apache.hadoop.security.token.delegation.AbstractDelegationTokenSecretManager: ExpiredTokenRemover received java.lang.InterruptedException: sleep interrupted
2016-03-19 19:55:29,557 INFO org.apache.hadoop.metrics2.impl.MetricsSystemImpl: Stopping ResourceManager metrics system...
2016-03-19 19:55:29,557 INFO org.apache.hadoop.metrics2.impl.MetricsSystemImpl: ResourceManager metrics system stopped.
2016-03-19 19:55:29,557 INFO org.apache.hadoop.metrics2.impl.MetricsSystemImpl: ResourceManager metrics system shutdown complete.
2016-03-19 19:55:29,565 INFO org.apache.hadoop.yarn.event.AsyncDispatcher: AsyncDispatcher is draining to stop, igonring any new events.
2016-03-19 19:55:29,575 INFO org.apache.hadoop.yarn.event.AsyncDispatcher: Registering class org.apache.hadoop.yarn.server.resourcemanager.RMFatalEventType for class org.apache.hadoop.yarn.server.resourcemanager.ResourceManager$RMFatalEventDispatcher
2016-03-19 19:55:29,581 INFO org.apache.hadoop.yarn.server.resourcemanager.security.NMTokenSecretManagerInRM: NMTokenKeyRollingInterval: 86400000ms and NMTokenKeyActivationDelay: 900000ms
2016-03-19 19:55:29,587 INFO org.apache.hadoop.yarn.server.resourcemanager.security.RMContainerTokenSecretManager: ContainerTokenKeyRollingInterval: 86400000ms and ContainerTokenKeyActivationDelay: 900000ms
2016-03-19 19:55:29,587 INFO org.apache.hadoop.yarn.server.resourcemanager.security.AMRMTokenSecretManager: AMRMTokenKeyRollingInterval: 86400000ms and AMRMTokenKeyActivationDelay: 900000 ms
2016-03-19 19:55:29,592 INFO org.apache.hadoop.yarn.event.AsyncDispatcher: Registering class org.apache.hadoop.yarn.server.resourcemanager.recovery.RMStateStoreEventType for class org.apache.hadoop.yarn.server.resourcemanager.recovery.RMStateStore$ForwardingEventHandler
2016-03-19 19:55:29,592 INFO org.apache.hadoop.yarn.event.AsyncDispatcher: Registering class org.apache.hadoop.yarn.server.resourcemanager.NodesListManagerEventType for class org.apache.hadoop.yarn.server.resourcemanager.NodesListManager
2016-03-19 19:55:29,592 INFO org.apache.hadoop.yarn.server.resourcemanager.ResourceManager: Using Scheduler: org.apache.hadoop.yarn.server.resourcemanager.scheduler.capacity.CapacityScheduler
2016-03-19 19:55:29,592 INFO org.apache.hadoop.yarn.event.AsyncDispatcher: Registering class org.apache.hadoop.yarn.server.resourcemanager.scheduler.event.SchedulerEventType for class org.apache.hadoop.yarn.server.resourcemanager.ResourceManager$SchedulerEventDispatcher
2016-03-19 19:55:29,592 INFO org.apache.hadoop.yarn.event.AsyncDispatcher: Registering class org.apache.hadoop.yarn.server.resourcemanager.rmapp.RMAppEventType for class org.apache.hadoop.yarn.server.resourcemanager.ResourceManager$ApplicationEventDispatcher
2016-03-19 19:55:29,592 INFO org.apache.hadoop.yarn.event.AsyncDispatcher: Registering class org.apache.hadoop.yarn.server.resourcemanager.rmapp.attempt.RMAppAttemptEventType for class org.apache.hadoop.yarn.server.resourcemanager.ResourceManager$ApplicationAttemptEventDispatcher
2016-03-19 19:55:29,592 INFO org.apache.hadoop.yarn.event.AsyncDispatcher: Registering class org.apache.hadoop.yarn.server.resourcemanager.rmnode.RMNodeEventType for class org.apache.hadoop.yarn.server.resourcemanager.ResourceManager$NodeEventDispatcher
2016-03-19 19:55:29,599 INFO org.apache.hadoop.metrics2.impl.MetricsConfig: loaded properties from hadoop-metrics2.properties
2016-03-19 19:55:29,610 INFO org.apache.hadoop.metrics2.impl.MetricsSystemImpl: Scheduled snapshot period at 10 second(s).
2016-03-19 19:55:29,613 INFO org.apache.hadoop.metrics2.impl.MetricsSystemImpl: ResourceManager metrics system started
2016-03-19 19:55:29,614 INFO org.apache.hadoop.yarn.event.AsyncDispatcher: Registering class org.apache.hadoop.yarn.server.resourcemanager.RMAppManagerEventType for class org.apache.hadoop.yarn.server.resourcemanager.RMAppManager
2016-03-19 19:55:29,614 INFO org.apache.hadoop.yarn.event.AsyncDispatcher: Registering class org.apache.hadoop.yarn.server.resourcemanager.amlauncher.AMLauncherEventType for class org.apache.hadoop.yarn.server.resourcemanager.amlauncher.ApplicationMasterLauncher
2016-03-19 19:55:29,615 WARN org.apache.hadoop.metrics2.util.MBeans: Failed to register MBean "Hadoop:service=ResourceManager,name=RMNMInfo": Instance already exists.
2016-03-19 19:55:29,615 INFO org.apache.hadoop.yarn.server.resourcemanager.RMNMInfo: Registered RMNMInfo MBean
2016-03-19 19:55:29,621 INFO org.apache.hadoop.util.HostsFileReader: Refreshing hosts (include/exclude) list
2016-03-19 19:55:29,625 INFO org.apache.hadoop.conf.Configuration: found resource capacity-scheduler.xml at file:/usr/local/hadoop/etc/hadoop/capacity-scheduler.xml
2016-03-19 19:55:29,857 INFO org.apache.hadoop.yarn.server.resourcemanager.scheduler.capacity.CapacitySchedulerConfiguration: max alloc mb per queue for root is undefined
2016-03-19 19:55:29,857 INFO org.apache.hadoop.yarn.server.resourcemanager.scheduler.capacity.CapacitySchedulerConfiguration: max alloc vcore per queue for root is undefined
2016-03-19 19:55:29,858 INFO org.apache.hadoop.yarn.server.resourcemanager.scheduler.capacity.ParentQueue: root, capacity=1.0, asboluteCapacity=1.0, maxCapacity=1.0, asboluteMaxCapacity=1.0, state=RUNNING, acls=SUBMIT_APP:*ADMINISTER_QUEUE:*, labels=*,
, reservationsContinueLooking=true
2016-03-19 19:55:29,858 INFO org.apache.hadoop.yarn.server.resourcemanager.scheduler.capacity.ParentQueue: Initialized parent-queue root name=root, fullname=root
2016-03-19 19:55:29,928 INFO org.apache.hadoop.yarn.server.resourcemanager.scheduler.capacity.CapacitySchedulerConfiguration: max alloc mb per queue for root.default is undefined
2016-03-19 19:55:29,928 INFO org.apache.hadoop.yarn.server.resourcemanager.scheduler.capacity.CapacitySchedulerConfiguration: max alloc vcore per queue for root.default is undefined
2016-03-19 19:55:29,933 INFO org.apache.hadoop.yarn.server.resourcemanager.scheduler.capacity.LeafQueue: Initializing default
capacity = 1.0 [= (float) configuredCapacity / 100 ]
asboluteCapacity = 1.0 [= parentAbsoluteCapacity * capacity ]
maxCapacity = 1.0 [= configuredMaxCapacity ]
absoluteMaxCapacity = 1.0 [= 1.0 maximumCapacity undefined, (parentAbsoluteMaxCapacity * maximumCapacity) / 100 otherwise ]
userLimit = 100 [= configuredUserLimit ]
userLimitFactor = 1.0 [= configuredUserLimitFactor ]
maxApplications = 10000 [= configuredMaximumSystemApplicationsPerQueue or (int)(configuredMaximumSystemApplications * absoluteCapacity)]
maxApplicationsPerUser = 10000 [= (int)(maxApplications * (userLimit / 100.0f) * userLimitFactor) ]
usedCapacity = 0.0 [= usedResourcesMemory / (clusterResourceMemory * absoluteCapacity)]
absoluteUsedCapacity = 0.0 [= usedResourcesMemory / clusterResourceMemory]
maxAMResourcePerQueuePercent = 0.1 [= configuredMaximumAMResourcePercent ]
minimumAllocationFactor = 0.875 [= (float)(maximumAllocationMemory - minimumAllocationMemory) / maximumAllocationMemory ]
maximumAllocation = <memory:8192, vCores:32> [= configuredMaxAllocation ]
numContainers = 0 [= currentNumContainers ]
state = RUNNING [= configuredState ]
acls = SUBMIT_APP:*ADMINISTER_QUEUE:* [= configuredAcls ]
nodeLocalityDelay = 40
labels=*,
nodeLocalityDelay = 40
reservationsContinueLooking = true
preemptionDisabled = true

2016-03-19 19:55:29,933 INFO org.apache.hadoop.yarn.server.resourcemanager.scheduler.capacity.CapacityScheduler: Initialized queue: default: capacity=1.0, absoluteCapacity=1.0, usedResources=<memory:0, vCores:0>, usedCapacity=0.0, absoluteUsedCapacity=0.0, numApps=0, numContainers=0
2016-03-19 19:55:29,933 INFO org.apache.hadoop.yarn.server.resourcemanager.scheduler.capacity.CapacityScheduler: Initialized queue: root: numChildQueue= 1, capacity=1.0, absoluteCapacity=1.0, usedResources=<memory:0, vCores:0>usedCapacity=0.0, numApps=0, numContainers=0
2016-03-19 19:55:29,933 INFO org.apache.hadoop.yarn.server.resourcemanager.scheduler.capacity.CapacityScheduler: Initialized root queue root: numChildQueue= 1, capacity=1.0, absoluteCapacity=1.0, usedResources=<memory:0, vCores:0>usedCapacity=0.0, numApps=0, numContainers=0
2016-03-19 19:55:29,933 INFO org.apache.hadoop.yarn.server.resourcemanager.scheduler.capacity.CapacityScheduler: Initialized queue mappings, override: false
2016-03-19 19:55:29,940 INFO org.apache.hadoop.yarn.server.resourcemanager.scheduler.capacity.CapacityScheduler: Initialized CapacityScheduler with calculator=class org.apache.hadoop.yarn.util.resource.DefaultResourceCalculator, minimumAllocation=<<memory:1024, vCores:1>>, maximumAllocation=<<memory:8192, vCores:32>>, asynchronousScheduling=false, asyncScheduleInterval=5ms
2016-03-19 19:55:29,945 INFO org.apache.hadoop.service.AbstractService: Service ResourceManager failed in state STARTED; cause: org.apache.hadoop.yarn.exceptions.YarnRuntimeException: java.net.BindException: Problem binding to [0.0.0.0:8031] java.net.BindException: Address already in use; For more details see:  http://wiki.apache.org/hadoop/BindException
org.apache.hadoop.yarn.exceptions.YarnRuntimeException: java.net.BindException: Problem binding to [0.0.0.0:8031] java.net.BindException: Address already in use; For more details see:  http://wiki.apache.org/hadoop/BindException
	at org.apache.hadoop.yarn.factories.impl.pb.RpcServerFactoryPBImpl.getServer(RpcServerFactoryPBImpl.java:139)
	at org.apache.hadoop.yarn.ipc.HadoopYarnProtoRPC.getServer(HadoopYarnProtoRPC.java:65)
	at org.apache.hadoop.yarn.ipc.YarnRPC.getServer(YarnRPC.java:54)
	at org.apache.hadoop.yarn.server.resourcemanager.ResourceTrackerService.serviceStart(ResourceTrackerService.java:162)
	at org.apache.hadoop.service.AbstractService.start(AbstractService.java:193)
	at org.apache.hadoop.service.CompositeService.serviceStart(CompositeService.java:120)
	at org.apache.hadoop.yarn.server.resourcemanager.ResourceManager$RMActiveServices.serviceStart(ResourceManager.java:579)
	at org.apache.hadoop.service.AbstractService.start(AbstractService.java:193)
	at org.apache.hadoop.yarn.server.resourcemanager.ResourceManager.startActiveServices(ResourceManager.java:964)
	at org.apache.hadoop.yarn.server.resourcemanager.ResourceManager$1.run(ResourceManager.java:1005)
	at org.apache.hadoop.yarn.server.resourcemanager.ResourceManager$1.run(ResourceManager.java:1001)
	at java.security.AccessController.doPrivileged(Native Method)
	at javax.security.auth.Subject.doAs(Subject.java:422)
	at org.apache.hadoop.security.UserGroupInformation.doAs(UserGroupInformation.java:1657)
	at org.apache.hadoop.yarn.server.resourcemanager.ResourceManager.transitionToActive(ResourceManager.java:1001)
	at org.apache.hadoop.yarn.server.resourcemanager.ResourceManager.serviceStart(ResourceManager.java:1041)
	at org.apache.hadoop.service.AbstractService.start(AbstractService.java:193)
	at org.apache.hadoop.yarn.server.resourcemanager.ResourceManager.main(ResourceManager.java:1178)
Caused by: java.net.BindException: Problem binding to [0.0.0.0:8031] java.net.BindException: Address already in use; For more details see:  http://wiki.apache.org/hadoop/BindException
	at sun.reflect.NativeConstructorAccessorImpl.newInstance0(Native Method)
	at sun.reflect.NativeConstructorAccessorImpl.newInstance(NativeConstructorAccessorImpl.java:62)
	at sun.reflect.DelegatingConstructorAccessorImpl.newInstance(DelegatingConstructorAccessorImpl.java:45)
	at java.lang.reflect.Constructor.newInstance(Constructor.java:423)
	at org.apache.hadoop.net.NetUtils.wrapWithMessage(NetUtils.java:792)
	at org.apache.hadoop.net.NetUtils.wrapException(NetUtils.java:721)
	at org.apache.hadoop.ipc.Server.bind(Server.java:425)
	at org.apache.hadoop.ipc.Server$Listener.<init>(Server.java:574)
	at org.apache.hadoop.ipc.Server.<init>(Server.java:2215)
	at org.apache.hadoop.ipc.RPC$Server.<init>(RPC.java:938)
	at org.apache.hadoop.ipc.ProtobufRpcEngine$Server.<init>(ProtobufRpcEngine.java:534)
	at org.apache.hadoop.ipc.ProtobufRpcEngine.getServer(ProtobufRpcEngine.java:509)
	at org.apache.hadoop.ipc.RPC$Builder.build(RPC.java:783)
	at org.apache.hadoop.yarn.factories.impl.pb.RpcServerFactoryPBImpl.createServer(RpcServerFactoryPBImpl.java:169)
	at org.apache.hadoop.yarn.factories.impl.pb.RpcServerFactoryPBImpl.getServer(RpcServerFactoryPBImpl.java:132)
	... 17 more
Caused by: java.net.BindException: Address already in use
	at sun.nio.ch.Net.bind0(Native Method)
	at sun.nio.ch.Net.bind(Net.java:433)
	at sun.nio.ch.Net.bind(Net.java:425)
	at sun.nio.ch.ServerSocketChannelImpl.bind(ServerSocketChannelImpl.java:223)
	at sun.nio.ch.ServerSocketAdaptor.bind(ServerSocketAdaptor.java:74)
	at org.apache.hadoop.ipc.Server.bind(Server.java:408)
	... 25 more
2016-03-19 19:55:29,953 INFO org.apache.hadoop.yarn.server.resourcemanager.ResourceManager: Transitioning to standby state
2016-03-19 19:55:29,953 INFO org.apache.hadoop.yarn.server.resourcemanager.ResourceManager: Transitioned to standby state
2016-03-19 19:55:29,953 FATAL org.apache.hadoop.yarn.server.resourcemanager.ResourceManager: Error starting ResourceManager
org.apache.hadoop.yarn.exceptions.YarnRuntimeException: java.net.BindException: Problem binding to [0.0.0.0:8031] java.net.BindException: Address already in use; For more details see:  http://wiki.apache.org/hadoop/BindException
	at org.apache.hadoop.yarn.factories.impl.pb.RpcServerFactoryPBImpl.getServer(RpcServerFactoryPBImpl.java:139)
	at org.apache.hadoop.yarn.ipc.HadoopYarnProtoRPC.getServer(HadoopYarnProtoRPC.java:65)
	at org.apache.hadoop.yarn.ipc.YarnRPC.getServer(YarnRPC.java:54)
	at org.apache.hadoop.yarn.server.resourcemanager.ResourceTrackerService.serviceStart(ResourceTrackerService.java:162)
	at org.apache.hadoop.service.AbstractService.start(AbstractService.java:193)
	at org.apache.hadoop.service.CompositeService.serviceStart(CompositeService.java:120)
	at org.apache.hadoop.yarn.server.resourcemanager.ResourceManager$RMActiveServices.serviceStart(ResourceManager.java:579)
	at org.apache.hadoop.service.AbstractService.start(AbstractService.java:193)
	at org.apache.hadoop.yarn.server.resourcemanager.ResourceManager.startActiveServices(ResourceManager.java:964)
	at org.apache.hadoop.yarn.server.resourcemanager.ResourceManager$1.run(ResourceManager.java:1005)
	at org.apache.hadoop.yarn.server.resourcemanager.ResourceManager$1.run(ResourceManager.java:1001)
	at java.security.AccessController.doPrivileged(Native Method)
	at javax.security.auth.Subject.doAs(Subject.java:422)
	at org.apache.hadoop.security.UserGroupInformation.doAs(UserGroupInformation.java:1657)
	at org.apache.hadoop.yarn.server.resourcemanager.ResourceManager.transitionToActive(ResourceManager.java:1001)
	at org.apache.hadoop.yarn.server.resourcemanager.ResourceManager.serviceStart(ResourceManager.java:1041)
	at org.apache.hadoop.service.AbstractService.start(AbstractService.java:193)
	at org.apache.hadoop.yarn.server.resourcemanager.ResourceManager.main(ResourceManager.java:1178)
Caused by: java.net.BindException: Problem binding to [0.0.0.0:8031] java.net.BindException: Address already in use; For more details see:  http://wiki.apache.org/hadoop/BindException
	at sun.reflect.NativeConstructorAccessorImpl.newInstance0(Native Method)
	at sun.reflect.NativeConstructorAccessorImpl.newInstance(NativeConstructorAccessorImpl.java:62)
	at sun.reflect.DelegatingConstructorAccessorImpl.newInstance(DelegatingConstructorAccessorImpl.java:45)
	at java.lang.reflect.Constructor.newInstance(Constructor.java:423)
	at org.apache.hadoop.net.NetUtils.wrapWithMessage(NetUtils.java:792)
	at org.apache.hadoop.net.NetUtils.wrapException(NetUtils.java:721)
	at org.apache.hadoop.ipc.Server.bind(Server.java:425)
	at org.apache.hadoop.ipc.Server$Listener.<init>(Server.java:574)
	at org.apache.hadoop.ipc.Server.<init>(Server.java:2215)
	at org.apache.hadoop.ipc.RPC$Server.<init>(RPC.java:938)
	at org.apache.hadoop.ipc.ProtobufRpcEngine$Server.<init>(ProtobufRpcEngine.java:534)
	at org.apache.hadoop.ipc.ProtobufRpcEngine.getServer(ProtobufRpcEngine.java:509)
	at org.apache.hadoop.ipc.RPC$Builder.build(RPC.java:783)
	at org.apache.hadoop.yarn.factories.impl.pb.RpcServerFactoryPBImpl.createServer(RpcServerFactoryPBImpl.java:169)
	at org.apache.hadoop.yarn.factories.impl.pb.RpcServerFactoryPBImpl.getServer(RpcServerFactoryPBImpl.java:132)
	... 17 more
Caused by: java.net.BindException: Address already in use
	at sun.nio.ch.Net.bind0(Native Method)
	at sun.nio.ch.Net.bind(Net.java:433)
	at sun.nio.ch.Net.bind(Net.java:425)
	at sun.nio.ch.ServerSocketChannelImpl.bind(ServerSocketChannelImpl.java:223)
	at sun.nio.ch.ServerSocketAdaptor.bind(ServerSocketAdaptor.java:74)
	at org.apache.hadoop.ipc.Server.bind(Server.java:408)
	... 25 more
2016-03-19 19:55:29,956 INFO org.apache.hadoop.yarn.server.resourcemanager.ResourceManager: SHUTDOWN_MSG: 
/************************************************************
SHUTDOWN_MSG: Shutting down ResourceManager at vishal-VirtualBox/127.0.1.1
************************************************************/
2016-03-19 19:56:32,319 INFO org.apache.hadoop.yarn.server.resourcemanager.ResourceManager: STARTUP_MSG: 
/************************************************************
STARTUP_MSG: Starting ResourceManager
STARTUP_MSG:   host = vishal-VirtualBox/127.0.1.1
STARTUP_MSG:   args = []
STARTUP_MSG:   version = 2.7.2
STARTUP_MSG:   build = https://git-wip-us.apache.org/repos/asf/hadoop.git -r b165c4fe8a74265c792ce23f546c64604acf0e41; compiled by 'jenkins' on 2016-01-26T00:08Z
STARTUP_MSG:   java = 1.8.0_74
************************************************************/
2016-03-19 19:56:32,353 INFO org.apache.hadoop.yarn.server.resourcemanager.ResourceManager: registered UNIX signal handlers for [TERM, HUP, INT]
2016-03-19 19:56:33,838 INFO org.apache.hadoop.conf.Configuration: found resource core-site.xml at file:/usr/local/hadoop/etc/hadoop/core-site.xml
2016-03-19 19:56:34,238 WARN org.apache.hadoop.util.NativeCodeLoader: Unable to load native-hadoop library for your platform... using builtin-java classes where applicable
2016-03-19 19:56:34,358 INFO org.apache.hadoop.security.Groups: clearing userToGroupsMap cache
2016-03-19 19:56:34,758 INFO org.apache.hadoop.conf.Configuration: found resource yarn-site.xml at file:/usr/local/hadoop/etc/hadoop/yarn-site.xml
2016-03-19 19:56:35,946 INFO org.apache.hadoop.yarn.event.AsyncDispatcher: Registering class org.apache.hadoop.yarn.server.resourcemanager.RMFatalEventType for class org.apache.hadoop.yarn.server.resourcemanager.ResourceManager$RMFatalEventDispatcher
2016-03-19 19:56:37,177 INFO org.apache.hadoop.yarn.server.resourcemanager.security.NMTokenSecretManagerInRM: NMTokenKeyRollingInterval: 86400000ms and NMTokenKeyActivationDelay: 900000ms
2016-03-19 19:56:37,224 INFO org.apache.hadoop.yarn.server.resourcemanager.security.RMContainerTokenSecretManager: ContainerTokenKeyRollingInterval: 86400000ms and ContainerTokenKeyActivationDelay: 900000ms
2016-03-19 19:56:37,278 INFO org.apache.hadoop.yarn.server.resourcemanager.security.AMRMTokenSecretManager: AMRMTokenKeyRollingInterval: 86400000ms and AMRMTokenKeyActivationDelay: 900000 ms
2016-03-19 19:56:37,599 INFO org.apache.hadoop.yarn.event.AsyncDispatcher: Registering class org.apache.hadoop.yarn.server.resourcemanager.recovery.RMStateStoreEventType for class org.apache.hadoop.yarn.server.resourcemanager.recovery.RMStateStore$ForwardingEventHandler
2016-03-19 19:56:37,606 INFO org.apache.hadoop.yarn.event.AsyncDispatcher: Registering class org.apache.hadoop.yarn.server.resourcemanager.NodesListManagerEventType for class org.apache.hadoop.yarn.server.resourcemanager.NodesListManager
2016-03-19 19:56:37,606 INFO org.apache.hadoop.yarn.server.resourcemanager.ResourceManager: Using Scheduler: org.apache.hadoop.yarn.server.resourcemanager.scheduler.capacity.CapacityScheduler
2016-03-19 19:56:37,956 INFO org.apache.hadoop.yarn.event.AsyncDispatcher: Registering class org.apache.hadoop.yarn.server.resourcemanager.scheduler.event.SchedulerEventType for class org.apache.hadoop.yarn.server.resourcemanager.ResourceManager$SchedulerEventDispatcher
2016-03-19 19:56:37,958 INFO org.apache.hadoop.yarn.event.AsyncDispatcher: Registering class org.apache.hadoop.yarn.server.resourcemanager.rmapp.RMAppEventType for class org.apache.hadoop.yarn.server.resourcemanager.ResourceManager$ApplicationEventDispatcher
2016-03-19 19:56:37,959 INFO org.apache.hadoop.yarn.event.AsyncDispatcher: Registering class org.apache.hadoop.yarn.server.resourcemanager.rmapp.attempt.RMAppAttemptEventType for class org.apache.hadoop.yarn.server.resourcemanager.ResourceManager$ApplicationAttemptEventDispatcher
2016-03-19 19:56:37,960 INFO org.apache.hadoop.yarn.event.AsyncDispatcher: Registering class org.apache.hadoop.yarn.server.resourcemanager.rmnode.RMNodeEventType for class org.apache.hadoop.yarn.server.resourcemanager.ResourceManager$NodeEventDispatcher
2016-03-19 19:56:38,521 INFO org.apache.hadoop.metrics2.impl.MetricsConfig: loaded properties from hadoop-metrics2.properties
2016-03-19 19:56:38,861 INFO org.apache.hadoop.metrics2.impl.MetricsSystemImpl: Scheduled snapshot period at 10 second(s).
2016-03-19 19:56:38,861 INFO org.apache.hadoop.metrics2.impl.MetricsSystemImpl: ResourceManager metrics system started
2016-03-19 19:56:38,937 INFO org.apache.hadoop.yarn.event.AsyncDispatcher: Registering class org.apache.hadoop.yarn.server.resourcemanager.RMAppManagerEventType for class org.apache.hadoop.yarn.server.resourcemanager.RMAppManager
2016-03-19 19:56:38,959 INFO org.apache.hadoop.yarn.event.AsyncDispatcher: Registering class org.apache.hadoop.yarn.server.resourcemanager.amlauncher.AMLauncherEventType for class org.apache.hadoop.yarn.server.resourcemanager.amlauncher.ApplicationMasterLauncher
2016-03-19 19:56:38,963 INFO org.apache.hadoop.yarn.server.resourcemanager.RMNMInfo: Registered RMNMInfo MBean
2016-03-19 19:56:38,966 INFO org.apache.hadoop.yarn.security.YarnAuthorizationProvider: org.apache.hadoop.yarn.security.ConfiguredYarnAuthorizer is instiantiated.
2016-03-19 19:56:38,968 INFO org.apache.hadoop.util.HostsFileReader: Refreshing hosts (include/exclude) list
2016-03-19 19:56:39,005 INFO org.apache.hadoop.conf.Configuration: found resource capacity-scheduler.xml at file:/usr/local/hadoop/etc/hadoop/capacity-scheduler.xml
2016-03-19 19:56:39,259 INFO org.apache.hadoop.yarn.server.resourcemanager.scheduler.capacity.CapacitySchedulerConfiguration: max alloc mb per queue for root is undefined
2016-03-19 19:56:39,259 INFO org.apache.hadoop.yarn.server.resourcemanager.scheduler.capacity.CapacitySchedulerConfiguration: max alloc vcore per queue for root is undefined
2016-03-19 19:56:39,264 INFO org.apache.hadoop.yarn.server.resourcemanager.scheduler.capacity.ParentQueue: root, capacity=1.0, asboluteCapacity=1.0, maxCapacity=1.0, asboluteMaxCapacity=1.0, state=RUNNING, acls=SUBMIT_APP:*ADMINISTER_QUEUE:*, labels=*,
, reservationsContinueLooking=true
2016-03-19 19:56:39,264 INFO org.apache.hadoop.yarn.server.resourcemanager.scheduler.capacity.ParentQueue: Initialized parent-queue root name=root, fullname=root
2016-03-19 19:56:39,301 INFO org.apache.hadoop.yarn.server.resourcemanager.scheduler.capacity.CapacitySchedulerConfiguration: max alloc mb per queue for root.default is undefined
2016-03-19 19:56:39,301 INFO org.apache.hadoop.yarn.server.resourcemanager.scheduler.capacity.CapacitySchedulerConfiguration: max alloc vcore per queue for root.default is undefined
2016-03-19 19:56:39,302 INFO org.apache.hadoop.yarn.server.resourcemanager.scheduler.capacity.LeafQueue: Initializing default
capacity = 1.0 [= (float) configuredCapacity / 100 ]
asboluteCapacity = 1.0 [= parentAbsoluteCapacity * capacity ]
maxCapacity = 1.0 [= configuredMaxCapacity ]
absoluteMaxCapacity = 1.0 [= 1.0 maximumCapacity undefined, (parentAbsoluteMaxCapacity * maximumCapacity) / 100 otherwise ]
userLimit = 100 [= configuredUserLimit ]
userLimitFactor = 1.0 [= configuredUserLimitFactor ]
maxApplications = 10000 [= configuredMaximumSystemApplicationsPerQueue or (int)(configuredMaximumSystemApplications * absoluteCapacity)]
maxApplicationsPerUser = 10000 [= (int)(maxApplications * (userLimit / 100.0f) * userLimitFactor) ]
usedCapacity = 0.0 [= usedResourcesMemory / (clusterResourceMemory * absoluteCapacity)]
absoluteUsedCapacity = 0.0 [= usedResourcesMemory / clusterResourceMemory]
maxAMResourcePerQueuePercent = 0.1 [= configuredMaximumAMResourcePercent ]
minimumAllocationFactor = 0.875 [= (float)(maximumAllocationMemory - minimumAllocationMemory) / maximumAllocationMemory ]
maximumAllocation = <memory:8192, vCores:32> [= configuredMaxAllocation ]
numContainers = 0 [= currentNumContainers ]
state = RUNNING [= configuredState ]
acls = SUBMIT_APP:*ADMINISTER_QUEUE:* [= configuredAcls ]
nodeLocalityDelay = 40
labels=*,
nodeLocalityDelay = 40
reservationsContinueLooking = true
preemptionDisabled = true

2016-03-19 19:56:39,303 INFO org.apache.hadoop.yarn.server.resourcemanager.scheduler.capacity.CapacityScheduler: Initialized queue: default: capacity=1.0, absoluteCapacity=1.0, usedResources=<memory:0, vCores:0>, usedCapacity=0.0, absoluteUsedCapacity=0.0, numApps=0, numContainers=0
2016-03-19 19:56:39,303 INFO org.apache.hadoop.yarn.server.resourcemanager.scheduler.capacity.CapacityScheduler: Initialized queue: root: numChildQueue= 1, capacity=1.0, absoluteCapacity=1.0, usedResources=<memory:0, vCores:0>usedCapacity=0.0, numApps=0, numContainers=0
2016-03-19 19:56:39,304 INFO org.apache.hadoop.yarn.server.resourcemanager.scheduler.capacity.CapacityScheduler: Initialized root queue root: numChildQueue= 1, capacity=1.0, absoluteCapacity=1.0, usedResources=<memory:0, vCores:0>usedCapacity=0.0, numApps=0, numContainers=0
2016-03-19 19:56:39,304 INFO org.apache.hadoop.yarn.server.resourcemanager.scheduler.capacity.CapacityScheduler: Initialized queue mappings, override: false
2016-03-19 19:56:39,304 INFO org.apache.hadoop.yarn.server.resourcemanager.scheduler.capacity.CapacityScheduler: Initialized CapacityScheduler with calculator=class org.apache.hadoop.yarn.util.resource.DefaultResourceCalculator, minimumAllocation=<<memory:1024, vCores:1>>, maximumAllocation=<<memory:8192, vCores:32>>, asynchronousScheduling=false, asyncScheduleInterval=5ms
2016-03-19 19:56:39,360 INFO org.apache.hadoop.yarn.server.resourcemanager.metrics.SystemMetricsPublisher: YARN system metrics publishing service is not enabled
2016-03-19 19:56:39,360 INFO org.apache.hadoop.yarn.server.resourcemanager.ResourceManager: Transitioning to active state
2016-03-19 19:56:39,413 INFO org.apache.hadoop.yarn.server.resourcemanager.recovery.RMStateStore: Updating AMRMToken
2016-03-19 19:56:39,414 INFO org.apache.hadoop.yarn.server.resourcemanager.security.RMContainerTokenSecretManager: Rolling master-key for container-tokens
2016-03-19 19:56:39,414 INFO org.apache.hadoop.yarn.server.resourcemanager.security.NMTokenSecretManagerInRM: Rolling master-key for nm-tokens
2016-03-19 19:56:39,414 INFO org.apache.hadoop.security.token.delegation.AbstractDelegationTokenSecretManager: Updating the current master key for generating delegation tokens
2016-03-19 19:56:39,416 INFO org.apache.hadoop.yarn.server.resourcemanager.security.RMDelegationTokenSecretManager: storing master key with keyID 1
2016-03-19 19:56:39,419 INFO org.apache.hadoop.yarn.server.resourcemanager.recovery.RMStateStore: Storing RMDTMasterKey.
2016-03-19 19:56:39,428 INFO org.apache.hadoop.security.token.delegation.AbstractDelegationTokenSecretManager: Starting expired delegation token remover thread, tokenRemoverScanInterval=60 min(s)
2016-03-19 19:56:39,437 INFO org.apache.hadoop.yarn.event.AsyncDispatcher: Registering class org.apache.hadoop.yarn.nodelabels.event.NodeLabelsStoreEventType for class org.apache.hadoop.yarn.nodelabels.CommonNodeLabelsManager$ForwardingEventHandler
2016-03-19 19:56:39,459 INFO org.apache.hadoop.security.token.delegation.AbstractDelegationTokenSecretManager: Updating the current master key for generating delegation tokens
2016-03-19 19:56:39,459 INFO org.apache.hadoop.yarn.server.resourcemanager.security.RMDelegationTokenSecretManager: storing master key with keyID 2
2016-03-19 19:56:39,460 INFO org.apache.hadoop.yarn.server.resourcemanager.recovery.RMStateStore: Storing RMDTMasterKey.
2016-03-19 19:56:40,830 INFO org.apache.hadoop.ipc.CallQueueManager: Using callQueue class java.util.concurrent.LinkedBlockingQueue
2016-03-19 19:56:40,919 INFO org.apache.hadoop.service.AbstractService: Service org.apache.hadoop.yarn.server.resourcemanager.ResourceTrackerService failed in state STARTED; cause: org.apache.hadoop.yarn.exceptions.YarnRuntimeException: java.net.BindException: Problem binding to [0.0.0.0:8031] java.net.BindException: Address already in use; For more details see:  http://wiki.apache.org/hadoop/BindException
org.apache.hadoop.yarn.exceptions.YarnRuntimeException: java.net.BindException: Problem binding to [0.0.0.0:8031] java.net.BindException: Address already in use; For more details see:  http://wiki.apache.org/hadoop/BindException
	at org.apache.hadoop.yarn.factories.impl.pb.RpcServerFactoryPBImpl.getServer(RpcServerFactoryPBImpl.java:139)
	at org.apache.hadoop.yarn.ipc.HadoopYarnProtoRPC.getServer(HadoopYarnProtoRPC.java:65)
	at org.apache.hadoop.yarn.ipc.YarnRPC.getServer(YarnRPC.java:54)
	at org.apache.hadoop.yarn.server.resourcemanager.ResourceTrackerService.serviceStart(ResourceTrackerService.java:162)
	at org.apache.hadoop.service.AbstractService.start(AbstractService.java:193)
	at org.apache.hadoop.service.CompositeService.serviceStart(CompositeService.java:120)
	at org.apache.hadoop.yarn.server.resourcemanager.ResourceManager$RMActiveServices.serviceStart(ResourceManager.java:579)
	at org.apache.hadoop.service.AbstractService.start(AbstractService.java:193)
	at org.apache.hadoop.yarn.server.resourcemanager.ResourceManager.startActiveServices(ResourceManager.java:964)
	at org.apache.hadoop.yarn.server.resourcemanager.ResourceManager$1.run(ResourceManager.java:1005)
	at org.apache.hadoop.yarn.server.resourcemanager.ResourceManager$1.run(ResourceManager.java:1001)
	at java.security.AccessController.doPrivileged(Native Method)
	at javax.security.auth.Subject.doAs(Subject.java:422)
	at org.apache.hadoop.security.UserGroupInformation.doAs(UserGroupInformation.java:1657)
	at org.apache.hadoop.yarn.server.resourcemanager.ResourceManager.transitionToActive(ResourceManager.java:1001)
	at org.apache.hadoop.yarn.server.resourcemanager.ResourceManager.serviceStart(ResourceManager.java:1041)
	at org.apache.hadoop.service.AbstractService.start(AbstractService.java:193)
	at org.apache.hadoop.yarn.server.resourcemanager.ResourceManager.main(ResourceManager.java:1178)
Caused by: java.net.BindException: Problem binding to [0.0.0.0:8031] java.net.BindException: Address already in use; For more details see:  http://wiki.apache.org/hadoop/BindException
	at sun.reflect.NativeConstructorAccessorImpl.newInstance0(Native Method)
	at sun.reflect.NativeConstructorAccessorImpl.newInstance(NativeConstructorAccessorImpl.java:62)
	at sun.reflect.DelegatingConstructorAccessorImpl.newInstance(DelegatingConstructorAccessorImpl.java:45)
	at java.lang.reflect.Constructor.newInstance(Constructor.java:423)
	at org.apache.hadoop.net.NetUtils.wrapWithMessage(NetUtils.java:792)
	at org.apache.hadoop.net.NetUtils.wrapException(NetUtils.java:721)
	at org.apache.hadoop.ipc.Server.bind(Server.java:425)
	at org.apache.hadoop.ipc.Server$Listener.<init>(Server.java:574)
	at org.apache.hadoop.ipc.Server.<init>(Server.java:2215)
	at org.apache.hadoop.ipc.RPC$Server.<init>(RPC.java:938)
	at org.apache.hadoop.ipc.ProtobufRpcEngine$Server.<init>(ProtobufRpcEngine.java:534)
	at org.apache.hadoop.ipc.ProtobufRpcEngine.getServer(ProtobufRpcEngine.java:509)
	at org.apache.hadoop.ipc.RPC$Builder.build(RPC.java:783)
